<robot name="onshape">
<link name="base">
<visual>
<origin xyz="-0.097390323626990391026 0.038328615593456176469 0.17660355737195296277" rpy="1.2500305778179556294e-16 0.040591453589793408119 -5.8064861387571024253e-16" />
<geometry>
<mesh filename="package:///base_motores_torso.stl"/>
</geometry>
<material name="base_motores_torso_material">
<color rgba="0.97254901960784312376 0.97254901960784312376 0.97254901960784312376 1.0"/>
</material>
</visual>
<collision>
<origin xyz="-0.097390323626990391026 0.038328615593456176469 0.17660355737195296277" rpy="1.2500305778179556294e-16 0.040591453589793408119 -5.8064861387571024253e-16" />
<geometry>
<mesh filename="package:///base_motores_torso.stl"/>
</geometry>
</collision>
<visual>
<origin xyz="-0.096560456335594874178 0.02275361559345624729 0.19703671229914565544" rpy="3.141592653589793116 -0.040591453589793415058 3.1415926535897926719" />
<geometry>
<mesh filename="package:///motor_semieje.stl"/>
</geometry>
<material name="motor_semieje_material">
<color rgba="0.64705882352941179736 0.64705882352941179736 0.64705882352941179736 1.0"/>
</material>
</visual>
<collision>
<origin xyz="-0.096560456335594874178 0.02275361559345624729 0.19703671229914565544" rpy="3.141592653589793116 -0.040591453589793415058 3.1415926535897926719" />
<geometry>
<mesh filename="package:///motor_semieje.stl"/>
</geometry>
</collision>
<visual>
<origin xyz="-0.096560456335594874178 0.02275361559345624729 0.19703671229914565544" rpy="3.141592653589793116 -0.040591453589793415058 3.1415926535897926719" />
<geometry>
<mesh filename="package:///motor_caja_semieje.stl"/>
</geometry>
<material name="motor_caja_semieje_material">
<color rgba="0.26274509803921569651 0.28235294117647058432 0.30196078431372547213 1.0"/>
</material>
</visual>
<collision>
<origin xyz="-0.096560456335594874178 0.02275361559345624729 0.19703671229914565544" rpy="3.141592653589793116 -0.040591453589793415058 3.1415926535897926719" />
<geometry>
<mesh filename="package:///motor_caja_semieje.stl"/>
</geometry>
</collision>
<visual>
<origin xyz="-0.066585167933845640365 0.022753615593456094635 0.19581930306971487288" rpy="3.141592653589793116 -0.040591453589792783618 3.1415926535897926719" />
<geometry>
<mesh filename="package:///motor_semieje.stl"/>
</geometry>
<material name="motor_semieje_material">
<color rgba="0.64705882352941179736 0.64705882352941179736 0.64705882352941179736 1.0"/>
</material>
</visual>
<collision>
<origin xyz="-0.066585167933845640365 0.022753615593456094635 0.19581930306971487288" rpy="3.141592653589793116 -0.040591453589792783618 3.1415926535897926719" />
<geometry>
<mesh filename="package:///motor_semieje.stl"/>
</geometry>
</collision>
<visual>
<origin xyz="-0.066585167933845640365 0.022753615593456094635 0.19581930306971487288" rpy="3.141592653589793116 -0.040591453589792783618 3.1415926535897926719" />
<geometry>
<mesh filename="package:///motor_caja_semieje.stl"/>
</geometry>
<material name="motor_caja_semieje_material">
<color rgba="0.26274509803921569651 0.28235294117647058432 0.30196078431372547213 1.0"/>
</material>
</visual>
<collision>
<origin xyz="-0.066585167933845640365 0.022753615593456094635 0.19581930306971487288" rpy="3.141592653589793116 -0.040591453589792783618 3.1415926535897926719" />
<geometry>
<mesh filename="package:///motor_caja_semieje.stl"/>
</geometry>
</collision>
<inertial>
<origin xyz="-0.081714154120115220503 0.030821333526022225147 0.19294785764690308705" rpy="0 0 0"/>
<mass value="0.55195805430744515618" />
<inertia ixx="0.00017925270825867140826" ixy="-6.7259210188834206998e-07"  ixz="3.824308151081946613e-06" iyy="0.00026073062357070405726" iyz="-1.6560694418488183604e-05" izz="0.00027326025276898065555" />
</inertial>
</link>

<link name="cintura_urdf">
<visual>
<origin xyz="-3.4694469519536141888e-18 -1.3877787807814456755e-17 -0.0020000000000000295319" rpy="3.141592653589793116 1.1240060740302143842e-32 -1.9653543675519863304e-32" />
<geometry>
<mesh filename="package:///center.stl"/>
</geometry>
<material name="center_material">
<color rgba="0.97254901960784312376 0.97254901960784312376 0.97254901960784312376 1.0"/>
</material>
</visual>
<collision>
<origin xyz="-3.4694469519536141888e-18 -1.3877787807814456755e-17 -0.0020000000000000295319" rpy="3.141592653589793116 1.1240060740302143842e-32 -1.9653543675519863304e-32" />
<geometry>
<mesh filename="package:///center.stl"/>
</geometry>
</collision>
<visual>
<origin xyz="0.00010000000000003061995 -6.9388939039072283776e-17 -0.0019750000000000600409" rpy="3.141592653589793116 -9.844558427537932224e-18 -5.121108743491018871e-16" />
<geometry>
<mesh filename="package:///side1.stl"/>
</geometry>
<material name="side1_material">
<color rgba="0.97254901960784312376 0.97254901960784312376 0.97254901960784312376 1.0"/>
</material>
</visual>
<collision>
<origin xyz="0.00010000000000003061995 -6.9388939039072283776e-17 -0.0019750000000000600409" rpy="3.141592653589793116 -9.844558427537932224e-18 -5.121108743491018871e-16" />
<geometry>
<mesh filename="package:///side1.stl"/>
</geometry>
</collision>
<visual>
<origin xyz="-0.00010000000000003061995 -2.7755575615628913511e-17 -0.0019750000000000045297" rpy="3.141592653589793116 1.5755504409386438617e-18 -5.7290602484837156692e-16" />
<geometry>
<mesh filename="package:///side2.stl"/>
</geometry>
<material name="side2_material">
<color rgba="0.97254901960784312376 0.97254901960784312376 0.97254901960784312376 1.0"/>
</material>
</visual>
<collision>
<origin xyz="-0.00010000000000003061995 -2.7755575615628913511e-17 -0.0019750000000000045297" rpy="3.141592653589793116 1.5755504409386438617e-18 -5.7290602484837156692e-16" />
<geometry>
<mesh filename="package:///side2.stl"/>
</geometry>
</collision>
<inertial>
<origin xyz="-4.2269804094182249261e-17 0.011217027911029905235 -0.0083553945903650297944" rpy="0 0 0"/>
<mass value="0.032703197933895256089" />
<inertia ixx="6.2216210938664859417e-06" ixy="6.352747104407252543e-22"  ixz="-1.2917252445628080171e-20" iyy="1.6362334574865388444e-05" iyz="2.1094691425943477329e-06" izz="1.6739093605366168056e-05" />
</inertial>
</link>

<link name="cadera_v01">
<visual>
<origin xyz="0.010027549229570192901 0.0097859849723237746222 -0.023550000000007363654" rpy="-1.5707963267951718933 8.6145617299483448611e-13 1.5707963267945310726" />
<geometry>
<mesh filename="package:///cadera_pt2_2.stl"/>
</geometry>
<material name="cadera_pt2_2_material">
<color rgba="0.97254901960784312376 0.97254901960784312376 0.97254901960784312376 1.0"/>
</material>
</visual>
<collision>
<origin xyz="0.010027549229570192901 0.0097859849723237746222 -0.023550000000007363654" rpy="-1.5707963267951718933 8.6145617299483448611e-13 1.5707963267945310726" />
<geometry>
<mesh filename="package:///cadera_pt2_2.stl"/>
</geometry>
</collision>
<visual>
<origin xyz="0.010027549229570248412 0.0098109849723238551356 -0.023650000000007716933" rpy="-1.5707963267951718933 8.6010037948055803797e-13 1.5707963267945301844" />
<geometry>
<mesh filename="package:///cadera_pt3_1.stl"/>
</geometry>
<material name="cadera_pt3_1_material">
<color rgba="0.97254901960784312376 0.97254901960784312376 0.97254901960784312376 1.0"/>
</material>
</visual>
<collision>
<origin xyz="0.010027549229570248412 0.0098109849723238551356 -0.023650000000007716933" rpy="-1.5707963267951718933 8.6010037948055803797e-13 1.5707963267945301844" />
<geometry>
<mesh filename="package:///cadera_pt3_1.stl"/>
</geometry>
</collision>
<visual>
<origin xyz="0.010027549229569915346 0.0098109849723239106467 -0.023450000000007239359" rpy="-1.5707963267951718933 8.6145617299483448611e-13 1.5707963267945310726" />
<geometry>
<mesh filename="package:///cadera_pt3_2.stl"/>
</geometry>
<material name="cadera_pt3_2_material">
<color rgba="0.97254901960784312376 0.97254901960784312376 0.97254901960784312376 1.0"/>
</material>
</visual>
<collision>
<origin xyz="0.010027549229569915346 0.0098109849723239106467 -0.023450000000007239359" rpy="-1.5707963267951718933 8.6145617299483448611e-13 1.5707963267945310726" />
<geometry>
<mesh filename="package:///cadera_pt3_2.stl"/>
</geometry>
</collision>
<visual>
<origin xyz="1.3877787807814456755e-16 5.5511151231257827021e-17 -0.023399999999999979844" rpy="-5.5511151231257503588e-15 1.0547118733939020266e-14 -5.9259167940431713256e-15" />
<geometry>
<mesh filename="package:///motor_eje2.stl"/>
</geometry>
<material name="motor_eje2_material">
<color rgba="0.64705882352941179736 0.64705882352941179736 0.64705882352941179736 1.0"/>
</material>
</visual>
<collision>
<origin xyz="1.3877787807814456755e-16 5.5511151231257827021e-17 -0.023399999999999979844" rpy="-5.5511151231257503588e-15 1.0547118733939020266e-14 -5.9259167940431713256e-15" />
<geometry>
<mesh filename="package:///motor_eje2.stl"/>
</geometry>
</collision>
<visual>
<origin xyz="1.3877787807814456755e-16 5.5511151231257827021e-17 -0.023399999999999979844" rpy="-9.5479180117763778021e-15 3.8857805861880818125e-15 -2.5026341088581760543e-16" />
<geometry>
<mesh filename="package:///motor_caja.stl"/>
</geometry>
<material name="motor_caja_material">
<color rgba="0.26274509803921569651 0.28235294117647058432 0.30196078431372547213 1.0"/>
</material>
</visual>
<collision>
<origin xyz="1.3877787807814456755e-16 5.5511151231257827021e-17 -0.023399999999999979844" rpy="-9.5479180117763778021e-15 3.8857805861880818125e-15 -2.5026341088581760543e-16" />
<geometry>
<mesh filename="package:///motor_caja.stl"/>
</geometry>
</collision>
<visual>
<origin xyz="0.010027549229569665545 0.0094859849723236688845 -0.023550000000007061812" rpy="-1.5707963267951721154 8.6177013744264155857e-13 1.5707963267945315167" />
<geometry>
<mesh filename="package:///cadera_pt1.stl"/>
</geometry>
<material name="cadera_pt1_material">
<color rgba="0.97254901960784312376 0.97254901960784312376 0.97254901960784312376 1.0"/>
</material>
</visual>
<collision>
<origin xyz="0.010027549229569665545 0.0094859849723236688845 -0.023550000000007061812" rpy="-1.5707963267951721154 8.6177013744264155857e-13 1.5707963267945315167" />
<geometry>
<mesh filename="package:///cadera_pt1.stl"/>
</geometry>
</collision>
<visual>
<origin xyz="0.010027549229570442701 0.0091859849723233411023 -0.023550000000006655887" rpy="-1.5707963267951721154 8.6177013744264155857e-13 1.5707963267945315167" />
<geometry>
<mesh filename="package:///cadera_pt2_1.stl"/>
</geometry>
<material name="cadera_pt2_1_material">
<color rgba="0.97254901960784312376 0.97254901960784312376 0.97254901960784312376 1.0"/>
</material>
</visual>
<collision>
<origin xyz="0.010027549229570442701 0.0091859849723233411023 -0.023550000000006655887" rpy="-1.5707963267951721154 8.6177013744264155857e-13 1.5707963267945315167" />
<geometry>
<mesh filename="package:///cadera_pt2_1.stl"/>
</geometry>
</collision>
<visual>
<origin xyz="0 0 -0.023400000000000007599" rpy="-2.5137092408305766932e-32 2.7435931685710129479e-31 1.970344369064794984e-18" />
<geometry>
<mesh filename="package:///motor_eje1.stl"/>
</geometry>
<material name="motor_eje1_material">
<color rgba="0.64705882352941179736 0.64705882352941179736 0.64705882352941179736 1.0"/>
</material>
</visual>
<collision>
<origin xyz="0 0 -0.023400000000000007599" rpy="-2.5137092408305766932e-32 2.7435931685710129479e-31 1.970344369064794984e-18" />
<geometry>
<mesh filename="package:///motor_eje1.stl"/>
</geometry>
</collision>
<inertial>
<origin xyz="0.0019229001328409350401 0.010041085604013563065 -0.023445491658511334598" rpy="0 0 0"/>
<mass value="0.36033150614011227875" />
<inertia ixx="0.00013063858229427321566" ixy="-1.4491083149777602626e-07"  ixz="7.2430643630443469983e-08" iyy="7.1173611389549167462e-05" iyz="4.005034109119581299e-08" izz="0.0001025385050059183221" />
</inertial>
</link>

<link name="femur_v01">
<visual>
<origin xyz="-1.9220736113823022606e-15 -0.065000000000000029976 -0.023400000000001419664" rpy="3.1415926535897717997 2.6622623739633904262e-14 3.1415926535897629179" />
<geometry>
<mesh filename="package:///motor_acople.stl"/>
</geometry>
<material name="motor_acople_material">
<color rgba="0.26274509803921569651 0.28235294117647058432 0.30196078431372547213 1.0"/>
</material>
</visual>
<collision>
<origin xyz="-1.9220736113823022606e-15 -0.065000000000000029976 -0.023400000000001419664" rpy="3.1415926535897717997 2.6622623739633904262e-14 3.1415926535897629179" />
<geometry>
<mesh filename="package:///motor_acople.stl"/>
</geometry>
</collision>
<visual>
<origin xyz="-1.8526846723432299768e-15 -0.065000000000000057732 -0.023400000000001336398" rpy="3.1415926535897717997 2.6586855277712074551e-14 3.141592653589763362" />
<geometry>
<mesh filename="package:///motora_eje2.stl"/>
</geometry>
<material name="motora_eje2_material">
<color rgba="0.64705882352941179736 0.64705882352941179736 0.64705882352941179736 1.0"/>
</material>
</visual>
<collision>
<origin xyz="-1.8526846723432299768e-15 -0.065000000000000057732 -0.023400000000001336398" rpy="3.1415926535897717997 2.6586855277712074551e-14 3.141592653589763362" />
<geometry>
<mesh filename="package:///motora_eje2.stl"/>
</geometry>
</collision>
<visual>
<origin xyz="3.4694469519536141888e-18 0 -0.02340000000000000413" rpy="3.141592653589793116 1.154536694580337067e-15 2.6350576731110167418e-16" />
<geometry>
<mesh filename="package:///motora_eje1.stl"/>
</geometry>
<material name="motora_eje1_material">
<color rgba="0.64705882352941179736 0.64705882352941179736 0.64705882352941179736 1.0"/>
</material>
</visual>
<collision>
<origin xyz="3.4694469519536141888e-18 0 -0.02340000000000000413" rpy="3.141592653589793116 1.154536694580337067e-15 2.6350576731110167418e-16" />
<geometry>
<mesh filename="package:///motora_eje1.stl"/>
</geometry>
</collision>
<visual>
<origin xyz="-1.9220736113823022606e-15 -0.065000000000000029976 -0.023400000000001419664" rpy="3.1415926535897722438 2.7847926105572942964e-14 3.1415926535897638061" />
<geometry>
<mesh filename="package:///motora_eje1.stl"/>
</geometry>
<material name="motora_eje1_material">
<color rgba="0.64705882352941179736 0.64705882352941179736 0.64705882352941179736 1.0"/>
</material>
</visual>
<collision>
<origin xyz="-1.9220736113823022606e-15 -0.065000000000000029976 -0.023400000000001419664" rpy="3.1415926535897722438 2.7847926105572942964e-14 3.1415926535897638061" />
<geometry>
<mesh filename="package:///motora_eje1.stl"/>
</geometry>
</collision>
<visual>
<origin xyz="3.4694469519536141888e-18 0 -0.02340000000000000413" rpy="-3.1415926535897717997 -2.7662705348042428501e-14 -2.9443818970015320325e-14" />
<geometry>
<mesh filename="package:///motor_acople.stl"/>
</geometry>
<material name="motor_acople_material">
<color rgba="0.26274509803921569651 0.28235294117647058432 0.30196078431372547213 1.0"/>
</material>
</visual>
<collision>
<origin xyz="3.4694469519536141888e-18 0 -0.02340000000000000413" rpy="-3.1415926535897717997 -2.7662705348042428501e-14 -2.9443818970015320325e-14" />
<geometry>
<mesh filename="package:///motor_acople.stl"/>
</geometry>
</collision>
<visual>
<origin xyz="-1.9186041644303486464e-15 -0.04374590901660892206 -9.4368957093138305936e-16" rpy="2.246445911392900689e-14 -2.7344474954065802396e-14 -2.9055772874031650635e-14" />
<geometry>
<mesh filename="package:///femur.stl"/>
</geometry>
<material name="femur_material">
<color rgba="0.97254901960784312376 0.97254901960784312376 0.97254901960784312376 1.0"/>
</material>
</visual>
<collision>
<origin xyz="-1.9186041644303486464e-15 -0.04374590901660892206 -9.4368957093138305936e-16" rpy="2.246445911392900689e-14 -2.7344474954065802396e-14 -2.9055772874031650635e-14" />
<geometry>
<mesh filename="package:///femur.stl"/>
</geometry>
</collision>
<visual>
<origin xyz="3.4694469519536141888e-18 0 -0.02340000000000000413" rpy="-3.141592653589793116 6.891785296844401421e-20 1.1796039996651199157e-19" />
<geometry>
<mesh filename="package:///motora_eje2.stl"/>
</geometry>
<material name="motora_eje2_material">
<color rgba="0.64705882352941179736 0.64705882352941179736 0.64705882352941179736 1.0"/>
</material>
</visual>
<collision>
<origin xyz="3.4694469519536141888e-18 0 -0.02340000000000000413" rpy="-3.141592653589793116 6.891785296844401421e-20 1.1796039996651199157e-19" />
<geometry>
<mesh filename="package:///motora_eje2.stl"/>
</geometry>
</collision>
<visual>
<origin xyz="-5.6898930012039272697e-16 -0.043745909016607867348 -0.04880000000000092597" rpy="2.2628920823147399563e-14 -2.7411466625944367776e-14 -3.0157403084559983597e-14" />
<geometry>
<mesh filename="package:///femur.stl"/>
</geometry>
<material name="femur_material">
<color rgba="0.97254901960784312376 0.97254901960784312376 0.97254901960784312376 1.0"/>
</material>
</visual>
<collision>
<origin xyz="-5.6898930012039272697e-16 -0.043745909016607867348 -0.04880000000000092597" rpy="2.2628920823147399563e-14 -2.7411466625944367776e-14 -3.0157403084559983597e-14" />
<geometry>
<mesh filename="package:///femur.stl"/>
</geometry>
</collision>
<inertial>
<origin xyz="-9.5216049199536704419e-16 -0.032500000000000014988 -0.023400000000000711897" rpy="0 0 0"/>
<mass value="0.53868761965446410045" />
<inertia ixx="0.00043791203235393571071" ixy="-9.6656309875735016191e-18"  ixz="1.7275895083038411669e-18" iyy="0.00010909446328561619207" iyz="-5.751961635013817617e-18" izz="0.00036348717125268587176" />
</inertial>
</link>

<link name="tibiaurdf">
<visual>
<origin xyz="-3.4694469519536141888e-18 -0.033745909016608385822 -0.0020000000000000017764" rpy="2.6524286470787448719e-18 8.5903713337797448255e-20 1.0079209112458232351e-17" />
<geometry>
<mesh filename="package:///tibia.stl"/>
</geometry>
<material name="tibia_material">
<color rgba="0.97254901960784312376 0.97254901960784312376 0.97254901960784312376 1.0"/>
</material>
</visual>
<collision>
<origin xyz="-3.4694469519536141888e-18 -0.033745909016608385822 -0.0020000000000000017764" rpy="2.6524286470787448719e-18 8.5903713337797448255e-20 1.0079209112458232351e-17" />
<geometry>
<mesh filename="package:///tibia.stl"/>
</geometry>
</collision>
<visual>
<origin xyz="-3.4694469519536141888e-18 -0.055000000000000007216 0.023399999999999976374" rpy="3.1415926535897913396 -1.0423664039495509169e-15 3.1415926535897913396" />
<geometry>
<mesh filename="package:///motora_eje2.stl"/>
</geometry>
<material name="motora_eje2_material">
<color rgba="0.64705882352941179736 0.64705882352941179736 0.64705882352941179736 1.0"/>
</material>
</visual>
<collision>
<origin xyz="-3.4694469519536141888e-18 -0.055000000000000007216 0.023399999999999976374" rpy="3.1415926535897913396 -1.0423664039495509169e-15 3.1415926535897913396" />
<geometry>
<mesh filename="package:///motora_eje2.stl"/>
</geometry>
</collision>
<visual>
<origin xyz="-3.4694469519536141888e-18 -0.055000000000000007216 0.023399999999999976374" rpy="-3.141592653589793116 6.4801723596414117015e-17 3.141592653589793116" />
<geometry>
<mesh filename="package:///motor_acople.stl"/>
</geometry>
<material name="motor_acople_material">
<color rgba="0.26274509803921569651 0.28235294117647058432 0.30196078431372547213 1.0"/>
</material>
</visual>
<collision>
<origin xyz="-3.4694469519536141888e-18 -0.055000000000000007216 0.023399999999999976374" rpy="-3.141592653589793116 6.4801723596414117015e-17 3.141592653589793116" />
<geometry>
<mesh filename="package:///motor_acople.stl"/>
</geometry>
</collision>
<visual>
<origin xyz="6.9388939039072283776e-17 -0.054999999999999896194 0.023400000000000059641" rpy="-3.1415926535897922278 1.35085571874846508e-15 -3.141592653589793116" />
<geometry>
<mesh filename="package:///motora_eje1.stl"/>
</geometry>
<material name="motora_eje1_material">
<color rgba="0.64705882352941179736 0.64705882352941179736 0.64705882352941179736 1.0"/>
</material>
</visual>
<collision>
<origin xyz="6.9388939039072283776e-17 -0.054999999999999896194 0.023400000000000059641" rpy="-3.1415926535897922278 1.35085571874846508e-15 -3.141592653589793116" />
<geometry>
<mesh filename="package:///motora_eje1.stl"/>
</geometry>
</collision>
<visual>
<origin xyz="2.7755575615628913511e-17 -0.0337459090166083997 0.048799999999999996159" rpy="3.141592653589793116 2.8909898811626803827e-16 3.141592653589793116" />
<geometry>
<mesh filename="package:///tibia.stl"/>
</geometry>
<material name="tibia_material">
<color rgba="0.97254901960784312376 0.97254901960784312376 0.97254901960784312376 1.0"/>
</material>
</visual>
<collision>
<origin xyz="2.7755575615628913511e-17 -0.0337459090166083997 0.048799999999999996159" rpy="3.141592653589793116 2.8909898811626803827e-16 3.141592653589793116" />
<geometry>
<mesh filename="package:///tibia.stl"/>
</geometry>
</collision>
<inertial>
<origin xyz="8.7359843467014747886e-18 -0.042938078357409245611 0.023399999999999979844" rpy="0 0 0"/>
<mass value="0.28552673687099017208" />
<inertia ixx="0.00011378661693733247643" ixy="7.933478094635735622e-21"  ixz="-4.485969713553914081e-16" iyy="6.4755066218591712129e-05" iyz="1.6940658945086006781e-20" izz="6.7501897454918515992e-05" />
</inertial>
</link>

<link name="tobillo_urdf">
<visual>
<origin xyz="-2.9837243786801082024e-16 0.035800000000000047062 0.023849999999999926814" rpy="1.570796326794896558 1.570796326794896558 0" />
<geometry>
<mesh filename="package:///tobillo_pt2_left.stl"/>
</geometry>
<material name="tobillo_pt2_left_material">
<color rgba="0.97254901960784312376 0.97254901960784312376 0.97254901960784312376 1.0"/>
</material>
</visual>
<collision>
<origin xyz="-2.9837243786801082024e-16 0.035800000000000047062 0.023849999999999926814" rpy="1.570796326794896558 1.570796326794896558 0" />
<geometry>
<mesh filename="package:///tobillo_pt2_left.stl"/>
</geometry>
</collision>
<visual>
<origin xyz="0.00019999999999962062014 0.025773004946418327787 0.033535984972318300112" rpy="-1.5707963267948596986 9.6518186653058046142e-14 -1.5707963267950080244" />
<geometry>
<mesh filename="package:///motor_caja.stl"/>
</geometry>
<material name="motor_caja_material">
<color rgba="0.26274509803921569651 0.28235294117647058432 0.30196078431372547213 1.0"/>
</material>
</visual>
<collision>
<origin xyz="0.00019999999999962062014 0.025773004946418327787 0.033535984972318300112" rpy="-1.5707963267948596986 9.6518186653058046142e-14 -1.5707963267950080244" />
<geometry>
<mesh filename="package:///motor_caja.stl"/>
</geometry>
</collision>
<visual>
<origin xyz="0.00019999999999962062014 0.025773004946418327787 0.033535984972318300112" rpy="-1.5707963267948594765 9.6515753078343760844e-14 -1.5707963267950089126" />
<geometry>
<mesh filename="package:///motor_eje2.stl"/>
</geometry>
<material name="motor_eje2_material">
<color rgba="0.64705882352941179736 0.64705882352941179736 0.64705882352941179736 1.0"/>
</material>
</visual>
<collision>
<origin xyz="0.00019999999999962062014 0.025773004946418327787 0.033535984972318300112" rpy="-1.5707963267948594765 9.6515753078343760844e-14 -1.5707963267950089126" />
<geometry>
<mesh filename="package:///motor_eje2.stl"/>
</geometry>
</collision>
<visual>
<origin xyz="0 0.035800000000000005429 0.023249999999999992895" rpy="1.570796326794896558 1.570796326794896558 0" />
<geometry>
<mesh filename="package:///tobillo_pt2_right.stl"/>
</geometry>
<material name="tobillo_pt2_right_material">
<color rgba="0.97254901960784312376 0.97254901960784312376 0.97254901960784312376 1.0"/>
</material>
</visual>
<collision>
<origin xyz="0 0.035800000000000005429 0.023249999999999992895" rpy="1.570796326794896558 1.570796326794896558 0" />
<geometry>
<mesh filename="package:///tobillo_pt2_right.stl"/>
</geometry>
</collision>
<visual>
<origin xyz="-0.0001500000000001326661 0.035800000000000019307 0.023724999999999746292" rpy="1.570796326794896336 1.5707963267948961139 0" />
<geometry>
<mesh filename="package:///tobillo_pt3_2.stl"/>
</geometry>
<material name="tobillo_pt3_2_material">
<color rgba="0.97254901960784312376 0.97254901960784312376 0.97254901960784312376 1.0"/>
</material>
</visual>
<collision>
<origin xyz="-0.0001500000000001326661 0.035800000000000019307 0.023724999999999746292" rpy="1.570796326794896336 1.5707963267948961139 0" />
<geometry>
<mesh filename="package:///tobillo_pt3_2.stl"/>
</geometry>
</collision>
<visual>
<origin xyz="0.00014999999999981694643 0.035800000000000165024 0.023724999999999607514" rpy="1.570796326794896558 1.570796326794896558 0" />
<geometry>
<mesh filename="package:///tobillo_pt3_1.stl"/>
</geometry>
<material name="tobillo_pt3_1_material">
<color rgba="0.97254901960784312376 0.97254901960784312376 0.97254901960784312376 1.0"/>
</material>
</visual>
<collision>
<origin xyz="0.00014999999999981694643 0.035800000000000165024 0.023724999999999607514" rpy="1.570796326794896558 1.570796326794896558 0" />
<geometry>
<mesh filename="package:///tobillo_pt3_1.stl"/>
</geometry>
</collision>
<visual>
<origin xyz="-1.9775847626135600876e-16 0.035799999999999859712 0.023549999999999932099" rpy="1.570796326794896558 1.570796326794896558 0" />
<geometry>
<mesh filename="package:///tobillo_pt1.stl"/>
</geometry>
<material name="tobillo_pt1_material">
<color rgba="0.97254901960784312376 0.97254901960784312376 0.97254901960784312376 1.0"/>
</material>
</visual>
<collision>
<origin xyz="-1.9775847626135600876e-16 0.035799999999999859712 0.023549999999999932099" rpy="1.570796326794896558 1.570796326794896558 0" />
<geometry>
<mesh filename="package:///tobillo_pt1.stl"/>
</geometry>
</collision>
<visual>
<origin xyz="0.00019999999999962062014 0.025773004946418327787 0.033535984972318300112" rpy="-1.5707963267948592545 9.6069592124018336352e-14 -1.5707963267950084685" />
<geometry>
<mesh filename="package:///motor_eje1.stl"/>
</geometry>
<material name="motor_eje1_material">
<color rgba="0.64705882352941179736 0.64705882352941179736 0.64705882352941179736 1.0"/>
</material>
</visual>
<collision>
<origin xyz="0.00019999999999962062014 0.025773004946418327787 0.033535984972318300112" rpy="-1.5707963267948592545 9.6069592124018336352e-14 -1.5707963267950084685" />
<geometry>
<mesh filename="package:///motor_eje1.stl"/>
</geometry>
</collision>
<inertial>
<origin xyz="0.00013965747905149864601 0.025656493095559260859 0.023411667663057734307" rpy="0 0 0"/>
<mass value="0.35953278469495464353" />
<inertia ixx="0.00010180135317569895552" ixy="-5.8502280567828745807e-09"  ixz="-5.7602954081918258602e-08" iyy="0.00013007031479290523672" iyz="5.264363436309942989e-07" izz="7.0605374967425360783e-05" />
</inertial>
</link>

<link name="pie_urdf">
<visual>
<origin xyz="-0.0099999999999997035705 -0.019000000000000075856 0.0234999999999999723" rpy="-1.570796326794896558 -1.570796326794896336 0" />
<geometry>
<mesh filename="package:///acoplepiemotor.stl"/>
</geometry>
<material name="acoplepiemotor_material">
<color rgba="0.97254901960784312376 0.97254901960784312376 0.97254901960784312376 1.0"/>
</material>
</visual>
<collision>
<origin xyz="-0.0099999999999997035705 -0.019000000000000075856 0.0234999999999999723" rpy="-1.570796326794896558 -1.570796326794896336 0" />
<geometry>
<mesh filename="package:///acoplepiemotor.stl"/>
</geometry>
</collision>
<visual>
<origin xyz="-0.0099999999999992594812 -0.018950000000000185446 0.023449999999999870254" rpy="-1.570796326794896558 -1.570796326794896336 0" />
<geometry>
<mesh filename="package:///plantapie.stl"/>
</geometry>
<material name="plantapie_material">
<color rgba="0.97254901960784312376 0.97254901960784312376 0.97254901960784312376 1.0"/>
</material>
</visual>
<collision>
<origin xyz="-0.0099999999999992594812 -0.018950000000000185446 0.023449999999999870254" rpy="-1.570796326794896558 -1.570796326794896336 0" />
<geometry>
<mesh filename="package:///plantapie.stl"/>
</geometry>
</collision>
<visual>
<origin xyz="-0.010000000000000036637 -0.018999999999999999528 0.023399999999999997191" rpy="-1.570796326794896558 -1.570796326794896336 0" />
<geometry>
<mesh filename="package:///acoplepiemotor.stl"/>
</geometry>
<material name="acoplepiemotor_material">
<color rgba="0.97254901960784312376 0.97254901960784312376 0.97254901960784312376 1.0"/>
</material>
</visual>
<collision>
<origin xyz="-0.010000000000000036637 -0.018999999999999999528 0.023399999999999997191" rpy="-1.570796326794896558 -1.570796326794896336 0" />
<geometry>
<mesh filename="package:///acoplepiemotor.stl"/>
</geometry>
</collision>
<inertial>
<origin xyz="-0.009598196287715562991 -0.018994815818902745924 0.023449999999999898009" rpy="0 0 0"/>
<mass value="0.12193030814742020218" />
<inertia ixx="5.5790028401553088278e-05" ixy="-1.0383957421082534511e-06"  ixz="-1.2763727723938238234e-19" iyy="7.8275338616850845762e-05" iyz="2.1175823681357508477e-20" izz="3.3440055653628893357e-05" />
</inertial>
</link>

<joint name="RightAnkle2" type="revolute">
<origin xyz="-0.023200000000000386979 0.025773004946420954159 0.033535984972317384178" rpy="-1.5707963267944831109 -1.4808651911478258878 -1.570796326795454112" />
<parent link="tobillo_urdf" />
<child link="pie_urdf" />
<axis xyz="0 0 1"/>
<limit effort="1" velocity="20" lower="-0.26179938779914940783" upper="0.26179938779914940783"/>
<joint_properties friction="0.0"/>
</joint>

<joint name="RightAnkle1" type="revolute">
<origin xyz="9.0205620750793968909e-17 -0.054999999999999903133 5.5511151231257827021e-17" rpy="2.2549919000224758686e-15 1.6152720456270272169e-15 -3.1415926535897829019" />
<parent link="tibiaurdf" />
<child link="tobillo_urdf" />
<axis xyz="0 0 1"/>
<limit effort="1" velocity="20" lower="-0.52359877559829881566" upper="0.785398163397448279"/>
<joint_properties friction="0.0"/>
</joint>

<joint name="RightKnee" type="revolute">
<origin xyz="-2.4841240175987877592e-15 -0.065000000000000557332 -1.360023205165816762e-15" rpy="-3.1415926535897886751 -3.2856652020904885758e-15 3.1415864293030528742" />
<parent link="femur_v01" />
<child link="tibiaurdf" />
<axis xyz="0 0 1"/>
<limit effort="1" velocity="20" lower="0" upper="2.0943951023931952626"/>
<joint_properties friction="0.0"/>
</joint>

<joint name="RightHip2" type="revolute">
<origin xyz="0.028027549229578702095 0.033035984972317189445 -0.023550000000022434932" rpy="-1.5707963268204001572 1.5370119106033031109 -2.5738881126654993852e-11" />
<parent link="cadera_v01" />
<child link="femur_v01" />
<axis xyz="0 0 1"/>
<limit effort="1" velocity="20" lower="-1.570796326794896558" upper="1.570796326794896558"/>
<joint_properties friction="0.0"/>
</joint>

<joint name="RightHip1" type="revolute">
<origin xyz="0.023150000000000128808 0.022673904349987922258 -0.023580436102933310938" rpy="-1.7849231868056687303e-15 1.5707963267948952257 0" />
<parent link="cintura_urdf" />
<child link="cadera_v01" />
<axis xyz="0 0 1"/>
<limit effort="1" velocity="20" lower="-0.34906585039886589561" upper="0.34906585039886589561"/>
<joint_properties friction="0.0"/>
</joint>

<joint name="RightWaist" type="revolute">
<origin xyz="-0.097510035534551134373 0.022753615593456243821 0.1736559873457808878" rpy="0.040591453589792783618 -1.1502857612098471035e-16 1.5707963267948961139" />
<parent link="base" />
<child link="cintura_urdf" />
<axis xyz="0 0 1"/>
<limit effort="1" velocity="20" lower="-0.785398163397448279" upper="1.570796326794896558"/>
<joint_properties friction="0.0"/>
</joint>

<link name="cintura_urdf_2">
<visual>
<origin xyz="3.4694469519536141888e-18 0 -0.0020000000000000017764" rpy="3.141592653589793116 1.6707442267559271025e-32 1.4414381927523218338e-32" />
<geometry>
<mesh filename="package:///center.stl"/>
</geometry>
<material name="center_material">
<color rgba="0.97254901960784312376 0.97254901960784312376 0.97254901960784312376 1.0"/>
</material>
</visual>
<collision>
<origin xyz="3.4694469519536141888e-18 0 -0.0020000000000000017764" rpy="3.141592653589793116 1.6707442267559271025e-32 1.4414381927523218338e-32" />
<geometry>
<mesh filename="package:///center.stl"/>
</geometry>
</collision>
<visual>
<origin xyz="0.00010000000000002021161 -5.5511151231257827021e-17 -0.0019750000000000322853" rpy="-3.141592653589793116 -1.1326747063155469669e-18 -5.2783393546644686779e-16" />
<geometry>
<mesh filename="package:///side1.stl"/>
</geometry>
<material name="side1_material">
<color rgba="0.97254901960784312376 0.97254901960784312376 0.97254901960784312376 1.0"/>
</material>
</visual>
<collision>
<origin xyz="0.00010000000000002021161 -5.5511151231257827021e-17 -0.0019750000000000322853" rpy="-3.141592653589793116 -1.1326747063155469669e-18 -5.2783393546644686779e-16" />
<geometry>
<mesh filename="package:///side1.stl"/>
</geometry>
</collision>
<visual>
<origin xyz="-0.00010000000000001327272 -2.7755575615628913511e-17 -0.0019750000000000045297" rpy="-3.141592653589793116 1.4234715612517442239e-18 -5.693979126439342041e-16" />
<geometry>
<mesh filename="package:///side2.stl"/>
</geometry>
<material name="side2_material">
<color rgba="0.97254901960784312376 0.97254901960784312376 0.97254901960784312376 1.0"/>
</material>
</visual>
<collision>
<origin xyz="-0.00010000000000001327272 -2.7755575615628913511e-17 -0.0019750000000000045297" rpy="-3.141592653589793116 1.4234715612517442239e-18 -5.693979126439342041e-16" />
<geometry>
<mesh filename="package:///side2.stl"/>
</geometry>
</collision>
<inertial>
<origin xyz="-3.978334502981858899e-17 0.011217027911029917378 -0.0083553945903650089777" rpy="0 0 0"/>
<mass value="0.032703197933895256089" />
<inertia ixx="6.2216210938664884828e-06" ixy="4.6586812098986518649e-21"  ixz="-7.8350547621022781364e-21" iyy="1.6362334574865401997e-05" iyz="2.109469142594349427e-06" izz="1.673909360536617822e-05" />
</inertial>
</link>

<link name="cadera_v01_2">
<visual>
<origin xyz="8.3266726846886740532e-17 4.8572257327350598644e-17 -0.023399999999999965966" rpy="-5.6135922733152385959e-15 1.0538878797428012103e-14 -5.9371331100096214712e-15" />
<geometry>
<mesh filename="package:///motor_eje2.stl"/>
</geometry>
<material name="motor_eje2_material">
<color rgba="0.64705882352941179736 0.64705882352941179736 0.64705882352941179736 1.0"/>
</material>
</visual>
<collision>
<origin xyz="8.3266726846886740532e-17 4.8572257327350598644e-17 -0.023399999999999965966" rpy="-5.6135922733152385959e-15 1.0538878797428012103e-14 -5.9371331100096214712e-15" />
<geometry>
<mesh filename="package:///motor_eje2.stl"/>
</geometry>
</collision>
<visual>
<origin xyz="0.010027549229570220657 0.0098109849723238481967 -0.023650000000007709994" rpy="-1.5707963267951718933 8.6013851206475795632e-13 1.5707963267945301844" />
<geometry>
<mesh filename="package:///cadera_pt3_1.stl"/>
</geometry>
<material name="cadera_pt3_1_material">
<color rgba="0.97254901960784312376 0.97254901960784312376 0.97254901960784312376 1.0"/>
</material>
</visual>
<collision>
<origin xyz="0.010027549229570220657 0.0098109849723238481967 -0.023650000000007709994" rpy="-1.5707963267951718933 8.6013851206475795632e-13 1.5707963267945301844" />
<geometry>
<mesh filename="package:///cadera_pt3_1.stl"/>
</geometry>
</collision>
<visual>
<origin xyz="8.3266726846886740532e-17 4.8572257327350598644e-17 -0.023399999999999965966" rpy="-9.5480535370478343605e-15 3.8797090540220990899e-15 -2.5904615213804635066e-16" />
<geometry>
<mesh filename="package:///motor_caja.stl"/>
</geometry>
<material name="motor_caja_material">
<color rgba="0.26274509803921569651 0.28235294117647058432 0.30196078431372547213 1.0"/>
</material>
</visual>
<collision>
<origin xyz="8.3266726846886740532e-17 4.8572257327350598644e-17 -0.023399999999999965966" rpy="-9.5480535370478343605e-15 3.8797090540220990899e-15 -2.5904615213804635066e-16" />
<geometry>
<mesh filename="package:///motor_caja.stl"/>
</geometry>
</collision>
<visual>
<origin xyz="0.010027549229570192901 0.0097859849723237815611 -0.023550000000007353246" rpy="-1.5707963267951718933 8.6151515066821670954e-13 1.5707963267945310726" />
<geometry>
<mesh filename="package:///cadera_pt2_2.stl"/>
</geometry>
<material name="cadera_pt2_2_material">
<color rgba="0.97254901960784312376 0.97254901960784312376 0.97254901960784312376 1.0"/>
</material>
</visual>
<collision>
<origin xyz="0.010027549229570192901 0.0097859849723237815611 -0.023550000000007353246" rpy="-1.5707963267951718933 8.6151515066821670954e-13 1.5707963267945310726" />
<geometry>
<mesh filename="package:///cadera_pt2_2.stl"/>
</geometry>
</collision>
<visual>
<origin xyz="0.010027549229569610034 0.0094859849723236550068 -0.023550000000007044465" rpy="-1.5707963267951721154 8.6178045493982371053e-13 1.5707963267945315167" />
<geometry>
<mesh filename="package:///cadera_pt1.stl"/>
</geometry>
<material name="cadera_pt1_material">
<color rgba="0.97254901960784312376 0.97254901960784312376 0.97254901960784312376 1.0"/>
</material>
</visual>
<collision>
<origin xyz="0.010027549229569610034 0.0094859849723236550068 -0.023550000000007044465" rpy="-1.5707963267951721154 8.6178045493982371053e-13 1.5707963267945315167" />
<geometry>
<mesh filename="package:///cadera_pt1.stl"/>
</geometry>
</collision>
<visual>
<origin xyz="0.010027549229569915346 0.0098109849723239175856 -0.023450000000007239359" rpy="-1.5707963267951718933 8.6151515066821670954e-13 1.5707963267945310726" />
<geometry>
<mesh filename="package:///cadera_pt3_2.stl"/>
</geometry>
<material name="cadera_pt3_2_material">
<color rgba="0.97254901960784312376 0.97254901960784312376 0.97254901960784312376 1.0"/>
</material>
</visual>
<collision>
<origin xyz="0.010027549229569915346 0.0098109849723239175856 -0.023450000000007239359" rpy="-1.5707963267951718933 8.6151515066821670954e-13 1.5707963267945310726" />
<geometry>
<mesh filename="package:///cadera_pt3_2.stl"/>
</geometry>
</collision>
<visual>
<origin xyz="-2.7755575615628913511e-17 -6.9388939039072283776e-18 -0.023400000000000000661" rpy="-2.5353944079709405017e-32 2.0914117685614855747e-31 9.1371354001133067616e-18" />
<geometry>
<mesh filename="package:///motor_eje1.stl"/>
</geometry>
<material name="motor_eje1_material">
<color rgba="0.64705882352941179736 0.64705882352941179736 0.64705882352941179736 1.0"/>
</material>
</visual>
<collision>
<origin xyz="-2.7755575615628913511e-17 -6.9388939039072283776e-18 -0.023400000000000000661" rpy="-2.5353944079709405017e-32 2.0914117685614855747e-31 9.1371354001133067616e-18" />
<geometry>
<mesh filename="package:///motor_eje1.stl"/>
</geometry>
</collision>
<visual>
<origin xyz="0.010027549229570414946 0.0091859849723233411023 -0.023550000000006652418" rpy="-1.5707963267951721154 8.6178045493982371053e-13 1.5707963267945315167" />
<geometry>
<mesh filename="package:///cadera_pt2_1.stl"/>
</geometry>
<material name="cadera_pt2_1_material">
<color rgba="0.97254901960784312376 0.97254901960784312376 0.97254901960784312376 1.0"/>
</material>
</visual>
<collision>
<origin xyz="0.010027549229570414946 0.0091859849723233411023 -0.023550000000006652418" rpy="-1.5707963267951721154 8.6178045493982371053e-13 1.5707963267945315167" />
<geometry>
<mesh filename="package:///cadera_pt2_1.stl"/>
</geometry>
</collision>
<inertial>
<origin xyz="0.0019229001328408908047 0.010041085604013557861 -0.02344549165851132419" rpy="0 0 0"/>
<mass value="0.36033150614011227875" />
<inertia ixx="0.00013063858229427321566" ixy="-1.4491083149780982817e-07"  ixz="7.2430643630434364378e-08" iyy="7.1173611389549167462e-05" iyz="4.005034109119039992e-08" izz="0.00010253850500591836275" />
</inertial>
</link>

<link name="femur_v01_2">
<visual>
<origin xyz="-7.0082828429463006614e-16 -0.043745909016607867348 -0.048800000000000995359" rpy="2.2634429007937945846e-14 -2.7347339726385990763e-14 -3.014929307657937044e-14" />
<geometry>
<mesh filename="package:///femur.stl"/>
</geometry>
<material name="femur_material">
<color rgba="0.97254901960784312376 0.97254901960784312376 0.97254901960784312376 1.0"/>
</material>
</visual>
<collision>
<origin xyz="-7.0082828429463006614e-16 -0.043745909016607867348 -0.048800000000000995359" rpy="2.2634429007937945846e-14 -2.7347339726385990763e-14 -3.014929307657937044e-14" />
<geometry>
<mesh filename="package:///femur.stl"/>
</geometry>
</collision>
<visual>
<origin xyz="0 -1.3877787807814456755e-17 -0.023400000000000000661" rpy="-3.1415926535897717997 -2.7635554776536413009e-14 -2.9442589823651160143e-14" />
<geometry>
<mesh filename="package:///motor_acople.stl"/>
</geometry>
<material name="motor_acople_material">
<color rgba="0.26274509803921569651 0.28235294117647058432 0.30196078431372547213 1.0"/>
</material>
</visual>
<collision>
<origin xyz="0 -1.3877787807814456755e-17 -0.023400000000000000661" rpy="-3.1415926535897717997 -2.7635554776536413009e-14 -2.9442589823651160143e-14" />
<geometry>
<mesh filename="package:///motor_acople.stl"/>
</geometry>
</collision>
<visual>
<origin xyz="-1.9186041644303486464e-15 -0.043745909016608935937 -9.5756735873919751612e-16" rpy="2.2472762703672537857e-14 -2.7313565338237528015e-14 -2.904765319400314842e-14" />
<geometry>
<mesh filename="package:///femur.stl"/>
</geometry>
<material name="femur_material">
<color rgba="0.97254901960784312376 0.97254901960784312376 0.97254901960784312376 1.0"/>
</material>
</visual>
<collision>
<origin xyz="-1.9186041644303486464e-15 -0.043745909016608935937 -9.5756735873919751612e-16" rpy="2.2472762703672537857e-14 -2.7313565338237528015e-14 -2.904765319400314842e-14" />
<geometry>
<mesh filename="package:///femur.stl"/>
</geometry>
</collision>
<visual>
<origin xyz="-2.0712598303163076707e-15 -0.065000000000000057732 -0.023400000000001457828" rpy="3.1415926535897709115 2.7347190729121285492e-14 3.1415926535897629179" />
<geometry>
<mesh filename="package:///motor_acople.stl"/>
</geometry>
<material name="motor_acople_material">
<color rgba="0.26274509803921569651 0.28235294117647058432 0.30196078431372547213 1.0"/>
</material>
</visual>
<collision>
<origin xyz="-2.0712598303163076707e-15 -0.065000000000000057732 -0.023400000000001457828" rpy="3.1415926535897709115 2.7347190729121285492e-14 3.1415926535897629179" />
<geometry>
<mesh filename="package:///motor_acople.stl"/>
</geometry>
</collision>
<visual>
<origin xyz="-2.0712598303163076707e-15 -0.065000000000000057732 -0.023400000000001457828" rpy="3.1415926535897713556 2.8520962600522785834e-14 3.1415926535897638061" />
<geometry>
<mesh filename="package:///motora_eje1.stl"/>
</geometry>
<material name="motora_eje1_material">
<color rgba="0.64705882352941179736 0.64705882352941179736 0.64705882352941179736 1.0"/>
</material>
</visual>
<collision>
<origin xyz="-2.0712598303163076707e-15 -0.065000000000000057732 -0.023400000000001457828" rpy="3.1415926535897713556 2.8520962600522785834e-14 3.1415926535897638061" />
<geometry>
<mesh filename="package:///motora_eje1.stl"/>
</geometry>
</collision>
<visual>
<origin xyz="-2.001870891277235387e-15 -0.065000000000000085487 -0.023400000000001374562" rpy="3.1415926535897709115 2.7350866806737361256e-14 3.141592653589763362" />
<geometry>
<mesh filename="package:///motora_eje2.stl"/>
</geometry>
<material name="motora_eje2_material">
<color rgba="0.64705882352941179736 0.64705882352941179736 0.64705882352941179736 1.0"/>
</material>
</visual>
<collision>
<origin xyz="-2.001870891277235387e-15 -0.065000000000000085487 -0.023400000000001374562" rpy="3.1415926535897709115 2.7350866806737361256e-14 3.141592653589763362" />
<geometry>
<mesh filename="package:///motora_eje2.stl"/>
</geometry>
</collision>
<visual>
<origin xyz="0 -1.3877787807814456755e-17 -0.023400000000000000661" rpy="-3.141592653589793116 2.6145370824920110591e-19 -1.7866367600105308344e-18" />
<geometry>
<mesh filename="package:///motora_eje2.stl"/>
</geometry>
<material name="motora_eje2_material">
<color rgba="0.64705882352941179736 0.64705882352941179736 0.64705882352941179736 1.0"/>
</material>
</visual>
<collision>
<origin xyz="0 -1.3877787807814456755e-17 -0.023400000000000000661" rpy="-3.141592653589793116 2.6145370824920110591e-19 -1.7866367600105308344e-18" />
<geometry>
<mesh filename="package:///motora_eje2.stl"/>
</geometry>
</collision>
<visual>
<origin xyz="0 -1.3877787807814456755e-17 -0.023400000000000000661" rpy="3.141592653589793116 1.1914604254210960814e-15 2.6839498333635323968e-16" />
<geometry>
<mesh filename="package:///motora_eje1.stl"/>
</geometry>
<material name="motora_eje1_material">
<color rgba="0.64705882352941179736 0.64705882352941179736 0.64705882352941179736 1.0"/>
</material>
</visual>
<collision>
<origin xyz="0 -1.3877787807814456755e-17 -0.023400000000000000661" rpy="3.141592653589793116 1.1914604254210960814e-15 2.6839498333635323968e-16" />
<geometry>
<mesh filename="package:///motora_eje1.stl"/>
</geometry>
</collision>
<inertial>
<origin xyz="-1.0283915941553741638e-15 -0.032500000000000028866 -0.023400000000000718836" rpy="0 0 0"/>
<mass value="0.53868761965446421147" />
<inertia ixx="0.00043791203235393592755" ixy="-1.0536257417930869474e-17"  ixz="1.7196653864175611123e-18" iyy="0.00010909446328561620563" iyz="-5.9360068943581367762e-18" izz="0.00036348717125268614281" />
</inertial>
</link>

<link name="tibiaurdf_2">
<visual>
<origin xyz="0 -0.0337459090166083997 -0.0019999999999999983069" rpy="4.7149387294164143688e-19 -3.3651748271778409415e-19 8.4990306694683402445e-18" />
<geometry>
<mesh filename="package:///tibia.stl"/>
</geometry>
<material name="tibia_material">
<color rgba="0.97254901960784312376 0.97254901960784312376 0.97254901960784312376 1.0"/>
</material>
</visual>
<collision>
<origin xyz="0 -0.0337459090166083997 -0.0019999999999999983069" rpy="4.7149387294164143688e-19 -3.3651748271778409415e-19 8.4990306694683402445e-18" />
<geometry>
<mesh filename="package:///tibia.stl"/>
</geometry>
</collision>
<visual>
<origin xyz="4.8572257327350598644e-16 -0.055000000000000527633 0.023400000000000333727" rpy="3.1415926535897904515 -1.0566825477505173544e-15 -3.141592653589793116" />
<geometry>
<mesh filename="package:///motor_acople.stl"/>
</geometry>
<material name="motor_acople_material">
<color rgba="0.26274509803921569651 0.28235294117647058432 0.30196078431372547213 1.0"/>
</material>
</visual>
<collision>
<origin xyz="4.8572257327350598644e-16 -0.055000000000000527633 0.023400000000000333727" rpy="3.1415926535897904515 -1.0566825477505173544e-15 -3.141592653589793116" />
<geometry>
<mesh filename="package:///motor_acople.stl"/>
</geometry>
</collision>
<visual>
<origin xyz="5.6205040621648549859e-16 -0.05500000000000042355 0.023400000000000410055" rpy="3.1415926535897913396 2.8011702283991439323e-16 -3.1415926535897926719" />
<geometry>
<mesh filename="package:///motora_eje1.stl"/>
</geometry>
<material name="motora_eje1_material">
<color rgba="0.64705882352941179736 0.64705882352941179736 0.64705882352941179736 1.0"/>
</material>
</visual>
<collision>
<origin xyz="5.6205040621648549859e-16 -0.05500000000000042355 0.023400000000000410055" rpy="3.1415926535897913396 2.8011702283991439323e-16 -3.1415926535897926719" />
<geometry>
<mesh filename="package:///motora_eje1.stl"/>
</geometry>
</collision>
<visual>
<origin xyz="7.2858385991025897965e-17 -0.033745909016608517661 0.048800000000000842704" rpy="3.1415926535897904515 -1.057093614229596986e-15 -3.141592653589793116" />
<geometry>
<mesh filename="package:///tibia.stl"/>
</geometry>
<material name="tibia_material">
<color rgba="0.97254901960784312376 0.97254901960784312376 0.97254901960784312376 1.0"/>
</material>
</visual>
<collision>
<origin xyz="7.2858385991025897965e-17 -0.033745909016608517661 0.048800000000000842704" rpy="3.1415926535897904515 -1.057093614229596986e-15 -3.141592653589793116" />
<geometry>
<mesh filename="package:///tibia.stl"/>
</geometry>
</collision>
<visual>
<origin xyz="4.8572257327350598644e-16 -0.055000000000000527633 0.023400000000000333727" rpy="3.1415926535897886751 -2.1331592364514286067e-15 3.1415926535897917837" />
<geometry>
<mesh filename="package:///motora_eje2.stl"/>
</geometry>
<material name="motora_eje2_material">
<color rgba="0.64705882352941179736 0.64705882352941179736 0.64705882352941179736 1.0"/>
</material>
</visual>
<collision>
<origin xyz="4.8572257327350598644e-16 -0.055000000000000527633 0.023400000000000333727" rpy="3.1415926535897886751 -2.1331592364514286067e-15 3.1415926535897917837" />
<geometry>
<mesh filename="package:///motora_eje2.stl"/>
</geometry>
</collision>
<inertial>
<origin xyz="2.6845414745608460296e-16 -0.042938078357409543984 0.023400000000000371891" rpy="0 0 0"/>
<mass value="0.28552673687099017208" />
<inertia ixx="0.0001137866169373349701" ixy="-4.1312726789332850449e-19"  ixz="-4.4859459973668130476e-16" iyy="6.4755066218594056716e-05" iyz="2.4563955470374709833e-20" izz="6.7501897454920643739e-05" />
</inertial>
</link>

<link name="tobillo_urdf_2">
<visual>
<origin xyz="0.00019999999999962408959 0.025773004946418331257 0.033535984972318265418" rpy="-1.5707963267948594765 9.6507602228301571193e-14 -1.5707963267950089126" />
<geometry>
<mesh filename="package:///motor_eje2.stl"/>
</geometry>
<material name="motor_eje2_material">
<color rgba="0.64705882352941179736 0.64705882352941179736 0.64705882352941179736 1.0"/>
</material>
</visual>
<collision>
<origin xyz="0.00019999999999962408959 0.025773004946418331257 0.033535984972318265418" rpy="-1.5707963267948594765 9.6507602228301571193e-14 -1.5707963267950089126" />
<geometry>
<mesh filename="package:///motor_eje2.stl"/>
</geometry>
</collision>
<visual>
<origin xyz="3.4694469519536141888e-18 0.035800000000000005429 0.023249999999999999833" rpy="1.570796326794896558 1.570796326794896558 0" />
<geometry>
<mesh filename="package:///tobillo_pt2_right.stl"/>
</geometry>
<material name="tobillo_pt2_right_material">
<color rgba="0.97254901960784312376 0.97254901960784312376 0.97254901960784312376 1.0"/>
</material>
</visual>
<collision>
<origin xyz="3.4694469519536141888e-18 0.035800000000000005429 0.023249999999999999833" rpy="1.570796326794896558 1.570796326794896558 0" />
<geometry>
<mesh filename="package:///tobillo_pt2_right.stl"/>
</geometry>
</collision>
<visual>
<origin xyz="0.00019999999999962408959 0.025773004946418331257 0.033535984972318265418" rpy="-1.5707963267948596986 9.6519046441395213947e-14 -1.5707963267950080244" />
<geometry>
<mesh filename="package:///motor_caja.stl"/>
</geometry>
<material name="motor_caja_material">
<color rgba="0.26274509803921569651 0.28235294117647058432 0.30196078431372547213 1.0"/>
</material>
</visual>
<collision>
<origin xyz="0.00019999999999962408959 0.025773004946418331257 0.033535984972318265418" rpy="-1.5707963267948596986 9.6519046441395213947e-14 -1.5707963267950080244" />
<geometry>
<mesh filename="package:///motor_caja.stl"/>
</geometry>
</collision>
<visual>
<origin xyz="-1.9081958235744878039e-16 0.03579999999999987359 0.023549999999999939038" rpy="1.570796326794896558 1.570796326794896558 0" />
<geometry>
<mesh filename="package:///tobillo_pt1.stl"/>
</geometry>
<material name="tobillo_pt1_material">
<color rgba="0.97254901960784312376 0.97254901960784312376 0.97254901960784312376 1.0"/>
</material>
</visual>
<collision>
<origin xyz="-1.9081958235744878039e-16 0.03579999999999987359 0.023549999999999939038" rpy="1.570796326794896558 1.570796326794896558 0" />
<geometry>
<mesh filename="package:///tobillo_pt1.stl"/>
</geometry>
</collision>
<visual>
<origin xyz="0.00019999999999962408959 0.025773004946418331257 0.033535984972318265418" rpy="-1.5707963267948592545 9.6065584762927085023e-14 -1.5707963267950084685" />
<geometry>
<mesh filename="package:///motor_eje1.stl"/>
</geometry>
<material name="motor_eje1_material">
<color rgba="0.64705882352941179736 0.64705882352941179736 0.64705882352941179736 1.0"/>
</material>
</visual>
<collision>
<origin xyz="0.00019999999999962408959 0.025773004946418331257 0.033535984972318265418" rpy="-1.5707963267948592545 9.6065584762927085023e-14 -1.5707963267950084685" />
<geometry>
<mesh filename="package:///motor_eje1.stl"/>
</geometry>
</collision>
<visual>
<origin xyz="-2.8796409701214997767e-16 0.03580000000000006094 0.023849999999999926814" rpy="1.570796326794896558 1.570796326794896558 0" />
<geometry>
<mesh filename="package:///tobillo_pt2_left.stl"/>
</geometry>
<material name="tobillo_pt2_left_material">
<color rgba="0.97254901960784312376 0.97254901960784312376 0.97254901960784312376 1.0"/>
</material>
</visual>
<collision>
<origin xyz="-2.8796409701214997767e-16 0.03580000000000006094 0.023849999999999926814" rpy="1.570796326794896558 1.570796326794896558 0" />
<geometry>
<mesh filename="package:///tobillo_pt2_left.stl"/>
</geometry>
</collision>
<visual>
<origin xyz="0.00014999999999982388532 0.035800000000000165024 0.023724999999999586697" rpy="1.570796326794896558 1.570796326794896558 0" />
<geometry>
<mesh filename="package:///tobillo_pt3_1.stl"/>
</geometry>
<material name="tobillo_pt3_1_material">
<color rgba="0.97254901960784312376 0.97254901960784312376 0.97254901960784312376 1.0"/>
</material>
</visual>
<collision>
<origin xyz="0.00014999999999982388532 0.035800000000000165024 0.023724999999999586697" rpy="1.570796326794896558 1.570796326794896558 0" />
<geometry>
<mesh filename="package:///tobillo_pt3_1.stl"/>
</geometry>
</collision>
<visual>
<origin xyz="-0.00015000000000012919665 0.035800000000000019307 0.023724999999999739353" rpy="1.570796326794896336 1.5707963267948961139 0" />
<geometry>
<mesh filename="package:///tobillo_pt3_2.stl"/>
</geometry>
<material name="tobillo_pt3_2_material">
<color rgba="0.97254901960784312376 0.97254901960784312376 0.97254901960784312376 1.0"/>
</material>
</visual>
<collision>
<origin xyz="-0.00015000000000012919665 0.035800000000000019307 0.023724999999999739353" rpy="1.570796326794896336 1.5707963267948961139 0" />
<geometry>
<mesh filename="package:///tobillo_pt3_2.stl"/>
</geometry>
</collision>
<inertial>
<origin xyz="0.00013965747905150292861 0.025656493095559267797 0.02341166766305771002" rpy="0 0 0"/>
<mass value="0.35953278469495464353" />
<inertia ixx="0.00010180135317569894197" ixy="-5.8502280567854024446e-09"  ixz="-5.7602954081918258602e-08" iyy="0.00013007031479290518251" iyz="5.2643634363098307571e-07" izz="7.0605374967425414993e-05" />
</inertial>
</link>

<link name="pie_urdf_2">
<visual>
<origin xyz="-0.010000000000000015821 -0.019000000000000002998 0.023399999999999997191" rpy="-1.570796326794896558 -1.570796326794896336 0" />
<geometry>
<mesh filename="package:///acoplepiemotor.stl"/>
</geometry>
<material name="acoplepiemotor_material">
<color rgba="0.97254901960784312376 0.97254901960784312376 0.97254901960784312376 1.0"/>
</material>
</visual>
<collision>
<origin xyz="-0.010000000000000015821 -0.019000000000000002998 0.023399999999999997191" rpy="-1.570796326794896558 -1.570796326794896336 0" />
<geometry>
<mesh filename="package:///acoplepiemotor.stl"/>
</geometry>
</collision>
<visual>
<origin xyz="-0.0099999999999992456035 -0.018950000000000209732 0.023449999999999866784" rpy="-1.570796326794896558 -1.570796326794896336 0" />
<geometry>
<mesh filename="package:///plantapie.stl"/>
</geometry>
<material name="plantapie_material">
<color rgba="0.97254901960784312376 0.97254901960784312376 0.97254901960784312376 1.0"/>
</material>
</visual>
<collision>
<origin xyz="-0.0099999999999992456035 -0.018950000000000209732 0.023449999999999866784" rpy="-1.570796326794896558 -1.570796326794896336 0" />
<geometry>
<mesh filename="package:///plantapie.stl"/>
</geometry>
</collision>
<visual>
<origin xyz="-0.0099999999999996896927 -0.019000000000000100142 0.0234999999999999723" rpy="-1.570796326794896558 -1.570796326794896336 0" />
<geometry>
<mesh filename="package:///acoplepiemotor.stl"/>
</geometry>
<material name="acoplepiemotor_material">
<color rgba="0.97254901960784312376 0.97254901960784312376 0.97254901960784312376 1.0"/>
</material>
</visual>
<collision>
<origin xyz="-0.0099999999999996896927 -0.019000000000000100142 0.0234999999999999723" rpy="-1.570796326794896558 -1.570796326794896336 0" />
<geometry>
<mesh filename="package:///acoplepiemotor.stl"/>
</geometry>
</collision>
<inertial>
<origin xyz="-0.0095981962877155508479 -0.01899481581890277368 0.023449999999999898009" rpy="0 0 0"/>
<mass value="0.1219303081474201883" />
<inertia ixx="5.5790028401553081502e-05" ixy="-1.0383957421082551451e-06"  ixz="-1.2409032677275499967e-19" iyy="7.8275338616850872867e-05" iyz="2.8375603733019061359e-20" izz="3.3440055653628900133e-05" />
</inertial>
</link>

<joint name="LeftAnkle2" type="revolute">
<origin xyz="-0.023200000000000386979 0.025773004946420954159 0.033535984972317398056" rpy="1.5707963267947531172 -1.3089969389957789581 1.5707963267949207609" />
<parent link="tobillo_urdf_2" />
<child link="pie_urdf_2" />
<axis xyz="0 0 1"/>
<limit effort="1" velocity="20" lower="-0.26179938779914940783" upper="0.26179938779914940783"/>
<joint_properties friction="0.0"/>
</joint>

<joint name="LeftAnkle1" type="revolute">
<origin xyz="5.9674487573602164048e-16 -0.055000000000000437428 1.0408340855860842566e-17" rpy="-1.9609509983142411855e-15 1.8008263821212345284e-16 -3.1415926535897926719" />
<parent link="tibiaurdf_2" />
<child link="tobillo_urdf_2" />
<axis xyz="0 0 1"/>
<limit effort="1" velocity="20" lower="-0.785398163397448279" upper="0.52359877559829881566"/>
<joint_properties friction="0.0"/>
</joint>

<joint name="LeftKnee" type="revolute">
<origin xyz="-2.6541269182445148545e-15 -0.065000000000000612843 -1.360023205165816762e-15" rpy="-3.1415926535897917837 -2.1125392990547635288e-15 3.1415926535897638061" />
<parent link="femur_v01_2" />
<child link="tibiaurdf_2" />
<axis xyz="0 0 1"/>
<limit effort="1" velocity="20" lower="-2.0943951023931952626" upper="0"/>
<joint_properties friction="0.0"/>
</joint>

<joint name="LeftHip2" type="revolute">
<origin xyz="0.028027549229578674339 0.033035984972317182506 -0.023550000000022431462" rpy="-1.570796326820399047 1.5370119106032991141 -2.574471375494626401e-11" />
<parent link="cadera_v01_2" />
<child link="femur_v01_2" />
<axis xyz="0 0 1"/>
<limit effort="1" velocity="20" lower="-1.570796326794896558" upper="1.570796326794896558"/>
<joint_properties friction="0.0"/>
</joint>

<joint name="LeftHip1" type="revolute">
<origin xyz="0.0231499999999999935 0.022673904349987915319 -0.023580436102933310938" rpy="-1.178442120830790527e-15 1.5707963267948934494 0" />
<parent link="cintura_urdf_2" />
<child link="cadera_v01_2" />
<axis xyz="0 0 1"/>
<limit effort="1" velocity="20" lower="-0.34906585039886589561" upper="0.34906585039886589561"/>
<joint_properties friction="0.0"/>
</joint>

<joint name="LeftWaist" type="revolute">
<origin xyz="-0.067534747132801886682 0.022753615593456101573 0.17243857811634974442" rpy="-0.040591453589791937073 -7.9363599025938875266e-17 -1.57079632679489678" />
<parent link="base" />
<child link="cintura_urdf_2" />
<axis xyz="0 0 1"/>
<limit effort="1" velocity="20" lower="-1.570796326794896558" upper="0.785398163397448279"/>
<joint_properties friction="0.0"/>
</joint>


</robot>
