<robot name="onshape">
<link name="torsourdf">
<visual>
<origin xyz="-0.030742981990015266769 0.038371218877194315788 -0.076728910040700981643" rpy="1.570796326794896558 -0 0" />
<geometry>
<mesh filename="package:///acople_tornillos_abdomen.stl"/>
</geometry>
<material name="acople_tornillos_abdomen_material">
<color rgba="0.26274509803921569651 0.28235294117647058432 0.30196078431372547213 1.0"/>
</material>
</visual>
<collision>
<origin xyz="-0.030742981990015266769 0.038371218877194315788 -0.076728910040700981643" rpy="1.570796326794896558 -0 0" />
<geometry>
<mesh filename="package:///acople_tornillos_abdomen.stl"/>
</geometry>
</collision>
<visual>
<origin xyz="0.064057018009984756368 0.038371218877194308849 0.050524780976926725318" rpy="-1.570796326794896558 -0 3.141592653589793116" />
<geometry>
<mesh filename="package:///acople_tornillos_cuello.stl"/>
</geometry>
<material name="acople_tornillos_cuello_material">
<color rgba="0.26274509803921569651 0.28235294117647058432 0.30196078431372547213 1.0"/>
</material>
</visual>
<collision>
<origin xyz="0.064057018009984756368 0.038371218877194308849 0.050524780976926725318" rpy="-1.570796326794896558 -0 3.141592653589793116" />
<geometry>
<mesh filename="package:///acople_tornillos_cuello.stl"/>
</geometry>
</collision>
<visual>
<origin xyz="0.019257018009984729068 0.0083712188771943168986 -0.059778910040700981854" rpy="3.141592653589793116 -0 3.141592653589793116" />
<geometry>
<mesh filename="package:///motorsemiejeeje.stl"/>
</geometry>
<material name="motorsemiejeeje_material">
<color rgba="0.64705882352941179736 0.64705882352941179736 0.64705882352941179736 1.0"/>
</material>
</visual>
<collision>
<origin xyz="0.019257018009984729068 0.0083712188771943168986 -0.059778910040700981854" rpy="3.141592653589793116 -0 3.141592653589793116" />
<geometry>
<mesh filename="package:///motorsemiejeeje.stl"/>
</geometry>
</collision>
<visual>
<origin xyz="-0.055542981990015269367 0.038371218877194329666 -0.037828910040700991502" rpy="1.570796326794896558 -0 0" />
<geometry>
<mesh filename="package:///acople_tornillos_abdomen.stl"/>
</geometry>
<material name="acople_tornillos_abdomen_material">
<color rgba="0.26274509803921569651 0.28235294117647058432 0.30196078431372547213 1.0"/>
</material>
</visual>
<collision>
<origin xyz="-0.055542981990015269367 0.038371218877194329666 -0.037828910040700991502" rpy="1.570796326794896558 -0 0" />
<geometry>
<mesh filename="package:///acople_tornillos_abdomen.stl"/>
</geometry>
</collision>
<visual>
<origin xyz="0.069405821023547836779 0.0073712188771943021326 0.025468521028911533799" rpy="-1.570796326794896558 -0 -1.570796326794896558" />
<geometry>
<mesh filename="package:///motorejeeje2.stl"/>
</geometry>
<material name="motorejeeje2_material">
<color rgba="0.64705882352941179736 0.64705882352941179736 0.64705882352941179736 1.0"/>
</material>
</visual>
<collision>
<origin xyz="0.069405821023547836779 0.0073712188771943021326 0.025468521028911533799" rpy="-1.570796326794896558 -0 -1.570796326794896558" />
<geometry>
<mesh filename="package:///motorejeeje2.stl"/>
</geometry>
</collision>
<visual>
<origin xyz="-0.060891785003578363655 0.0073712188771943021326 0.025468521028911547677" rpy="-1.570796326794896558 -0 1.570796326794896558" />
<geometry>
<mesh filename="package:///motorejeeje1.stl"/>
</geometry>
<material name="motorejeeje1_material">
<color rgba="0.64705882352941179736 0.64705882352941179736 0.64705882352941179736 1.0"/>
</material>
</visual>
<collision>
<origin xyz="-0.060891785003578363655 0.0073712188771943021326 0.025468521028911547677" rpy="-1.570796326794896558 -0 1.570796326794896558" />
<geometry>
<mesh filename="package:///motorejeeje1.stl"/>
</geometry>
</collision>
<visual>
<origin xyz="0.004057018009984730833 -0.023628781122805697645 -0.0045580513594990768045" rpy="1.570796326794896558 -0 0" />
<geometry>
<mesh filename="package:///pecho.stl"/>
</geometry>
<material name="pecho_material">
<color rgba="0.97254901960784312376 0.97254901960784312376 0.97254901960784312376 1.0"/>
</material>
</visual>
<collision>
<origin xyz="0.004057018009984730833 -0.023628781122805697645 -0.0045580513594990768045" rpy="1.570796326794896558 -0 0" />
<geometry>
<mesh filename="package:///pecho.stl"/>
</geometry>
</collision>
<visual>
<origin xyz="0.069405821023547836779 0.0073712188771943021326 0.025468521028911547677" rpy="-1.5707963267948976682 1.9721522630525216312e-31 -1.570796326794896336" />
<geometry>
<mesh filename="package:///motorejeeje1.stl"/>
</geometry>
<material name="motorejeeje1_material">
<color rgba="0.64705882352941179736 0.64705882352941179736 0.64705882352941179736 1.0"/>
</material>
</visual>
<collision>
<origin xyz="0.069405821023547836779 0.0073712188771943021326 0.025468521028911547677" rpy="-1.5707963267948976682 1.9721522630525216312e-31 -1.570796326794896336" />
<geometry>
<mesh filename="package:///motorejeeje1.stl"/>
</geometry>
</collision>
<visual>
<origin xyz="0.087855821023547830961 0.007371218877194305602 0.025468521028911547677" rpy="-1.570796326794896558 -0 -1.570796326794896558" />
<geometry>
<mesh filename="package:///hombro_pecho.stl"/>
</geometry>
<material name="hombro_pecho_material">
<color rgba="0.97254901960784312376 0.97254901960784312376 0.97254901960784312376 1.0"/>
</material>
</visual>
<collision>
<origin xyz="0.087855821023547830961 0.007371218877194305602 0.025468521028911547677" rpy="-1.570796326794896558 -0 -1.570796326794896558" />
<geometry>
<mesh filename="package:///hombro_pecho.stl"/>
</geometry>
</collision>
<visual>
<origin xyz="-0.010742981990015254209 0.0083712188771943238375 -0.059778910040700974915" rpy="3.141592653589793116 -0 3.141592653589793116" />
<geometry>
<mesh filename="package:///motorsemiejecaja.stl"/>
</geometry>
<material name="motorsemiejecaja_material">
<color rgba="0.26274509803921569651 0.28235294117647058432 0.30196078431372547213 1.0"/>
</material>
</visual>
<collision>
<origin xyz="-0.010742981990015254209 0.0083712188771943238375 -0.059778910040700974915" rpy="3.141592653589793116 -0 3.141592653589793116" />
<geometry>
<mesh filename="package:///motorsemiejecaja.stl"/>
</geometry>
</collision>
<visual>
<origin xyz="-0.079341785003578357838 0.0073712188771942951937 0.025468521028911547677" rpy="-1.570796326794896558 -0 1.570796326794896558" />
<geometry>
<mesh filename="package:///hombro_pecho.stl"/>
</geometry>
<material name="hombro_pecho_material">
<color rgba="0.97254901960784312376 0.97254901960784312376 0.97254901960784312376 1.0"/>
</material>
</visual>
<collision>
<origin xyz="-0.079341785003578357838 0.0073712188771942951937 0.025468521028911547677" rpy="-1.570796326794896558 -0 1.570796326794896558" />
<geometry>
<mesh filename="package:///hombro_pecho.stl"/>
</geometry>
</collision>
<visual>
<origin xyz="-0.060891785003578363655 0.0073712188771943021326 0.025468521028911547677" rpy="-1.57079632679489678 -7.8886090522100182116e-31 1.57079632679489678" />
<geometry>
<mesh filename="package:///motorejeeje2.stl"/>
</geometry>
<material name="motorejeeje2_material">
<color rgba="0.64705882352941179736 0.64705882352941179736 0.64705882352941179736 1.0"/>
</material>
</visual>
<collision>
<origin xyz="-0.060891785003578363655 0.0073712188771943021326 0.025468521028911547677" rpy="-1.57079632679489678 -7.8886090522100182116e-31 1.57079632679489678" />
<geometry>
<mesh filename="package:///motorejeeje2.stl"/>
</geometry>
</collision>
<visual>
<origin xyz="-0.010742981990015255944 0.0083712188771943168986 -0.059778910040700981854" rpy="3.141592653589793116 -0 3.141592653589793116" />
<geometry>
<mesh filename="package:///motorsemiejeeje.stl"/>
</geometry>
<material name="motorsemiejeeje_material">
<color rgba="0.64705882352941179736 0.64705882352941179736 0.64705882352941179736 1.0"/>
</material>
</visual>
<collision>
<origin xyz="-0.010742981990015255944 0.0083712188771943168986 -0.059778910040700981854" rpy="3.141592653589793116 -0 3.141592653589793116" />
<geometry>
<mesh filename="package:///motorsemiejeeje.stl"/>
</geometry>
</collision>
<visual>
<origin xyz="0.0042570180099847365618 0.040371218877194303687 -0.0045580513594990490489" rpy="1.570796326794896558 -0 0" />
<geometry>
<mesh filename="package:///espalda.stl"/>
</geometry>
<material name="espalda_material">
<color rgba="0.97254901960784312376 0.97254901960784312376 0.97254901960784312376 1.0"/>
</material>
</visual>
<collision>
<origin xyz="0.0042570180099847365618 0.040371218877194303687 -0.0045580513594990490489" rpy="1.570796326794896558 -0 0" />
<geometry>
<mesh filename="package:///espalda.stl"/>
</geometry>
</collision>
<visual>
<origin xyz="-0.060891785003578363655 0.0073712188771942917243 0.025468521028911547677" rpy="-1.570796326794896558 -0 1.570796326794896558" />
<geometry>
<mesh filename="package:///motorejecaja.stl"/>
</geometry>
<material name="motorejecaja_material">
<color rgba="0.26274509803921569651 0.28235294117647058432 0.30196078431372547213 1.0"/>
</material>
</visual>
<collision>
<origin xyz="-0.060891785003578363655 0.0073712188771942917243 0.025468521028911547677" rpy="-1.570796326794896558 -0 1.570796326794896558" />
<geometry>
<mesh filename="package:///motorejecaja.stl"/>
</geometry>
</collision>
<visual>
<origin xyz="-0.055942981990015253069 -0.023628781122805697645 0.050524780976926725318" rpy="-1.570796326794896558 -0 0" />
<geometry>
<mesh filename="package:///acople_tornillos_cuello.stl"/>
</geometry>
<material name="acople_tornillos_cuello_material">
<color rgba="0.26274509803921569651 0.28235294117647058432 0.30196078431372547213 1.0"/>
</material>
</visual>
<collision>
<origin xyz="-0.055942981990015253069 -0.023628781122805697645 0.050524780976926725318" rpy="-1.570796326794896558 -0 0" />
<geometry>
<mesh filename="package:///acople_tornillos_cuello.stl"/>
</geometry>
</collision>
<visual>
<origin xyz="0.014057018009984739715 0.007371218877194305602 0.054024780976926728426" rpy="3.141592653589793116 -0 -1.570796326794896558" />
<geometry>
<mesh filename="package:///base_cabeza.stl"/>
</geometry>
<material name="base_cabeza_material">
<color rgba="0.97254901960784312376 0.97254901960784312376 0.97254901960784312376 1.0"/>
</material>
</visual>
<collision>
<origin xyz="0.014057018009984739715 0.007371218877194305602 0.054024780976926728426" rpy="3.141592653589793116 -0 -1.570796326794896558" />
<geometry>
<mesh filename="package:///base_cabeza.stl"/>
</geometry>
</collision>
<visual>
<origin xyz="-0.010542981990015257154 0.023946218877194329344 -0.04132891004070099461" rpy="0 -0 0" />
<geometry>
<mesh filename="package:///acoplemotorestorso1.stl"/>
</geometry>
<material name="acoplemotorestorso1_material">
<color rgba="0.97254901960784312376 0.97254901960784312376 0.97254901960784312376 1.0"/>
</material>
</visual>
<collision>
<origin xyz="-0.010542981990015257154 0.023946218877194329344 -0.04132891004070099461" rpy="0 -0 0" />
<geometry>
<mesh filename="package:///acoplemotorestorso1.stl"/>
</geometry>
</collision>
<visual>
<origin xyz="-0.010742981990015262883 0.023946218877194322405 -0.080228910040700984752" rpy="0 -0 0" />
<geometry>
<mesh filename="package:///acoplemotorestorso2.stl"/>
</geometry>
<material name="acoplemotorestorso2_material">
<color rgba="0.97254901960784312376 0.97254901960784312376 0.97254901960784312376 1.0"/>
</material>
</visual>
<collision>
<origin xyz="-0.010742981990015262883 0.023946218877194322405 -0.080228910040700984752" rpy="0 -0 0" />
<geometry>
<mesh filename="package:///acoplemotorestorso2.stl"/>
</geometry>
</collision>
<visual>
<origin xyz="-0.077841785003578356505 -0.023628781122805683768 -0.0070314789710884256779" rpy="-1.570796326794896558 -1.570796326794896558 0" />
<geometry>
<mesh filename="package:///acople_tornillos_hombro.stl"/>
</geometry>
<material name="acople_tornillos_hombro_material">
<color rgba="0.26274509803921569651 0.28235294117647058432 0.30196078431372547213 1.0"/>
</material>
</visual>
<collision>
<origin xyz="-0.077841785003578356505 -0.023628781122805683768 -0.0070314789710884256779" rpy="-1.570796326794896558 -1.570796326794896558 0" />
<geometry>
<mesh filename="package:///acople_tornillos_hombro.stl"/>
</geometry>
</collision>
<visual>
<origin xyz="0.086355821023547829629 0.038371218877194274155 -0.0070314789710884395557" rpy="1.570796326794896558 -1.570796326794896558 0" />
<geometry>
<mesh filename="package:///acople_tornillos_hombro.stl"/>
</geometry>
<material name="acople_tornillos_hombro_material">
<color rgba="0.26274509803921569651 0.28235294117647058432 0.30196078431372547213 1.0"/>
</material>
</visual>
<collision>
<origin xyz="0.086355821023547829629 0.038371218877194274155 -0.0070314789710884395557" rpy="1.570796326794896558 -1.570796326794896558 0" />
<geometry>
<mesh filename="package:///acople_tornillos_hombro.stl"/>
</geometry>
</collision>
<visual>
<origin xyz="0.086355821023547829629 -0.023628781122805697645 0.037968521028911544901" rpy="-1.570796326794896558 1.570796326794896558 0" />
<geometry>
<mesh filename="package:///acople_tornillos_hombro.stl"/>
</geometry>
<material name="acople_tornillos_hombro_material">
<color rgba="0.26274509803921569651 0.28235294117647058432 0.30196078431372547213 1.0"/>
</material>
</visual>
<collision>
<origin xyz="0.086355821023547829629 -0.023628781122805697645 0.037968521028911544901" rpy="-1.570796326794896558 1.570796326794896558 0" />
<geometry>
<mesh filename="package:///acople_tornillos_hombro.stl"/>
</geometry>
</collision>
<visual>
<origin xyz="0.039257018009984739892 -0.0216287811228056924 -0.076728910040700981643" rpy="1.570796326794896558 -0 3.141592653589793116" />
<geometry>
<mesh filename="package:///acople_tornillos_abdomen.stl"/>
</geometry>
<material name="acople_tornillos_abdomen_material">
<color rgba="0.26274509803921569651 0.28235294117647058432 0.30196078431372547213 1.0"/>
</material>
</visual>
<collision>
<origin xyz="0.039257018009984739892 -0.0216287811228056924 -0.076728910040700981643" rpy="1.570796326794896558 -0 3.141592653589793116" />
<geometry>
<mesh filename="package:///acople_tornillos_abdomen.stl"/>
</geometry>
</collision>
<visual>
<origin xyz="0.064457018009984712315 -0.021628781122805678522 -0.037828910040700991502" rpy="1.570796326794896558 -0 3.141592653589793116" />
<geometry>
<mesh filename="package:///acople_tornillos_abdomen.stl"/>
</geometry>
<material name="acople_tornillos_abdomen_material">
<color rgba="0.26274509803921569651 0.28235294117647058432 0.30196078431372547213 1.0"/>
</material>
</visual>
<collision>
<origin xyz="0.064457018009984712315 -0.021628781122805678522 -0.037828910040700991502" rpy="1.570796326794896558 -0 3.141592653589793116" />
<geometry>
<mesh filename="package:///acople_tornillos_abdomen.stl"/>
</geometry>
</collision>
<visual>
<origin xyz="0.0042570180099847365618 -0.023628781122805683768 -0.0045580513594990629267" rpy="1.570796326794896558 -0 3.141592653589793116" />
<geometry>
<mesh filename="package:///abdomen.stl"/>
</geometry>
<material name="abdomen_material">
<color rgba="0.26274509803921569651 0.28235294117647058432 0.30196078431372547213 1.0"/>
</material>
</visual>
<collision>
<origin xyz="0.0042570180099847365618 -0.023628781122805683768 -0.0045580513594990629267" rpy="1.570796326794896558 -0 3.141592653589793116" />
<geometry>
<mesh filename="package:///abdomen.stl"/>
</geometry>
</collision>
<visual>
<origin xyz="-0.077841785003578356505 0.038371218877194301911 0.037968521028911544901" rpy="1.570796326794896558 1.570796326794896558 0" />
<geometry>
<mesh filename="package:///acople_tornillos_hombro.stl"/>
</geometry>
<material name="acople_tornillos_hombro_material">
<color rgba="0.26274509803921569651 0.28235294117647058432 0.30196078431372547213 1.0"/>
</material>
</visual>
<collision>
<origin xyz="-0.077841785003578356505 0.038371218877194301911 0.037968521028911544901" rpy="1.570796326794896558 1.570796326794896558 0" />
<geometry>
<mesh filename="package:///acople_tornillos_hombro.stl"/>
</geometry>
</collision>
<visual>
<origin xyz="0.069405821023547836779 0.0073712188771943021326 0.025468521028911533799" rpy="-1.570796326794896558 -0 -1.570796326794896558" />
<geometry>
<mesh filename="package:///motorejecaja.stl"/>
</geometry>
<material name="motorejecaja_material">
<color rgba="0.26274509803921569651 0.28235294117647058432 0.30196078431372547213 1.0"/>
</material>
</visual>
<collision>
<origin xyz="0.069405821023547836779 0.0073712188771943021326 0.025468521028911533799" rpy="-1.570796326794896558 -0 -1.570796326794896558" />
<geometry>
<mesh filename="package:///motorejecaja.stl"/>
</geometry>
</collision>
<visual>
<origin xyz="0.004057018009984730833 -0.023628781122805697645 -0.0045580513594990768045" rpy="1.570796326794896558 -0 0" />
<geometry>
<mesh filename="package:///luzpecho.stl"/>
</geometry>
<material name="luzpecho_material">
<color rgba="0.14117647058823529216 0.6941176470588235059 0.65098039215686276382 1.0"/>
</material>
</visual>
<collision>
<origin xyz="0.004057018009984730833 -0.023628781122805697645 -0.0045580513594990768045" rpy="1.570796326794896558 -0 0" />
<geometry>
<mesh filename="package:///luzpecho.stl"/>
</geometry>
</collision>
<visual>
<origin xyz="0.01925701800998471519 0.0083712188771943238375 -0.059778910040700974915" rpy="3.141592653589793116 -0 3.141592653589793116" />
<geometry>
<mesh filename="package:///motorsemiejecaja.stl"/>
</geometry>
<material name="motorsemiejecaja_material">
<color rgba="0.26274509803921569651 0.28235294117647058432 0.30196078431372547213 1.0"/>
</material>
</visual>
<collision>
<origin xyz="0.01925701800998471519 0.0083712188771943238375 -0.059778910040700974915" rpy="3.141592653589793116 -0 3.141592653589793116" />
<geometry>
<mesh filename="package:///motorsemiejecaja.stl"/>
</geometry>
</collision>
<inertial>
<origin xyz="0.0041641753467128710814 -0.0069926972537796014753 -0.0054565398185849878221" rpy="0 0 0"/>
<mass value="3.2921674694110931725" />
<inertia ixx="0.0076880102936372892927" ixy="-6.7916077198655838785e-06"  ixz="6.7702832083638695478e-06" iyy="0.013499449690620241721" iyz="0.00096379853423097215388" izz="0.0097359687391730398431" />
</inertial>
</link>

<link name="hombro-brazo">
<visual>
<origin xyz="-1.1362438767648086468e-16 -0.010999809727072717286 -0.0020000000000000017764" rpy="3.141592653589793116 -4.9303806576206958108e-32 0" />
<geometry>
<mesh filename="package:///hombro_brazo1.stl"/>
</geometry>
<material name="hombro_brazo1_material">
<color rgba="0.97254901960784312376 0.97254901960784312376 0.97254901960784312376 1.0"/>
</material>
</visual>
<collision>
<origin xyz="-1.1362438767648086468e-16 -0.010999809727072717286 -0.0020000000000000017764" rpy="3.141592653589793116 -4.9303806576206958108e-32 0" />
<geometry>
<mesh filename="package:///hombro_brazo1.stl"/>
</geometry>
</collision>
<visual>
<origin xyz="-0.0002999999999956952032 0.011000190272924889254 9.4368957093138305936e-16" rpy="-3.1415926535897895633 -2.6645352591003760126e-14 -3.1415926535897864547" />
<geometry>
<mesh filename="package:///hombro_brazo2.stl"/>
</geometry>
<material name="hombro_brazo2_material">
<color rgba="0.97254901960784312376 0.97254901960784312376 0.97254901960784312376 1.0"/>
</material>
</visual>
<collision>
<origin xyz="-0.0002999999999956952032 0.011000190272924889254 9.4368957093138305936e-16" rpy="-3.1415926535897895633 -2.6645352591003760126e-14 -3.1415926535897864547" />
<geometry>
<mesh filename="package:///hombro_brazo2.stl"/>
</geometry>
</collision>
<visual>
<origin xyz="0.00029999999999982904925 -0.010999809727072731164 6.8001160258290838101e-16" rpy="3.1415926535897926719 5.5511151231205328328e-16 -2.488009798184976312e-13" />
<geometry>
<mesh filename="package:///hombro_brazo2.stl"/>
</geometry>
<material name="hombro_brazo2_material">
<color rgba="0.97254901960784312376 0.97254901960784312376 0.97254901960784312376 1.0"/>
</material>
</visual>
<collision>
<origin xyz="0.00029999999999982904925 -0.010999809727072731164 6.8001160258290838101e-16" rpy="3.1415926535897926719 5.5511151231205328328e-16 -2.488009798184976312e-13" />
<geometry>
<mesh filename="package:///hombro_brazo2.stl"/>
</geometry>
</collision>
<inertial>
<origin xyz="1.7014733176725471617e-15 1.1044824123134683803e-07 -0.0076081599888872253334" rpy="0 0 0"/>
<mass value="0.028276359613946901173" />
<inertia ixx="3.1909882339227915847e-06" ixy="7.6383436214787764834e-11"  ixz="4.6036240683271223428e-19" iyy="1.3925926827988112166e-05" iyz="1.491561761143591943e-11" izz="1.2743353645780909449e-05" />
</inertial>
</link>

<link name="brazourdf">
<visual>
<origin xyz="2.7755575615628913511e-17 -6.9388939039072283776e-18 -0.02340000000000000413" rpy="2.1094237467878266147e-15 -4.4408920985025036506e-16 1.570796326794896558" />
<geometry>
<mesh filename="package:///motorejeacopleeje2.stl"/>
</geometry>
<material name="motorejeacopleeje2_material">
<color rgba="0.64705882352941179736 0.64705882352941179736 0.64705882352941179736 1.0"/>
</material>
</visual>
<collision>
<origin xyz="2.7755575615628913511e-17 -6.9388939039072283776e-18 -0.02340000000000000413" rpy="2.1094237467878266147e-15 -4.4408920985025036506e-16 1.570796326794896558" />
<geometry>
<mesh filename="package:///motorejeacopleeje2.stl"/>
</geometry>
</collision>
<visual>
<origin xyz="-0.030000000000000012768 0 -0.023399999999999990252" rpy="1.5707963267948970021 -5.5511151229433647808e-17 1.570796326794896336" />
<geometry>
<mesh filename="package:///brazo.stl"/>
</geometry>
<material name="brazo_material">
<color rgba="0.97254901960784312376 0.97254901960784312376 0.97254901960784312376 1.0"/>
</material>
</visual>
<collision>
<origin xyz="-0.030000000000000012768 0 -0.023399999999999990252" rpy="1.5707963267948970021 -5.5511151229433647808e-17 1.570796326794896336" />
<geometry>
<mesh filename="package:///brazo.stl"/>
</geometry>
</collision>
<visual>
<origin xyz="1.3877787807814456755e-17 0 -0.023399999999999997191" rpy="-7.0879359787127582264e-31 -0 1.570796326794896558" />
<geometry>
<mesh filename="package:///motorejeacopleeje1.stl"/>
</geometry>
<material name="motorejeacopleeje1_material">
<color rgba="0.64705882352941179736 0.64705882352941179736 0.64705882352941179736 1.0"/>
</material>
</visual>
<collision>
<origin xyz="1.3877787807814456755e-17 0 -0.023399999999999997191" rpy="-7.0879359787127582264e-31 -0 1.570796326794896558" />
<geometry>
<mesh filename="package:///motorejeacopleeje1.stl"/>
</geometry>
</collision>
<visual>
<origin xyz="0 3.4694469519536141888e-18 -0.023400000000000000661" rpy="4.4408920984990405513e-16 -2.2204460492507504056e-16 1.570796326794896336" />
<geometry>
<mesh filename="package:///motorejeacoplecaja.stl"/>
</geometry>
<material name="motorejeacoplecaja_material">
<color rgba="0.26274509803921569651 0.28235294117647058432 0.30196078431372547213 1.0"/>
</material>
</visual>
<collision>
<origin xyz="0 3.4694469519536141888e-18 -0.023400000000000000661" rpy="4.4408920984990405513e-16 -2.2204460492507504056e-16 1.570796326794896336" />
<geometry>
<mesh filename="package:///motorejeacoplecaja.stl"/>
</geometry>
</collision>
<inertial>
<origin xyz="-0.064612740306650359723 0.00024409654353023776041 -0.023399999587718614547" rpy="0 0 0"/>
<mass value="1.080760232398511711" />
<inertia ixx="0.00022953897767025226119" ixy="2.114633785486257661e-05"  ixz="-1.3608742072787944333e-10" iyy="0.0024710869173820300924" iyz="-1.0815339249029047288e-11" izz="0.0023133411907278666683" />
</inertial>
</link>

<joint name="LeftShoulder2" type="revolute">
<origin xyz="-0.02354999999999616081 3.8054585194818857374e-07 -0.020946406845601450719" rpy="7.7715611723741378302e-15 -1.5707963267948685804 0" />
<parent link="hombro-brazo" />
<child link="brazourdf" />
<axis xyz="0 0 1"/>
<limit effort="1" velocity="20" lower="-1.570796326794896558" upper="1.570796326794896558"/>
<joint_properties friction="0.0"/>
</joint>

<joint name="LeftShoulder1" type="revolute">
<origin xyz="0.092805821023547840909 0.0073712188771943082041 0.02546852102891152686" rpy="-1.5707963267948943376 -5.5511151231257851673e-17 1.570796326794896336" />
<parent link="torsourdf" />
<child link="hombro-brazo" />
<axis xyz="0 0 1"/>
<limit effort="1" velocity="20" lower="-1.570796326794896558" upper="1.570796326794896558"/>
<joint_properties friction="0.0"/>
</joint>

<link name="cintura_v01">
<visual>
<origin xyz="0 0 -0.0020000000000000017764" rpy="3.141592653589793116 -0 0.785398163397448279" />
<geometry>
<mesh filename="package:///cinturapt1.stl"/>
</geometry>
<material name="cinturapt1_material">
<color rgba="0.97254901960784312376 0.97254901960784312376 0.97254901960784312376 1.0"/>
</material>
</visual>
<collision>
<origin xyz="0 0 -0.0020000000000000017764" rpy="3.141592653589793116 -0 0.785398163397448279" />
<geometry>
<mesh filename="package:///cinturapt1.stl"/>
</geometry>
</collision>
<visual>
<origin xyz="0.00021213203435581189094 0.00021213203435587260626 -0.0020000000000000017764" rpy="-3.141592653589793116 -3.6977854932234928379e-32 0.78539816339744905616" />
<geometry>
<mesh filename="package:///cinturapt2_2.stl"/>
</geometry>
<material name="cinturapt2_2_material">
<color rgba="0.97254901960784312376 0.97254901960784312376 0.97254901960784312376 1.0"/>
</material>
</visual>
<collision>
<origin xyz="0.00021213203435581189094 0.00021213203435587260626 -0.0020000000000000017764" rpy="-3.141592653589793116 -3.6977854932234928379e-32 0.78539816339744905616" />
<geometry>
<mesh filename="package:///cinturapt2_2.stl"/>
</geometry>
</collision>
<visual>
<origin xyz="-0.0002121320343557719923 -0.00021213203435579974787 -0.0020000000000000017764" rpy="-3.141592653589793116 -3.6977854932234928379e-32 0.78539816339744905616" />
<geometry>
<mesh filename="package:///cinturapt2_1.stl"/>
</geometry>
<material name="cinturapt2_1_material">
<color rgba="0.97254901960784312376 0.97254901960784312376 0.97254901960784312376 1.0"/>
</material>
</visual>
<collision>
<origin xyz="-0.0002121320343557719923 -0.00021213203435579974787 -0.0020000000000000017764" rpy="-3.141592653589793116 -3.6977854932234928379e-32 0.78539816339744905616" />
<geometry>
<mesh filename="package:///cinturapt2_1.stl"/>
</geometry>
</collision>
<inertial>
<origin xyz="-0.007931636500648049648 0.0079316365006479958716 -0.0083693257381815735346" rpy="0 0 0"/>
<mass value="0.032703197933895256089" />
<inertia ixx="1.1474475218213188552e-05" ixy="-5.2475239690138025795e-06"  ixz="-1.4935382828704791702e-06" iyy="1.1474475218213158058e-05" iyz="1.4935382828704762056e-06" izz="1.70934280623948741e-05" />
</inertial>
</link>

<link name="cadera_v01">
<visual>
<origin xyz="0.010027549229561977251 0.0091859849723162564916 -0.0235499999999974792" rpy="-1.570796326794946296 -2.335879699734695518e-13 1.5707963267949807129" />
<geometry>
<mesh filename="package:///caderapt2_1.stl"/>
</geometry>
<material name="caderapt2_1_material">
<color rgba="0.97254901960784312376 0.97254901960784312376 0.97254901960784312376 1.0"/>
</material>
</visual>
<collision>
<origin xyz="0.010027549229561977251 0.0091859849723162564916 -0.0235499999999974792" rpy="-1.570796326794946296 -2.335879699734695518e-13 1.5707963267949807129" />
<geometry>
<mesh filename="package:///caderapt2_1.stl"/>
</geometry>
</collision>
<visual>
<origin xyz="-1.3877787807814456755e-17 -6.9388939039072283776e-18 -0.023399999999999993722" rpy="1.0146536357601248696e-17 2.0692863565770277314e-31 -6.3657489617453146459e-31" />
<geometry>
<mesh filename="package:///motorejecaja.stl"/>
</geometry>
<material name="motorejecaja_material">
<color rgba="0.26274509803921569651 0.28235294117647058432 0.30196078431372547213 1.0"/>
</material>
</visual>
<collision>
<origin xyz="-1.3877787807814456755e-17 -6.9388939039072283776e-18 -0.023399999999999993722" rpy="1.0146536357601248696e-17 2.0692863565770277314e-31 -6.3657489617453146459e-31" />
<geometry>
<mesh filename="package:///motorejecaja.stl"/>
</geometry>
</collision>
<visual>
<origin xyz="0.010027549229561977251 0.0097859849723161418389 -0.023549999999997357769" rpy="-1.570796326794946296 -2.3404552844719718913e-13 1.5707963267949807129" />
<geometry>
<mesh filename="package:///caderapt2_2.stl"/>
</geometry>
<material name="caderapt2_2_material">
<color rgba="0.97254901960784312376 0.97254901960784312376 0.97254901960784312376 1.0"/>
</material>
</visual>
<collision>
<origin xyz="0.010027549229561977251 0.0097859849723161418389 -0.023549999999997357769" rpy="-1.570796326794946296 -2.3404552844719718913e-13 1.5707963267949807129" />
<geometry>
<mesh filename="package:///caderapt2_2.stl"/>
</geometry>
</collision>
<visual>
<origin xyz="-6.9388939039072283776e-17 -3.4694469519536141888e-17 -0.023399999999999990252" rpy="1.9967346175430972093e-16 2.6645352591003248155e-15 4.4408920985035863622e-16" />
<geometry>
<mesh filename="package:///motorejeeje2.stl"/>
</geometry>
<material name="motorejeeje2_material">
<color rgba="0.64705882352941179736 0.64705882352941179736 0.64705882352941179736 1.0"/>
</material>
</visual>
<collision>
<origin xyz="-6.9388939039072283776e-17 -3.4694469519536141888e-17 -0.023399999999999990252" rpy="1.9967346175430972093e-16 2.6645352591003248155e-15 4.4408920985035863622e-16" />
<geometry>
<mesh filename="package:///motorejeeje2.stl"/>
</geometry>
</collision>
<visual>
<origin xyz="0.010027549229561893984 0.0098109849723160488799 -0.023449999999997403477" rpy="-1.570796326794946296 -2.3404552844719718913e-13 1.5707963267949807129" />
<geometry>
<mesh filename="package:///caderapt3_2.stl"/>
</geometry>
<material name="caderapt3_2_material">
<color rgba="0.97254901960784312376 0.97254901960784312376 0.97254901960784312376 1.0"/>
</material>
</visual>
<collision>
<origin xyz="0.010027549229561893984 0.0098109849723160488799 -0.023449999999997403477" rpy="-1.570796326794946296 -2.3404552844719718913e-13 1.5707963267949807129" />
<geometry>
<mesh filename="package:///caderapt3_2.stl"/>
</geometry>
</collision>
<visual>
<origin xyz="0.010027549229561893984 0.00981098497231611133 -0.023649999999997329408" rpy="-1.570796326794946296 -2.3690190159202527635e-13 1.5707963267949789365" />
<geometry>
<mesh filename="package:///caderapt3_1.stl"/>
</geometry>
<material name="caderapt3_1_material">
<color rgba="0.97254901960784312376 0.97254901960784312376 0.97254901960784312376 1.0"/>
</material>
</visual>
<collision>
<origin xyz="0.010027549229561893984 0.00981098497231611133 -0.023649999999997329408" rpy="-1.570796326794946296 -2.3690190159202527635e-13 1.5707963267949789365" />
<geometry>
<mesh filename="package:///caderapt3_1.stl"/>
</geometry>
</collision>
<visual>
<origin xyz="0.010027549229562157662 0.0094859849723163691682 -0.023549999999997399402" rpy="-1.570796326794946296 -2.335879699734695518e-13 1.5707963267949807129" />
<geometry>
<mesh filename="package:///caderapt1.stl"/>
</geometry>
<material name="caderapt1_material">
<color rgba="0.97254901960784312376 0.97254901960784312376 0.97254901960784312376 1.0"/>
</material>
</visual>
<collision>
<origin xyz="0.010027549229562157662 0.0094859849723163691682 -0.023549999999997399402" rpy="-1.570796326794946296 -2.335879699734695518e-13 1.5707963267949807129" />
<geometry>
<mesh filename="package:///caderapt1.stl"/>
</geometry>
</collision>
<visual>
<origin xyz="-1.3877787807814456755e-17 -6.9388939039072283776e-18 -0.023399999999999993722" rpy="1.0146536357601248696e-17 2.0692863565770277314e-31 -6.3657489617453146459e-31" />
<geometry>
<mesh filename="package:///motorejeeje1.stl"/>
</geometry>
<material name="motorejeeje1_material">
<color rgba="0.64705882352941179736 0.64705882352941179736 0.64705882352941179736 1.0"/>
</material>
</visual>
<collision>
<origin xyz="-1.3877787807814456755e-17 -6.9388939039072283776e-18 -0.023399999999999993722" rpy="1.0146536357601248696e-17 2.0692863565770277314e-31 -6.3657489617453146459e-31" />
<geometry>
<mesh filename="package:///motorejeeje1.stl"/>
</geometry>
</collision>
<inertial>
<origin xyz="0.0019229001328379597725 0.010041085604010778834 -0.02344549165850712269" rpy="0 0 0"/>
<mass value="0.36033150614011222324" />
<inertia ixx="0.0001306385822942654094" ixy="-1.449108314746341597e-07"  ixz="7.2430643624797042477e-08" iyy="7.1173611389541185024e-05" iyz="4.0050341049170696829e-08" izz="0.00010253850500590345498" />
</inertial>
</link>

<link name="femururdf">
<visual>
<origin xyz="-2.8622937353617317058e-17 0.043745909016608436337 -0.04680000000000000826" rpy="-3.141592653589793116 -1.0146536390614296422e-17 -1.893266172530428333e-29" />
<geometry>
<mesh filename="package:///femur.stl"/>
</geometry>
<material name="femur_material">
<color rgba="0.97254901960784312376 0.97254901960784312376 0.97254901960784312376 1.0"/>
</material>
</visual>
<collision>
<origin xyz="-2.8622937353617317058e-17 0.043745909016608436337 -0.04680000000000000826" rpy="-3.141592653589793116 -1.0146536390614296422e-17 -1.893266172530428333e-29" />
<geometry>
<mesh filename="package:///femur.stl"/>
</geometry>
</collision>
<visual>
<origin xyz="-1.1275702593849246114e-17 8.3266726846886740532e-17 -0.023400000000000035355" rpy="2.2933996985004109251e-16 7.0591927784234854676e-16 -3.2816613657194077653e-28" />
<geometry>
<mesh filename="package:///motorejeacopleeje2.stl"/>
</geometry>
<material name="motorejeacopleeje2_material">
<color rgba="0.64705882352941179736 0.64705882352941179736 0.64705882352941179736 1.0"/>
</material>
</visual>
<collision>
<origin xyz="-1.1275702593849246114e-17 8.3266726846886740532e-17 -0.023400000000000035355" rpy="2.2933996985004109251e-16 7.0591927784234854676e-16 -3.2816613657194077653e-28" />
<geometry>
<mesh filename="package:///motorejeacopleeje2.stl"/>
</geometry>
</collision>
<visual>
<origin xyz="-4.336808689942017736e-17 0.065000000000000085487 -0.023399999999999917394" rpy="-6.5400839892276137016e-16 -8.0347231642738611815e-16 3.141592653589793116" />
<geometry>
<mesh filename="package:///motorejeacopleeje1.stl"/>
</geometry>
<material name="motorejeacopleeje1_material">
<color rgba="0.64705882352941179736 0.64705882352941179736 0.64705882352941179736 1.0"/>
</material>
</visual>
<collision>
<origin xyz="-4.336808689942017736e-17 0.065000000000000085487 -0.023399999999999917394" rpy="-6.5400839892276137016e-16 -8.0347231642738611815e-16 3.141592653589793116" />
<geometry>
<mesh filename="package:///motorejeacopleeje1.stl"/>
</geometry>
</collision>
<visual>
<origin xyz="-1.0408340855860842566e-17 2.7755575615628913511e-17 -0.023400000000000014538" rpy="1.1575759365794268443e-15 -1.5725688164002905608e-17 0" />
<geometry>
<mesh filename="package:///motorejeacoplecaja.stl"/>
</geometry>
<material name="motorejeacoplecaja_material">
<color rgba="0.26274509803921569651 0.28235294117647058432 0.30196078431372547213 1.0"/>
</material>
</visual>
<collision>
<origin xyz="-1.0408340855860842566e-17 2.7755575615628913511e-17 -0.023400000000000014538" rpy="1.1575759365794268443e-15 -1.5725688164002905608e-17 0" />
<geometry>
<mesh filename="package:///motorejeacoplecaja.stl"/>
</geometry>
</collision>
<visual>
<origin xyz="1.561251128379126385e-17 0.065000000000000085487 -0.023400000000000014538" rpy="-1.521365528404791004e-17 -1.7938038900607129731e-16 -3.141592653589793116" />
<geometry>
<mesh filename="package:///motorejeacopleeje2.stl"/>
</geometry>
<material name="motorejeacopleeje2_material">
<color rgba="0.64705882352941179736 0.64705882352941179736 0.64705882352941179736 1.0"/>
</material>
</visual>
<collision>
<origin xyz="1.561251128379126385e-17 0.065000000000000085487 -0.023400000000000014538" rpy="-1.521365528404791004e-17 -1.7938038900607129731e-16 -3.141592653589793116" />
<geometry>
<mesh filename="package:///motorejeacopleeje2.stl"/>
</geometry>
</collision>
<visual>
<origin xyz="3.4694469519536141888e-18 0.043745909016608436337 0.0020000000000000156541" rpy="-3.141592653589793116 -1.0146536390614296422e-17 -1.893266172530428333e-29" />
<geometry>
<mesh filename="package:///femur.stl"/>
</geometry>
<material name="femur_material">
<color rgba="0.97254901960784312376 0.97254901960784312376 0.97254901960784312376 1.0"/>
</material>
</visual>
<collision>
<origin xyz="3.4694469519536141888e-18 0.043745909016608436337 0.0020000000000000156541" rpy="-3.141592653589793116 -1.0146536390614296422e-17 -1.893266172530428333e-29" />
<geometry>
<mesh filename="package:///femur.stl"/>
</geometry>
</collision>
<visual>
<origin xyz="1.3877787807814456755e-17 0.065000000000000057732 -0.023400000000000007599" rpy="-2.0433732487542564638e-16 -7.6143042907360647239e-16 3.141592653589793116" />
<geometry>
<mesh filename="package:///motorejeacoplecaja.stl"/>
</geometry>
<material name="motorejeacoplecaja_material">
<color rgba="0.26274509803921569651 0.28235294117647058432 0.30196078431372547213 1.0"/>
</material>
</visual>
<collision>
<origin xyz="1.3877787807814456755e-17 0.065000000000000057732 -0.023400000000000007599" rpy="-2.0433732487542564638e-16 -7.6143042907360647239e-16 3.141592653589793116" />
<geometry>
<mesh filename="package:///motorejeacoplecaja.stl"/>
</geometry>
</collision>
<visual>
<origin xyz="0 2.7755575615628913511e-17 -0.023400000000000007599" rpy="-1.2621774483536188887e-29 -1.0146536390614296422e-17 -6.3108872417680944433e-30" />
<geometry>
<mesh filename="package:///motorejeacopleeje1.stl"/>
</geometry>
<material name="motorejeacopleeje1_material">
<color rgba="0.64705882352941179736 0.64705882352941179736 0.64705882352941179736 1.0"/>
</material>
</visual>
<collision>
<origin xyz="0 2.7755575615628913511e-17 -0.023400000000000007599" rpy="-1.2621774483536188887e-29 -1.0146536390614296422e-17 -6.3108872417680944433e-30" />
<geometry>
<mesh filename="package:///motorejeacopleeje1.stl"/>
</geometry>
</collision>
<inertial>
<origin xyz="-2.9673033563538138872e-18 0.032500000000000042744 -0.02340000000000000413" rpy="0 0 0"/>
<mass value="0.53868761965446410045" />
<inertia ixx="0.00043791203235393576492" ixy="-1.1701812293009696496e-19"  ixz="-2.6362147560330833941e-20" iyy="0.00010909446328561627339" iyz="8.6397360619938634585e-20" izz="0.00036348717125268587176" />
</inertial>
</link>

<link name="tibiaurdf">
<visual>
<origin xyz="-0.047631397208144132804 0.027499999999999996669 0.023400000000000011069" rpy="-3.141592653589793116 9.7382293339934341904e-16 1.0471975511965978534" />
<geometry>
<mesh filename="package:///motorejeacopleeje2.stl"/>
</geometry>
<material name="motorejeacopleeje2_material">
<color rgba="0.64705882352941179736 0.64705882352941179736 0.64705882352941179736 1.0"/>
</material>
</visual>
<collision>
<origin xyz="-0.047631397208144132804 0.027499999999999996669 0.023400000000000011069" rpy="-3.141592653589793116 9.7382293339934341904e-16 1.0471975511965978534" />
<geometry>
<mesh filename="package:///motorejeacopleeje2.stl"/>
</geometry>
</collision>
<visual>
<origin xyz="-0.047631397208144132804 0.027499999999999968914 0.023400000000000011069" rpy="-3.141592653589793116 1.1863433304989806116e-15 1.0471975511965978534" />
<geometry>
<mesh filename="package:///motorejeacopleeje1.stl"/>
</geometry>
<material name="motorejeacopleeje1_material">
<color rgba="0.64705882352941179736 0.64705882352941179736 0.64705882352941179736 1.0"/>
</material>
</visual>
<collision>
<origin xyz="-0.047631397208144132804 0.027499999999999968914 0.023400000000000011069" rpy="-3.141592653589793116 1.1863433304989806116e-15 1.0471975511965978534" />
<geometry>
<mesh filename="package:///motorejeacopleeje1.stl"/>
</geometry>
</collision>
<visual>
<origin xyz="-0.029224814482181192543 0.016872954508304172094 0.04880000000000005167" rpy="-3.1415926535897926719 9.8055756533808009378e-16 1.0471975511965976313" />
<geometry>
<mesh filename="package:///tibia.stl"/>
</geometry>
<material name="tibia_material">
<color rgba="0.97254901960784312376 0.97254901960784312376 0.97254901960784312376 1.0"/>
</material>
</visual>
<collision>
<origin xyz="-0.029224814482181192543 0.016872954508304172094 0.04880000000000005167" rpy="-3.1415926535897926719 9.8055756533808009378e-16 1.0471975511965976313" />
<geometry>
<mesh filename="package:///tibia.stl"/>
</geometry>
</collision>
<visual>
<origin xyz="-0.029224814482181206421 0.01687295450830419985 -3.4694469519536141888e-18" rpy="-3.141592653589793116 -3.5397972257948427656e-18 1.0471975511965976313" />
<geometry>
<mesh filename="package:///tibia.stl"/>
</geometry>
<material name="tibia_material">
<color rgba="0.97254901960784312376 0.97254901960784312376 0.97254901960784312376 1.0"/>
</material>
</visual>
<collision>
<origin xyz="-0.029224814482181206421 0.01687295450830419985 -3.4694469519536141888e-18" rpy="-3.141592653589793116 -3.5397972257948427656e-18 1.0471975511965976313" />
<geometry>
<mesh filename="package:///tibia.stl"/>
</geometry>
</collision>
<visual>
<origin xyz="-0.047631397208144125865 0.027499999999999996669 0.023400000000000011069" rpy="3.141592653589793116 9.6429872557392051011e-16 1.0471975511965976313" />
<geometry>
<mesh filename="package:///motorejeacoplecaja.stl"/>
</geometry>
<material name="motorejeacoplecaja_material">
<color rgba="0.26274509803921569651 0.28235294117647058432 0.30196078431372547213 1.0"/>
</material>
</visual>
<collision>
<origin xyz="-0.047631397208144125865 0.027499999999999996669 0.023400000000000011069" rpy="3.141592653589793116 9.6429872557392051011e-16 1.0471975511965976313" />
<geometry>
<mesh filename="package:///motorejeacoplecaja.stl"/>
</geometry>
</collision>
<inertial>
<origin xyz="-0.037185466647235397575 0.021469039178648844507 0.023400000000000014538" rpy="0 0 0"/>
<mass value="0.28552673687099017208" />
<inertia ixx="7.7012953898987983976e-05" ixy="2.1231284255097826875e-05"  ixz="-4.7905050071253678197e-20" iyy="0.00010152872925693661116" iyz="-6.0545330915044112304e-20" izz="6.750189745491861086e-05" />
</inertial>
</link>

<link name="tobillourdf">
<visual>
<origin xyz="-0.00014999999999926183492 0.035799999999999720934 0.023725000000000218137" rpy="1.57079632679489678 1.5707963267948932273 0" />
<geometry>
<mesh filename="package:///tobillopt3_2.stl"/>
</geometry>
<material name="tobillopt3_2_material">
<color rgba="0.97254901960784312376 0.97254901960784312376 0.97254901960784312376 1.0"/>
</material>
</visual>
<collision>
<origin xyz="-0.00014999999999926183492 0.035799999999999720934 0.023725000000000218137" rpy="1.57079632679489678 1.5707963267948932273 0" />
<geometry>
<mesh filename="package:///tobillopt3_2.stl"/>
</geometry>
</collision>
<visual>
<origin xyz="1.9428902930940239457e-16 0.035799999999999915223 0.023550000000000161082" rpy="1.570796326794896558 1.570796326794896558 0" />
<geometry>
<mesh filename="package:///tobillopt1.stl"/>
</geometry>
<material name="tobillopt1_material">
<color rgba="0.97254901960784312376 0.97254901960784312376 0.97254901960784312376 1.0"/>
</material>
</visual>
<collision>
<origin xyz="1.9428902930940239457e-16 0.035799999999999915223 0.023550000000000161082" rpy="1.570796326794896558 1.570796326794896558 0" />
<geometry>
<mesh filename="package:///tobillopt1.stl"/>
</geometry>
</collision>
<visual>
<origin xyz="0.00020000000000125472965 0.025772450770437022038 0.033535984972324253683" rpy="-1.5707963267948525932 -1.0482043121696583563e-13 -1.570796326794742237" />
<geometry>
<mesh filename="package:///motorejecaja.stl"/>
</geometry>
<material name="motorejecaja_material">
<color rgba="0.26274509803921569651 0.28235294117647058432 0.30196078431372547213 1.0"/>
</material>
</visual>
<collision>
<origin xyz="0.00020000000000125472965 0.025772450770437022038 0.033535984972324253683" rpy="-1.5707963267948525932 -1.0482043121696583563e-13 -1.570796326794742237" />
<geometry>
<mesh filename="package:///motorejecaja.stl"/>
</geometry>
</collision>
<visual>
<origin xyz="0.00020000000000125472965 0.025772450770437022038 0.033535984972324253683" rpy="-1.5707963267948539254 -1.0468641544280050201e-13 -1.5707963267947429031" />
<geometry>
<mesh filename="package:///motorejeeje2.stl"/>
</geometry>
<material name="motorejeeje2_material">
<color rgba="0.64705882352941179736 0.64705882352941179736 0.64705882352941179736 1.0"/>
</material>
</visual>
<collision>
<origin xyz="0.00020000000000125472965 0.025772450770437022038 0.033535984972324253683" rpy="-1.5707963267948539254 -1.0468641544280050201e-13 -1.5707963267947429031" />
<geometry>
<mesh filename="package:///motorejeeje2.stl"/>
</geometry>
</collision>
<visual>
<origin xyz="0.00015000000000067736927 0.035799999999999609912 0.023725000000000349976" rpy="1.570796326794896558 1.570796326794896558 0" />
<geometry>
<mesh filename="package:///tobillopt3_1.stl"/>
</geometry>
<material name="tobillopt3_1_material">
<color rgba="0.97254901960784312376 0.97254901960784312376 0.97254901960784312376 1.0"/>
</material>
</visual>
<collision>
<origin xyz="0.00015000000000067736927 0.035799999999999609912 0.023725000000000349976" rpy="1.570796326794896558 1.570796326794896558 0" />
<geometry>
<mesh filename="package:///tobillopt3_1.stl"/>
</geometry>
</collision>
<visual>
<origin xyz="0.00020000000000125472965 0.025772450770437022038 0.033535984972324253683" rpy="-1.5707963267948532593 -1.0642467545089895908e-13 -1.570796326794742015" />
<geometry>
<mesh filename="package:///motorejeeje1.stl"/>
</geometry>
<material name="motorejeeje1_material">
<color rgba="0.64705882352941179736 0.64705882352941179736 0.64705882352941179736 1.0"/>
</material>
</visual>
<collision>
<origin xyz="0.00020000000000125472965 0.025772450770437022038 0.033535984972324253683" rpy="-1.5707963267948532593 -1.0642467545089895908e-13 -1.570796326794742015" />
<geometry>
<mesh filename="package:///motorejeeje1.stl"/>
</geometry>
</collision>
<visual>
<origin xyz="2.498001805406602216e-16 0.035799999999999970735 0.023850000000000350087" rpy="1.570796326794896558 1.570796326794896558 0" />
<geometry>
<mesh filename="package:///tobillopt2_1.stl"/>
</geometry>
<material name="tobillopt2_1_material">
<color rgba="0.97254901960784312376 0.97254901960784312376 0.97254901960784312376 1.0"/>
</material>
</visual>
<collision>
<origin xyz="2.498001805406602216e-16 0.035799999999999970735 0.023850000000000350087" rpy="1.570796326794896558 1.570796326794896558 0" />
<geometry>
<mesh filename="package:///tobillopt2_1.stl"/>
</geometry>
</collision>
<visual>
<origin xyz="-2.7755575615628913511e-17 0.035800000000000026246 0.02325000000000002065" rpy="1.570796326794896558 1.570796326794896558 0" />
<geometry>
<mesh filename="package:///tobillopt2_2.stl"/>
</geometry>
<material name="tobillopt2_2_material">
<color rgba="0.97254901960784312376 0.97254901960784312376 0.97254901960784312376 1.0"/>
</material>
</visual>
<collision>
<origin xyz="-2.7755575615628913511e-17 0.035800000000000026246 0.02325000000000002065" rpy="1.570796326794896558 1.570796326794896558 0" />
<geometry>
<mesh filename="package:///tobillopt2_2.stl"/>
</geometry>
</collision>
<inertial>
<origin xyz="0.00013965747905279673417 0.025656106121455492936 0.023411667663061973971" rpy="0 0 0"/>
<mass value="0.35953278469495458802" />
<inertia ixx="0.00010180132077840650586" ixy="-5.8418326168137097583e-09"  ixz="-5.7602954082775707408e-08" iyy="0.00013007031479290903143" iyz="5.2659589177169549527e-07" izz="7.0605342570129224836e-05" />
</inertial>
</link>

<link name="pieurdf">
<visual>
<origin xyz="-0.010000000000000133782 0.019000000000000155653 0.023500000000000603739" rpy="1.570796326794896558 1.570796326794896336 0" />
<geometry>
<mesh filename="package:///acoplepiemotor.stl"/>
</geometry>
<material name="acoplepiemotor_material">
<color rgba="0.97254901960784312376 0.97254901960784312376 0.97254901960784312376 1.0"/>
</material>
</visual>
<collision>
<origin xyz="-0.010000000000000133782 0.019000000000000155653 0.023500000000000603739" rpy="1.570796326794896558 1.570796326794896336 0" />
<geometry>
<mesh filename="package:///acoplepiemotor.stl"/>
</geometry>
</collision>
<visual>
<origin xyz="-0.010000000000000015821 0.01899999999999998912 0.02340000000000000413" rpy="1.570796326794896558 1.570796326794896336 0" />
<geometry>
<mesh filename="package:///acoplepiemotor.stl"/>
</geometry>
<material name="acoplepiemotor_material">
<color rgba="0.97254901960784312376 0.97254901960784312376 0.97254901960784312376 1.0"/>
</material>
</visual>
<collision>
<origin xyz="-0.010000000000000015821 0.01899999999999998912 0.02340000000000000413" rpy="1.570796326794896558 1.570796326794896336 0" />
<geometry>
<mesh filename="package:///acoplepiemotor.stl"/>
</geometry>
</collision>
<visual>
<origin xyz="-0.0099999999999997452038 0.018949999999999772582 0.023450000000000414957" rpy="1.570796326794896558 1.570796326794896336 0" />
<geometry>
<mesh filename="package:///plantapie.stl"/>
</geometry>
<material name="plantapie_material">
<color rgba="0.97254901960784312376 0.97254901960784312376 0.97254901960784312376 1.0"/>
</material>
</visual>
<collision>
<origin xyz="-0.0099999999999997452038 0.018949999999999772582 0.023450000000000414957" rpy="1.570796326794896558 1.570796326794896336 0" />
<geometry>
<mesh filename="package:///plantapie.stl"/>
</geometry>
</collision>
<inertial>
<origin xyz="-0.0095981962877159689163 0.018994815818902464899 0.023450000000000387201" rpy="0 0 0"/>
<mass value="0.12193030814742022994" />
<inertia ixx="5.5790028401553366105e-05" ixy="1.0383957421083110493e-06"  ixz="4.0829143620627416213e-20" iyy="7.8275338616851374311e-05" iyz="-7.7946260025728903846e-20" izz="3.3440055653628696845e-05" />
</inertial>
</link>

<joint name="LeftAnkle2" type="revolute">
<origin xyz="0.023600000000001231104 0.025772450770440658019 0.033535984972325266762" rpy="1.5454106253939043597e-13 -1.5707963267947788744 0" />
<parent link="tobillourdf" />
<child link="pieurdf" />
<axis xyz="0 0 1"/>
<limit effort="1" velocity="20" lower="-0.26179938779914940783" upper="0.26179938779914940783"/>
<joint_properties friction="0.0"/>
</joint>

<joint name="LeftAnkle1" type="revolute">
<origin xyz="-0.047631397208144125865 0.027499999999999968914 0.046800000000000036016" rpy="-3.1415926535897917837 -4.9721604402088067868e-16 -2.0943951023931961508" />
<parent link="tibiaurdf" />
<child link="tobillourdf" />
<axis xyz="0 0 1"/>
<limit effort="1" velocity="20" lower="-0.785398163397448279" upper="0.785398163397448279"/>
<joint_properties friction="0.0"/>
</joint>

<joint name="LeftKnee" type="revolute">
<origin xyz="-5.898059818321144121e-17 0.065000000000000196509 -7.147060721024445229e-16" rpy="-3.1415926535897926719 9.8471969112908084787e-16 -3.1415926535897922278" />
<parent link="femururdf" />
<child link="tibiaurdf" />
<axis xyz="0 0 1"/>
<limit effort="1" velocity="20" lower="-1.0471975511965976313" upper="1.0471975511965976313"/>
<joint_properties friction="0.0"/>
</joint>

<joint name="LeftHip2" type="revolute">
<origin xyz="0.028027549229563922251 -0.014064015027682230663 -0.023550000000002006828" rpy="1.570796326794806852 1.5707963267946500885 0" />
<parent link="cadera_v01" />
<child link="femururdf" />
<axis xyz="0 0 1"/>
<limit effort="1" velocity="20" lower="-1.570796326794896558" upper="1.570796326794896558"/>
<joint_properties friction="0.0"/>
</joint>

<joint name="LeftHip1" type="revolute">
<origin xyz="0.0006194931750914097271 0.03268523621879472485 -0.023605436102933363696" rpy="-0.78539816339744661366 1.5707963267948883423 0" />
<parent link="cintura_v01" />
<child link="cadera_v01" />
<axis xyz="0 0 1"/>
<limit effort="1" velocity="20" lower="-0.785398163397448279" upper="0.785398163397448279"/>
<joint_properties friction="0.0"/>
</joint>

<joint name="LeftWaist" type="revolute">
<origin xyz="0.019257018009984729068 0.0083712188771943168986 -0.083178910040700979045" rpy="-4.9415502631049690248e-17 6.1232339957363309298e-17 -1.570796326794896558" />
<parent link="torsourdf" />
<child link="cintura_v01" />
<axis xyz="0 0 1"/>
<limit effort="1" velocity="20" lower="-1.570796326794896558" upper="1.570796326794896558"/>
<joint_properties friction="0.0"/>
</joint>

<link name="hombro-brazo_2">
<visual>
<origin xyz="-1.1449174941446926823e-16 0.010999809727072717286 0" rpy="3.0423430958599903309e-32 -5.2989295050620434327e-34 -4.0926011306615500854e-33" />
<geometry>
<mesh filename="package:///hombro_brazo1.stl"/>
</geometry>
<material name="hombro_brazo1_material">
<color rgba="0.97254901960784312376 0.97254901960784312376 0.97254901960784312376 1.0"/>
</material>
</visual>
<collision>
<origin xyz="-1.1449174941446926823e-16 0.010999809727072717286 0" rpy="3.0423430958599903309e-32 -5.2989295050620434327e-34 -4.0926011306615500854e-33" />
<geometry>
<mesh filename="package:///hombro_brazo1.stl"/>
</geometry>
</collision>
<visual>
<origin xyz="0.00029999999999985333538 0.010999809727072842186 -0.001999999999999960143" rpy="3.4416913763379651594e-15 4.6629367034255091639e-15 1.6819922191157922558e-13" />
<geometry>
<mesh filename="package:///hombro_brazo2.stl"/>
</geometry>
<material name="hombro_brazo2_material">
<color rgba="0.97254901960784312376 0.97254901960784312376 0.97254901960784312376 1.0"/>
</material>
</visual>
<collision>
<origin xyz="0.00029999999999985333538 0.010999809727072842186 -0.001999999999999960143" rpy="3.4416913763379651594e-15 4.6629367034255091639e-15 1.6819922191157922558e-13" />
<geometry>
<mesh filename="package:///hombro_brazo2.stl"/>
</geometry>
</collision>
<visual>
<origin xyz="-0.00029999999999145467167 -0.011000190272921067658 -0.0020000000000004042322" rpy="9.1038288019263151859e-15 2.0761170560490714451e-14 -3.1415926535894769245" />
<geometry>
<mesh filename="package:///hombro_brazo2.stl"/>
</geometry>
<material name="hombro_brazo2_material">
<color rgba="0.97254901960784312376 0.97254901960784312376 0.97254901960784312376 1.0"/>
</material>
</visual>
<collision>
<origin xyz="-0.00029999999999145467167 -0.011000190272921067658 -0.0020000000000004042322" rpy="9.1038288019263151859e-15 2.0761170560490714451e-14 -3.1415926535894769245" />
<geometry>
<mesh filename="package:///hombro_brazo2.stl"/>
</geometry>
</collision>
<inertial>
<origin xyz="1.6890118229515651572e-15 -1.1044824278885071913e-07 0.0056081599888875384094" rpy="0 0 0"/>
<mass value="0.028276359613946901173" />
<inertia ixx="3.1909882339228915346e-06" ixy="-7.6383436528518307247e-11"  ixz="-4.5273911030742353123e-19" iyy="1.3925926827987627663e-05" iyz="1.4915617865722697473e-11" izz="1.2743353645780324996e-05" />
</inertial>
</link>

<link name="brazourdf_2">
<visual>
<origin xyz="0 0 -0.023400000000000000661" rpy="1.8806818552538889383e-30 -2.3576385711398787497e-29 1.570796326794896558" />
<geometry>
<mesh filename="package:///motorejeacopleeje1.stl"/>
</geometry>
<material name="motorejeacopleeje1_material">
<color rgba="0.64705882352941179736 0.64705882352941179736 0.64705882352941179736 1.0"/>
</material>
</visual>
<collision>
<origin xyz="0 0 -0.023400000000000000661" rpy="1.8806818552538889383e-30 -2.3576385711398787497e-29 1.570796326794896558" />
<geometry>
<mesh filename="package:///motorejeacopleeje1.stl"/>
</geometry>
</collision>
<visual>
<origin xyz="-0.029999999999999915623 -3.4694469519536141888e-18 -0.023399999999999997191" rpy="1.5707963267948970021 3.3306690739421194931e-16 1.5707963267948972241" />
<geometry>
<mesh filename="package:///brazo.stl"/>
</geometry>
<material name="brazo_material">
<color rgba="0.97254901960784312376 0.97254901960784312376 0.97254901960784312376 1.0"/>
</material>
</visual>
<collision>
<origin xyz="-0.029999999999999915623 -3.4694469519536141888e-18 -0.023399999999999997191" rpy="1.5707963267948970021 3.3306690739421194931e-16 1.5707963267948972241" />
<geometry>
<mesh filename="package:///brazo.stl"/>
</geometry>
</collision>
<visual>
<origin xyz="0 0 -0.023400000000000000661" rpy="5.6354964637312311918e-28 4.7796026711870344834e-28 1.570796326794896558" />
<geometry>
<mesh filename="package:///motorejeacoplecaja.stl"/>
</geometry>
<material name="motorejeacoplecaja_material">
<color rgba="0.26274509803921569651 0.28235294117647058432 0.30196078431372547213 1.0"/>
</material>
</visual>
<collision>
<origin xyz="0 0 -0.023400000000000000661" rpy="5.6354964637312311918e-28 4.7796026711870344834e-28 1.570796326794896558" />
<geometry>
<mesh filename="package:///motorejeacoplecaja.stl"/>
</geometry>
</collision>
<visual>
<origin xyz="0 0 -0.023400000000000000661" rpy="2.1329540445451286226e-28 7.7397810156890723595e-29 1.570796326794896558" />
<geometry>
<mesh filename="package:///motorejeacopleeje2.stl"/>
</geometry>
<material name="motorejeacopleeje2_material">
<color rgba="0.64705882352941179736 0.64705882352941179736 0.64705882352941179736 1.0"/>
</material>
</visual>
<collision>
<origin xyz="0 0 -0.023400000000000000661" rpy="2.1329540445451286226e-28 7.7397810156890723595e-29 1.570796326794896558" />
<geometry>
<mesh filename="package:///motorejeacopleeje2.stl"/>
</geometry>
</collision>
<inertial>
<origin xyz="-0.064612740306650165434 0.00024409654353026548888 -0.023399999587718614547" rpy="0 0 0"/>
<mass value="1.080760232398511711" />
<inertia ixx="0.00022953897767025085172" ixy="2.1146337854861607604e-05"  ixz="-1.3608742167623495874e-10" iyy="0.002471086917382017082" iyz="-1.0815340757996149668e-11" izz="0.0023133411907278610305" />
</inertial>
</link>

<joint name="RightShoulder2" type="revolute">
<origin xyz="-0.023549999999995352429 -3.8054585540028829094e-07 0.018946406845602128954" rpy="3.1415926535894787008 1.5707963267948730213 0" />
<parent link="hombro-brazo_2" />
<child link="brazourdf_2" />
<axis xyz="0 0 1"/>
<limit effort="1" velocity="20" lower="-1.570796326794896558" upper="1.570796326794896558"/>
<joint_properties friction="0.0"/>
</joint>

<joint name="RightShoulder1" type="revolute">
<origin xyz="-0.085191785003578324176 0.0073712188771942856527 0.025468521028911415838" rpy="1.57079632679489678 -2.222614453594627363e-16 -1.57079632679489678" />
<parent link="torsourdf" />
<child link="hombro-brazo_2" />
<axis xyz="0 0 1"/>
<limit effort="1" velocity="20" lower="-1.570796326794896558" upper="1.570796326794896558"/>
<joint_properties friction="0.0"/>
</joint>

<link name="cintura_v01_2">
<visual>
<origin xyz="-0.00021213203435598709801 0.00021213203435595240354 -0.0020000000000000017764" rpy="3.141592653589793116 9.9213537583989466916e-33 -0.78539816339744772389" />
<geometry>
<mesh filename="package:///cinturapt2_1.stl"/>
</geometry>
<material name="cinturapt2_1_material">
<color rgba="0.97254901960784312376 0.97254901960784312376 0.97254901960784312376 1.0"/>
</material>
</visual>
<collision>
<origin xyz="-0.00021213203435598709801 0.00021213203435595240354 -0.0020000000000000017764" rpy="3.141592653589793116 9.9213537583989466916e-33 -0.78539816339744772389" />
<geometry>
<mesh filename="package:///cinturapt2_1.stl"/>
</geometry>
</collision>
<visual>
<origin xyz="0 0 -0.0020000000000000017764" rpy="3.141592653589793116 -1.1847256930835519218e-46 -0.785398163397448279" />
<geometry>
<mesh filename="package:///cinturapt1.stl"/>
</geometry>
<material name="cinturapt1_material">
<color rgba="0.97254901960784312376 0.97254901960784312376 0.97254901960784312376 1.0"/>
</material>
</visual>
<collision>
<origin xyz="0 0 -0.0020000000000000017764" rpy="3.141592653589793116 -1.1847256930835519218e-46 -0.785398163397448279" />
<geometry>
<mesh filename="package:///cinturapt1.stl"/>
</geometry>
</collision>
<visual>
<origin xyz="0.0002121320343559350563 -0.00021213203435596628132 -0.0020000000000000017764" rpy="3.141592653589793116 9.547971805108427851e-33 -0.78539816339744772389" />
<geometry>
<mesh filename="package:///cinturapt2_2.stl"/>
</geometry>
<material name="cinturapt2_2_material">
<color rgba="0.97254901960784312376 0.97254901960784312376 0.97254901960784312376 1.0"/>
</material>
</visual>
<collision>
<origin xyz="0.0002121320343559350563 -0.00021213203435596628132 -0.0020000000000000017764" rpy="3.141592653589793116 9.547971805108427851e-33 -0.78539816339744772389" />
<geometry>
<mesh filename="package:///cinturapt2_2.stl"/>
</geometry>
</collision>
<inertial>
<origin xyz="0.0079316365006479611771 0.0079316365006480479133 -0.0083693257381815735346" rpy="0 0 0"/>
<mass value="0.032703197933895256089" />
<inertia ixx="1.1474475218213261397e-05" ixy="5.2475239690138999882e-06"  ixz="1.4935382828704690058e-06" iyy="1.1474475218213258008e-05" iyz="1.4935382828704774762e-06" izz="1.7093428062395046895e-05" />
</inertial>
</link>

<link name="cadera_v01_2">
<visual>
<origin xyz="0.010027549229562504607 -0.0094859849723192973814 -0.023250000000000041467" rpy="1.5707963267949289765 -1.5657194067685196511e-14 -1.5707963267948827912" />
<geometry>
<mesh filename="package:///caderapt1.stl"/>
</geometry>
<material name="caderapt1_material">
<color rgba="0.97254901960784312376 0.97254901960784312376 0.97254901960784312376 1.0"/>
</material>
</visual>
<collision>
<origin xyz="0.010027549229562504607 -0.0094859849723192973814 -0.023250000000000041467" rpy="1.5707963267949289765 -1.5657194067685196511e-14 -1.5707963267948827912" />
<geometry>
<mesh filename="package:///caderapt1.stl"/>
</geometry>
</collision>
<visual>
<origin xyz="0.010027549229562240929 -0.0091859849723193581772 -0.023250000000000079631" rpy="1.5707963267949289765 -1.5657194067685196511e-14 -1.5707963267948827912" />
<geometry>
<mesh filename="package:///caderapt2_1.stl"/>
</geometry>
<material name="caderapt2_1_material">
<color rgba="0.97254901960784312376 0.97254901960784312376 0.97254901960784312376 1.0"/>
</material>
</visual>
<collision>
<origin xyz="0.010027549229562240929 -0.0091859849723193581772 -0.023250000000000079631" rpy="1.5707963267949289765 -1.5657194067685196511e-14 -1.5707963267948827912" />
<geometry>
<mesh filename="package:///caderapt2_1.stl"/>
</geometry>
</collision>
<visual>
<origin xyz="0.010027549229562282562 -0.0098109849723194697546 -0.023350000000000120659" rpy="1.5707963267949291986 -1.4807112479286665885e-14 -1.5707963267948830133" />
<geometry>
<mesh filename="package:///caderapt3_2.stl"/>
</geometry>
<material name="caderapt3_2_material">
<color rgba="0.97254901960784312376 0.97254901960784312376 0.97254901960784312376 1.0"/>
</material>
</visual>
<collision>
<origin xyz="0.010027549229562282562 -0.0098109849723194697546 -0.023350000000000120659" rpy="1.5707963267949291986 -1.4807112479286665885e-14 -1.5707963267948830133" />
<geometry>
<mesh filename="package:///caderapt3_2.stl"/>
</geometry>
</collision>
<visual>
<origin xyz="1.1102230246251565404e-16 -1.5265566588595902431e-16 -0.023399999999999976374" rpy="-3.141592653589793116 5.1028004907220281346e-16 -3.532708032038753155e-16" />
<geometry>
<mesh filename="package:///motorejecaja.stl"/>
</geometry>
<material name="motorejecaja_material">
<color rgba="0.26274509803921569651 0.28235294117647058432 0.30196078431372547213 1.0"/>
</material>
</visual>
<collision>
<origin xyz="1.1102230246251565404e-16 -1.5265566588595902431e-16 -0.023399999999999976374" rpy="-3.141592653589793116 5.1028004907220281346e-16 -3.532708032038753155e-16" />
<geometry>
<mesh filename="package:///motorejecaja.stl"/>
</geometry>
</collision>
<visual>
<origin xyz="1.3877787807814456755e-17 0 -0.023399999999999997191" rpy="3.141592653589793116 -2.0551600064082776505e-31 -4.1048585224827636755e-31" />
<geometry>
<mesh filename="package:///motorejeeje2.stl"/>
</geometry>
<material name="motorejeeje2_material">
<color rgba="0.64705882352941179736 0.64705882352941179736 0.64705882352941179736 1.0"/>
</material>
</visual>
<collision>
<origin xyz="1.3877787807814456755e-17 0 -0.023399999999999997191" rpy="3.141592653589793116 -2.0551600064082776505e-31 -4.1048585224827636755e-31" />
<geometry>
<mesh filename="package:///motorejeeje2.stl"/>
</geometry>
</collision>
<visual>
<origin xyz="1.3877787807814456755e-17 0 -0.023399999999999997191" rpy="3.141592653589793116 8.2429854080898915472e-16 1.1775693440123790742e-16" />
<geometry>
<mesh filename="package:///motorejeeje1.stl"/>
</geometry>
<material name="motorejeeje1_material">
<color rgba="0.64705882352941179736 0.64705882352941179736 0.64705882352941179736 1.0"/>
</material>
</visual>
<collision>
<origin xyz="1.3877787807814456755e-17 0 -0.023399999999999997191" rpy="3.141592653589793116 8.2429854080898915472e-16 1.1775693440123790742e-16" />
<geometry>
<mesh filename="package:///motorejeeje1.stl"/>
</geometry>
</collision>
<visual>
<origin xyz="0.010027549229562199296 -0.0097859849723192157689 -0.0232500000000000831" rpy="1.5707963267949291986 -1.4807112479286665885e-14 -1.5707963267948830133" />
<geometry>
<mesh filename="package:///caderapt2_2.stl"/>
</geometry>
<material name="caderapt2_2_material">
<color rgba="0.97254901960784312376 0.97254901960784312376 0.97254901960784312376 1.0"/>
</material>
</visual>
<collision>
<origin xyz="0.010027549229562199296 -0.0097859849723192157689 -0.0232500000000000831" rpy="1.5707963267949291986 -1.4807112479286665885e-14 -1.5707963267948830133" />
<geometry>
<mesh filename="package:///caderapt2_2.stl"/>
</geometry>
</collision>
<visual>
<origin xyz="0.010027549229562351951 -0.0098109849723193448545 -0.023150000000000031664" rpy="1.5707963267949298647 -1.4081522457228129389e-14 -1.5707963267949027752" />
<geometry>
<mesh filename="package:///caderapt3_1.stl"/>
</geometry>
<material name="caderapt3_1_material">
<color rgba="0.97254901960784312376 0.97254901960784312376 0.97254901960784312376 1.0"/>
</material>
</visual>
<collision>
<origin xyz="0.010027549229562351951 -0.0098109849723193448545 -0.023150000000000031664" rpy="1.5707963267949298647 -1.4081522457228129389e-14 -1.5707963267949027752" />
<geometry>
<mesh filename="package:///caderapt3_1.stl"/>
</geometry>
</collision>
<inertial>
<origin xyz="0.0019229001328382071875 -0.010041085604011923751 -0.023354508341491976575" rpy="0 0 0"/>
<mass value="0.36033150614011227875" />
<inertia ixx="0.00013063858229426779465" ixy="1.4491083147984981802e-07"  ixz="-7.2430643625584690474e-08" iyy="7.1173611389541510284e-05" iyz="4.0050341058355922109e-08" izz="0.00010253850500590588088" />
</inertial>
</link>

<link name="femururdf_2">
<visual>
<origin xyz="-3.9031278209478159624e-18 0 -0.023399999999999997191" rpy="-3.141592653589793116 -1.0146536357064405739e-17 -7.7380770829627854272e-31" />
<geometry>
<mesh filename="package:///motorejeacopleeje2.stl"/>
</geometry>
<material name="motorejeacopleeje2_material">
<color rgba="0.64705882352941179736 0.64705882352941179736 0.64705882352941179736 1.0"/>
</material>
</visual>
<collision>
<origin xyz="-3.9031278209478159624e-18 0 -0.023399999999999997191" rpy="-3.141592653589793116 -1.0146536357064405739e-17 -7.7380770829627854272e-31" />
<geometry>
<mesh filename="package:///motorejeacopleeje2.stl"/>
</geometry>
</collision>
<visual>
<origin xyz="-2.168404344971008868e-18 2.7755575615628913511e-17 -0.02339999999999969188" rpy="3.1415926535897860106 4.4302294772783549173e-14 -1.3449927902049318639e-27" />
<geometry>
<mesh filename="package:///motorejeacopleeje1.stl"/>
</geometry>
<material name="motorejeacopleeje1_material">
<color rgba="0.64705882352941179736 0.64705882352941179736 0.64705882352941179736 1.0"/>
</material>
</visual>
<collision>
<origin xyz="-2.168404344971008868e-18 2.7755575615628913511e-17 -0.02339999999999969188" rpy="3.1415926535897860106 4.4302294772783549173e-14 -1.3449927902049318639e-27" />
<geometry>
<mesh filename="package:///motorejeacopleeje1.stl"/>
</geometry>
</collision>
<visual>
<origin xyz="4.1286418728248008847e-16 -0.064999999999999974465 -0.023399999999999913924" rpy="3.1415926535897922278 -2.2202997064466968476e-14 3.141592653589793116" />
<geometry>
<mesh filename="package:///motorejeacoplecaja.stl"/>
</geometry>
<material name="motorejeacoplecaja_material">
<color rgba="0.26274509803921569651 0.28235294117647058432 0.30196078431372547213 1.0"/>
</material>
</visual>
<collision>
<origin xyz="4.1286418728248008847e-16 -0.064999999999999974465 -0.023399999999999913924" rpy="3.1415926535897922278 -2.2202997064466968476e-14 3.141592653589793116" />
<geometry>
<mesh filename="package:///motorejeacoplecaja.stl"/>
</geometry>
</collision>
<visual>
<origin xyz="1.7867651802561113072e-16 -0.043745909016608380826 -2.3592239273284576484e-16" rpy="8.6709952743964700826e-15 4.560325133169030399e-18 -1.6289827160844916297e-27" />
<geometry>
<mesh filename="package:///femur.stl"/>
</geometry>
<material name="femur_material">
<color rgba="0.97254901960784312376 0.97254901960784312376 0.97254901960784312376 1.0"/>
</material>
</visual>
<collision>
<origin xyz="1.7867651802561113072e-16 -0.043745909016608380826 -2.3592239273284576484e-16" rpy="8.6709952743964700826e-15 4.560325133169030399e-18 -1.6289827160844916297e-27" />
<geometry>
<mesh filename="package:///femur.stl"/>
</geometry>
</collision>
<visual>
<origin xyz="1.561251128379126385e-17 -0.064999999999999946709 -0.023399999999999476774" rpy="3.1415926535897926719 -2.2125730039145867067e-14 3.141592653589793116" />
<geometry>
<mesh filename="package:///motorejeacopleeje2.stl"/>
</geometry>
<material name="motorejeacopleeje2_material">
<color rgba="0.64705882352941179736 0.64705882352941179736 0.64705882352941179736 1.0"/>
</material>
</visual>
<collision>
<origin xyz="1.561251128379126385e-17 -0.064999999999999946709 -0.023399999999999476774" rpy="3.1415926535897926719 -2.2125730039145867067e-14 3.141592653589793116" />
<geometry>
<mesh filename="package:///motorejeacopleeje2.stl"/>
</geometry>
</collision>
<visual>
<origin xyz="4.336808689942017736e-19 2.7755575615628913511e-17 -0.023399999999999997191" rpy="3.1415926535897926719 1.6591112516210829069e-16 -1.6037391671173927057e-27" />
<geometry>
<mesh filename="package:///motorejeacoplecaja.stl"/>
</geometry>
<material name="motorejeacoplecaja_material">
<color rgba="0.26274509803921569651 0.28235294117647058432 0.30196078431372547213 1.0"/>
</material>
</visual>
<collision>
<origin xyz="4.336808689942017736e-19 2.7755575615628913511e-17 -0.023399999999999997191" rpy="3.1415926535897926719 1.6591112516210829069e-16 -1.6037391671173927057e-27" />
<geometry>
<mesh filename="package:///motorejeacoplecaja.stl"/>
</geometry>
</collision>
<visual>
<origin xyz="1.856154119295183591e-16 -0.043745909016608380826 -0.048800000000000190448" rpy="8.6709952743964700826e-15 4.560325133169030399e-18 -1.6289827160844916297e-27" />
<geometry>
<mesh filename="package:///femur.stl"/>
</geometry>
<material name="femur_material">
<color rgba="0.97254901960784312376 0.97254901960784312376 0.97254901960784312376 1.0"/>
</material>
</visual>
<collision>
<origin xyz="1.856154119295183591e-16 -0.043745909016608380826 -0.048800000000000190448" rpy="8.6709952743964700826e-15 4.560325133169030399e-18 -1.6289827160844916297e-27" />
<geometry>
<mesh filename="package:///femur.stl"/>
</geometry>
</collision>
<visual>
<origin xyz="4.0115480381963664058e-16 -0.065000000000000029976 -0.023399999999999997191" rpy="3.1415926535897877869 -2.2139595801131476845e-14 3.141592653589793116" />
<geometry>
<mesh filename="package:///motorejeacopleeje1.stl"/>
</geometry>
<material name="motorejeacopleeje1_material">
<color rgba="0.64705882352941179736 0.64705882352941179736 0.64705882352941179736 1.0"/>
</material>
</visual>
<collision>
<origin xyz="4.0115480381963664058e-16 -0.065000000000000029976 -0.023399999999999997191" rpy="3.1415926535897877869 -2.2139595801131476845e-14 3.141592653589793116" />
<geometry>
<mesh filename="package:///motorejeacopleeje1.stl"/>
</geometry>
</collision>
<inertial>
<origin xyz="1.4590295176714249999e-16 -0.032499999999999980294 -0.023399999999999955558" rpy="0 0 0"/>
<mass value="0.53868761965446410045" />
<inertia ixx="0.00043791203235393695754" ixy="1.3716554475268304796e-18"  ixz="-1.4201020929900158581e-18" iyy="0.0001090944632856163547" iyz="5.6412394287136402582e-19" izz="0.00036348717125268695596" />
</inertial>
</link>

<link name="tibiaurdf_2">
<visual>
<origin xyz="-0.02922481448218120989 0.016872954508304227605 0" rpy="3.141592653589793116 -2.0287423770944833997e-17 1.0471975511965976313" />
<geometry>
<mesh filename="package:///tibia.stl"/>
</geometry>
<material name="tibia_material">
<color rgba="0.97254901960784312376 0.97254901960784312376 0.97254901960784312376 1.0"/>
</material>
</visual>
<collision>
<origin xyz="-0.02922481448218120989 0.016872954508304227605 0" rpy="3.141592653589793116 -2.0287423770944833997e-17 1.0471975511965976313" />
<geometry>
<mesh filename="package:///tibia.stl"/>
</geometry>
</collision>
<visual>
<origin xyz="-0.047631397208144292399 0.027499999999999968914 0.023400000000000011069" rpy="-3.1415926535897917837 -1.0831625453053833588e-16 1.0471975511965976313" />
<geometry>
<mesh filename="package:///motorejeacopleeje1.stl"/>
</geometry>
<material name="motorejeacopleeje1_material">
<color rgba="0.64705882352941179736 0.64705882352941179736 0.64705882352941179736 1.0"/>
</material>
</visual>
<collision>
<origin xyz="-0.047631397208144292399 0.027499999999999968914 0.023400000000000011069" rpy="-3.1415926535897917837 -1.0831625453053833588e-16 1.0471975511965976313" />
<geometry>
<mesh filename="package:///motorejeacopleeje1.stl"/>
</geometry>
</collision>
<visual>
<origin xyz="-0.047631397208144334032 0.027499999999999885647 0.023400000000000018008" rpy="-3.1415926535897917837 -8.0420495664017016228e-17 1.0471975511965974093" />
<geometry>
<mesh filename="package:///motorejeacoplecaja.stl"/>
</geometry>
<material name="motorejeacoplecaja_material">
<color rgba="0.26274509803921569651 0.28235294117647058432 0.30196078431372547213 1.0"/>
</material>
</visual>
<collision>
<origin xyz="-0.047631397208144334032 0.027499999999999885647 0.023400000000000018008" rpy="-3.1415926535897917837 -8.0420495664017016228e-17 1.0471975511965974093" />
<geometry>
<mesh filename="package:///motorejeacoplecaja.stl"/>
</geometry>
</collision>
<visual>
<origin xyz="-0.029224814482181185604 0.016872954508304310872 0.048799999999999982281" rpy="-3.1415926535897922278 -8.0420495664017016228e-17 1.0471975511965974093" />
<geometry>
<mesh filename="package:///tibia.stl"/>
</geometry>
<material name="tibia_material">
<color rgba="0.97254901960784312376 0.97254901960784312376 0.97254901960784312376 1.0"/>
</material>
</visual>
<collision>
<origin xyz="-0.029224814482181185604 0.016872954508304310872 0.048799999999999982281" rpy="-3.1415926535897922278 -8.0420495664017016228e-17 1.0471975511965974093" />
<geometry>
<mesh filename="package:///tibia.stl"/>
</geometry>
</collision>
<visual>
<origin xyz="-0.04763139720814434791 0.027499999999999913403 0.023399999999999983313" rpy="-3.141592653589793116 1.9651233722326121006e-15 1.0471975511965976313" />
<geometry>
<mesh filename="package:///motorejeacopleeje2.stl"/>
</geometry>
<material name="motorejeacopleeje2_material">
<color rgba="0.64705882352941179736 0.64705882352941179736 0.64705882352941179736 1.0"/>
</material>
</visual>
<collision>
<origin xyz="-0.04763139720814434791 0.027499999999999913403 0.023399999999999983313" rpy="-3.141592653589793116 1.9651233722326121006e-15 1.0471975511965976313" />
<geometry>
<mesh filename="package:///motorejeacopleeje2.stl"/>
</geometry>
</collision>
<inertial>
<origin xyz="-0.037185466647235480842 0.021469039178648858385 0.02340000000000000413" rpy="0 0 0"/>
<mass value="0.28552673687099011657" />
<inertia ixx="7.7012953898988851338e-05" ixy="2.1231284255098450292e-05"  ixz="-1.4230153513872245696e-19" iyy="0.00010152872925693730234" iyz="-4.4257471494037192716e-20" izz="6.7501897454918637965e-05" />
</inertial>
</link>

<link name="tobillourdf_2">
<visual>
<origin xyz="0.000149999999999844702 -0.035799999999999221334 0.023375000000000003414" rpy="-1.570796326794896558 -1.570796326794896558 0" />
<geometry>
<mesh filename="package:///tobillopt3_1.stl"/>
</geometry>
<material name="tobillopt3_1_material">
<color rgba="0.97254901960784312376 0.97254901960784312376 0.97254901960784312376 1.0"/>
</material>
</visual>
<collision>
<origin xyz="0.000149999999999844702 -0.035799999999999221334 0.023375000000000003414" rpy="-1.570796326794896558 -1.570796326794896558 0" />
<geometry>
<mesh filename="package:///tobillopt3_1.stl"/>
</geometry>
</collision>
<visual>
<origin xyz="2.2204460492503130808e-16 -0.03579999999999999849 0.023550000000000185368" rpy="-1.570796326794896558 -1.570796326794896558 0" />
<geometry>
<mesh filename="package:///tobillopt1.stl"/>
</geometry>
<material name="tobillopt1_material">
<color rgba="0.97254901960784312376 0.97254901960784312376 0.97254901960784312376 1.0"/>
</material>
</visual>
<collision>
<origin xyz="2.2204460492503130808e-16 -0.03579999999999999849 0.023550000000000185368" rpy="-1.570796326794896558 -1.570796326794896558 0" />
<geometry>
<mesh filename="package:///tobillopt1.stl"/>
</geometry>
</collision>
<visual>
<origin xyz="0.00019999999999920081706 -0.025772450770436577949 0.013564015027677751163" rpy="1.5707963267949669461 -1.4981390300812931148e-13 1.5707963267949953678" />
<geometry>
<mesh filename="package:///motorejecaja.stl"/>
</geometry>
<material name="motorejecaja_material">
<color rgba="0.26274509803921569651 0.28235294117647058432 0.30196078431372547213 1.0"/>
</material>
</visual>
<collision>
<origin xyz="0.00019999999999920081706 -0.025772450770436577949 0.013564015027677751163" rpy="1.5707963267949669461 -1.4981390300812931148e-13 1.5707963267949953678" />
<geometry>
<mesh filename="package:///motorejecaja.stl"/>
</geometry>
</collision>
<visual>
<origin xyz="-0.00014999999999995572431 -0.035799999999999526645 0.023374999999999982597" rpy="-1.570796326794896558 -1.5707963267948956698 0" />
<geometry>
<mesh filename="package:///tobillopt3_2.stl"/>
</geometry>
<material name="tobillopt3_2_material">
<color rgba="0.97254901960784312376 0.97254901960784312376 0.97254901960784312376 1.0"/>
</material>
</visual>
<collision>
<origin xyz="-0.00014999999999995572431 -0.035799999999999526645 0.023374999999999982597" rpy="-1.570796326794896558 -1.5707963267948956698 0" />
<geometry>
<mesh filename="package:///tobillopt3_2.stl"/>
</geometry>
</collision>
<visual>
<origin xyz="0.00019999999999920081706 -0.025772450770436577949 0.013564015027677751163" rpy="1.5707963267949669461 -1.4888926185284871784e-13 1.5707963267949955899" />
<geometry>
<mesh filename="package:///motorejeeje2.stl"/>
</geometry>
<material name="motorejeeje2_material">
<color rgba="0.64705882352941179736 0.64705882352941179736 0.64705882352941179736 1.0"/>
</material>
</visual>
<collision>
<origin xyz="0.00019999999999920081706 -0.025772450770436577949 0.013564015027677751163" rpy="1.5707963267949669461 -1.4888926185284871784e-13 1.5707963267949955899" />
<geometry>
<mesh filename="package:///motorejeeje2.stl"/>
</geometry>
</collision>
<visual>
<origin xyz="0.00019999999999920081706 -0.025772450770436577949 0.01356401502767770953" rpy="1.570796326794966502 -1.6447713354339410106e-13 1.5707963267949989206" />
<geometry>
<mesh filename="package:///motorejeeje1.stl"/>
</geometry>
<material name="motorejeeje1_material">
<color rgba="0.64705882352941179736 0.64705882352941179736 0.64705882352941179736 1.0"/>
</material>
</visual>
<collision>
<origin xyz="0.00019999999999920081706 -0.025772450770436577949 0.01356401502767770953" rpy="1.570796326794966502 -1.6447713354339410106e-13 1.5707963267949989206" />
<geometry>
<mesh filename="package:///motorejeeje1.stl"/>
</geometry>
</collision>
<visual>
<origin xyz="1.3877787807814456755e-16 -0.035799999999999942979 0.023850000000000124573" rpy="-1.570796326794896558 -1.570796326794896558 0" />
<geometry>
<mesh filename="package:///tobillopt2_2.stl"/>
</geometry>
<material name="tobillopt2_2_material">
<color rgba="0.97254901960784312376 0.97254901960784312376 0.97254901960784312376 1.0"/>
</material>
</visual>
<collision>
<origin xyz="1.3877787807814456755e-16 -0.035799999999999942979 0.023850000000000124573" rpy="-1.570796326794896558 -1.570796326794896558 0" />
<geometry>
<mesh filename="package:///tobillopt2_2.stl"/>
</geometry>
</collision>
<visual>
<origin xyz="2.7755575615628913511e-17 -0.035799999999999970735 0.023250000000000010242" rpy="-1.570796326794896558 -1.570796326794896558 0" />
<geometry>
<mesh filename="package:///tobillopt2_1.stl"/>
</geometry>
<material name="tobillopt2_1_material">
<color rgba="0.97254901960784312376 0.97254901960784312376 0.97254901960784312376 1.0"/>
</material>
</visual>
<collision>
<origin xyz="2.7755575615628913511e-17 -0.035799999999999970735 0.023250000000000010242" rpy="-1.570796326794896558 -1.570796326794896558 0" />
<geometry>
<mesh filename="package:///tobillopt2_1.stl"/>
</geometry>
</collision>
<inertial>
<origin xyz="0.00013965747905148943029 -0.025656106121456755814 0.02368833233693950352" rpy="0 0 0"/>
<mass value="0.35953278469495453251" />
<inertia ixx="0.00010180132077840532679" ixy="5.8418326095888926038e-09"  ixz="5.7602954082226975642e-08" iyy="0.00013007031479290759486" iyz="5.2659589177728379514e-07" izz="7.0605342570129279046e-05" />
</inertial>
</link>

<link name="pieurdf_2">
<visual>
<origin xyz="-0.010000000000000043576 -0.018999999999999961364 0.02340000000000000413" rpy="-1.57079632679489678 -1.5707963267948961139 0" />
<geometry>
<mesh filename="package:///acoplepiemotor.stl"/>
</geometry>
<material name="acoplepiemotor_material">
<color rgba="0.97254901960784312376 0.97254901960784312376 0.97254901960784312376 1.0"/>
</material>
</visual>
<collision>
<origin xyz="-0.010000000000000043576 -0.018999999999999961364 0.02340000000000000413" rpy="-1.57079632679489678 -1.5707963267948961139 0" />
<geometry>
<mesh filename="package:///acoplepiemotor.stl"/>
</geometry>
</collision>
<visual>
<origin xyz="-0.0099999999999999811262 -0.018999999999999933609 0.023500000000000437206" rpy="-1.57079632679489678 -1.5707963267948961139 0" />
<geometry>
<mesh filename="package:///acoplepiemotor.stl"/>
</geometry>
<material name="acoplepiemotor_material">
<color rgba="0.97254901960784312376 0.97254901960784312376 0.97254901960784312376 1.0"/>
</material>
</visual>
<collision>
<origin xyz="-0.0099999999999999811262 -0.018999999999999933609 0.023500000000000437206" rpy="-1.57079632679489678 -1.5707963267948961139 0" />
<geometry>
<mesh filename="package:///acoplepiemotor.stl"/>
</geometry>
</collision>
<visual>
<origin xyz="-0.0099999999999999533706 -0.018950000000000133404 0.023450000000000470468" rpy="-1.57079632679489678 -1.5707963267948961139 0" />
<geometry>
<mesh filename="package:///plantapie.stl"/>
</geometry>
<material name="plantapie_material">
<color rgba="0.97254901960784312376 0.97254901960784312376 0.97254901960784312376 1.0"/>
</material>
</visual>
<collision>
<origin xyz="-0.0099999999999999533706 -0.018950000000000133404 0.023450000000000470468" rpy="-1.57079632679489678 -1.5707963267948961139 0" />
<geometry>
<mesh filename="package:///plantapie.stl"/>
</geometry>
</collision>
<inertial>
<origin xyz="-0.00959819628771610249 -0.018994815818902686944 0.02345000000000039761" rpy="0 0 0"/>
<mass value="0.12193030814742022994" />
<inertia ixx="5.5790028401553460973e-05" ixy="-1.0383957421083932115e-06"  ixz="-2.5246223932549079441e-21" iyy="7.8275338616851252338e-05" iyz="7.3834889668061930283e-20" izz="3.3440055653628954343e-05" />
</inertial>
</link>

<joint name="RightAnkle2" type="revolute">
<origin xyz="-0.023200000000000831069 -0.025772450770438881662 0.013564015027679409559" rpy="-9.8713777730327891289e-14 1.5707963267947468999 0" />
<parent link="tobillourdf_2" />
<child link="pieurdf_2" />
<axis xyz="0 0 1"/>
<limit effort="1" velocity="20" lower="-0.26179938779914940783" upper="0.26179938779914940783"/>
<joint_properties friction="0.0"/>
</joint>

<joint name="RightAnkle1" type="revolute">
<origin xyz="-0.047631397208144354849 0.027499999999999885647 0.046800000000000029077" rpy="-3.1415926535897908956 -2.4069865602134688359e-15 1.0471975511965929684" />
<parent link="tibiaurdf_2" />
<child link="tobillourdf_2" />
<axis xyz="0 0 1"/>
<limit effort="1" velocity="20" lower="-0.785398163397448279" upper="0.52359877559829881566"/>
<joint_properties friction="0.0"/>
</joint>

<joint name="RightKnee" type="revolute">
<origin xyz="1.3053794156725473385e-16 -0.064999999999999807931 -1.0963452368173420837e-15" rpy="3.1415926535897895633 -5.1908057209288357076e-17 3.6528103707004495366e-15" />
<parent link="femururdf_2" />
<child link="tibiaurdf_2" />
<axis xyz="0 0 1"/>
<limit effort="1" velocity="20" lower="-1.0471975511965976313" upper="1.0471975511965976313"/>
<joint_properties friction="0.0"/>
</joint>

<joint name="RightHip2" type="revolute">
<origin xyz="0.028027549229562492838 -0.03303598497231897968 -0.023249999999999160227" rpy="1.5707963267949229813 -1.5707963267948594765 0" />
<parent link="cadera_v01_2" />
<child link="femururdf_2" />
<axis xyz="0 0 1"/>
<limit effort="1" velocity="20" lower="-1.570796326794896558" upper="1.570796326794896558"/>
<joint_properties friction="0.0"/>
</joint>

<joint name="RightHip1" type="revolute">
<origin xyz="-0.00061949317509201601295 0.032685236218795134244 -0.023605436102933322062" rpy="-2.3561944901923403961 1.570796326794891673 0" />
<parent link="cintura_v01_2" />
<child link="cadera_v01_2" />
<axis xyz="0 0 1"/>
<limit effort="1" velocity="20" lower="-0.785398163397448279" upper="0.785398163397448279"/>
<joint_properties friction="0.0"/>
</joint>

<joint name="RightWaist" type="revolute">
<origin xyz="-0.010742981990015255944 0.0083712188771943186333 -0.083178910040700965167" rpy="5.1336160526084935663e-31 -6.2213430271953116103e-32 1.5707963267948970021" />
<parent link="torsourdf" />
<child link="cintura_v01_2" />
<axis xyz="0 0 1"/>
<limit effort="1" velocity="20" lower="-1.570796326794896558" upper="1.570796326794896558"/>
<joint_properties friction="0.0"/>
</joint>


</robot>
