<robot name="onshape">
<link name="torsourdf">
<visual>
<origin xyz="-0.030742981990015266769 0.038371218877194315788 -0.076728910040700981643" rpy="1.570796326794896558 -0 0" />
<geometry>
<mesh filename="package:///acople_tornillos_abdomen.stl"/>
</geometry>
<material name="acople_tornillos_abdomen_material">
<color rgba="0.26274509803921569651 0.28235294117647058432 0.30196078431372547213 1.0"/>
</material>
</visual>
<collision>
<origin xyz="-0.030742981990015266769 0.038371218877194315788 -0.076728910040700981643" rpy="1.570796326794896558 -0 0" />
<geometry>
<mesh filename="package:///acople_tornillos_abdomen.stl"/>
</geometry>
</collision>
<visual>
<origin xyz="0.064057018009984756368 0.038371218877194308849 0.050524780976926725318" rpy="-1.570796326794896558 -0 3.141592653589793116" />
<geometry>
<mesh filename="package:///acople_tornillos_cuello.stl"/>
</geometry>
<material name="acople_tornillos_cuello_material">
<color rgba="0.26274509803921569651 0.28235294117647058432 0.30196078431372547213 1.0"/>
</material>
</visual>
<collision>
<origin xyz="0.064057018009984756368 0.038371218877194308849 0.050524780976926725318" rpy="-1.570796326794896558 -0 3.141592653589793116" />
<geometry>
<mesh filename="package:///acople_tornillos_cuello.stl"/>
</geometry>
</collision>
<visual>
<origin xyz="0.019257018009984729068 0.0083712188771943168986 -0.059778910040700981854" rpy="3.141592653589793116 -0 3.141592653589793116" />
<geometry>
<mesh filename="package:///motorsemiejeeje.stl"/>
</geometry>
<material name="motorsemiejeeje_material">
<color rgba="0.64705882352941179736 0.64705882352941179736 0.64705882352941179736 1.0"/>
</material>
</visual>
<collision>
<origin xyz="0.019257018009984729068 0.0083712188771943168986 -0.059778910040700981854" rpy="3.141592653589793116 -0 3.141592653589793116" />
<geometry>
<mesh filename="package:///motorsemiejeeje.stl"/>
</geometry>
</collision>
<visual>
<origin xyz="-0.055542981990015269367 0.038371218877194329666 -0.037828910040700991502" rpy="1.570796326794896558 -0 0" />
<geometry>
<mesh filename="package:///acople_tornillos_abdomen.stl"/>
</geometry>
<material name="acople_tornillos_abdomen_material">
<color rgba="0.26274509803921569651 0.28235294117647058432 0.30196078431372547213 1.0"/>
</material>
</visual>
<collision>
<origin xyz="-0.055542981990015269367 0.038371218877194329666 -0.037828910040700991502" rpy="1.570796326794896558 -0 0" />
<geometry>
<mesh filename="package:///acople_tornillos_abdomen.stl"/>
</geometry>
</collision>
<visual>
<origin xyz="0.069405821023547836779 0.0073712188771943021326 0.025468521028911533799" rpy="-1.570796326794896558 -0 -1.570796326794896558" />
<geometry>
<mesh filename="package:///motorejeeje2.stl"/>
</geometry>
<material name="motorejeeje2_material">
<color rgba="0.64705882352941179736 0.64705882352941179736 0.64705882352941179736 1.0"/>
</material>
</visual>
<collision>
<origin xyz="0.069405821023547836779 0.0073712188771943021326 0.025468521028911533799" rpy="-1.570796326794896558 -0 -1.570796326794896558" />
<geometry>
<mesh filename="package:///motorejeeje2.stl"/>
</geometry>
</collision>
<visual>
<origin xyz="-0.060891785003578363655 0.0073712188771943021326 0.025468521028911547677" rpy="-1.570796326794896558 -0 1.570796326794896558" />
<geometry>
<mesh filename="package:///motorejeeje1.stl"/>
</geometry>
<material name="motorejeeje1_material">
<color rgba="0.64705882352941179736 0.64705882352941179736 0.64705882352941179736 1.0"/>
</material>
</visual>
<collision>
<origin xyz="-0.060891785003578363655 0.0073712188771943021326 0.025468521028911547677" rpy="-1.570796326794896558 -0 1.570796326794896558" />
<geometry>
<mesh filename="package:///motorejeeje1.stl"/>
</geometry>
</collision>
<visual>
<origin xyz="0.004057018009984730833 -0.023628781122805697645 -0.0045580513594990768045" rpy="1.570796326794896558 -0 0" />
<geometry>
<mesh filename="package:///pecho.stl"/>
</geometry>
<material name="pecho_material">
<color rgba="0.97254901960784312376 0.97254901960784312376 0.97254901960784312376 1.0"/>
</material>
</visual>
<collision>
<origin xyz="0.004057018009984730833 -0.023628781122805697645 -0.0045580513594990768045" rpy="1.570796326794896558 -0 0" />
<geometry>
<mesh filename="package:///pecho.stl"/>
</geometry>
</collision>
<visual>
<origin xyz="0.069405821023547836779 0.0073712188771943021326 0.025468521028911547677" rpy="-1.5707963267948976682 1.9721522630525216312e-31 -1.570796326794896336" />
<geometry>
<mesh filename="package:///motorejeeje1.stl"/>
</geometry>
<material name="motorejeeje1_material">
<color rgba="0.64705882352941179736 0.64705882352941179736 0.64705882352941179736 1.0"/>
</material>
</visual>
<collision>
<origin xyz="0.069405821023547836779 0.0073712188771943021326 0.025468521028911547677" rpy="-1.5707963267948976682 1.9721522630525216312e-31 -1.570796326794896336" />
<geometry>
<mesh filename="package:///motorejeeje1.stl"/>
</geometry>
</collision>
<visual>
<origin xyz="0.087855821023547830961 0.007371218877194305602 0.025468521028911547677" rpy="-1.570796326794896558 -0 -1.570796326794896558" />
<geometry>
<mesh filename="package:///hombro_pecho.stl"/>
</geometry>
<material name="hombro_pecho_material">
<color rgba="0.97254901960784312376 0.97254901960784312376 0.97254901960784312376 1.0"/>
</material>
</visual>
<collision>
<origin xyz="0.087855821023547830961 0.007371218877194305602 0.025468521028911547677" rpy="-1.570796326794896558 -0 -1.570796326794896558" />
<geometry>
<mesh filename="package:///hombro_pecho.stl"/>
</geometry>
</collision>
<visual>
<origin xyz="-0.010742981990015254209 0.0083712188771943238375 -0.059778910040700974915" rpy="3.141592653589793116 -0 3.141592653589793116" />
<geometry>
<mesh filename="package:///motorsemiejecaja.stl"/>
</geometry>
<material name="motorsemiejecaja_material">
<color rgba="0.26274509803921569651 0.28235294117647058432 0.30196078431372547213 1.0"/>
</material>
</visual>
<collision>
<origin xyz="-0.010742981990015254209 0.0083712188771943238375 -0.059778910040700974915" rpy="3.141592653589793116 -0 3.141592653589793116" />
<geometry>
<mesh filename="package:///motorsemiejecaja.stl"/>
</geometry>
</collision>
<visual>
<origin xyz="-0.079341785003578357838 0.0073712188771942951937 0.025468521028911547677" rpy="-1.570796326794896558 -0 1.570796326794896558" />
<geometry>
<mesh filename="package:///hombro_pecho.stl"/>
</geometry>
<material name="hombro_pecho_material">
<color rgba="0.97254901960784312376 0.97254901960784312376 0.97254901960784312376 1.0"/>
</material>
</visual>
<collision>
<origin xyz="-0.079341785003578357838 0.0073712188771942951937 0.025468521028911547677" rpy="-1.570796326794896558 -0 1.570796326794896558" />
<geometry>
<mesh filename="package:///hombro_pecho.stl"/>
</geometry>
</collision>
<visual>
<origin xyz="-0.060891785003578363655 0.0073712188771943021326 0.025468521028911547677" rpy="-1.57079632679489678 -7.8886090522100182116e-31 1.57079632679489678" />
<geometry>
<mesh filename="package:///motorejeeje2.stl"/>
</geometry>
<material name="motorejeeje2_material">
<color rgba="0.64705882352941179736 0.64705882352941179736 0.64705882352941179736 1.0"/>
</material>
</visual>
<collision>
<origin xyz="-0.060891785003578363655 0.0073712188771943021326 0.025468521028911547677" rpy="-1.57079632679489678 -7.8886090522100182116e-31 1.57079632679489678" />
<geometry>
<mesh filename="package:///motorejeeje2.stl"/>
</geometry>
</collision>
<visual>
<origin xyz="-0.010742981990015255944 0.0083712188771943168986 -0.059778910040700981854" rpy="3.141592653589793116 -0 3.141592653589793116" />
<geometry>
<mesh filename="package:///motorsemiejeeje.stl"/>
</geometry>
<material name="motorsemiejeeje_material">
<color rgba="0.64705882352941179736 0.64705882352941179736 0.64705882352941179736 1.0"/>
</material>
</visual>
<collision>
<origin xyz="-0.010742981990015255944 0.0083712188771943168986 -0.059778910040700981854" rpy="3.141592653589793116 -0 3.141592653589793116" />
<geometry>
<mesh filename="package:///motorsemiejeeje.stl"/>
</geometry>
</collision>
<visual>
<origin xyz="0.0042570180099847365618 0.040371218877194303687 -0.0045580513594990490489" rpy="1.570796326794896558 -0 0" />
<geometry>
<mesh filename="package:///espalda.stl"/>
</geometry>
<material name="espalda_material">
<color rgba="0.97254901960784312376 0.97254901960784312376 0.97254901960784312376 1.0"/>
</material>
</visual>
<collision>
<origin xyz="0.0042570180099847365618 0.040371218877194303687 -0.0045580513594990490489" rpy="1.570796326794896558 -0 0" />
<geometry>
<mesh filename="package:///espalda.stl"/>
</geometry>
</collision>
<visual>
<origin xyz="-0.060891785003578363655 0.0073712188771942917243 0.025468521028911547677" rpy="-1.570796326794896558 -0 1.570796326794896558" />
<geometry>
<mesh filename="package:///motorejecaja.stl"/>
</geometry>
<material name="motorejecaja_material">
<color rgba="0.26274509803921569651 0.28235294117647058432 0.30196078431372547213 1.0"/>
</material>
</visual>
<collision>
<origin xyz="-0.060891785003578363655 0.0073712188771942917243 0.025468521028911547677" rpy="-1.570796326794896558 -0 1.570796326794896558" />
<geometry>
<mesh filename="package:///motorejecaja.stl"/>
</geometry>
</collision>
<visual>
<origin xyz="-0.055942981990015253069 -0.023628781122805697645 0.050524780976926725318" rpy="-1.570796326794896558 -0 0" />
<geometry>
<mesh filename="package:///acople_tornillos_cuello.stl"/>
</geometry>
<material name="acople_tornillos_cuello_material">
<color rgba="0.26274509803921569651 0.28235294117647058432 0.30196078431372547213 1.0"/>
</material>
</visual>
<collision>
<origin xyz="-0.055942981990015253069 -0.023628781122805697645 0.050524780976926725318" rpy="-1.570796326794896558 -0 0" />
<geometry>
<mesh filename="package:///acople_tornillos_cuello.stl"/>
</geometry>
</collision>
<visual>
<origin xyz="0.014057018009984739715 0.007371218877194305602 0.054024780976926728426" rpy="3.141592653589793116 -0 -1.570796326794896558" />
<geometry>
<mesh filename="package:///base_cabeza.stl"/>
</geometry>
<material name="base_cabeza_material">
<color rgba="0.97254901960784312376 0.97254901960784312376 0.97254901960784312376 1.0"/>
</material>
</visual>
<collision>
<origin xyz="0.014057018009984739715 0.007371218877194305602 0.054024780976926728426" rpy="3.141592653589793116 -0 -1.570796326794896558" />
<geometry>
<mesh filename="package:///base_cabeza.stl"/>
</geometry>
</collision>
<visual>
<origin xyz="-0.010542981990015257154 0.023946218877194329344 -0.04132891004070099461" rpy="0 -0 0" />
<geometry>
<mesh filename="package:///acoplemotorestorso1.stl"/>
</geometry>
<material name="acoplemotorestorso1_material">
<color rgba="0.97254901960784312376 0.97254901960784312376 0.97254901960784312376 1.0"/>
</material>
</visual>
<collision>
<origin xyz="-0.010542981990015257154 0.023946218877194329344 -0.04132891004070099461" rpy="0 -0 0" />
<geometry>
<mesh filename="package:///acoplemotorestorso1.stl"/>
</geometry>
</collision>
<visual>
<origin xyz="-0.010742981990015262883 0.023946218877194322405 -0.080228910040700984752" rpy="0 -0 0" />
<geometry>
<mesh filename="package:///acoplemotorestorso2.stl"/>
</geometry>
<material name="acoplemotorestorso2_material">
<color rgba="0.97254901960784312376 0.97254901960784312376 0.97254901960784312376 1.0"/>
</material>
</visual>
<collision>
<origin xyz="-0.010742981990015262883 0.023946218877194322405 -0.080228910040700984752" rpy="0 -0 0" />
<geometry>
<mesh filename="package:///acoplemotorestorso2.stl"/>
</geometry>
</collision>
<visual>
<origin xyz="-0.077841785003578356505 -0.023628781122805683768 -0.0070314789710884256779" rpy="-1.570796326794896558 -1.570796326794896558 0" />
<geometry>
<mesh filename="package:///acople_tornillos_hombro.stl"/>
</geometry>
<material name="acople_tornillos_hombro_material">
<color rgba="0.26274509803921569651 0.28235294117647058432 0.30196078431372547213 1.0"/>
</material>
</visual>
<collision>
<origin xyz="-0.077841785003578356505 -0.023628781122805683768 -0.0070314789710884256779" rpy="-1.570796326794896558 -1.570796326794896558 0" />
<geometry>
<mesh filename="package:///acople_tornillos_hombro.stl"/>
</geometry>
</collision>
<visual>
<origin xyz="0.086355821023547829629 0.038371218877194274155 -0.0070314789710884395557" rpy="1.570796326794896558 -1.570796326794896558 0" />
<geometry>
<mesh filename="package:///acople_tornillos_hombro.stl"/>
</geometry>
<material name="acople_tornillos_hombro_material">
<color rgba="0.26274509803921569651 0.28235294117647058432 0.30196078431372547213 1.0"/>
</material>
</visual>
<collision>
<origin xyz="0.086355821023547829629 0.038371218877194274155 -0.0070314789710884395557" rpy="1.570796326794896558 -1.570796326794896558 0" />
<geometry>
<mesh filename="package:///acople_tornillos_hombro.stl"/>
</geometry>
</collision>
<visual>
<origin xyz="0.086355821023547829629 -0.023628781122805697645 0.037968521028911544901" rpy="-1.570796326794896558 1.570796326794896558 0" />
<geometry>
<mesh filename="package:///acople_tornillos_hombro.stl"/>
</geometry>
<material name="acople_tornillos_hombro_material">
<color rgba="0.26274509803921569651 0.28235294117647058432 0.30196078431372547213 1.0"/>
</material>
</visual>
<collision>
<origin xyz="0.086355821023547829629 -0.023628781122805697645 0.037968521028911544901" rpy="-1.570796326794896558 1.570796326794896558 0" />
<geometry>
<mesh filename="package:///acople_tornillos_hombro.stl"/>
</geometry>
</collision>
<visual>
<origin xyz="0.039257018009984739892 -0.0216287811228056924 -0.076728910040700981643" rpy="1.570796326794896558 -0 3.141592653589793116" />
<geometry>
<mesh filename="package:///acople_tornillos_abdomen.stl"/>
</geometry>
<material name="acople_tornillos_abdomen_material">
<color rgba="0.26274509803921569651 0.28235294117647058432 0.30196078431372547213 1.0"/>
</material>
</visual>
<collision>
<origin xyz="0.039257018009984739892 -0.0216287811228056924 -0.076728910040700981643" rpy="1.570796326794896558 -0 3.141592653589793116" />
<geometry>
<mesh filename="package:///acople_tornillos_abdomen.stl"/>
</geometry>
</collision>
<visual>
<origin xyz="0.064457018009984712315 -0.021628781122805678522 -0.037828910040700991502" rpy="1.570796326794896558 -0 3.141592653589793116" />
<geometry>
<mesh filename="package:///acople_tornillos_abdomen.stl"/>
</geometry>
<material name="acople_tornillos_abdomen_material">
<color rgba="0.26274509803921569651 0.28235294117647058432 0.30196078431372547213 1.0"/>
</material>
</visual>
<collision>
<origin xyz="0.064457018009984712315 -0.021628781122805678522 -0.037828910040700991502" rpy="1.570796326794896558 -0 3.141592653589793116" />
<geometry>
<mesh filename="package:///acople_tornillos_abdomen.stl"/>
</geometry>
</collision>
<visual>
<origin xyz="0.0042570180099847365618 -0.023628781122805683768 -0.0045580513594990629267" rpy="1.570796326794896558 -0 3.141592653589793116" />
<geometry>
<mesh filename="package:///abdomen.stl"/>
</geometry>
<material name="abdomen_material">
<color rgba="0.26274509803921569651 0.28235294117647058432 0.30196078431372547213 1.0"/>
</material>
</visual>
<collision>
<origin xyz="0.0042570180099847365618 -0.023628781122805683768 -0.0045580513594990629267" rpy="1.570796326794896558 -0 3.141592653589793116" />
<geometry>
<mesh filename="package:///abdomen.stl"/>
</geometry>
</collision>
<visual>
<origin xyz="-0.077841785003578356505 0.038371218877194301911 0.037968521028911544901" rpy="1.570796326794896558 1.570796326794896558 0" />
<geometry>
<mesh filename="package:///acople_tornillos_hombro.stl"/>
</geometry>
<material name="acople_tornillos_hombro_material">
<color rgba="0.26274509803921569651 0.28235294117647058432 0.30196078431372547213 1.0"/>
</material>
</visual>
<collision>
<origin xyz="-0.077841785003578356505 0.038371218877194301911 0.037968521028911544901" rpy="1.570796326794896558 1.570796326794896558 0" />
<geometry>
<mesh filename="package:///acople_tornillos_hombro.stl"/>
</geometry>
</collision>
<visual>
<origin xyz="0.069405821023547836779 0.0073712188771943021326 0.025468521028911533799" rpy="-1.570796326794896558 -0 -1.570796326794896558" />
<geometry>
<mesh filename="package:///motorejecaja.stl"/>
</geometry>
<material name="motorejecaja_material">
<color rgba="0.26274509803921569651 0.28235294117647058432 0.30196078431372547213 1.0"/>
</material>
</visual>
<collision>
<origin xyz="0.069405821023547836779 0.0073712188771943021326 0.025468521028911533799" rpy="-1.570796326794896558 -0 -1.570796326794896558" />
<geometry>
<mesh filename="package:///motorejecaja.stl"/>
</geometry>
</collision>
<visual>
<origin xyz="0.004057018009984730833 -0.023628781122805697645 -0.0045580513594990768045" rpy="1.570796326794896558 -0 0" />
<geometry>
<mesh filename="package:///luzpecho.stl"/>
</geometry>
<material name="luzpecho_material">
<color rgba="0.14117647058823529216 0.6941176470588235059 0.65098039215686276382 1.0"/>
</material>
</visual>
<collision>
<origin xyz="0.004057018009984730833 -0.023628781122805697645 -0.0045580513594990768045" rpy="1.570796326794896558 -0 0" />
<geometry>
<mesh filename="package:///luzpecho.stl"/>
</geometry>
</collision>
<visual>
<origin xyz="0.01925701800998471519 0.0083712188771943238375 -0.059778910040700974915" rpy="3.141592653589793116 -0 3.141592653589793116" />
<geometry>
<mesh filename="package:///motorsemiejecaja.stl"/>
</geometry>
<material name="motorsemiejecaja_material">
<color rgba="0.26274509803921569651 0.28235294117647058432 0.30196078431372547213 1.0"/>
</material>
</visual>
<collision>
<origin xyz="0.01925701800998471519 0.0083712188771943238375 -0.059778910040700974915" rpy="3.141592653589793116 -0 3.141592653589793116" />
<geometry>
<mesh filename="package:///motorsemiejecaja.stl"/>
</geometry>
</collision>
<inertial>
<origin xyz="0.0041641753467128710814 -0.0069926972537796023427 -0.0054565398185849878221" rpy="0 0 0"/>
<mass value="3.2921674694110931725" />
<inertia ixx="0.0076880102936372884254" ixy="-6.7916077198656380886e-06"  ixz="6.7702832083639237579e-06" iyy="0.013499449690620241721" iyz="0.00096379853423097215388" izz="0.0097359687391730415779" />
</inertial>
</link>

<link name="hombro-brazo">
<visual>
<origin xyz="-1.1362438767648086468e-16 -0.010999809727072717286 -0.0020000000000000017764" rpy="3.141592653589793116 -4.9303806576206958108e-32 0" />
<geometry>
<mesh filename="package:///hombro_brazo1.stl"/>
</geometry>
<material name="hombro_brazo1_material">
<color rgba="0.97254901960784312376 0.97254901960784312376 0.97254901960784312376 1.0"/>
</material>
</visual>
<collision>
<origin xyz="-1.1362438767648086468e-16 -0.010999809727072717286 -0.0020000000000000017764" rpy="3.141592653589793116 -4.9303806576206958108e-32 0" />
<geometry>
<mesh filename="package:///hombro_brazo1.stl"/>
</geometry>
</collision>
<visual>
<origin xyz="-0.0002999999999956952032 0.011000190272924889254 9.4368957093138305936e-16" rpy="-3.1415926535897895633 -2.6645352591003760126e-14 -3.1415926535897864547" />
<geometry>
<mesh filename="package:///hombro_brazo2.stl"/>
</geometry>
<material name="hombro_brazo2_material">
<color rgba="0.97254901960784312376 0.97254901960784312376 0.97254901960784312376 1.0"/>
</material>
</visual>
<collision>
<origin xyz="-0.0002999999999956952032 0.011000190272924889254 9.4368957093138305936e-16" rpy="-3.1415926535897895633 -2.6645352591003760126e-14 -3.1415926535897864547" />
<geometry>
<mesh filename="package:///hombro_brazo2.stl"/>
</geometry>
</collision>
<visual>
<origin xyz="0.00029999999999982904925 -0.010999809727072731164 6.8001160258290838101e-16" rpy="3.1415926535897926719 5.5511151231205328328e-16 -2.488009798184976312e-13" />
<geometry>
<mesh filename="package:///hombro_brazo2.stl"/>
</geometry>
<material name="hombro_brazo2_material">
<color rgba="0.97254901960784312376 0.97254901960784312376 0.97254901960784312376 1.0"/>
</material>
</visual>
<collision>
<origin xyz="0.00029999999999982904925 -0.010999809727072731164 6.8001160258290838101e-16" rpy="3.1415926535897926719 5.5511151231205328328e-16 -2.488009798184976312e-13" />
<geometry>
<mesh filename="package:///hombro_brazo2.stl"/>
</geometry>
</collision>
<inertial>
<origin xyz="1.7014733176725469645e-15 1.1044824123134685127e-07 -0.0076081599888872270682" rpy="0 0 0"/>
<mass value="0.028276359613946904642" />
<inertia ixx="3.1909882339227924317e-06" ixy="7.6383436214142512257e-11"  ixz="4.601506485958986592e-19" iyy="1.3925926827988112166e-05" iyz="1.4915617611435925893e-11" izz="1.2743353645780911143e-05" />
</inertial>
</link>

<link name="brazourdf">
<visual>
<origin xyz="1.3877787807814456755e-17 -6.9388939039072283776e-18 -0.023399999999999643308" rpy="-1.5543122344752879847e-15 3.901006815962737386e-29 -2.0462065805301541492e-27" />
<geometry>
<mesh filename="package:///motorejeacopleeje2.stl"/>
</geometry>
<material name="motorejeacopleeje2_material">
<color rgba="0.64705882352941179736 0.64705882352941179736 0.64705882352941179736 1.0"/>
</material>
</visual>
<collision>
<origin xyz="1.3877787807814456755e-17 -6.9388939039072283776e-18 -0.023399999999999643308" rpy="-1.5543122344752879847e-15 3.901006815962737386e-29 -2.0462065805301541492e-27" />
<geometry>
<mesh filename="package:///motorejeacopleeje2.stl"/>
</geometry>
</collision>
<visual>
<origin xyz="-1.3877787807814456755e-17 0.029999999999999985012 -0.023400000000000042294" rpy="1.5707963267948945596 5.4787286264067272988e-29 8.1844318916698710172e-30" />
<geometry>
<mesh filename="package:///brazo.stl"/>
</geometry>
<material name="brazo_material">
<color rgba="0.97254901960784312376 0.97254901960784312376 0.97254901960784312376 1.0"/>
</material>
</visual>
<collision>
<origin xyz="-1.3877787807814456755e-17 0.029999999999999985012 -0.023400000000000042294" rpy="1.5707963267948945596 5.4787286264067272988e-29 8.1844318916698710172e-30" />
<geometry>
<mesh filename="package:///brazo.stl"/>
</geometry>
</collision>
<visual>
<origin xyz="0 0 -0.023399999999999997191" rpy="-5.46823854811810266e-32 1.1447447090382596754e-30 -9.8607613150772295065e-32" />
<geometry>
<mesh filename="package:///motorejeacopleeje1.stl"/>
</geometry>
<material name="motorejeacopleeje1_material">
<color rgba="0.64705882352941179736 0.64705882352941179736 0.64705882352941179736 1.0"/>
</material>
</visual>
<collision>
<origin xyz="0 0 -0.023399999999999997191" rpy="-5.46823854811810266e-32 1.1447447090382596754e-30 -9.8607613150772295065e-32" />
<geometry>
<mesh filename="package:///motorejeacopleeje1.stl"/>
</geometry>
</collision>
<visual>
<origin xyz="0 3.4694469519536141888e-18 -0.023399999999999986783" rpy="-1.9984014443249279686e-15 5.7942729884944885448e-29 -6.6510835071446504034e-28" />
<geometry>
<mesh filename="package:///motorejeacoplecaja.stl"/>
</geometry>
<material name="motorejeacoplecaja_material">
<color rgba="0.26274509803921569651 0.28235294117647058432 0.30196078431372547213 1.0"/>
</material>
</visual>
<collision>
<origin xyz="0 3.4694469519536141888e-18 -0.023399999999999986783" rpy="-1.9984014443249279686e-15 5.7942729884944885448e-29 -6.6510835071446504034e-28" />
<geometry>
<mesh filename="package:///motorejeacoplecaja.stl"/>
</geometry>
</collision>
<inertial>
<origin xyz="0.00024409654353024182617 0.064612740306650290334 -0.023399999587718742916" rpy="0 0 0"/>
<mass value="1.080760232398511711" />
<inertia ixx="0.0024710869173820175157" ixy="-2.1146337854862071778e-05"  ixz="-1.0815339438050045539e-11" iyy="0.00022953897767025147514" iyz="1.3608742295544966522e-10" izz="0.0023133411907278627652" />
</inertial>
</link>

<joint name="LeftShoulder2" type="revolute">
<origin xyz="-0.023549999999996178157 3.805458519655358085e-07 -0.020946406845601492352" rpy="7.6131020406662958056e-15 -1.5707963267948694686 0" />
<parent link="hombro-brazo" />
<child link="brazourdf" />
<axis xyz="0 0 1"/>
<limit effort="1" velocity="20" lower="-0.26179938779914940783" upper="3.141592653589793116"/>
<joint_properties friction="0.0"/>
</joint>

<joint name="LeftShoulder1" type="revolute">
<origin xyz="0.092805821023547840909 0.0073712188771943082041 0.02546852102891152686" rpy="-1.5707963267948943376 -5.5511151231257851673e-17 1.570796326794896336" />
<parent link="torsourdf" />
<child link="hombro-brazo" />
<axis xyz="0 0 1"/>
<limit effort="1" velocity="20" lower="-1.570796326794896558" upper="1.570796326794896558"/>
<joint_properties friction="0.0"/>
</joint>

<link name="hombro-brazo_2">
<visual>
<origin xyz="-1.1362438767648086468e-16 0.010999809727072713816 0" rpy="-4.9303806576217599218e-32 -6.1629758221069863336e-33 5.6051938572992682837e-45" />
<geometry>
<mesh filename="package:///hombro_brazo1.stl"/>
</geometry>
<material name="hombro_brazo1_material">
<color rgba="0.97254901960784312376 0.97254901960784312376 0.97254901960784312376 1.0"/>
</material>
</visual>
<collision>
<origin xyz="-1.1362438767648086468e-16 0.010999809727072713816 0" rpy="-4.9303806576217599218e-32 -6.1629758221069863336e-33 5.6051938572992682837e-45" />
<geometry>
<mesh filename="package:///hombro_brazo1.stl"/>
</geometry>
</collision>
<visual>
<origin xyz="0.00029999999999984466176 0.010999809727072838716 -0.001999999999999960143" rpy="3.1086244689505874079e-15 4.5519144009628885914e-15 1.6869838859179256156e-13" />
<geometry>
<mesh filename="package:///hombro_brazo2.stl"/>
</geometry>
<material name="hombro_brazo2_material">
<color rgba="0.97254901960784312376 0.97254901960784312376 0.97254901960784312376 1.0"/>
</material>
</visual>
<collision>
<origin xyz="0.00029999999999984466176 0.010999809727072838716 -0.001999999999999960143" rpy="3.1086244689505874079e-15 4.5519144009628885914e-15 1.6869838859179256156e-13" />
<geometry>
<mesh filename="package:///hombro_brazo2.stl"/>
</geometry>
</collision>
<visual>
<origin xyz="-0.00029999999999202452833 -0.011000190272922242066 -0.0020000000000003903544" rpy="8.7152507433071980078e-15 2.1538326677728513356e-14 -3.1415926535894769245" />
<geometry>
<mesh filename="package:///hombro_brazo2.stl"/>
</geometry>
<material name="hombro_brazo2_material">
<color rgba="0.97254901960784312376 0.97254901960784312376 0.97254901960784312376 1.0"/>
</material>
</visual>
<collision>
<origin xyz="-0.00029999999999202452833 -0.011000190272922242066 -0.0020000000000003903544" rpy="8.7152507433071980078e-15 2.1538326677728513356e-14 -3.1415926535894769245" />
<geometry>
<mesh filename="package:///hombro_brazo2.stl"/>
</geometry>
</collision>
<inertial>
<origin xyz="1.5404324628167791432e-15 -1.104482431037076887e-07 0.0056081599888875410115" rpy="0 0 0"/>
<mass value="0.028276359613946904642" />
<inertia ixx="3.1909882339228936522e-06" ixy="-7.6383436747454765718e-11"  ixz="-4.2881042954748954665e-19" iyy="1.392592682798785128e-05" iyz="1.4915617916304636834e-11" izz="1.2743353645780548613e-05" />
</inertial>
</link>

<link name="brazourdf_2">
<visual>
<origin xyz="0 -3.4694469519536141888e-18 -0.023399999999999997191" rpy="5.8419632214026605965e-29 1.2164590951028526392e-30 -4.9303806576176611238e-31" />
<geometry>
<mesh filename="package:///motorejeacopleeje1.stl"/>
</geometry>
<material name="motorejeacopleeje1_material">
<color rgba="0.64705882352941179736 0.64705882352941179736 0.64705882352941179736 1.0"/>
</material>
</visual>
<collision>
<origin xyz="0 -3.4694469519536141888e-18 -0.023399999999999997191" rpy="5.8419632214026605965e-29 1.2164590951028526392e-30 -4.9303806576176611238e-31" />
<geometry>
<mesh filename="package:///motorejeacopleeje1.stl"/>
</geometry>
</collision>
<visual>
<origin xyz="-1.3877787807814456755e-17 0.030000000000000002359 -0.023399999999999993722" rpy="1.570796326794896558 -6.1232339958244023195e-17 4.5222529891157539048e-16" />
<geometry>
<mesh filename="package:///brazo.stl"/>
</geometry>
<material name="brazo_material">
<color rgba="0.97254901960784312376 0.97254901960784312376 0.97254901960784312376 1.0"/>
</material>
</visual>
<collision>
<origin xyz="-1.3877787807814456755e-17 0.030000000000000002359 -0.023399999999999993722" rpy="1.570796326794896558 -6.1232339958244023195e-17 4.5222529891157539048e-16" />
<geometry>
<mesh filename="package:///brazo.stl"/>
</geometry>
</collision>
<visual>
<origin xyz="0 -3.4694469519536141888e-18 -0.023399999999999997191" rpy="2.0988092601646088381e-28 -6.1232339958244023195e-17 4.5222529891157539048e-16" />
<geometry>
<mesh filename="package:///motorejeacoplecaja.stl"/>
</geometry>
<material name="motorejeacoplecaja_material">
<color rgba="0.26274509803921569651 0.28235294117647058432 0.30196078431372547213 1.0"/>
</material>
</visual>
<collision>
<origin xyz="0 -3.4694469519536141888e-18 -0.023399999999999997191" rpy="2.0988092601646088381e-28 -6.1232339958244023195e-17 4.5222529891157539048e-16" />
<geometry>
<mesh filename="package:///motorejeacoplecaja.stl"/>
</geometry>
</collision>
<visual>
<origin xyz="1.3877787807814456755e-17 -3.4694469519536141888e-18 -0.023400000000000049233" rpy="2.2898349883157165556e-16 -6.1232339958240621232e-17 4.5222529891157677099e-16" />
<geometry>
<mesh filename="package:///motorejeacopleeje2.stl"/>
</geometry>
<material name="motorejeacopleeje2_material">
<color rgba="0.64705882352941179736 0.64705882352941179736 0.64705882352941179736 1.0"/>
</material>
</visual>
<collision>
<origin xyz="1.3877787807814456755e-17 -3.4694469519536141888e-18 -0.023400000000000049233" rpy="2.2898349883157165556e-16 -6.1232339958240621232e-17 4.5222529891157677099e-16" />
<geometry>
<mesh filename="package:///motorejeacopleeje2.stl"/>
</geometry>
</collision>
<inertial>
<origin xyz="0.00024409654353022336762 0.064612740306650304212 -0.023399999587718624955" rpy="0 0 0"/>
<mass value="1.080760232398511711" />
<inertia ixx="0.0024710869173820261893" ixy="-2.1146337854861319613e-05"  ixz="-1.081533947722939386e-11" iyy="0.00022953897767025166488" iyz="1.3608742104604244598e-10" izz="0.0023133411907278631989" />
</inertial>
</link>

<joint name="RightShoulder2" type="revolute">
<origin xyz="-0.023549999999995938765 -3.8054585671173923878e-07 0.018946406845602059565" rpy="3.1415926535894782567 1.5707963267948730213 0" />
<parent link="hombro-brazo_2" />
<child link="brazourdf_2" />
<axis xyz="0 0 1"/>
<limit effort="1" velocity="20" lower="-0.26179938779914940783" upper="3.141592653589793116"/>
<joint_properties friction="0.0"/>
</joint>

<joint name="RightShoulder1" type="revolute">
<origin xyz="-0.085191785003578379687 0.0073712188771942830506 0.025468521028911540738" rpy="1.5707963267948954478 -1.6653345369376078533e-16 -1.5707963267948976682" />
<parent link="torsourdf" />
<child link="hombro-brazo_2" />
<axis xyz="0 0 1"/>
<limit effort="1" velocity="20" lower="-1.570796326794896558" upper="1.570796326794896558"/>
<joint_properties friction="0.0"/>
</joint>

<link name="cintura_v01">
<visual>
<origin xyz="0 0 -0.0020000000000000017764" rpy="3.141592653589793116 -8.1566305849981556584e-56 -3.0814879109020215609e-33" />
<geometry>
<mesh filename="package:///cinturapt1.stl"/>
</geometry>
<material name="cinturapt1_material">
<color rgba="0.97254901960784312376 0.97254901960784312376 0.97254901960784312376 1.0"/>
</material>
</visual>
<collision>
<origin xyz="0 0 -0.0020000000000000017764" rpy="3.141592653589793116 -8.1566305849981556584e-56 -3.0814879109020215609e-33" />
<geometry>
<mesh filename="package:///cinturapt1.stl"/>
</geometry>
</collision>
<visual>
<origin xyz="0.0003000000000000068584 4.1633363423443370266e-17 -0.0020000000000000017764" rpy="-3.141592653589793116 9.1835496157991700958e-41 6.3837823915949469164e-16" />
<geometry>
<mesh filename="package:///cinturapt2_2.stl"/>
</geometry>
<material name="cinturapt2_2_material">
<color rgba="0.97254901960784312376 0.97254901960784312376 0.97254901960784312376 1.0"/>
</material>
</visual>
<collision>
<origin xyz="0.0003000000000000068584 4.1633363423443370266e-17 -0.0020000000000000017764" rpy="-3.141592653589793116 9.1835496157991700958e-41 6.3837823915949469164e-16" />
<geometry>
<mesh filename="package:///cinturapt2_2.stl"/>
</geometry>
</collision>
<visual>
<origin xyz="-0.00029999999999997389866 2.7755575615628913511e-17 -0.0020000000000000017764" rpy="-3.141592653589793116 9.1835496157991700958e-41 6.3837823915949469164e-16" />
<geometry>
<mesh filename="package:///cinturapt2_1.stl"/>
</geometry>
<material name="cinturapt2_1_material">
<color rgba="0.97254901960784312376 0.97254901960784312376 0.97254901960784312376 1.0"/>
</material>
</visual>
<collision>
<origin xyz="-0.00029999999999997389866 2.7755575615628913511e-17 -0.0020000000000000017764" rpy="-3.141592653589793116 9.1835496157991700958e-41 6.3837823915949469164e-16" />
<geometry>
<mesh filename="package:///cinturapt2_1.stl"/>
</geometry>
</collision>
<inertial>
<origin xyz="-3.3981607212970044249e-17 0.011217027911029915643 -0.0083693257381815665957" rpy="0 0 0"/>
<mass value="0.032703197933895256089" />
<inertia ixx="6.2269512491993698786e-06" ixy="-1.9058241313221757629e-21"  ixz="-8.4703294725430033907e-22" iyy="1.6721999187227146985e-05" iyz="2.1121820955588526791e-06" izz="1.7093428062395053671e-05" />
</inertial>
</link>

<link name="cadera_v01">
<visual>
<origin xyz="0.010027549229561449895 0.0091859849723176234537 -0.023549999999998821876" rpy="-1.5707963267949436315 -6.8240229874675704155e-14 1.5707963267949376363" />
<geometry>
<mesh filename="package:///caderapt2_1.stl"/>
</geometry>
<material name="caderapt2_1_material">
<color rgba="0.97254901960784312376 0.97254901960784312376 0.97254901960784312376 1.0"/>
</material>
</visual>
<collision>
<origin xyz="0.010027549229561449895 0.0091859849723176234537 -0.023549999999998821876" rpy="-1.5707963267949436315 -6.8240229874675704155e-14 1.5707963267949376363" />
<geometry>
<mesh filename="package:///caderapt2_1.stl"/>
</geometry>
</collision>
<visual>
<origin xyz="-1.3877787807814456755e-17 6.9388939039072283776e-18 -0.023400000000000000661" rpy="-1.3246151313922950519e-31 9.110429776695333117e-32 -2.8308136372785403082e-47" />
<geometry>
<mesh filename="package:///motorejecaja.stl"/>
</geometry>
<material name="motorejecaja_material">
<color rgba="0.26274509803921569651 0.28235294117647058432 0.30196078431372547213 1.0"/>
</material>
</visual>
<collision>
<origin xyz="-1.3877787807814456755e-17 6.9388939039072283776e-18 -0.023400000000000000661" rpy="-1.3246151313922950519e-31 9.110429776695333117e-32 -2.8308136372785403082e-47" />
<geometry>
<mesh filename="package:///motorejecaja.stl"/>
</geometry>
</collision>
<visual>
<origin xyz="0.010027549229561560917 0.0097859849723176961511 -0.023549999999998807998" rpy="-1.5707963267949436315 -6.8850906924347619699e-14 1.5707963267949376363" />
<geometry>
<mesh filename="package:///caderapt2_2.stl"/>
</geometry>
<material name="caderapt2_2_material">
<color rgba="0.97254901960784312376 0.97254901960784312376 0.97254901960784312376 1.0"/>
</material>
</visual>
<collision>
<origin xyz="0.010027549229561560917 0.0097859849723176961511 -0.023549999999998807998" rpy="-1.5707963267949436315 -6.8850906924347619699e-14 1.5707963267949376363" />
<geometry>
<mesh filename="package:///caderapt2_2.stl"/>
</geometry>
</collision>
<visual>
<origin xyz="-5.5511151231257827021e-17 -4.1633363423443370266e-17 -0.023400000000000011069" rpy="-3.3306690738754755377e-16 1.8318679906316467368e-15 -9.9920072216263516714e-16" />
<geometry>
<mesh filename="package:///motorejeeje2.stl"/>
</geometry>
<material name="motorejeeje2_material">
<color rgba="0.64705882352941179736 0.64705882352941179736 0.64705882352941179736 1.0"/>
</material>
</visual>
<collision>
<origin xyz="-5.5511151231257827021e-17 -4.1633363423443370266e-17 -0.023400000000000011069" rpy="-3.3306690738754755377e-16 1.8318679906316467368e-15 -9.9920072216263516714e-16" />
<geometry>
<mesh filename="package:///motorejeeje2.stl"/>
</geometry>
</collision>
<visual>
<origin xyz="0.010027549229561477651 0.0098109849723176378866 -0.023449999999998815542" rpy="-1.5707963267949436315 -6.8850906924347619699e-14 1.5707963267949376363" />
<geometry>
<mesh filename="package:///caderapt3_2.stl"/>
</geometry>
<material name="caderapt3_2_material">
<color rgba="0.97254901960784312376 0.97254901960784312376 0.97254901960784312376 1.0"/>
</material>
</visual>
<collision>
<origin xyz="0.010027549229561477651 0.0098109849723176378866 -0.023449999999998815542" rpy="-1.5707963267949436315 -6.8850906924347619699e-14 1.5707963267949376363" />
<geometry>
<mesh filename="package:///caderapt3_2.stl"/>
</geometry>
</collision>
<visual>
<origin xyz="0.010027549229561463773 0.0098109849723175407421 -0.023649999999998817801" rpy="-1.5707963267949436315 -7.1779186659990561428e-14 1.5707963267949360819" />
<geometry>
<mesh filename="package:///caderapt3_1.stl"/>
</geometry>
<material name="caderapt3_1_material">
<color rgba="0.97254901960784312376 0.97254901960784312376 0.97254901960784312376 1.0"/>
</material>
</visual>
<collision>
<origin xyz="0.010027549229561463773 0.0098109849723175407421 -0.023649999999998817801" rpy="-1.5707963267949436315 -7.1779186659990561428e-14 1.5707963267949360819" />
<geometry>
<mesh filename="package:///caderapt3_1.stl"/>
</geometry>
</collision>
<visual>
<origin xyz="0.010027549229561713573 0.0094859849723177430691 -0.023549999999998821876" rpy="-1.5707963267949436315 -6.8240229874675704155e-14 1.5707963267949376363" />
<geometry>
<mesh filename="package:///caderapt1.stl"/>
</geometry>
<material name="caderapt1_material">
<color rgba="0.97254901960784312376 0.97254901960784312376 0.97254901960784312376 1.0"/>
</material>
</visual>
<collision>
<origin xyz="0.010027549229561713573 0.0094859849723177430691 -0.023549999999998821876" rpy="-1.5707963267949436315 -6.8240229874675704155e-14 1.5707963267949376363" />
<geometry>
<mesh filename="package:///caderapt1.stl"/>
</geometry>
</collision>
<visual>
<origin xyz="-1.3877787807814456755e-17 6.9388939039072283776e-18 -0.023400000000000000661" rpy="-1.3246151313922950519e-31 9.110429776695333117e-32 -2.8308136372785403082e-47" />
<geometry>
<mesh filename="package:///motorejeeje1.stl"/>
</geometry>
<material name="motorejeeje1_material">
<color rgba="0.64705882352941179736 0.64705882352941179736 0.64705882352941179736 1.0"/>
</material>
</visual>
<collision>
<origin xyz="-1.3877787807814456755e-17 6.9388939039072283776e-18 -0.023400000000000000661" rpy="-1.3246151313922950519e-31 9.110429776695333117e-32 -2.8308136372785403082e-47" />
<geometry>
<mesh filename="package:///motorejeeje1.stl"/>
</geometry>
</collision>
<inertial>
<origin xyz="0.0019229001328378595922 0.01004108560401127323 -0.023445491658507691679" rpy="0 0 0"/>
<mass value="0.36033150614011227875" />
<inertia ixx="0.00013063858229426684597" ixy="-1.4491083147698171152e-07"  ixz="7.2430643625445657956e-08" iyy="7.1173611389540832658e-05" iyz="4.0050341055353190311e-08" izz="0.00010253850500590433589" />
</inertial>
</link>

<link name="femururdf">
<visual>
<origin xyz="2.0816681711721685133e-17 0.043745909016608408582 -0.046800000000000022138" rpy="3.1415926535897926719 -6.8227481454312175064e-30 -9.4547752829872139431e-30" />
<geometry>
<mesh filename="package:///femur.stl"/>
</geometry>
<material name="femur_material">
<color rgba="0.97254901960784312376 0.97254901960784312376 0.97254901960784312376 1.0"/>
</material>
</visual>
<collision>
<origin xyz="2.0816681711721685133e-17 0.043745909016608408582 -0.046800000000000022138" rpy="3.1415926535897926719 -6.8227481454312175064e-30 -9.4547752829872139431e-30" />
<geometry>
<mesh filename="package:///femur.stl"/>
</geometry>
</collision>
<visual>
<origin xyz="5.2041704279304212832e-18 -2.7755575615628913511e-17 -0.023399999999999993722" rpy="4.0417637784836712167e-27 1.110223024622564023e-16 -4.1009211491827680554e-29" />
<geometry>
<mesh filename="package:///motorejeacopleeje2.stl"/>
</geometry>
<material name="motorejeacopleeje2_material">
<color rgba="0.64705882352941179736 0.64705882352941179736 0.64705882352941179736 1.0"/>
</material>
</visual>
<collision>
<origin xyz="5.2041704279304212832e-18 -2.7755575615628913511e-17 -0.023399999999999993722" rpy="4.0417637784836712167e-27 1.110223024622564023e-16 -4.1009211491827680554e-29" />
<geometry>
<mesh filename="package:///motorejeacopleeje2.stl"/>
</geometry>
</collision>
<visual>
<origin xyz="6.7654215563095476682e-17 0.064999999999999946709 -0.023400000000000035355" rpy="-2.4202290664982800219e-15 -2.2872447674893787733e-15 -3.1415926535897917837" />
<geometry>
<mesh filename="package:///motorejeacopleeje1.stl"/>
</geometry>
<material name="motorejeacopleeje1_material">
<color rgba="0.64705882352941179736 0.64705882352941179736 0.64705882352941179736 1.0"/>
</material>
</visual>
<collision>
<origin xyz="6.7654215563095476682e-17 0.064999999999999946709 -0.023400000000000035355" rpy="-2.4202290664982800219e-15 -2.2872447674893787733e-15 -3.1415926535897917837" />
<geometry>
<mesh filename="package:///motorejeacopleeje1.stl"/>
</geometry>
</collision>
<visual>
<origin xyz="3.4694469519536141888e-18 0 -0.023399999999999993722" rpy="1.1102230246718497104e-16 -9.0732377119147292228e-30 -2.8387437008291486063e-29" />
<geometry>
<mesh filename="package:///motorejeacoplecaja.stl"/>
</geometry>
<material name="motorejeacoplecaja_material">
<color rgba="0.26274509803921569651 0.28235294117647058432 0.30196078431372547213 1.0"/>
</material>
</visual>
<collision>
<origin xyz="3.4694469519536141888e-18 0 -0.023399999999999993722" rpy="1.1102230246718497104e-16 -9.0732377119147292228e-30 -2.8387437008291486063e-29" />
<geometry>
<mesh filename="package:///motorejeacoplecaja.stl"/>
</geometry>
</collision>
<visual>
<origin xyz="4.5102810375396984455e-17 0.064999999999999974465 -0.023400000000000000661" rpy="1.1102230245846408909e-16 -5.5511151233229708113e-17 3.141592653589793116" />
<geometry>
<mesh filename="package:///motorejeacopleeje2.stl"/>
</geometry>
<material name="motorejeacopleeje2_material">
<color rgba="0.64705882352941179736 0.64705882352941179736 0.64705882352941179736 1.0"/>
</material>
</visual>
<collision>
<origin xyz="4.5102810375396984455e-17 0.064999999999999974465 -0.023400000000000000661" rpy="1.1102230245846408909e-16 -5.5511151233229708113e-17 3.141592653589793116" />
<geometry>
<mesh filename="package:///motorejeacopleeje2.stl"/>
</geometry>
</collision>
<visual>
<origin xyz="2.2551405187698492227e-17 0.043745909016608380826 0.0020000000000000017764" rpy="3.1415926535897926719 -6.8227481454312175064e-30 -9.4547752829872139431e-30" />
<geometry>
<mesh filename="package:///femur.stl"/>
</geometry>
<material name="femur_material">
<color rgba="0.97254901960784312376 0.97254901960784312376 0.97254901960784312376 1.0"/>
</material>
</visual>
<collision>
<origin xyz="2.2551405187698492227e-17 0.043745909016608380826 0.0020000000000000017764" rpy="3.1415926535897926719 -6.8227481454312175064e-30 -9.4547752829872139431e-30" />
<geometry>
<mesh filename="package:///femur.stl"/>
</geometry>
</collision>
<visual>
<origin xyz="4.336808689942017736e-17 0.064999999999999974465 -0.023400000000000007599" rpy="-2.775557561311085964e-16 -1.1102230246041044067e-15 3.141592653589793116" />
<geometry>
<mesh filename="package:///motorejeacoplecaja.stl"/>
</geometry>
<material name="motorejeacoplecaja_material">
<color rgba="0.26274509803921569651 0.28235294117647058432 0.30196078431372547213 1.0"/>
</material>
</visual>
<collision>
<origin xyz="4.336808689942017736e-17 0.064999999999999974465 -0.023400000000000007599" rpy="-2.775557561311085964e-16 -1.1102230246041044067e-15 3.141592653589793116" />
<geometry>
<mesh filename="package:///motorejeacoplecaja.stl"/>
</geometry>
</collision>
<visual>
<origin xyz="1.7347234759768070944e-18 0 -0.023399999999999993722" rpy="2.7959437520906006001e-30 -6.8227481454312175064e-30 -9.4547752829872139431e-30" />
<geometry>
<mesh filename="package:///motorejeacopleeje1.stl"/>
</geometry>
<material name="motorejeacopleeje1_material">
<color rgba="0.64705882352941179736 0.64705882352941179736 0.64705882352941179736 1.0"/>
</material>
</visual>
<collision>
<origin xyz="1.7347234759768070944e-18 0 -0.023399999999999993722" rpy="2.7959437520906006001e-30 -6.8227481454312175064e-30 -9.4547752829872139431e-30" />
<geometry>
<mesh filename="package:///motorejeacopleeje1.stl"/>
</geometry>
</collision>
<inertial>
<origin xyz="1.874680775725036815e-17 0.032499999999999987232 -0.02340000000000000413" rpy="0 0 0"/>
<mass value="0.53868761965446410045" />
<inertia ixx="0.00043791203235393527703" ixy="-1.7277011298782811142e-19"  ixz="-6.7144274078926772454e-20" iyy="0.0001090944632856160701" iyz="9.1479558303464436619e-20" izz="0.00036348717125268549229" />
</inertial>
</link>

<link name="tibiaurdf">
<visual>
<origin xyz="2.7755575615628913511e-17 0.054999999999999993339 0.023399999999999959027" rpy="-3.1415926535897926719 -2.0616559974846433813e-16 -3.9443045261050667342e-30" />
<geometry>
<mesh filename="package:///motorejeacopleeje2.stl"/>
</geometry>
<material name="motorejeacopleeje2_material">
<color rgba="0.64705882352941179736 0.64705882352941179736 0.64705882352941179736 1.0"/>
</material>
</visual>
<collision>
<origin xyz="2.7755575615628913511e-17 0.054999999999999993339 0.023399999999999959027" rpy="-3.1415926535897926719 -2.0616559974846433813e-16 -3.9443045261050667342e-30" />
<geometry>
<mesh filename="package:///motorejeacopleeje2.stl"/>
</geometry>
</collision>
<visual>
<origin xyz="2.2551405187698492227e-17 0.054999999999999993339 0.023399999999999972905" rpy="-3.1415926535897926719 -9.5143297285473814475e-17 -3.9443045261049644394e-30" />
<geometry>
<mesh filename="package:///motorejeacopleeje1.stl"/>
</geometry>
<material name="motorejeacopleeje1_material">
<color rgba="0.64705882352941179736 0.64705882352941179736 0.64705882352941179736 1.0"/>
</material>
</visual>
<collision>
<origin xyz="2.2551405187698492227e-17 0.054999999999999993339 0.023399999999999972905" rpy="-3.1415926535897926719 -9.5143297285473814475e-17 -3.9443045261049644394e-30" />
<geometry>
<mesh filename="package:///motorejeacopleeje1.stl"/>
</geometry>
</collision>
<visual>
<origin xyz="-3.4694469519536141888e-18 0.033745909016608371944 0.048799999999999899014" rpy="3.141592653589793116 -9.514329728547115207e-17 -3.9443045261047087024e-30" />
<geometry>
<mesh filename="package:///tibia.stl"/>
</geometry>
<material name="tibia_material">
<color rgba="0.97254901960784312376 0.97254901960784312376 0.97254901960784312376 1.0"/>
</material>
</visual>
<collision>
<origin xyz="-3.4694469519536141888e-18 0.033745909016608371944 0.048799999999999899014" rpy="3.141592653589793116 -9.514329728547115207e-17 -3.9443045261047087024e-30" />
<geometry>
<mesh filename="package:///tibia.stl"/>
</geometry>
</collision>
<visual>
<origin xyz="-1.7347234759768070944e-18 0.0337459090166083997 3.4694469519536141888e-18" rpy="-3.141592653589793116 1.7010289415089807767e-30 -3.9443045261045545596e-30" />
<geometry>
<mesh filename="package:///tibia.stl"/>
</geometry>
<material name="tibia_material">
<color rgba="0.97254901960784312376 0.97254901960784312376 0.97254901960784312376 1.0"/>
</material>
</visual>
<collision>
<origin xyz="-1.7347234759768070944e-18 0.0337459090166083997 3.4694469519536141888e-18" rpy="-3.141592653589793116 1.7010289415089807767e-30 -3.9443045261045545596e-30" />
<geometry>
<mesh filename="package:///tibia.stl"/>
</geometry>
</collision>
<visual>
<origin xyz="2.9490299091605720605e-17 0.054999999999999937828 0.023399999999999959027" rpy="-3.1415926535897926719 -9.5143297285468834791e-17 -3.9443045261050667342e-30" />
<geometry>
<mesh filename="package:///motorejeacoplecaja.stl"/>
</geometry>
<material name="motorejeacoplecaja_material">
<color rgba="0.26274509803921569651 0.28235294117647058432 0.30196078431372547213 1.0"/>
</material>
</visual>
<collision>
<origin xyz="2.9490299091605720605e-17 0.054999999999999937828 0.023399999999999959027" rpy="-3.1415926535897926719 -9.5143297285468834791e-17 -3.9443045261050667342e-30" />
<geometry>
<mesh filename="package:///motorejeacoplecaja.stl"/>
</geometry>
</collision>
<inertial>
<origin xyz="-6.4386754382438032675e-14 0.042938078357409217856 0.023399999999999955558" rpy="0 0 0"/>
<mass value="0.28552673687099017208" />
<inertia ixx="0.00011378661693733217828" ixy="-8.2082745679900866674e-16"  ixz="6.8613247918721703282e-21" iyy="6.4755066218591454631e-05" iyz="2.3646038688080147531e-20" izz="6.7501897454918299152e-05" />
</inertial>
</link>

<link name="tobillourdf">
<visual>
<origin xyz="-0.0001500000000001621564 0.035800000000000109512 0.023725000000000016909" rpy="1.5707963267948972241 1.5707963267948936714 0" />
<geometry>
<mesh filename="package:///tobillopt3_2.stl"/>
</geometry>
<material name="tobillopt3_2_material">
<color rgba="0.97254901960784312376 0.97254901960784312376 0.97254901960784312376 1.0"/>
</material>
</visual>
<collision>
<origin xyz="-0.0001500000000001621564 0.035800000000000109512 0.023725000000000016909" rpy="1.5707963267948972241 1.5707963267948936714 0" />
<geometry>
<mesh filename="package:///tobillopt3_2.stl"/>
</geometry>
</collision>
<visual>
<origin xyz="1.1102230246251565404e-16 0.035800000000000276046 0.023550000000000001488" rpy="1.570796326794896558 1.570796326794896558 0" />
<geometry>
<mesh filename="package:///tobillopt1.stl"/>
</geometry>
<material name="tobillopt1_material">
<color rgba="0.97254901960784312376 0.97254901960784312376 0.97254901960784312376 1.0"/>
</material>
</visual>
<collision>
<origin xyz="1.1102230246251565404e-16 0.035800000000000276046 0.023550000000000001488" rpy="1.570796326794896558 1.570796326794896558 0" />
<geometry>
<mesh filename="package:///tobillopt1.stl"/>
</geometry>
</collision>
<visual>
<origin xyz="0.000199999999999972769 0.02577245077043732735 0.033535984972321658537" rpy="-1.5707963267948323871 -5.9724835109239921969e-14 -1.5707963267948761299" />
<geometry>
<mesh filename="package:///motorejecaja.stl"/>
</geometry>
<material name="motorejecaja_material">
<color rgba="0.26274509803921569651 0.28235294117647058432 0.30196078431372547213 1.0"/>
</material>
</visual>
<collision>
<origin xyz="0.000199999999999972769 0.02577245077043732735 0.033535984972321658537" rpy="-1.5707963267948323871 -5.9724835109239921969e-14 -1.5707963267948761299" />
<geometry>
<mesh filename="package:///motorejecaja.stl"/>
</geometry>
</collision>
<visual>
<origin xyz="0.000199999999999972769 0.02577245077043732735 0.033535984972321658537" rpy="-1.5707963267948332753 -5.9280745899389871975e-14 -1.5707963267948763519" />
<geometry>
<mesh filename="package:///motorejeeje2.stl"/>
</geometry>
<material name="motorejeeje2_material">
<color rgba="0.64705882352941179736 0.64705882352941179736 0.64705882352941179736 1.0"/>
</material>
</visual>
<collision>
<origin xyz="0.000199999999999972769 0.02577245077043732735 0.033535984972321658537" rpy="-1.5707963267948332753 -5.9280745899389871975e-14 -1.5707963267948763519" />
<geometry>
<mesh filename="package:///motorejeeje2.stl"/>
</geometry>
</collision>
<visual>
<origin xyz="0.00015000000000005633827 0.035800000000000109512 0.023725000000000148748" rpy="1.570796326794896558 1.570796326794896558 0" />
<geometry>
<mesh filename="package:///tobillopt3_1.stl"/>
</geometry>
<material name="tobillopt3_1_material">
<color rgba="0.97254901960784312376 0.97254901960784312376 0.97254901960784312376 1.0"/>
</material>
</visual>
<collision>
<origin xyz="0.00015000000000005633827 0.035800000000000109512 0.023725000000000148748" rpy="1.570796326794896558 1.570796326794896558 0" />
<geometry>
<mesh filename="package:///tobillopt3_1.stl"/>
</geometry>
</collision>
<visual>
<origin xyz="0.000199999999999972769 0.02577245077043732735 0.033535984972321658537" rpy="-1.5707963267948326092 -6.1945281158490222429e-14 -1.5707963267948759079" />
<geometry>
<mesh filename="package:///motorejeeje1.stl"/>
</geometry>
<material name="motorejeeje1_material">
<color rgba="0.64705882352941179736 0.64705882352941179736 0.64705882352941179736 1.0"/>
</material>
</visual>
<collision>
<origin xyz="0.000199999999999972769 0.02577245077043732735 0.033535984972321658537" rpy="-1.5707963267948326092 -6.1945281158490222429e-14 -1.5707963267948759079" />
<geometry>
<mesh filename="package:///motorejeeje1.stl"/>
</geometry>
</collision>
<visual>
<origin xyz="4.6837533851373791549e-17 0.035799999999999942979 0.023850000000000121103" rpy="1.570796326794896558 1.570796326794896558 0" />
<geometry>
<mesh filename="package:///tobillopt2_1.stl"/>
</geometry>
<material name="tobillopt2_1_material">
<color rgba="0.97254901960784312376 0.97254901960784312376 0.97254901960784312376 1.0"/>
</material>
</visual>
<collision>
<origin xyz="4.6837533851373791549e-17 0.035799999999999942979 0.023850000000000121103" rpy="1.570796326794896558 1.570796326794896558 0" />
<geometry>
<mesh filename="package:///tobillopt2_1.stl"/>
</geometry>
</collision>
<visual>
<origin xyz="-1.7347234759768070944e-18 0.035800000000000054001 0.023249999999999992895" rpy="1.570796326794896558 1.570796326794896558 0" />
<geometry>
<mesh filename="package:///tobillopt2_2.stl"/>
</geometry>
<material name="tobillopt2_2_material">
<color rgba="0.97254901960784312376 0.97254901960784312376 0.97254901960784312376 1.0"/>
</material>
</visual>
<collision>
<origin xyz="-1.7347234759768070944e-18 0.035800000000000054001 0.023249999999999992895" rpy="1.570796326794896558 1.570796326794896558 0" />
<geometry>
<mesh filename="package:///tobillopt2_2.stl"/>
</geometry>
</collision>
<inertial>
<origin xyz="0.00013965747905197206289 0.0256561061214560307 0.023411667663060128225" rpy="0 0 0"/>
<mass value="0.35953278469495458802" />
<inertia ixx="0.00010180132077840498798" ixy="-5.8418326130015651873e-09"  ixz="-5.7602954082537214694e-08" iyy="0.0001300703147929072696" iyz="5.2659589177284237788e-07" izz="7.0605342570129482334e-05" />
</inertial>
</link>

<link name="pieurdf">
<visual>
<origin xyz="-0.0099999999999999603095 0.01899999999999973932 0.023500000000000100669" rpy="1.570796326794896558 1.570796326794896336 0" />
<geometry>
<mesh filename="package:///acoplepiemotor.stl"/>
</geometry>
<material name="acoplepiemotor_material">
<color rgba="0.97254901960784312376 0.97254901960784312376 0.97254901960784312376 1.0"/>
</material>
</visual>
<collision>
<origin xyz="-0.0099999999999999603095 0.01899999999999973932 0.023500000000000100669" rpy="1.570796326794896558 1.570796326794896336 0" />
<geometry>
<mesh filename="package:///acoplepiemotor.stl"/>
</geometry>
</collision>
<visual>
<origin xyz="-0.010000000000000015821 0.018999999999999961364 0.02340000000000000413" rpy="1.570796326794896558 1.570796326794896336 0" />
<geometry>
<mesh filename="package:///acoplepiemotor.stl"/>
</geometry>
<material name="acoplepiemotor_material">
<color rgba="0.97254901960784312376 0.97254901960784312376 0.97254901960784312376 1.0"/>
</material>
</visual>
<collision>
<origin xyz="-0.010000000000000015821 0.018999999999999961364 0.02340000000000000413" rpy="1.570796326794896558 1.570796326794896336 0" />
<geometry>
<mesh filename="package:///acoplepiemotor.stl"/>
</geometry>
</collision>
<visual>
<origin xyz="-0.0099999999999996966316 0.018949999999999522782 0.023450000000000057604" rpy="1.570796326794896558 1.570796326794896336 0" />
<geometry>
<mesh filename="package:///plantapie.stl"/>
</geometry>
<material name="plantapie_material">
<color rgba="0.97254901960784312376 0.97254901960784312376 0.97254901960784312376 1.0"/>
</material>
</visual>
<collision>
<origin xyz="-0.0099999999999996966316 0.018949999999999522782 0.023450000000000057604" rpy="1.570796326794896558 1.570796326794896336 0" />
<geometry>
<mesh filename="package:///plantapie.stl"/>
</geometry>
</collision>
<inertial>
<origin xyz="-0.0095981962877159116704 0.018994815818902218568 0.023450000000000061073" rpy="0 0 0"/>
<mass value="0.12193030814742022994" />
<inertia ixx="5.5790028401552932424e-05" ixy="1.0383957421083121081e-06"  ixz="-3.3070244280832144483e-20" iyy="7.8275338616850967735e-05" iyz="1.0582913822139555343e-19" izz="3.3440055653628696845e-05" />
</inertial>
</link>

<joint name="LeftAnkle2" type="revolute">
<origin xyz="0.023599999999999961287 0.025772450770437771439 0.033535984972323150399" rpy="2.037085777839408061e-14 -1.5707963267947913089 0" />
<parent link="tobillourdf" />
<child link="pieurdf" />
<axis xyz="0 0 1"/>
<limit effort="1" velocity="20" lower="-0.26179938779914940783" upper="0.26179938779914940783"/>
<joint_properties friction="0.0"/>
</joint>

<joint name="LeftAnkle1" type="revolute">
<origin xyz="2.7755575615628913511e-17 0.054999999999999882316 0.046799999999999897238" rpy="3.1415926535897868987 -2.4196156553935806658e-14 -3.1415926535897114036" />
<parent link="tibiaurdf" />
<child link="tobillourdf" />
<axis xyz="0 0 1"/>
<limit effort="1" velocity="20" lower="-0.785398163397448279" upper="0.52359877559829881566"/>
<joint_properties friction="0.0"/>
</joint>

<joint name="LeftKnee" type="revolute">
<origin xyz="2.7755575615628913511e-17 0.065000000000000029976 2.0816681711721685133e-17" rpy="3.1415926535897926719 -1.1730918729772736225e-15 -3.1415926535897114036" />
<parent link="femururdf" />
<child link="tibiaurdf" />
<axis xyz="0 0 1"/>
<limit effort="1" velocity="20" lower="-0.26179938779914940783" upper="2.356194490192344837"/>
<joint_properties friction="0.0"/>
</joint>

<joint name="LeftHip2" type="revolute">
<origin xyz="0.028027549229560577704 -0.014064015027681592285 -0.023549999999998755956" rpy="1.5707963267948557018 1.5707963267948159558 0" />
<parent link="cadera_v01" />
<child link="femururdf" />
<axis xyz="0 0 1"/>
<limit effort="1" velocity="20" lower="-1.570796326794896558" upper="1.570796326794896558"/>
<joint_properties friction="0.0"/>
</joint>

<joint name="LeftHip1" type="revolute">
<origin xyz="0.02354999999999998414 0.022673904349987897971 -0.02360543610293333594" rpy="-2.1049685500540671756e-15 1.5707963267948954478 0" />
<parent link="cintura_v01" />
<child link="cadera_v01" />
<axis xyz="0 0 1"/>
<limit effort="1" velocity="20" lower="-0.52359877559829881566" upper="0.52359877559829881566"/>
<joint_properties friction="0.0"/>
</joint>

<joint name="LeftWaist" type="revolute">
<origin xyz="0.019257018009984725598 0.0083712188771943082249 -0.083178910040700965167" rpy="1.72907851597959344e-39 7.0653760931075006984e-40 -1.570796326794896558" />
<parent link="torsourdf" />
<child link="cintura_v01" />
<axis xyz="0 0 1"/>
<limit effort="1" velocity="20" lower="-0.26179938779914940783" upper="0.26179938779914940783"/>
<joint_properties friction="0.0"/>
</joint>

<link name="cintura_v01_2">
<visual>
<origin xyz="-0.0003000000000000068584 -1.561251128379126385e-17 -0.0020000000000000017764" rpy="3.141592653589793116 -9.8607613152626431886e-32 4.4408920985006675769e-16" />
<geometry>
<mesh filename="package:///cinturapt2_1.stl"/>
</geometry>
<material name="cinturapt2_1_material">
<color rgba="0.97254901960784312376 0.97254901960784312376 0.97254901960784312376 1.0"/>
</material>
</visual>
<collision>
<origin xyz="-0.0003000000000000068584 -1.561251128379126385e-17 -0.0020000000000000017764" rpy="3.141592653589793116 -9.8607613152626431886e-32 4.4408920985006675769e-16" />
<geometry>
<mesh filename="package:///cinturapt2_1.stl"/>
</geometry>
</collision>
<visual>
<origin xyz="0 0 -0.0020000000000000017764" rpy="3.141592653589793116 -9.8607613152626475676e-32 -1.2325951644008395066e-32" />
<geometry>
<mesh filename="package:///cinturapt1.stl"/>
</geometry>
<material name="cinturapt1_material">
<color rgba="0.97254901960784312376 0.97254901960784312376 0.97254901960784312376 1.0"/>
</material>
</visual>
<collision>
<origin xyz="0 0 -0.0020000000000000017764" rpy="3.141592653589793116 -9.8607613152626475676e-32 -1.2325951644008395066e-32" />
<geometry>
<mesh filename="package:///cinturapt1.stl"/>
</geometry>
</collision>
<visual>
<origin xyz="0.00030000000000001206257 -2.0816681711721685133e-17 -0.0020000000000000017764" rpy="3.141592653589793116 -9.8607613152626431886e-32 4.4408920985006675769e-16" />
<geometry>
<mesh filename="package:///cinturapt2_2.stl"/>
</geometry>
<material name="cinturapt2_2_material">
<color rgba="0.97254901960784312376 0.97254901960784312376 0.97254901960784312376 1.0"/>
</material>
</visual>
<collision>
<origin xyz="0.00030000000000001206257 -2.0816681711721685133e-17 -0.0020000000000000017764" rpy="3.141592653589793116 -9.8607613152626431886e-32 4.4408920985006675769e-16" />
<geometry>
<mesh filename="package:///cinturapt2_2.stl"/>
</geometry>
</collision>
<inertial>
<origin xyz="-4.5585082846667133731e-17 0.011217027911029887888 -0.0083693257381815717999" rpy="0 0 0"/>
<mass value="0.032703197933895256089" />
<inertia ixx="6.2269512491993639494e-06" ixy="5.2939559203393771192e-21"  ixz="-3.599890025830776441e-21" iyy="1.672199918722717409e-05" iyz="2.1121820955588484439e-06" izz="1.7093428062395067224e-05" />
</inertial>
</link>

<link name="cadera_v01_2">
<visual>
<origin xyz="0.010027549229562476851 -0.0094859849723201161709 -0.023250000000000728417" rpy="1.5707963267948970021 8.1856744252466624676e-14 -1.5707963267948852337" />
<geometry>
<mesh filename="package:///caderapt1.stl"/>
</geometry>
<material name="caderapt1_material">
<color rgba="0.97254901960784312376 0.97254901960784312376 0.97254901960784312376 1.0"/>
</material>
</visual>
<collision>
<origin xyz="0.010027549229562476851 -0.0094859849723201161709 -0.023250000000000728417" rpy="1.5707963267948970021 8.1856744252466624676e-14 -1.5707963267948852337" />
<geometry>
<mesh filename="package:///caderapt1.stl"/>
</geometry>
</collision>
<visual>
<origin xyz="0.010027549229562199296 -0.0091859849723201839056 -0.023250000000000738826" rpy="1.5707963267948970021 8.1856744252466624676e-14 -1.5707963267948852337" />
<geometry>
<mesh filename="package:///caderapt2_1.stl"/>
</geometry>
<material name="caderapt2_1_material">
<color rgba="0.97254901960784312376 0.97254901960784312376 0.97254901960784312376 1.0"/>
</material>
</visual>
<collision>
<origin xyz="0.010027549229562199296 -0.0091859849723201839056 -0.023250000000000738826" rpy="1.5707963267948970021 8.1856744252466624676e-14 -1.5707963267948852337" />
<geometry>
<mesh filename="package:///caderapt2_1.stl"/>
</geometry>
</collision>
<visual>
<origin xyz="0.010027549229562240929 -0.009810984972320357933 -0.02335000000000080761" rpy="1.5707963267948970021 8.2503244919184006847e-14 -1.5707963267948856778" />
<geometry>
<mesh filename="package:///caderapt3_2.stl"/>
</geometry>
<material name="caderapt3_2_material">
<color rgba="0.97254901960784312376 0.97254901960784312376 0.97254901960784312376 1.0"/>
</material>
</visual>
<collision>
<origin xyz="0.010027549229562240929 -0.009810984972320357933 -0.02335000000000080761" rpy="1.5707963267948970021 8.2503244919184006847e-14 -1.5707963267948856778" />
<geometry>
<mesh filename="package:///caderapt3_2.stl"/>
</geometry>
</collision>
<visual>
<origin xyz="8.3266726846886740532e-17 -1.5959455978986625269e-16 -0.023399999999999965966" rpy="-3.1415926535897926719 1.0161424075165139562e-15 4.568831093306311365e-30" />
<geometry>
<mesh filename="package:///motorejecaja.stl"/>
</geometry>
<material name="motorejecaja_material">
<color rgba="0.26274509803921569651 0.28235294117647058432 0.30196078431372547213 1.0"/>
</material>
</visual>
<collision>
<origin xyz="8.3266726846886740532e-17 -1.5959455978986625269e-16 -0.023399999999999965966" rpy="-3.1415926535897926719 1.0161424075165139562e-15 4.568831093306311365e-30" />
<geometry>
<mesh filename="package:///motorejecaja.stl"/>
</geometry>
</collision>
<visual>
<origin xyz="-1.3877787807814456755e-17 -6.9388939039072283776e-18 -0.023400000000000000661" rpy="3.141592653589793116 9.1762779228166398948e-33 6.3969734370262392561e-45" />
<geometry>
<mesh filename="package:///motorejeeje2.stl"/>
</geometry>
<material name="motorejeeje2_material">
<color rgba="0.64705882352941179736 0.64705882352941179736 0.64705882352941179736 1.0"/>
</material>
</visual>
<collision>
<origin xyz="-1.3877787807814456755e-17 -6.9388939039072283776e-18 -0.023400000000000000661" rpy="3.141592653589793116 9.1762779228166398948e-33 6.3969734370262392561e-45" />
<geometry>
<mesh filename="package:///motorejeeje2.stl"/>
</geometry>
</collision>
<visual>
<origin xyz="-1.3877787807814456755e-17 -6.9388939039072283776e-18 -0.023400000000000000661" rpy="-3.141592653589793116 8.7566783882884751779e-16 1.1102230246252297566e-16" />
<geometry>
<mesh filename="package:///motorejeeje1.stl"/>
</geometry>
<material name="motorejeeje1_material">
<color rgba="0.64705882352941179736 0.64705882352941179736 0.64705882352941179736 1.0"/>
</material>
</visual>
<collision>
<origin xyz="-1.3877787807814456755e-17 -6.9388939039072283776e-18 -0.023400000000000000661" rpy="-3.141592653589793116 8.7566783882884751779e-16 1.1102230246252297566e-16" />
<geometry>
<mesh filename="package:///motorejeeje1.stl"/>
</geometry>
</collision>
<visual>
<origin xyz="0.010027549229562157662 -0.0097859849723201386418 -0.02325000000000077352" rpy="1.5707963267948970021 8.2503244919184006847e-14 -1.5707963267948856778" />
<geometry>
<mesh filename="package:///caderapt2_2.stl"/>
</geometry>
<material name="caderapt2_2_material">
<color rgba="0.97254901960784312376 0.97254901960784312376 0.97254901960784312376 1.0"/>
</material>
</visual>
<collision>
<origin xyz="0.010027549229562157662 -0.0097859849723201386418 -0.02325000000000077352" rpy="1.5707963267948970021 8.2503244919184006847e-14 -1.5707963267948856778" />
<geometry>
<mesh filename="package:///caderapt2_2.stl"/>
</geometry>
</collision>
<visual>
<origin xyz="0.010027549229562310318 -0.0098109849723202469107 -0.02315000000000068392" rpy="1.5707963267948978903 8.3455727590886918872e-14 -1.5707963267949052177" />
<geometry>
<mesh filename="package:///caderapt3_1.stl"/>
</geometry>
<material name="caderapt3_1_material">
<color rgba="0.97254901960784312376 0.97254901960784312376 0.97254901960784312376 1.0"/>
</material>
</visual>
<collision>
<origin xyz="0.010027549229562310318 -0.0098109849723202469107 -0.02315000000000068392" rpy="1.5707963267948978903 8.3455727590886918872e-14 -1.5707963267949052177" />
<geometry>
<mesh filename="package:///caderapt3_1.stl"/>
</geometry>
</collision>
<inertial>
<origin xyz="0.0019229001328381735772 -0.010041085604012187429 -0.023354508341492229845" rpy="0 0 0"/>
<mass value="0.36033150614011233426" />
<inertia ixx="0.00013063858229426836386" ixy="1.449108314801708435e-07"  ixz="-7.2430643625424045381e-08" iyy="7.1173611389541483179e-05" iyz="4.0050341054866146366e-08" izz="0.00010253850500590642298" />
</inertial>
</link>

<link name="femururdf_2">
<visual>
<origin xyz="0 2.7755575615628913511e-17 -0.02340000000000000413" rpy="-3.141592653589793116 3.9537782859479195091e-30 4.4568781045721269686e-31" />
<geometry>
<mesh filename="package:///motorejeacopleeje2.stl"/>
</geometry>
<material name="motorejeacopleeje2_material">
<color rgba="0.64705882352941179736 0.64705882352941179736 0.64705882352941179736 1.0"/>
</material>
</visual>
<collision>
<origin xyz="0 2.7755575615628913511e-17 -0.02340000000000000413" rpy="-3.141592653589793116 3.9537782859479195091e-30 4.4568781045721269686e-31" />
<geometry>
<mesh filename="package:///motorejeacopleeje2.stl"/>
</geometry>
</collision>
<visual>
<origin xyz="3.6429192995512948983e-17 5.5511151231257827021e-17 -0.023400000000000031886" rpy="3.141592653589793116 2.605554660898342429e-15 7.4940054162163179105e-16" />
<geometry>
<mesh filename="package:///motorejeacopleeje1.stl"/>
</geometry>
<material name="motorejeacopleeje1_material">
<color rgba="0.64705882352941179736 0.64705882352941179736 0.64705882352941179736 1.0"/>
</material>
</visual>
<collision>
<origin xyz="3.6429192995512948983e-17 5.5511151231257827021e-17 -0.023400000000000031886" rpy="3.141592653589793116 2.605554660898342429e-15 7.4940054162163179105e-16" />
<geometry>
<mesh filename="package:///motorejeacopleeje1.stl"/>
</geometry>
</collision>
<visual>
<origin xyz="-4.04190569902596053e-16 -0.065000000000000168754 -0.023400000000000115152" rpy="3.141592653589793116 -3.7227165794273158733e-15 3.141592653589793116" />
<geometry>
<mesh filename="package:///motorejeacoplecaja.stl"/>
</geometry>
<material name="motorejeacoplecaja_material">
<color rgba="0.26274509803921569651 0.28235294117647058432 0.30196078431372547213 1.0"/>
</material>
</visual>
<collision>
<origin xyz="-4.04190569902596053e-16 -0.065000000000000168754 -0.023400000000000115152" rpy="3.141592653589793116 -3.7227165794273158733e-15 3.141592653589793116" />
<geometry>
<mesh filename="package:///motorejeacoplecaja.stl"/>
</geometry>
</collision>
<visual>
<origin xyz="-2.185751579730776939e-16 -0.043745909016607797959 1.3877787807814456755e-17" rpy="-1.3997618880526594785e-16 3.7227165794273292839e-15 1.1865508575677392555e-15" />
<geometry>
<mesh filename="package:///femur.stl"/>
</geometry>
<material name="femur_material">
<color rgba="0.97254901960784312376 0.97254901960784312376 0.97254901960784312376 1.0"/>
</material>
</visual>
<collision>
<origin xyz="-2.185751579730776939e-16 -0.043745909016607797959 1.3877787807814456755e-17" rpy="-1.3997618880526594785e-16 3.7227165794273292839e-15 1.1865508575677392555e-15" />
<geometry>
<mesh filename="package:///femur.stl"/>
</geometry>
</collision>
<visual>
<origin xyz="-5.7245874707234634116e-16 -0.065000000000000168754 -0.023400000000000018008" rpy="3.141592653589793116 -3.7227165794273261285e-15 3.141592653589793116" />
<geometry>
<mesh filename="package:///motorejeacopleeje2.stl"/>
</geometry>
<material name="motorejeacopleeje2_material">
<color rgba="0.64705882352941179736 0.64705882352941179736 0.64705882352941179736 1.0"/>
</material>
</visual>
<collision>
<origin xyz="-5.7245874707234634116e-16 -0.065000000000000168754 -0.023400000000000018008" rpy="3.141592653589793116 -3.7227165794273261285e-15 3.141592653589793116" />
<geometry>
<mesh filename="package:///motorejeacopleeje2.stl"/>
</geometry>
</collision>
<visual>
<origin xyz="7.8062556418956319249e-17 0 -0.023400000000000115152" rpy="-3.1415926535897926719 -7.9199650073278229869e-30 -3.431730947635558519e-31" />
<geometry>
<mesh filename="package:///motorejeacoplecaja.stl"/>
</geometry>
<material name="motorejeacoplecaja_material">
<color rgba="0.26274509803921569651 0.28235294117647058432 0.30196078431372547213 1.0"/>
</material>
</visual>
<collision>
<origin xyz="7.8062556418956319249e-17 0 -0.023400000000000115152" rpy="-3.1415926535897926719 -7.9199650073278229869e-30 -3.431730947635558519e-31" />
<geometry>
<mesh filename="package:///motorejeacoplecaja.stl"/>
</geometry>
</collision>
<visual>
<origin xyz="-5.2041704279304212832e-17 -0.043745909016607825714 -0.048800000000000079425" rpy="-1.3997618880526594785e-16 3.7227165794273292839e-15 1.1865508575677392555e-15" />
<geometry>
<mesh filename="package:///femur.stl"/>
</geometry>
<material name="femur_material">
<color rgba="0.97254901960784312376 0.97254901960784312376 0.97254901960784312376 1.0"/>
</material>
</visual>
<collision>
<origin xyz="-5.2041704279304212832e-17 -0.043745909016607825714 -0.048800000000000079425" rpy="-1.3997618880526594785e-16 3.7227165794273292839e-15 1.1865508575677392555e-15" />
<geometry>
<mesh filename="package:///femur.stl"/>
</geometry>
</collision>
<visual>
<origin xyz="-4.04190569902596053e-16 -0.065000000000000168754 -0.023400000000000226175" rpy="-3.141592653589793116 1.2951445471662465471e-14 -3.141592653589793116" />
<geometry>
<mesh filename="package:///motorejeacopleeje1.stl"/>
</geometry>
<material name="motorejeacopleeje1_material">
<color rgba="0.64705882352941179736 0.64705882352941179736 0.64705882352941179736 1.0"/>
</material>
</visual>
<collision>
<origin xyz="-4.04190569902596053e-16 -0.065000000000000168754 -0.023400000000000226175" rpy="-3.141592653589793116 1.2951445471662465471e-14 -3.141592653589793116" />
<geometry>
<mesh filename="package:///motorejeacopleeje1.stl"/>
</geometry>
</collision>
<inertial>
<origin xyz="-1.7555760442170576657e-16 -0.032500000000000008049 -0.023400000000000111683" rpy="0 0 0"/>
<mass value="0.53868761965446410045" />
<inertia ixx="0.00043791203235393798754" ixy="-1.7386978810405262725e-18"  ixz="-7.1417101781604849223e-19" iyy="0.00010909446328561719496" iyz="6.7762635780344027125e-20" izz="0.00036348717125268738964" />
</inertial>
</link>

<link name="tibiaurdf_2">
<visual>
<origin xyz="0 0.0337459090166083997 0" rpy="3.141592653589793116 -1.0452388093474432008e-30 0" />
<geometry>
<mesh filename="package:///tibia.stl"/>
</geometry>
<material name="tibia_material">
<color rgba="0.97254901960784312376 0.97254901960784312376 0.97254901960784312376 1.0"/>
</material>
</visual>
<collision>
<origin xyz="0 0.0337459090166083997 0" rpy="3.141592653589793116 -1.0452388093474432008e-30 0" />
<geometry>
<mesh filename="package:///tibia.stl"/>
</geometry>
</collision>
<visual>
<origin xyz="-3.4694469519536141888e-18 0.05500000000000004885 0.023400000000000011069" rpy="3.141592653589793116 -6.0102164404024450695e-27 -1.1102230246170461875e-16" />
<geometry>
<mesh filename="package:///motorejeacopleeje1.stl"/>
</geometry>
<material name="motorejeacopleeje1_material">
<color rgba="0.64705882352941179736 0.64705882352941179736 0.64705882352941179736 1.0"/>
</material>
</visual>
<collision>
<origin xyz="-3.4694469519536141888e-18 0.05500000000000004885 0.023400000000000011069" rpy="3.141592653589793116 -6.0102164404024450695e-27 -1.1102230246170461875e-16" />
<geometry>
<mesh filename="package:///motorejeacopleeje1.stl"/>
</geometry>
</collision>
<visual>
<origin xyz="6.9388939039072283776e-18 0.05500000000000004885 0.02340000000000000413" rpy="-3.141592653589793116 -2.2204460493114986118e-16 1.1102230246203309304e-16" />
<geometry>
<mesh filename="package:///motorejeacoplecaja.stl"/>
</geometry>
<material name="motorejeacoplecaja_material">
<color rgba="0.26274509803921569651 0.28235294117647058432 0.30196078431372547213 1.0"/>
</material>
</visual>
<collision>
<origin xyz="6.9388939039072283776e-18 0.05500000000000004885 0.02340000000000000413" rpy="-3.141592653589793116 -2.2204460493114986118e-16 1.1102230246203309304e-16" />
<geometry>
<mesh filename="package:///motorejeacoplecaja.stl"/>
</geometry>
</collision>
<visual>
<origin xyz="1.2143064331837649661e-17 0.033745909016608455211 0.04879999999999998922" rpy="3.141592653589793116 -1.1102230246945306941e-16 -2.9473569052287319094e-27" />
<geometry>
<mesh filename="package:///tibia.stl"/>
</geometry>
<material name="tibia_material">
<color rgba="0.97254901960784312376 0.97254901960784312376 0.97254901960784312376 1.0"/>
</material>
</visual>
<collision>
<origin xyz="1.2143064331837649661e-17 0.033745909016608455211 0.04879999999999998922" rpy="3.141592653589793116 -1.1102230246945306941e-16 -2.9473569052287319094e-27" />
<geometry>
<mesh filename="package:///tibia.stl"/>
</geometry>
</collision>
<visual>
<origin xyz="5.2041704279304212832e-18 0.05500000000000004885 0.023399999999999983313" rpy="3.1415926535897926719 7.7715611723223911186e-16 1.1102230246202425533e-16" />
<geometry>
<mesh filename="package:///motorejeacopleeje2.stl"/>
</geometry>
<material name="motorejeacopleeje2_material">
<color rgba="0.64705882352941179736 0.64705882352941179736 0.64705882352941179736 1.0"/>
</material>
</visual>
<collision>
<origin xyz="5.2041704279304212832e-18 0.05500000000000004885 0.023399999999999983313" rpy="3.1415926535897926719 7.7715611723223911186e-16 1.1102230246202425533e-16" />
<geometry>
<mesh filename="package:///motorejeacopleeje2.stl"/>
</geometry>
</collision>
<inertial>
<origin xyz="-6.439096043453285443e-14 0.042938078357409301122 0.023400000000000000661" rpy="0 0 0"/>
<mass value="0.28552673687099017208" />
<inertia ixx="0.00011378661693733243578" ixy="-8.2086911698779303439e-16"  ixz="1.30984738376194311e-20" iyy="6.4755066218591657919e-05" iyz="-3.5151867311053464071e-20" izz="6.750189745491844823e-05" />
</inertial>
</link>

<link name="tobillourdf_2">
<visual>
<origin xyz="0.00015000000000018817725 -0.03579999999999949889 0.023374999999999875044" rpy="-1.570796326794896558 -1.570796326794896558 0" />
<geometry>
<mesh filename="package:///tobillopt3_1.stl"/>
</geometry>
<material name="tobillopt3_1_material">
<color rgba="0.97254901960784312376 0.97254901960784312376 0.97254901960784312376 1.0"/>
</material>
</visual>
<collision>
<origin xyz="0.00015000000000018817725 -0.03579999999999949889 0.023374999999999875044" rpy="-1.570796326794896558 -1.570796326794896558 0" />
<geometry>
<mesh filename="package:///tobillopt3_1.stl"/>
</geometry>
</collision>
<visual>
<origin xyz="2.498001805406602216e-16 -0.03579999999999999849 0.023550000000000077816" rpy="-1.570796326794896558 -1.570796326794896558 0" />
<geometry>
<mesh filename="package:///tobillopt1.stl"/>
</geometry>
<material name="tobillopt1_material">
<color rgba="0.97254901960784312376 0.97254901960784312376 0.97254901960784312376 1.0"/>
</material>
</visual>
<collision>
<origin xyz="2.498001805406602216e-16 -0.03579999999999999849 0.023550000000000077816" rpy="-1.570796326794896558 -1.570796326794896558 0" />
<geometry>
<mesh filename="package:///tobillopt1.stl"/>
</geometry>
</collision>
<visual>
<origin xyz="0.00020000000000010981216 -0.025772450770437105305 0.013564015027679114656" rpy="1.5707963267948978903 -1.4797253911378100871e-13 1.5707963267949893726" />
<geometry>
<mesh filename="package:///motorejecaja.stl"/>
</geometry>
<material name="motorejecaja_material">
<color rgba="0.26274509803921569651 0.28235294117647058432 0.30196078431372547213 1.0"/>
</material>
</visual>
<collision>
<origin xyz="0.00020000000000010981216 -0.025772450770437105305 0.013564015027679114656" rpy="1.5707963267948978903 -1.4797253911378100871e-13 1.5707963267949893726" />
<geometry>
<mesh filename="package:///motorejecaja.stl"/>
</geometry>
</collision>
<visual>
<origin xyz="-0.00014999999999977878251 -0.035799999999999720934 0.023374999999999944433" rpy="-1.570796326794896558 -1.570796326794896336 0" />
<geometry>
<mesh filename="package:///tobillopt3_2.stl"/>
</geometry>
<material name="tobillopt3_2_material">
<color rgba="0.97254901960784312376 0.97254901960784312376 0.97254901960784312376 1.0"/>
</material>
</visual>
<collision>
<origin xyz="-0.00014999999999977878251 -0.035799999999999720934 0.023374999999999944433" rpy="-1.570796326794896558 -1.570796326794896336 0" />
<geometry>
<mesh filename="package:///tobillopt3_2.stl"/>
</geometry>
</collision>
<visual>
<origin xyz="0.00020000000000010981216 -0.025772450770437105305 0.013564015027679114656" rpy="1.5707963267948976682 -1.4708436069408085823e-13 1.5707963267949895947" />
<geometry>
<mesh filename="package:///motorejeeje2.stl"/>
</geometry>
<material name="motorejeeje2_material">
<color rgba="0.64705882352941179736 0.64705882352941179736 0.64705882352941179736 1.0"/>
</material>
</visual>
<collision>
<origin xyz="0.00020000000000010981216 -0.025772450770437105305 0.013564015027679114656" rpy="1.5707963267948976682 -1.4708436069408085823e-13 1.5707963267949895947" />
<geometry>
<mesh filename="package:///motorejeeje2.stl"/>
</geometry>
</collision>
<visual>
<origin xyz="0.00020000000000013756773 -0.025772450770437105305 0.013564015027679059144" rpy="1.5707963267948972241 -1.6329361685360847189e-13 1.5707963267949929254" />
<geometry>
<mesh filename="package:///motorejeeje1.stl"/>
</geometry>
<material name="motorejeeje1_material">
<color rgba="0.64705882352941179736 0.64705882352941179736 0.64705882352941179736 1.0"/>
</material>
</visual>
<collision>
<origin xyz="0.00020000000000013756773 -0.025772450770437105305 0.013564015027679059144" rpy="1.5707963267948972241 -1.6329361685360847189e-13 1.5707963267949929254" />
<geometry>
<mesh filename="package:///motorejeeje1.stl"/>
</geometry>
</collision>
<visual>
<origin xyz="8.3266726846886740532e-17 -0.035799999999999942979 0.023850000000000030898" rpy="-1.570796326794896558 -1.570796326794896558 0" />
<geometry>
<mesh filename="package:///tobillopt2_2.stl"/>
</geometry>
<material name="tobillopt2_2_material">
<color rgba="0.97254901960784312376 0.97254901960784312376 0.97254901960784312376 1.0"/>
</material>
</visual>
<collision>
<origin xyz="8.3266726846886740532e-17 -0.035799999999999942979 0.023850000000000030898" rpy="-1.570796326794896558 -1.570796326794896558 0" />
<geometry>
<mesh filename="package:///tobillopt2_2.stl"/>
</geometry>
</collision>
<visual>
<origin xyz="0 -0.035800000000000054001 0.023249999999999999833" rpy="-1.570796326794896558 -1.570796326794896558 0" />
<geometry>
<mesh filename="package:///tobillopt2_1.stl"/>
</geometry>
<material name="tobillopt2_1_material">
<color rgba="0.97254901960784312376 0.97254901960784312376 0.97254901960784312376 1.0"/>
</material>
</visual>
<collision>
<origin xyz="0 -0.035800000000000054001 0.023249999999999999833" rpy="-1.570796326794896558 -1.570796326794896558 0" />
<geometry>
<mesh filename="package:///tobillopt2_1.stl"/>
</geometry>
</collision>
<inertial>
<origin xyz="0.00013965747905169662133 -0.025656106121457127045 0.023688332336940433331" rpy="0 0 0"/>
<mass value="0.35953278469495464353" />
<inertia ixx="0.00010180132077840433745" ixy="5.8418326098165327084e-09"  ixz="5.7602954081975565675e-08" iyy="0.00013007031479290664618" iyz="5.2659589177709744789e-07" izz="7.0605342570129360361e-05" />
</inertial>
</link>

<link name="pieurdf_2">
<visual>
<origin xyz="-0.010000000000000015821 -0.018999999999999961364 0.023400000000000011069" rpy="-1.570796326794896558 -1.570796326794896336 0" />
<geometry>
<mesh filename="package:///acoplepiemotor.stl"/>
</geometry>
<material name="acoplepiemotor_material">
<color rgba="0.97254901960784312376 0.97254901960784312376 0.97254901960784312376 1.0"/>
</material>
</visual>
<collision>
<origin xyz="-0.010000000000000015821 -0.018999999999999961364 0.023400000000000011069" rpy="-1.570796326794896558 -1.570796326794896336 0" />
<geometry>
<mesh filename="package:///acoplepiemotor.stl"/>
</geometry>
</collision>
<visual>
<origin xyz="-0.0099999999999998978595 -0.018999999999999905853 0.0235000000000002221" rpy="-1.570796326794896558 -1.570796326794896336 0" />
<geometry>
<mesh filename="package:///acoplepiemotor.stl"/>
</geometry>
<material name="acoplepiemotor_material">
<color rgba="0.97254901960784312376 0.97254901960784312376 0.97254901960784312376 1.0"/>
</material>
</visual>
<collision>
<origin xyz="-0.0099999999999998978595 -0.018999999999999905853 0.0235000000000002221" rpy="-1.570796326794896558 -1.570796326794896336 0" />
<geometry>
<mesh filename="package:///acoplepiemotor.stl"/>
</geometry>
</collision>
<visual>
<origin xyz="-0.0099999999999998978595 -0.018949999999999966871 0.023450000000000137401" rpy="-1.570796326794896558 -1.570796326794896336 0" />
<geometry>
<mesh filename="package:///plantapie.stl"/>
</geometry>
<material name="plantapie_material">
<color rgba="0.97254901960784312376 0.97254901960784312376 0.97254901960784312376 1.0"/>
</material>
</visual>
<collision>
<origin xyz="-0.0099999999999998978595 -0.018949999999999966871 0.023450000000000137401" rpy="-1.570796326794896558 -1.570796326794896336 0" />
<geometry>
<mesh filename="package:///plantapie.stl"/>
</geometry>
</collision>
<inertial>
<origin xyz="-0.0095981962877160469788 -0.018994815818902558574 0.023450000000000126993" rpy="0 0 0"/>
<mass value="0.12193030814742022994" />
<inertia ixx="5.5790028401553196698e-05" ixy="-1.0383957421083800825e-06"  ixz="-3.3544701418326122002e-20" iyy="7.8275338616851076155e-05" iyz="-4.3351251070551846844e-21" izz="3.3440055653628886581e-05" />
</inertial>
</link>

<joint name="RightAnkle2" type="revolute">
<origin xyz="-0.023199999999999894318 -0.02577245077043927024 0.013564015027679135472" rpy="-9.2675866980585320865e-14 1.5707963267947497865 0" />
<parent link="tobillourdf_2" />
<child link="pieurdf_2" />
<axis xyz="0 0 1"/>
<limit effort="1" velocity="20" lower="-0.26179938779914940783" upper="0.26179938779914940783"/>
<joint_properties friction="0.0"/>
</joint>

<joint name="RightAnkle1" type="revolute">
<origin xyz="8.6736173798840354721e-18 0.05500000000000004885 0.046799999999999994382" rpy="3.141592653589793116 4.3896650401099704644e-16 9.5660208773739903412e-16" />
<parent link="tibiaurdf_2" />
<child link="tobillourdf_2" />
<axis xyz="0 0 1"/>
<limit effort="1" velocity="20" lower="-0.785398163397448279" upper="0.52359877559829881566"/>
<joint_properties friction="0.0"/>
</joint>

<joint name="RightKnee" type="revolute">
<origin xyz="-6.3664351568348820365e-16 -0.065000000000000168754 -1.3877787807814456755e-17" rpy="3.141592653589793116 6.0472093121809969072e-15 2.2482016248737809052e-15" />
<parent link="femururdf_2" />
<child link="tibiaurdf_2" />
<axis xyz="0 0 1"/>
<limit effort="1" velocity="20" lower="-0.26179938779914940783" upper="2.356194490192344837"/>
<joint_properties friction="0.0"/>
</joint>

<joint name="RightHip2" type="revolute">
<origin xyz="0.028027549229562395694 -0.033035984972319951125 -0.023250000000002636613" rpy="1.5707963267949076602 -1.5707963267948039654 0" />
<parent link="cadera_v01_2" />
<child link="femururdf_2" />
<axis xyz="0 0 1"/>
<limit effort="1" velocity="20" lower="-1.570796326794896558" upper="1.570796326794896558"/>
<joint_properties friction="0.0"/>
</joint>

<joint name="RightHip1" type="revolute">
<origin xyz="-0.023550000000000039652 0.022673904349987825113 -0.02360543610293333594" rpy="3.1415926535897913396 1.5707963267948956698 0" />
<parent link="cintura_v01_2" />
<child link="cadera_v01_2" />
<axis xyz="0 0 1"/>
<limit effort="1" velocity="20" lower="-0.52359877559829881566" upper="0.52359877559829881566"/>
<joint_properties friction="0.0"/>
</joint>

<joint name="RightWaist" type="revolute">
<origin xyz="-0.010742981990015255944 0.0083712188771943168986 -0.083178910040700979045" rpy="-1.2602862693222394471e-29 5.03337832939847449e-16 1.57079632679489678" />
<parent link="torsourdf" />
<child link="cintura_v01_2" />
<axis xyz="0 0 1"/>
<limit effort="1" velocity="20" lower="-0.26179938779914940783" upper="0.26179938779914940783"/>
<joint_properties friction="0.0"/>
</joint>


</robot>
