<robot name="onshape">
<link name="torsourdf">
<visual>
<origin xyz="-0.030742981990015266769 0.038371218877194315788 -0.076728910040700981643" rpy="1.570796326794896558 -0 0" />
<geometry>
<mesh filename="package:///acople_tornillos_abdomen.stl"/>
</geometry>
<material name="acople_tornillos_abdomen_material">
<color rgba="0.26274509803921569651 0.28235294117647058432 0.30196078431372547213 1.0"/>
</material>
</visual>
<collision>
<origin xyz="-0.030742981990015266769 0.038371218877194315788 -0.076728910040700981643" rpy="1.570796326794896558 -0 0" />
<geometry>
<mesh filename="package:///acople_tornillos_abdomen.stl"/>
</geometry>
</collision>
<visual>
<origin xyz="0.064057018009984756368 0.038371218877194308849 0.050524780976926725318" rpy="-1.570796326794896558 -0 3.141592653589793116" />
<geometry>
<mesh filename="package:///acople_tornillos_cuello.stl"/>
</geometry>
<material name="acople_tornillos_cuello_material">
<color rgba="0.26274509803921569651 0.28235294117647058432 0.30196078431372547213 1.0"/>
</material>
</visual>
<collision>
<origin xyz="0.064057018009984756368 0.038371218877194308849 0.050524780976926725318" rpy="-1.570796326794896558 -0 3.141592653589793116" />
<geometry>
<mesh filename="package:///acople_tornillos_cuello.stl"/>
</geometry>
</collision>
<visual>
<origin xyz="0.019257018009984729068 0.0083712188771943168986 -0.059778910040700981854" rpy="3.141592653589793116 -0 3.141592653589793116" />
<geometry>
<mesh filename="package:///motorsemiejeeje.stl"/>
</geometry>
<material name="motorsemiejeeje_material">
<color rgba="0.64705882352941179736 0.64705882352941179736 0.64705882352941179736 1.0"/>
</material>
</visual>
<collision>
<origin xyz="0.019257018009984729068 0.0083712188771943168986 -0.059778910040700981854" rpy="3.141592653589793116 -0 3.141592653589793116" />
<geometry>
<mesh filename="package:///motorsemiejeeje.stl"/>
</geometry>
</collision>
<visual>
<origin xyz="-0.055542981990015269367 0.038371218877194329666 -0.037828910040700991502" rpy="1.570796326794896558 -0 0" />
<geometry>
<mesh filename="package:///acople_tornillos_abdomen.stl"/>
</geometry>
<material name="acople_tornillos_abdomen_material">
<color rgba="0.26274509803921569651 0.28235294117647058432 0.30196078431372547213 1.0"/>
</material>
</visual>
<collision>
<origin xyz="-0.055542981990015269367 0.038371218877194329666 -0.037828910040700991502" rpy="1.570796326794896558 -0 0" />
<geometry>
<mesh filename="package:///acople_tornillos_abdomen.stl"/>
</geometry>
</collision>
<visual>
<origin xyz="0.069405821023547836779 0.0073712188771943021326 0.025468521028911533799" rpy="-1.570796326794896558 -0 -1.570796326794896558" />
<geometry>
<mesh filename="package:///motorejeeje2.stl"/>
</geometry>
<material name="motorejeeje2_material">
<color rgba="0.64705882352941179736 0.64705882352941179736 0.64705882352941179736 1.0"/>
</material>
</visual>
<collision>
<origin xyz="0.069405821023547836779 0.0073712188771943021326 0.025468521028911533799" rpy="-1.570796326794896558 -0 -1.570796326794896558" />
<geometry>
<mesh filename="package:///motorejeeje2.stl"/>
</geometry>
</collision>
<visual>
<origin xyz="-0.060891785003578363655 0.0073712188771943021326 0.025468521028911547677" rpy="-1.570796326794896558 -0 1.570796326794896558" />
<geometry>
<mesh filename="package:///motorejeeje1.stl"/>
</geometry>
<material name="motorejeeje1_material">
<color rgba="0.64705882352941179736 0.64705882352941179736 0.64705882352941179736 1.0"/>
</material>
</visual>
<collision>
<origin xyz="-0.060891785003578363655 0.0073712188771943021326 0.025468521028911547677" rpy="-1.570796326794896558 -0 1.570796326794896558" />
<geometry>
<mesh filename="package:///motorejeeje1.stl"/>
</geometry>
</collision>
<visual>
<origin xyz="0.004057018009984730833 -0.023628781122805697645 -0.0045580513594990768045" rpy="1.570796326794896558 -0 0" />
<geometry>
<mesh filename="package:///pecho.stl"/>
</geometry>
<material name="pecho_material">
<color rgba="0.97254901960784312376 0.97254901960784312376 0.97254901960784312376 1.0"/>
</material>
</visual>
<collision>
<origin xyz="0.004057018009984730833 -0.023628781122805697645 -0.0045580513594990768045" rpy="1.570796326794896558 -0 0" />
<geometry>
<mesh filename="package:///pecho.stl"/>
</geometry>
</collision>
<visual>
<origin xyz="0.069405821023547836779 0.0073712188771943021326 0.025468521028911547677" rpy="-1.5707963267948976682 1.9721522630525216312e-31 -1.570796326794896336" />
<geometry>
<mesh filename="package:///motorejeeje1.stl"/>
</geometry>
<material name="motorejeeje1_material">
<color rgba="0.64705882352941179736 0.64705882352941179736 0.64705882352941179736 1.0"/>
</material>
</visual>
<collision>
<origin xyz="0.069405821023547836779 0.0073712188771943021326 0.025468521028911547677" rpy="-1.5707963267948976682 1.9721522630525216312e-31 -1.570796326794896336" />
<geometry>
<mesh filename="package:///motorejeeje1.stl"/>
</geometry>
</collision>
<visual>
<origin xyz="0.087855821023547830961 0.007371218877194305602 0.025468521028911547677" rpy="-1.570796326794896558 -0 -1.570796326794896558" />
<geometry>
<mesh filename="package:///hombro_pecho.stl"/>
</geometry>
<material name="hombro_pecho_material">
<color rgba="0.97254901960784312376 0.97254901960784312376 0.97254901960784312376 1.0"/>
</material>
</visual>
<collision>
<origin xyz="0.087855821023547830961 0.007371218877194305602 0.025468521028911547677" rpy="-1.570796326794896558 -0 -1.570796326794896558" />
<geometry>
<mesh filename="package:///hombro_pecho.stl"/>
</geometry>
</collision>
<visual>
<origin xyz="-0.010742981990015254209 0.0083712188771943238375 -0.059778910040700974915" rpy="3.141592653589793116 -0 3.141592653589793116" />
<geometry>
<mesh filename="package:///motorsemiejecaja.stl"/>
</geometry>
<material name="motorsemiejecaja_material">
<color rgba="0.26274509803921569651 0.28235294117647058432 0.30196078431372547213 1.0"/>
</material>
</visual>
<collision>
<origin xyz="-0.010742981990015254209 0.0083712188771943238375 -0.059778910040700974915" rpy="3.141592653589793116 -0 3.141592653589793116" />
<geometry>
<mesh filename="package:///motorsemiejecaja.stl"/>
</geometry>
</collision>
<visual>
<origin xyz="-0.079341785003578357838 0.0073712188771942951937 0.025468521028911547677" rpy="-1.570796326794896558 -0 1.570796326794896558" />
<geometry>
<mesh filename="package:///hombro_pecho.stl"/>
</geometry>
<material name="hombro_pecho_material">
<color rgba="0.97254901960784312376 0.97254901960784312376 0.97254901960784312376 1.0"/>
</material>
</visual>
<collision>
<origin xyz="-0.079341785003578357838 0.0073712188771942951937 0.025468521028911547677" rpy="-1.570796326794896558 -0 1.570796326794896558" />
<geometry>
<mesh filename="package:///hombro_pecho.stl"/>
</geometry>
</collision>
<visual>
<origin xyz="-0.060891785003578363655 0.0073712188771943021326 0.025468521028911547677" rpy="-1.57079632679489678 -7.8886090522100182116e-31 1.57079632679489678" />
<geometry>
<mesh filename="package:///motorejeeje2.stl"/>
</geometry>
<material name="motorejeeje2_material">
<color rgba="0.64705882352941179736 0.64705882352941179736 0.64705882352941179736 1.0"/>
</material>
</visual>
<collision>
<origin xyz="-0.060891785003578363655 0.0073712188771943021326 0.025468521028911547677" rpy="-1.57079632679489678 -7.8886090522100182116e-31 1.57079632679489678" />
<geometry>
<mesh filename="package:///motorejeeje2.stl"/>
</geometry>
</collision>
<visual>
<origin xyz="-0.010742981990015255944 0.0083712188771943168986 -0.059778910040700981854" rpy="3.141592653589793116 -0 3.141592653589793116" />
<geometry>
<mesh filename="package:///motorsemiejeeje.stl"/>
</geometry>
<material name="motorsemiejeeje_material">
<color rgba="0.64705882352941179736 0.64705882352941179736 0.64705882352941179736 1.0"/>
</material>
</visual>
<collision>
<origin xyz="-0.010742981990015255944 0.0083712188771943168986 -0.059778910040700981854" rpy="3.141592653589793116 -0 3.141592653589793116" />
<geometry>
<mesh filename="package:///motorsemiejeeje.stl"/>
</geometry>
</collision>
<visual>
<origin xyz="0.0042570180099847365618 0.040371218877194303687 -0.0045580513594990490489" rpy="1.570796326794896558 -0 0" />
<geometry>
<mesh filename="package:///espalda.stl"/>
</geometry>
<material name="espalda_material">
<color rgba="0.97254901960784312376 0.97254901960784312376 0.97254901960784312376 1.0"/>
</material>
</visual>
<collision>
<origin xyz="0.0042570180099847365618 0.040371218877194303687 -0.0045580513594990490489" rpy="1.570796326794896558 -0 0" />
<geometry>
<mesh filename="package:///espalda.stl"/>
</geometry>
</collision>
<visual>
<origin xyz="-0.060891785003578363655 0.0073712188771942917243 0.025468521028911547677" rpy="-1.570796326794896558 -0 1.570796326794896558" />
<geometry>
<mesh filename="package:///motorejecaja.stl"/>
</geometry>
<material name="motorejecaja_material">
<color rgba="0.26274509803921569651 0.28235294117647058432 0.30196078431372547213 1.0"/>
</material>
</visual>
<collision>
<origin xyz="-0.060891785003578363655 0.0073712188771942917243 0.025468521028911547677" rpy="-1.570796326794896558 -0 1.570796326794896558" />
<geometry>
<mesh filename="package:///motorejecaja.stl"/>
</geometry>
</collision>
<visual>
<origin xyz="-0.055942981990015253069 -0.023628781122805697645 0.050524780976926725318" rpy="-1.570796326794896558 -0 0" />
<geometry>
<mesh filename="package:///acople_tornillos_cuello.stl"/>
</geometry>
<material name="acople_tornillos_cuello_material">
<color rgba="0.26274509803921569651 0.28235294117647058432 0.30196078431372547213 1.0"/>
</material>
</visual>
<collision>
<origin xyz="-0.055942981990015253069 -0.023628781122805697645 0.050524780976926725318" rpy="-1.570796326794896558 -0 0" />
<geometry>
<mesh filename="package:///acople_tornillos_cuello.stl"/>
</geometry>
</collision>
<visual>
<origin xyz="0.014057018009984739715 0.007371218877194305602 0.054024780976926728426" rpy="3.141592653589793116 -0 -1.570796326794896558" />
<geometry>
<mesh filename="package:///base_cabeza.stl"/>
</geometry>
<material name="base_cabeza_material">
<color rgba="0.97254901960784312376 0.97254901960784312376 0.97254901960784312376 1.0"/>
</material>
</visual>
<collision>
<origin xyz="0.014057018009984739715 0.007371218877194305602 0.054024780976926728426" rpy="3.141592653589793116 -0 -1.570796326794896558" />
<geometry>
<mesh filename="package:///base_cabeza.stl"/>
</geometry>
</collision>
<visual>
<origin xyz="-0.010542981990015257154 0.023946218877194329344 -0.04132891004070099461" rpy="0 -0 0" />
<geometry>
<mesh filename="package:///acoplemotorestorso1.stl"/>
</geometry>
<material name="acoplemotorestorso1_material">
<color rgba="0.97254901960784312376 0.97254901960784312376 0.97254901960784312376 1.0"/>
</material>
</visual>
<collision>
<origin xyz="-0.010542981990015257154 0.023946218877194329344 -0.04132891004070099461" rpy="0 -0 0" />
<geometry>
<mesh filename="package:///acoplemotorestorso1.stl"/>
</geometry>
</collision>
<visual>
<origin xyz="-0.010742981990015262883 0.023946218877194322405 -0.080228910040700984752" rpy="0 -0 0" />
<geometry>
<mesh filename="package:///acoplemotorestorso2.stl"/>
</geometry>
<material name="acoplemotorestorso2_material">
<color rgba="0.97254901960784312376 0.97254901960784312376 0.97254901960784312376 1.0"/>
</material>
</visual>
<collision>
<origin xyz="-0.010742981990015262883 0.023946218877194322405 -0.080228910040700984752" rpy="0 -0 0" />
<geometry>
<mesh filename="package:///acoplemotorestorso2.stl"/>
</geometry>
</collision>
<visual>
<origin xyz="-0.077841785003578356505 -0.023628781122805683768 -0.0070314789710884256779" rpy="-1.570796326794896558 -1.570796326794896558 0" />
<geometry>
<mesh filename="package:///acople_tornillos_hombro.stl"/>
</geometry>
<material name="acople_tornillos_hombro_material">
<color rgba="0.26274509803921569651 0.28235294117647058432 0.30196078431372547213 1.0"/>
</material>
</visual>
<collision>
<origin xyz="-0.077841785003578356505 -0.023628781122805683768 -0.0070314789710884256779" rpy="-1.570796326794896558 -1.570796326794896558 0" />
<geometry>
<mesh filename="package:///acople_tornillos_hombro.stl"/>
</geometry>
</collision>
<visual>
<origin xyz="0.086355821023547829629 0.038371218877194274155 -0.0070314789710884395557" rpy="1.570796326794896558 -1.570796326794896558 0" />
<geometry>
<mesh filename="package:///acople_tornillos_hombro.stl"/>
</geometry>
<material name="acople_tornillos_hombro_material">
<color rgba="0.26274509803921569651 0.28235294117647058432 0.30196078431372547213 1.0"/>
</material>
</visual>
<collision>
<origin xyz="0.086355821023547829629 0.038371218877194274155 -0.0070314789710884395557" rpy="1.570796326794896558 -1.570796326794896558 0" />
<geometry>
<mesh filename="package:///acople_tornillos_hombro.stl"/>
</geometry>
</collision>
<visual>
<origin xyz="0.086355821023547829629 -0.023628781122805697645 0.037968521028911544901" rpy="-1.570796326794896558 1.570796326794896558 0" />
<geometry>
<mesh filename="package:///acople_tornillos_hombro.stl"/>
</geometry>
<material name="acople_tornillos_hombro_material">
<color rgba="0.26274509803921569651 0.28235294117647058432 0.30196078431372547213 1.0"/>
</material>
</visual>
<collision>
<origin xyz="0.086355821023547829629 -0.023628781122805697645 0.037968521028911544901" rpy="-1.570796326794896558 1.570796326794896558 0" />
<geometry>
<mesh filename="package:///acople_tornillos_hombro.stl"/>
</geometry>
</collision>
<visual>
<origin xyz="0.039257018009984739892 -0.0216287811228056924 -0.076728910040700981643" rpy="1.570796326794896558 -0 3.141592653589793116" />
<geometry>
<mesh filename="package:///acople_tornillos_abdomen.stl"/>
</geometry>
<material name="acople_tornillos_abdomen_material">
<color rgba="0.26274509803921569651 0.28235294117647058432 0.30196078431372547213 1.0"/>
</material>
</visual>
<collision>
<origin xyz="0.039257018009984739892 -0.0216287811228056924 -0.076728910040700981643" rpy="1.570796326794896558 -0 3.141592653589793116" />
<geometry>
<mesh filename="package:///acople_tornillos_abdomen.stl"/>
</geometry>
</collision>
<visual>
<origin xyz="0.064457018009984712315 -0.021628781122805678522 -0.037828910040700991502" rpy="1.570796326794896558 -0 3.141592653589793116" />
<geometry>
<mesh filename="package:///acople_tornillos_abdomen.stl"/>
</geometry>
<material name="acople_tornillos_abdomen_material">
<color rgba="0.26274509803921569651 0.28235294117647058432 0.30196078431372547213 1.0"/>
</material>
</visual>
<collision>
<origin xyz="0.064457018009984712315 -0.021628781122805678522 -0.037828910040700991502" rpy="1.570796326794896558 -0 3.141592653589793116" />
<geometry>
<mesh filename="package:///acople_tornillos_abdomen.stl"/>
</geometry>
</collision>
<visual>
<origin xyz="0.0042570180099847365618 -0.023628781122805683768 -0.0045580513594990629267" rpy="1.570796326794896558 -0 3.141592653589793116" />
<geometry>
<mesh filename="package:///abdomen.stl"/>
</geometry>
<material name="abdomen_material">
<color rgba="0.26274509803921569651 0.28235294117647058432 0.30196078431372547213 1.0"/>
</material>
</visual>
<collision>
<origin xyz="0.0042570180099847365618 -0.023628781122805683768 -0.0045580513594990629267" rpy="1.570796326794896558 -0 3.141592653589793116" />
<geometry>
<mesh filename="package:///abdomen.stl"/>
</geometry>
</collision>
<visual>
<origin xyz="-0.077841785003578356505 0.038371218877194301911 0.037968521028911544901" rpy="1.570796326794896558 1.570796326794896558 0" />
<geometry>
<mesh filename="package:///acople_tornillos_hombro.stl"/>
</geometry>
<material name="acople_tornillos_hombro_material">
<color rgba="0.26274509803921569651 0.28235294117647058432 0.30196078431372547213 1.0"/>
</material>
</visual>
<collision>
<origin xyz="-0.077841785003578356505 0.038371218877194301911 0.037968521028911544901" rpy="1.570796326794896558 1.570796326794896558 0" />
<geometry>
<mesh filename="package:///acople_tornillos_hombro.stl"/>
</geometry>
</collision>
<visual>
<origin xyz="0.069405821023547836779 0.0073712188771943021326 0.025468521028911533799" rpy="-1.570796326794896558 -0 -1.570796326794896558" />
<geometry>
<mesh filename="package:///motorejecaja.stl"/>
</geometry>
<material name="motorejecaja_material">
<color rgba="0.26274509803921569651 0.28235294117647058432 0.30196078431372547213 1.0"/>
</material>
</visual>
<collision>
<origin xyz="0.069405821023547836779 0.0073712188771943021326 0.025468521028911533799" rpy="-1.570796326794896558 -0 -1.570796326794896558" />
<geometry>
<mesh filename="package:///motorejecaja.stl"/>
</geometry>
</collision>
<visual>
<origin xyz="0.004057018009984730833 -0.023628781122805697645 -0.0045580513594990768045" rpy="1.570796326794896558 -0 0" />
<geometry>
<mesh filename="package:///luzpecho.stl"/>
</geometry>
<material name="luzpecho_material">
<color rgba="0.14117647058823529216 0.6941176470588235059 0.65098039215686276382 1.0"/>
</material>
</visual>
<collision>
<origin xyz="0.004057018009984730833 -0.023628781122805697645 -0.0045580513594990768045" rpy="1.570796326794896558 -0 0" />
<geometry>
<mesh filename="package:///luzpecho.stl"/>
</geometry>
</collision>
<visual>
<origin xyz="0.01925701800998471519 0.0083712188771943238375 -0.059778910040700974915" rpy="3.141592653589793116 -0 3.141592653589793116" />
<geometry>
<mesh filename="package:///motorsemiejecaja.stl"/>
</geometry>
<material name="motorsemiejecaja_material">
<color rgba="0.26274509803921569651 0.28235294117647058432 0.30196078431372547213 1.0"/>
</material>
</visual>
<collision>
<origin xyz="0.01925701800998471519 0.0083712188771943238375 -0.059778910040700974915" rpy="3.141592653589793116 -0 3.141592653589793116" />
<geometry>
<mesh filename="package:///motorsemiejecaja.stl"/>
</geometry>
</collision>
<inertial>
<origin xyz="0.0041641753467128710814 -0.0069926972537796040774 -0.0054565398185849869547" rpy="0 0 0"/>
<mass value="3.2921674694110936166" />
<inertia ixx="0.0076880102936372884254" ixy="-6.7916077198654890108e-06"  ixz="6.7702832083639237579e-06" iyy="0.013499449690620241721" iyz="0.00096379853423097193704" izz="0.0097359687391730415779" />
</inertial>
</link>

<link name="hombro-brazo">
<visual>
<origin xyz="-1.1362438767648086468e-16 -0.010999809727072717286 -0.0020000000000000017764" rpy="3.141592653589793116 -4.9303806576206958108e-32 0" />
<geometry>
<mesh filename="package:///hombro_brazo1.stl"/>
</geometry>
<material name="hombro_brazo1_material">
<color rgba="0.97254901960784312376 0.97254901960784312376 0.97254901960784312376 1.0"/>
</material>
</visual>
<collision>
<origin xyz="-1.1362438767648086468e-16 -0.010999809727072717286 -0.0020000000000000017764" rpy="3.141592653589793116 -4.9303806576206958108e-32 0" />
<geometry>
<mesh filename="package:///hombro_brazo1.stl"/>
</geometry>
</collision>
<visual>
<origin xyz="-0.0002999999999956952032 0.011000190272924889254 9.4368957093138305936e-16" rpy="-3.1415926535897895633 -2.6645352591003760126e-14 -3.1415926535897864547" />
<geometry>
<mesh filename="package:///hombro_brazo2.stl"/>
</geometry>
<material name="hombro_brazo2_material">
<color rgba="0.97254901960784312376 0.97254901960784312376 0.97254901960784312376 1.0"/>
</material>
</visual>
<collision>
<origin xyz="-0.0002999999999956952032 0.011000190272924889254 9.4368957093138305936e-16" rpy="-3.1415926535897895633 -2.6645352591003760126e-14 -3.1415926535897864547" />
<geometry>
<mesh filename="package:///hombro_brazo2.stl"/>
</geometry>
</collision>
<visual>
<origin xyz="0.00029999999999982904925 -0.010999809727072731164 6.8001160258290838101e-16" rpy="3.1415926535897926719 5.5511151231205328328e-16 -2.488009798184976312e-13" />
<geometry>
<mesh filename="package:///hombro_brazo2.stl"/>
</geometry>
<material name="hombro_brazo2_material">
<color rgba="0.97254901960784312376 0.97254901960784312376 0.97254901960784312376 1.0"/>
</material>
</visual>
<collision>
<origin xyz="0.00029999999999982904925 -0.010999809727072731164 6.8001160258290838101e-16" rpy="3.1415926535897926719 5.5511151231205328328e-16 -2.488009798184976312e-13" />
<geometry>
<mesh filename="package:///hombro_brazo2.stl"/>
</geometry>
</collision>
<inertial>
<origin xyz="1.7014733176725471617e-15 1.1044824123134683803e-07 -0.0076081599888872253334" rpy="0 0 0"/>
<mass value="0.028276359613946901173" />
<inertia ixx="3.1909882339227915847e-06" ixy="7.6383436214788023328e-11"  ixz="4.6036240683271223428e-19" iyy="1.3925926827988112166e-05" iyz="1.491561761143591943e-11" izz="1.2743353645780909449e-05" />
</inertial>
</link>

<link name="brazourdf">
<visual>
<origin xyz="2.7755575615628913511e-17 -6.9388939039072283776e-18 -0.02340000000000000413" rpy="2.1094237467878266147e-15 -4.4408920985025036506e-16 1.570796326794896558" />
<geometry>
<mesh filename="package:///motorejeacopleeje2.stl"/>
</geometry>
<material name="motorejeacopleeje2_material">
<color rgba="0.64705882352941179736 0.64705882352941179736 0.64705882352941179736 1.0"/>
</material>
</visual>
<collision>
<origin xyz="2.7755575615628913511e-17 -6.9388939039072283776e-18 -0.02340000000000000413" rpy="2.1094237467878266147e-15 -4.4408920985025036506e-16 1.570796326794896558" />
<geometry>
<mesh filename="package:///motorejeacopleeje2.stl"/>
</geometry>
</collision>
<visual>
<origin xyz="-0.030000000000000012768 0 -0.023399999999999990252" rpy="1.5707963267948970021 -5.5511151229433647808e-17 1.570796326794896336" />
<geometry>
<mesh filename="package:///brazo.stl"/>
</geometry>
<material name="brazo_material">
<color rgba="0.97254901960784312376 0.97254901960784312376 0.97254901960784312376 1.0"/>
</material>
</visual>
<collision>
<origin xyz="-0.030000000000000012768 0 -0.023399999999999990252" rpy="1.5707963267948970021 -5.5511151229433647808e-17 1.570796326794896336" />
<geometry>
<mesh filename="package:///brazo.stl"/>
</geometry>
</collision>
<visual>
<origin xyz="1.3877787807814456755e-17 0 -0.023399999999999997191" rpy="-7.0879359787127582264e-31 -0 1.570796326794896558" />
<geometry>
<mesh filename="package:///motorejeacopleeje1.stl"/>
</geometry>
<material name="motorejeacopleeje1_material">
<color rgba="0.64705882352941179736 0.64705882352941179736 0.64705882352941179736 1.0"/>
</material>
</visual>
<collision>
<origin xyz="1.3877787807814456755e-17 0 -0.023399999999999997191" rpy="-7.0879359787127582264e-31 -0 1.570796326794896558" />
<geometry>
<mesh filename="package:///motorejeacopleeje1.stl"/>
</geometry>
</collision>
<visual>
<origin xyz="0 3.4694469519536141888e-18 -0.023400000000000000661" rpy="4.4408920984990405513e-16 -2.2204460492507504056e-16 1.570796326794896336" />
<geometry>
<mesh filename="package:///motorejeacoplecaja.stl"/>
</geometry>
<material name="motorejeacoplecaja_material">
<color rgba="0.26274509803921569651 0.28235294117647058432 0.30196078431372547213 1.0"/>
</material>
</visual>
<collision>
<origin xyz="0 3.4694469519536141888e-18 -0.023400000000000000661" rpy="4.4408920984990405513e-16 -2.2204460492507504056e-16 1.570796326794896336" />
<geometry>
<mesh filename="package:///motorejeacoplecaja.stl"/>
</geometry>
</collision>
<inertial>
<origin xyz="-0.064612740306650345845 0.00024409654353023776041 -0.023399999587718614547" rpy="0 0 0"/>
<mass value="1.080760232398511711" />
<inertia ixx="0.00022953897767025226119" ixy="2.1146337854862573221e-05"  ixz="-1.3608742073126757512e-10" iyy="0.0024710869173820300924" iyz="-1.0815339248804054162e-11" izz="0.0023133411907278662346" />
</inertial>
</link>

<joint name="LeftShoulder2" type="revolute">
<origin xyz="-0.02354999999999616081 3.8054585194818857374e-07 -0.020946406845601450719" rpy="7.7715611723741378302e-15 -1.5707963267948685804 0" />
<parent link="hombro-brazo" />
<child link="brazourdf" />
<axis xyz="0 0 1"/>
<limit effort="1" velocity="20" lower="-1.570796326794896558" upper="1.570796326794896558"/>
<joint_properties friction="0.0"/>
</joint>

<joint name="LeftShoulder1" type="revolute">
<origin xyz="0.092805821023547840909 0.0073712188771943082041 0.02546852102891152686" rpy="-1.5707963267948943376 -5.5511151231257851673e-17 1.570796326794896336" />
<parent link="torsourdf" />
<child link="hombro-brazo" />
<axis xyz="0 0 1"/>
<limit effort="1" velocity="20" lower="-1.570796326794896558" upper="1.570796326794896558"/>
<joint_properties friction="0.0"/>
</joint>

<link name="cintura_v01">
<visual>
<origin xyz="0 0 -0.0020000000000000017764" rpy="-3.141592653589793116 1.2293852596703309173e-40 0.785398163397448279" />
<geometry>
<mesh filename="package:///cinturapt1.stl"/>
</geometry>
<material name="cinturapt1_material">
<color rgba="0.97254901960784312376 0.97254901960784312376 0.97254901960784312376 1.0"/>
</material>
</visual>
<collision>
<origin xyz="0 0 -0.0020000000000000017764" rpy="-3.141592653589793116 1.2293852596703309173e-40 0.785398163397448279" />
<geometry>
<mesh filename="package:///cinturapt1.stl"/>
</geometry>
</collision>
<visual>
<origin xyz="0.00021213203435583617706 0.00021213203435584138123 -0.0020000000000000017764" rpy="-3.141592653589793116 -4.9303807922742689394e-32 0.78539816339744938922" />
<geometry>
<mesh filename="package:///cinturapt2_2.stl"/>
</geometry>
<material name="cinturapt2_2_material">
<color rgba="0.97254901960784312376 0.97254901960784312376 0.97254901960784312376 1.0"/>
</material>
</visual>
<collision>
<origin xyz="0.00021213203435583617706 0.00021213203435584138123 -0.0020000000000000017764" rpy="-3.141592653589793116 -4.9303807922742689394e-32 0.78539816339744938922" />
<geometry>
<mesh filename="package:///cinturapt2_2.stl"/>
</geometry>
</collision>
<visual>
<origin xyz="-0.00021213203435577546174 -0.00021213203435578240064 -0.0020000000000000017764" rpy="-3.141592653589793116 -4.9303807922742689394e-32 0.78539816339744938922" />
<geometry>
<mesh filename="package:///cinturapt2_1.stl"/>
</geometry>
<material name="cinturapt2_1_material">
<color rgba="0.97254901960784312376 0.97254901960784312376 0.97254901960784312376 1.0"/>
</material>
</visual>
<collision>
<origin xyz="-0.00021213203435577546174 -0.00021213203435578240064 -0.0020000000000000017764" rpy="-3.141592653589793116 -4.9303807922742689394e-32 0.78539816339744938922" />
<geometry>
<mesh filename="package:///cinturapt2_1.stl"/>
</geometry>
</collision>
<inertial>
<origin xyz="-0.0079316365006480479133 0.0079316365006479924021 -0.0083693257381815735346" rpy="0 0 0"/>
<mass value="0.032703197933895256089" />
<inertia ixx="1.1474475218213178387e-05" ixy="-5.2475239690138017324e-06"  ixz="-1.4935382828704789585e-06" iyy="1.1474475218213164835e-05" iyz="1.4935382828704757821e-06" izz="1.7093428062394867324e-05" />
</inertial>
</link>

<link name="cadera_v01">
<visual>
<origin xyz="0.010027549229565529965 0.0091859849723225708851 -0.023549999999994977729" rpy="-1.5707963267951956521 -8.8284103325924701914e-14 1.570796326795155462" />
<geometry>
<mesh filename="package:///caderapt2_1.stl"/>
</geometry>
<material name="caderapt2_1_material">
<color rgba="0.97254901960784312376 0.97254901960784312376 0.97254901960784312376 1.0"/>
</material>
</visual>
<collision>
<origin xyz="0.010027549229565529965 0.0091859849723225708851 -0.023549999999994977729" rpy="-1.5707963267951956521 -8.8284103325924701914e-14 1.570796326795155462" />
<geometry>
<mesh filename="package:///caderapt2_1.stl"/>
</geometry>
</collision>
<visual>
<origin xyz="0 -6.9388939039072283776e-18 -0.02340000000000000413" rpy="1.0146536357571251952e-17 -0 -7.3955709864469856757e-32" />
<geometry>
<mesh filename="package:///motorejecaja.stl"/>
</geometry>
<material name="motorejecaja_material">
<color rgba="0.26274509803921569651 0.28235294117647058432 0.30196078431372547213 1.0"/>
</material>
</visual>
<collision>
<origin xyz="0 -6.9388939039072283776e-18 -0.02340000000000000413" rpy="1.0146536357571251952e-17 -0 -7.3955709864469856757e-32" />
<geometry>
<mesh filename="package:///motorejecaja.stl"/>
</geometry>
</collision>
<visual>
<origin xyz="0.010027549229565377309 0.009785984972322740727 -0.023549999999994894462" rpy="-1.5707963267951956521 -8.9042211027511509456e-14 1.570796326795155462" />
<geometry>
<mesh filename="package:///caderapt2_2.stl"/>
</geometry>
<material name="caderapt2_2_material">
<color rgba="0.97254901960784312376 0.97254901960784312376 0.97254901960784312376 1.0"/>
</material>
</visual>
<collision>
<origin xyz="0.010027549229565377309 0.009785984972322740727 -0.023549999999994894462" rpy="-1.5707963267951956521 -8.9042211027511509456e-14 1.570796326795155462" />
<geometry>
<mesh filename="package:///caderapt2_2.stl"/>
</geometry>
</collision>
<visual>
<origin xyz="-6.9388939039072283776e-17 -3.4694469519536141888e-17 -0.023399999999999990252" rpy="1.1607773526153298705e-15 6.1626129003337801016e-15 -2.3158863765586263584e-15" />
<geometry>
<mesh filename="package:///motorejeeje2.stl"/>
</geometry>
<material name="motorejeeje2_material">
<color rgba="0.64705882352941179736 0.64705882352941179736 0.64705882352941179736 1.0"/>
</material>
</visual>
<collision>
<origin xyz="-6.9388939039072283776e-17 -3.4694469519536141888e-17 -0.023399999999999990252" rpy="1.1607773526153298705e-15 6.1626129003337801016e-15 -2.3158863765586263584e-15" />
<geometry>
<mesh filename="package:///motorejeeje2.stl"/>
</geometry>
</collision>
<visual>
<origin xyz="0.010027549229565238531 0.0098109849723226130735 -0.023449999999994836086" rpy="-1.5707963267951956521 -8.9042211027511509456e-14 1.570796326795155462" />
<geometry>
<mesh filename="package:///caderapt3_2.stl"/>
</geometry>
<material name="caderapt3_2_material">
<color rgba="0.97254901960784312376 0.97254901960784312376 0.97254901960784312376 1.0"/>
</material>
</visual>
<collision>
<origin xyz="0.010027549229565238531 0.0098109849723226130735 -0.023449999999994836086" rpy="-1.5707963267951956521 -8.9042211027511509456e-14 1.570796326795155462" />
<geometry>
<mesh filename="package:///caderapt3_2.stl"/>
</geometry>
</collision>
<visual>
<origin xyz="0.010027549229565349553 0.0098109849723227032792 -0.023649999999994859162" rpy="-1.5707963267951958741 -9.1251498773215304792e-14 1.5707963267951536857" />
<geometry>
<mesh filename="package:///caderapt3_1.stl"/>
</geometry>
<material name="caderapt3_1_material">
<color rgba="0.97254901960784312376 0.97254901960784312376 0.97254901960784312376 1.0"/>
</material>
</visual>
<collision>
<origin xyz="0.010027549229565349553 0.0098109849723227032792 -0.023649999999994859162" rpy="-1.5707963267951958741 -9.1251498773215304792e-14 1.5707963267951536857" />
<geometry>
<mesh filename="package:///caderapt3_1.stl"/>
</geometry>
</collision>
<visual>
<origin xyz="0.010027549229565627109 0.0094859849723228709117 -0.023549999999994915278" rpy="-1.5707963267951956521 -8.8284103325924701914e-14 1.570796326795155462" />
<geometry>
<mesh filename="package:///caderapt1.stl"/>
</geometry>
<material name="caderapt1_material">
<color rgba="0.97254901960784312376 0.97254901960784312376 0.97254901960784312376 1.0"/>
</material>
</visual>
<collision>
<origin xyz="0.010027549229565627109 0.0094859849723228709117 -0.023549999999994915278" rpy="-1.5707963267951956521 -8.8284103325924701914e-14 1.570796326795155462" />
<geometry>
<mesh filename="package:///caderapt1.stl"/>
</geometry>
</collision>
<visual>
<origin xyz="0 -6.9388939039072283776e-18 -0.02340000000000000413" rpy="1.0146536357571251952e-17 -0 -7.3955709864469856757e-32" />
<geometry>
<mesh filename="package:///motorejeeje1.stl"/>
</geometry>
<material name="motorejeeje1_material">
<color rgba="0.64705882352941179736 0.64705882352941179736 0.64705882352941179736 1.0"/>
</material>
</visual>
<collision>
<origin xyz="0 -6.9388939039072283776e-18 -0.02340000000000000413" rpy="1.0146536357571251952e-17 -0 -7.3955709864469856757e-32" />
<geometry>
<mesh filename="package:///motorejeeje1.stl"/>
</geometry>
</collision>
<inertial>
<origin xyz="0.0019229001328388607445 0.010041085604012551721 -0.023445491658506775745" rpy="0 0 0"/>
<mass value="0.36033150614011227875" />
<inertia ixx="0.00013063858229426855359" ixy="-1.4491083147167716768e-07"  ixz="7.2430643624769672725e-08" iyy="7.1173611389544586708e-05" iyz="4.0050341054266870556e-08" izz="0.00010253850500590998729" />
</inertial>
</link>

<link name="femururdf">
<visual>
<origin xyz="-4.7878367936959875806e-16 0.043745909016608658382 -0.046800000000000091527" rpy="-3.141592653589793116 1.4781994054498918092e-16 -2.2409811191447901499e-16" />
<geometry>
<mesh filename="package:///femur.stl"/>
</geometry>
<material name="femur_material">
<color rgba="0.97254901960784312376 0.97254901960784312376 0.97254901960784312376 1.0"/>
</material>
</visual>
<collision>
<origin xyz="-4.7878367936959875806e-16 0.043745909016608658382 -0.046800000000000091527" rpy="-3.141592653589793116 1.4781994054498918092e-16 -2.2409811191447901499e-16" />
<geometry>
<mesh filename="package:///femur.stl"/>
</geometry>
</collision>
<visual>
<origin xyz="-1.9255430583342558748e-16 2.7755575615628913511e-17 -0.02340000000000019148" rpy="1.9921620702795648446e-15 9.9697451505334033141e-15 -5.1166839977620517837e-29" />
<geometry>
<mesh filename="package:///motorejeacopleeje2.stl"/>
</geometry>
<material name="motorejeacopleeje2_material">
<color rgba="0.64705882352941179736 0.64705882352941179736 0.64705882352941179736 1.0"/>
</material>
</visual>
<collision>
<origin xyz="-1.9255430583342558748e-16 2.7755575615628913511e-17 -0.02340000000000019148" rpy="1.9921620702795648446e-15 9.9697451505334033141e-15 -5.1166839977620517837e-29" />
<geometry>
<mesh filename="package:///motorejeacopleeje2.stl"/>
</geometry>
</collision>
<visual>
<origin xyz="-3.400058012914541905e-16 0.065000000000000501821 -0.023399999999999150646" rpy="-1.9451290359144178722e-15 -3.6276081481846276596e-15 3.141592653589793116" />
<geometry>
<mesh filename="package:///motorejeacopleeje1.stl"/>
</geometry>
<material name="motorejeacopleeje1_material">
<color rgba="0.64705882352941179736 0.64705882352941179736 0.64705882352941179736 1.0"/>
</material>
</visual>
<collision>
<origin xyz="-3.400058012914541905e-16 0.065000000000000501821 -0.023399999999999150646" rpy="-1.9451290359144178722e-15 -3.6276081481846276596e-15 3.141592653589793116" />
<geometry>
<mesh filename="package:///motorejeacopleeje1.stl"/>
</geometry>
</collision>
<visual>
<origin xyz="-1.9255430583342558748e-16 2.7755575615628913511e-17 -0.023400000000000122091" rpy="1.1101976786768684117e-14 8.9717462481015712046e-17 1.0029445382482751516e-28" />
<geometry>
<mesh filename="package:///motorejeacoplecaja.stl"/>
</geometry>
<material name="motorejeacoplecaja_material">
<color rgba="0.26274509803921569651 0.28235294117647058432 0.30196078431372547213 1.0"/>
</material>
</visual>
<collision>
<origin xyz="-1.9255430583342558748e-16 2.7755575615628913511e-17 -0.023400000000000122091" rpy="1.1101976786768684117e-14 8.9717462481015712046e-17 1.0029445382482751516e-28" />
<geometry>
<mesh filename="package:///motorejeacoplecaja.stl"/>
</geometry>
</collision>
<visual>
<origin xyz="1.9515639104739079812e-16 0.065000000000000501821 -0.023400000000000052702" rpy="2.455312086344945399e-16 -3.3965782627260365364e-16 3.141592653589793116" />
<geometry>
<mesh filename="package:///motorejeacopleeje2.stl"/>
</geometry>
<material name="motorejeacopleeje2_material">
<color rgba="0.64705882352941179736 0.64705882352941179736 0.64705882352941179736 1.0"/>
</material>
</visual>
<collision>
<origin xyz="1.9515639104739079812e-16 0.065000000000000501821 -0.023400000000000052702" rpy="2.455312086344945399e-16 -3.3965782627260365364e-16 3.141592653589793116" />
<geometry>
<mesh filename="package:///motorejeacopleeje2.stl"/>
</geometry>
</collision>
<visual>
<origin xyz="1.561251128379126385e-17 0.043745909016608658382 0.0020000000000001995348" rpy="-3.141592653589793116 1.4781994054498918092e-16 -2.2409811191447901499e-16" />
<geometry>
<mesh filename="package:///femur.stl"/>
</geometry>
<material name="femur_material">
<color rgba="0.97254901960784312376 0.97254901960784312376 0.97254901960784312376 1.0"/>
</material>
</visual>
<collision>
<origin xyz="1.561251128379126385e-17 0.043745909016608658382 0.0020000000000001995348" rpy="-3.141592653589793116 1.4781994054498918092e-16 -2.2409811191447901499e-16" />
<geometry>
<mesh filename="package:///femur.stl"/>
</geometry>
</collision>
<visual>
<origin xyz="1.4745149545802860303e-16 0.065000000000000474065 -0.02339999999999994168" rpy="-2.3925979523023053839e-15 -3.5964441978757125135e-15 3.141592653589793116" />
<geometry>
<mesh filename="package:///motorejeacoplecaja.stl"/>
</geometry>
<material name="motorejeacoplecaja_material">
<color rgba="0.26274509803921569651 0.28235294117647058432 0.30196078431372547213 1.0"/>
</material>
</visual>
<collision>
<origin xyz="1.4745149545802860303e-16 0.065000000000000474065 -0.02339999999999994168" rpy="-2.3925979523023053839e-15 -3.5964441978757125135e-15 3.141592653589793116" />
<geometry>
<mesh filename="package:///motorejeacoplecaja.stl"/>
</geometry>
</collision>
<visual>
<origin xyz="-5.2041704279304212832e-18 0 -0.02340000000000000413" rpy="-1.2870296577023528274e-29 1.7749222431599642845e-17 -6.797420434703141302e-31" />
<geometry>
<mesh filename="package:///motorejeacopleeje1.stl"/>
</geometry>
<material name="motorejeacopleeje1_material">
<color rgba="0.64705882352941179736 0.64705882352941179736 0.64705882352941179736 1.0"/>
</material>
</visual>
<collision>
<origin xyz="-5.2041704279304212832e-18 0 -0.02340000000000000413" rpy="-1.2870296577023528274e-29 1.7749222431599642845e-17 -6.797420434703141302e-31" />
<geometry>
<mesh filename="package:///motorejeacopleeje1.stl"/>
</geometry>
</collision>
<inertial>
<origin xyz="-6.6369072716922747685e-17 0.032500000000000237033 -0.023399999999999993722" rpy="0 0 0"/>
<mass value="0.53868761965446410045" />
<inertia ixx="0.00043791203235393928858" ixy="-1.7041909991209538754e-18"  ixz="-5.7185893886035787399e-20" iyy="0.00010909446328561867219" iyz="2.4394548880923849765e-19" izz="0.00036348717125268890753" />
</inertial>
</link>

<link name="tibiaurdf">
<visual>
<origin xyz="-0.047631397208144701794 0.027500000000000357492 0.023399999999997912054" rpy="3.1415926535897926719 -2.5218114884524950908e-16 1.0471975511965976313" />
<geometry>
<mesh filename="package:///motorejeacopleeje2.stl"/>
</geometry>
<material name="motorejeacopleeje2_material">
<color rgba="0.64705882352941179736 0.64705882352941179736 0.64705882352941179736 1.0"/>
</material>
</visual>
<collision>
<origin xyz="-0.047631397208144701794 0.027500000000000357492 0.023399999999997912054" rpy="3.1415926535897926719 -2.5218114884524950908e-16 1.0471975511965976313" />
<geometry>
<mesh filename="package:///motorejeacopleeje2.stl"/>
</geometry>
</collision>
<visual>
<origin xyz="-0.047631397208144743427 0.027500000000000301981 0.023399999999999757799" rpy="3.1415926535897926719 -3.2033177563715373981e-15 1.0471975511965978534" />
<geometry>
<mesh filename="package:///motorejeacopleeje1.stl"/>
</geometry>
<material name="motorejeacopleeje1_material">
<color rgba="0.64705882352941179736 0.64705882352941179736 0.64705882352941179736 1.0"/>
</material>
</visual>
<collision>
<origin xyz="-0.047631397208144743427 0.027500000000000301981 0.023399999999999757799" rpy="3.1415926535897926719 -3.2033177563715373981e-15 1.0471975511965978534" />
<geometry>
<mesh filename="package:///motorejeacopleeje1.stl"/>
</geometry>
</collision>
<visual>
<origin xyz="-0.029224814482181220299 0.016872954508304172094 0.04879999999999766469" rpy="3.1415926535897926719 -3.2195765961357230142e-15 1.0471975511965976313" />
<geometry>
<mesh filename="package:///tibia.stl"/>
</geometry>
<material name="tibia_material">
<color rgba="0.97254901960784312376 0.97254901960784312376 0.97254901960784312376 1.0"/>
</material>
</visual>
<collision>
<origin xyz="-0.029224814482181220299 0.016872954508304172094 0.04879999999999766469" rpy="3.1415926535897926719 -3.2195765961357230142e-15 1.0471975511965976313" />
<geometry>
<mesh filename="package:///tibia.stl"/>
</geometry>
</collision>
<visual>
<origin xyz="-0.029224814482181206421 0.01687295450830419985 -3.4694469519536141888e-18" rpy="3.141592653589793116 -4.0844027850839294298e-19 1.0471975511965976313" />
<geometry>
<mesh filename="package:///tibia.stl"/>
</geometry>
<material name="tibia_material">
<color rgba="0.97254901960784312376 0.97254901960784312376 0.97254901960784312376 1.0"/>
</material>
</visual>
<collision>
<origin xyz="-0.029224814482181206421 0.01687295450830419985 -3.4694469519536141888e-18" rpy="3.141592653589793116 -4.0844027850839294298e-19 1.0471975511965976313" />
<geometry>
<mesh filename="package:///tibia.stl"/>
</geometry>
</collision>
<visual>
<origin xyz="-0.047631397208144708733 0.027500000000000357492 0.023399999999998827988" rpy="3.1415926535897926719 -3.1917629547110018732e-15 1.0471975511965976313" />
<geometry>
<mesh filename="package:///motorejeacoplecaja.stl"/>
</geometry>
<material name="motorejeacoplecaja_material">
<color rgba="0.26274509803921569651 0.28235294117647058432 0.30196078431372547213 1.0"/>
</material>
</visual>
<collision>
<origin xyz="-0.047631397208144708733 0.027500000000000357492 0.023399999999998827988" rpy="3.1415926535897926719 -3.1917629547110018732e-15 1.0471975511965976313" />
<geometry>
<mesh filename="package:///motorejeacoplecaja.stl"/>
</geometry>
</collision>
<inertial>
<origin xyz="-0.037185466647235619619 0.021469039178648972876 0.023399999999998838396" rpy="0 0 0"/>
<mass value="0.28552673687099017208" />
<inertia ixx="7.7012953898988932653e-05" ixy="2.1231284255097969177e-05"  ixz="1.1509661269676135716e-19" iyy="0.0001015287292569379122" iyz="1.6748188156447059839e-19" izz="6.7501897454915114308e-05" />
</inertial>
</link>

<link name="tobillourdf">
<visual>
<origin xyz="-0.00014999999999953939067 0.035800000000000276046 0.023724999999999510369" rpy="1.57079632679489678 1.5707963267948934494 0" />
<geometry>
<mesh filename="package:///tobillopt3_2.stl"/>
</geometry>
<material name="tobillopt3_2_material">
<color rgba="0.97254901960784312376 0.97254901960784312376 0.97254901960784312376 1.0"/>
</material>
</visual>
<collision>
<origin xyz="-0.00014999999999953939067 0.035800000000000276046 0.023724999999999510369" rpy="1.57079632679489678 1.5707963267948934494 0" />
<geometry>
<mesh filename="package:///tobillopt3_2.stl"/>
</geometry>
</collision>
<visual>
<origin xyz="-2.7755575615628913511e-17 0.035800000000000109512 0.023549999999999765565" rpy="1.57079632679489678 1.570796326794896558 0" />
<geometry>
<mesh filename="package:///tobillopt1.stl"/>
</geometry>
<material name="tobillopt1_material">
<color rgba="0.97254901960784312376 0.97254901960784312376 0.97254901960784312376 1.0"/>
</material>
</visual>
<collision>
<origin xyz="-2.7755575615628913511e-17 0.035800000000000109512 0.023549999999999765565" rpy="1.57079632679489678 1.570796326794896558 0" />
<geometry>
<mesh filename="package:///tobillopt1.stl"/>
</geometry>
</collision>
<visual>
<origin xyz="0.00020000000000142126311 0.025772450770445876067 0.033535984972313942487" rpy="-1.5707963267943436669 3.9058732185431556085e-13 -1.5707963267946958297" />
<geometry>
<mesh filename="package:///motorejecaja.stl"/>
</geometry>
<material name="motorejecaja_material">
<color rgba="0.26274509803921569651 0.28235294117647058432 0.30196078431372547213 1.0"/>
</material>
</visual>
<collision>
<origin xyz="0.00020000000000142126311 0.025772450770445876067 0.033535984972313942487" rpy="-1.5707963267943436669 3.9058732185431556085e-13 -1.5707963267946958297" />
<geometry>
<mesh filename="package:///motorejecaja.stl"/>
</geometry>
</collision>
<visual>
<origin xyz="0.00020000000000142126311 0.025772450770445876067 0.033535984972313942487" rpy="-1.5707963267943414465 3.9416139490909708775e-13 -1.5707963267946991603" />
<geometry>
<mesh filename="package:///motorejeeje2.stl"/>
</geometry>
<material name="motorejeeje2_material">
<color rgba="0.64705882352941179736 0.64705882352941179736 0.64705882352941179736 1.0"/>
</material>
</visual>
<collision>
<origin xyz="0.00020000000000142126311 0.025772450770445876067 0.033535984972313942487" rpy="-1.5707963267943414465 3.9416139490909708775e-13 -1.5707963267946991603" />
<geometry>
<mesh filename="package:///motorejeeje2.stl"/>
</geometry>
</collision>
<visual>
<origin xyz="0.00015000000000037205794 0.03579999999999974869 0.023724999999999704658" rpy="1.57079632679489678 1.570796326794896558 0" />
<geometry>
<mesh filename="package:///tobillopt3_1.stl"/>
</geometry>
<material name="tobillopt3_1_material">
<color rgba="0.97254901960784312376 0.97254901960784312376 0.97254901960784312376 1.0"/>
</material>
</visual>
<collision>
<origin xyz="0.00015000000000037205794 0.03579999999999974869 0.023724999999999704658" rpy="1.57079632679489678 1.570796326794896558 0" />
<geometry>
<mesh filename="package:///tobillopt3_1.stl"/>
</geometry>
</collision>
<visual>
<origin xyz="0.00020000000000142126311 0.025772450770445876067 0.033535984972313942487" rpy="-1.5707963267943443331 3.566626790729210606e-13 -1.5707963267946754016" />
<geometry>
<mesh filename="package:///motorejeeje1.stl"/>
</geometry>
<material name="motorejeeje1_material">
<color rgba="0.64705882352941179736 0.64705882352941179736 0.64705882352941179736 1.0"/>
</material>
</visual>
<collision>
<origin xyz="0.00020000000000142126311 0.025772450770445876067 0.033535984972313942487" rpy="-1.5707963267943443331 3.566626790729210606e-13 -1.5707963267946754016" />
<geometry>
<mesh filename="package:///motorejeeje1.stl"/>
</geometry>
</collision>
<visual>
<origin xyz="0 0.035800000000000220535 0.023849999999999496603" rpy="1.57079632679489678 1.570796326794896558 0" />
<geometry>
<mesh filename="package:///tobillopt2_1.stl"/>
</geometry>
<material name="tobillopt2_1_material">
<color rgba="0.97254901960784312376 0.97254901960784312376 0.97254901960784312376 1.0"/>
</material>
</visual>
<collision>
<origin xyz="0 0.035800000000000220535 0.023849999999999496603" rpy="1.57079632679489678 1.570796326794896558 0" />
<geometry>
<mesh filename="package:///tobillopt2_1.stl"/>
</geometry>
</collision>
<visual>
<origin xyz="-2.7755575615628913511e-17 0.03579999999999999849 0.023249999999999999833" rpy="1.57079632679489678 1.570796326794896558 0" />
<geometry>
<mesh filename="package:///tobillopt2_2.stl"/>
</geometry>
<material name="tobillopt2_2_material">
<color rgba="0.97254901960784312376 0.97254901960784312376 0.97254901960784312376 1.0"/>
</material>
</visual>
<collision>
<origin xyz="-2.7755575615628913511e-17 0.03579999999999999849 0.023249999999999999833" rpy="1.57079632679489678 1.570796326794896558 0" />
<geometry>
<mesh filename="package:///tobillopt2_2.stl"/>
</geometry>
</collision>
<inertial>
<origin xyz="0.00013965747905605327092 0.025656106121464850034 0.02341166766305463956" rpy="0 0 0"/>
<mass value="0.35953278469495453251" />
<inertia ixx="0.00010180132077840035301" ixy="-5.8418326184622972627e-09"  ixz="-5.7602954085915724718e-08" iyy="0.00013007031479290217385" iyz="5.2659589177997947749e-07" izz="7.0605342570130132855e-05" />
</inertial>
</link>

<link name="pieurdf">
<visual>
<origin xyz="-0.0099999999999999603095 0.018999999999999322986 0.023500000000000464961" rpy="1.570796326794896558 1.570796326794896558 0" />
<geometry>
<mesh filename="package:///acoplepiemotor.stl"/>
</geometry>
<material name="acoplepiemotor_material">
<color rgba="0.97254901960784312376 0.97254901960784312376 0.97254901960784312376 1.0"/>
</material>
</visual>
<collision>
<origin xyz="-0.0099999999999999603095 0.018999999999999322986 0.023500000000000464961" rpy="1.570796326794896558 1.570796326794896558 0" />
<geometry>
<mesh filename="package:///acoplepiemotor.stl"/>
</geometry>
</collision>
<visual>
<origin xyz="-0.009999999999999995004 0.01899999999999998912 0.02340000000000000413" rpy="1.570796326794896558 1.570796326794896558 0" />
<geometry>
<mesh filename="package:///acoplepiemotor.stl"/>
</geometry>
<material name="acoplepiemotor_material">
<color rgba="0.97254901960784312376 0.97254901960784312376 0.97254901960784312376 1.0"/>
</material>
</visual>
<collision>
<origin xyz="-0.009999999999999995004 0.01899999999999998912 0.02340000000000000413" rpy="1.570796326794896558 1.570796326794896558 0" />
<geometry>
<mesh filename="package:///acoplepiemotor.stl"/>
</geometry>
</collision>
<visual>
<origin xyz="-0.0099999999999995925481 0.018949999999998912159 0.023450000000000137401" rpy="1.570796326794896558 1.570796326794896558 0" />
<geometry>
<mesh filename="package:///plantapie.stl"/>
</geometry>
<material name="plantapie_material">
<color rgba="0.97254901960784312376 0.97254901960784312376 0.97254901960784312376 1.0"/>
</material>
</visual>
<collision>
<origin xyz="-0.0099999999999995925481 0.018949999999998912159 0.023450000000000137401" rpy="1.570796326794896558 1.570796326794896558 0" />
<geometry>
<mesh filename="package:///plantapie.stl"/>
</geometry>
</collision>
<inertial>
<origin xyz="-0.0095981962877158318731 0.018994815818901722437 0.023450000000000165157" rpy="0 0 0"/>
<mass value="0.12193030814742021606" />
<inertia ixx="5.5790028401553034068e-05" ixy="1.0383957421082729328e-06"  ixz="-3.0874448111593210622e-20" iyy="7.8275338616851238786e-05" iyz="3.1732620351738408426e-19" izz="3.3440055653628493557e-05" />
</inertial>
</link>

<joint name="LeftAnkle2" type="revolute">
<origin xyz="0.023600000000001397638 0.02577245077045106636 0.033535984972326855769" rpy="2.2132700711385145215e-13 -1.570796326794244635 0" />
<parent link="tobillourdf" />
<child link="pieurdf" />
<axis xyz="0 0 1"/>
<limit effort="1" velocity="20" lower="-0.26179938779914940783" upper="0.26179938779914940783"/>
<joint_properties friction="0.0"/>
</joint>

<joint name="LeftAnkle1" type="revolute">
<origin xyz="-0.04763139720814472261 0.027500000000000357492 0.046799999999997926592" rpy="3.141592653589793116 5.3675190344367677838e-16 -2.0943951023932081412" />
<parent link="tibiaurdf" />
<child link="tobillourdf" />
<axis xyz="0 0 1"/>
<limit effort="1" velocity="20" lower="-0.785398163397448279" upper="0.785398163397448279"/>
<joint_properties friction="0.0"/>
</joint>

<joint name="LeftKnee" type="revolute">
<origin xyz="-2.1510571102112407971e-16 0.065000000000001029177 -7.5980888247784150735e-16" rpy="-3.1415926535897904515 -9.7897424329627288022e-15 3.1415926535897908956" />
<parent link="femururdf" />
<child link="tibiaurdf" />
<axis xyz="0 0 1"/>
<limit effort="1" velocity="20" lower="-1.0471975511965976313" upper="1.0471975511965976313"/>
<joint_properties friction="0.0"/>
</joint>

<joint name="LeftHip2" type="revolute">
<origin xyz="0.028027549229571513401 -0.014064015027672766012 -0.023549999999991647059" rpy="1.5707963267946409847 1.5707963267945965757 0" />
<parent link="cadera_v01" />
<child link="femururdf" />
<axis xyz="0 0 1"/>
<limit effort="1" velocity="20" lower="-1.570796326794896558" upper="1.570796326794896558"/>
<joint_properties friction="0.0"/>
</joint>

<joint name="LeftHip1" type="revolute">
<origin xyz="0.00061949317509150773897 0.032685236218795377106 -0.023605436102933363696" rpy="-0.78539816339745072149 1.5707963267948956698 0" />
<parent link="cintura_v01" />
<child link="cadera_v01" />
<axis xyz="0 0 1"/>
<limit effort="1" velocity="20" lower="-0.785398163397448279" upper="0.785398163397448279"/>
<joint_properties friction="0.0"/>
</joint>

<joint name="LeftWaist" type="revolute">
<origin xyz="0.019257018009984791518 0.0083712188771943828181 -0.083178910040700979045" rpy="-7.0498275397804529719e-24 -1.2781389790328887556e-24 -1.570796326794896558" />
<parent link="torsourdf" />
<child link="cintura_v01" />
<axis xyz="0 0 1"/>
<limit effort="1" velocity="20" lower="-1.570796326794896558" upper="1.570796326794896558"/>
<joint_properties friction="0.0"/>
</joint>

<link name="hombro-brazo_2">
<visual>
<origin xyz="-1.1449174941446926823e-16 0.010999809727072717286 0" rpy="3.0423430958599903309e-32 -5.2989295050620434327e-34 -4.0926011306615500854e-33" />
<geometry>
<mesh filename="package:///hombro_brazo1.stl"/>
</geometry>
<material name="hombro_brazo1_material">
<color rgba="0.97254901960784312376 0.97254901960784312376 0.97254901960784312376 1.0"/>
</material>
</visual>
<collision>
<origin xyz="-1.1449174941446926823e-16 0.010999809727072717286 0" rpy="3.0423430958599903309e-32 -5.2989295050620434327e-34 -4.0926011306615500854e-33" />
<geometry>
<mesh filename="package:///hombro_brazo1.stl"/>
</geometry>
</collision>
<visual>
<origin xyz="0.00029999999999985333538 0.010999809727072842186 -0.001999999999999960143" rpy="3.4416913763379651594e-15 4.6629367034255091639e-15 1.6819922191157922558e-13" />
<geometry>
<mesh filename="package:///hombro_brazo2.stl"/>
</geometry>
<material name="hombro_brazo2_material">
<color rgba="0.97254901960784312376 0.97254901960784312376 0.97254901960784312376 1.0"/>
</material>
</visual>
<collision>
<origin xyz="0.00029999999999985333538 0.010999809727072842186 -0.001999999999999960143" rpy="3.4416913763379651594e-15 4.6629367034255091639e-15 1.6819922191157922558e-13" />
<geometry>
<mesh filename="package:///hombro_brazo2.stl"/>
</geometry>
</collision>
<visual>
<origin xyz="-0.00029999999999145467167 -0.011000190272921067658 -0.0020000000000004042322" rpy="9.1038288019263151859e-15 2.0761170560490714451e-14 -3.1415926535894769245" />
<geometry>
<mesh filename="package:///hombro_brazo2.stl"/>
</geometry>
<material name="hombro_brazo2_material">
<color rgba="0.97254901960784312376 0.97254901960784312376 0.97254901960784312376 1.0"/>
</material>
</visual>
<collision>
<origin xyz="-0.00029999999999145467167 -0.011000190272921067658 -0.0020000000000004042322" rpy="9.1038288019263151859e-15 2.0761170560490714451e-14 -3.1415926535894769245" />
<geometry>
<mesh filename="package:///hombro_brazo2.stl"/>
</geometry>
</collision>
<inertial>
<origin xyz="1.6899703994685637881e-15 -1.1044824278885071913e-07 0.0056081599888875384094" rpy="0 0 0"/>
<mass value="0.028276359613946901173" />
<inertia ixx="3.1909882339228915346e-06" ixy="-7.6383436528518565741e-11"  ixz="-4.5273911030742353123e-19" iyy="1.3925926827987627663e-05" iyz="1.4915617865722697473e-11" izz="1.2743353645780324996e-05" />
</inertial>
</link>

<link name="brazourdf_2">
<visual>
<origin xyz="0 0 -0.023400000000000000661" rpy="1.8806818552538889383e-30 -2.3576385711398787497e-29 1.570796326794896558" />
<geometry>
<mesh filename="package:///motorejeacopleeje1.stl"/>
</geometry>
<material name="motorejeacopleeje1_material">
<color rgba="0.64705882352941179736 0.64705882352941179736 0.64705882352941179736 1.0"/>
</material>
</visual>
<collision>
<origin xyz="0 0 -0.023400000000000000661" rpy="1.8806818552538889383e-30 -2.3576385711398787497e-29 1.570796326794896558" />
<geometry>
<mesh filename="package:///motorejeacopleeje1.stl"/>
</geometry>
</collision>
<visual>
<origin xyz="-0.029999999999999915623 -3.4694469519536141888e-18 -0.023399999999999997191" rpy="1.5707963267948970021 3.3306690739421194931e-16 1.5707963267948972241" />
<geometry>
<mesh filename="package:///brazo.stl"/>
</geometry>
<material name="brazo_material">
<color rgba="0.97254901960784312376 0.97254901960784312376 0.97254901960784312376 1.0"/>
</material>
</visual>
<collision>
<origin xyz="-0.029999999999999915623 -3.4694469519536141888e-18 -0.023399999999999997191" rpy="1.5707963267948970021 3.3306690739421194931e-16 1.5707963267948972241" />
<geometry>
<mesh filename="package:///brazo.stl"/>
</geometry>
</collision>
<visual>
<origin xyz="0 0 -0.023400000000000000661" rpy="5.6354964637312311918e-28 4.7796026711870344834e-28 1.570796326794896558" />
<geometry>
<mesh filename="package:///motorejeacoplecaja.stl"/>
</geometry>
<material name="motorejeacoplecaja_material">
<color rgba="0.26274509803921569651 0.28235294117647058432 0.30196078431372547213 1.0"/>
</material>
</visual>
<collision>
<origin xyz="0 0 -0.023400000000000000661" rpy="5.6354964637312311918e-28 4.7796026711870344834e-28 1.570796326794896558" />
<geometry>
<mesh filename="package:///motorejeacoplecaja.stl"/>
</geometry>
</collision>
<visual>
<origin xyz="0 0 -0.023400000000000000661" rpy="2.1329540445451286226e-28 7.7397810156890723595e-29 1.570796326794896558" />
<geometry>
<mesh filename="package:///motorejeacopleeje2.stl"/>
</geometry>
<material name="motorejeacopleeje2_material">
<color rgba="0.64705882352941179736 0.64705882352941179736 0.64705882352941179736 1.0"/>
</material>
</visual>
<collision>
<origin xyz="0 0 -0.023400000000000000661" rpy="2.1329540445451286226e-28 7.7397810156890723595e-29 1.570796326794896558" />
<geometry>
<mesh filename="package:///motorejeacopleeje2.stl"/>
</geometry>
</collision>
<inertial>
<origin xyz="-0.064612740306650151556 0.00024409654353026548888 -0.023399999587718614547" rpy="0 0 0"/>
<mass value="1.080760232398511711" />
<inertia ixx="0.00022953897767025085172" ixy="2.1146337854861604216e-05"  ixz="-1.3608742167962309053e-10" iyy="0.002471086917382017082" iyz="-1.0815340757757921651e-11" izz="0.0023133411907278605968" />
</inertial>
</link>

<joint name="RightShoulder2" type="revolute">
<origin xyz="-0.023549999999995352429 -3.8054585540028829094e-07 0.018946406845602128954" rpy="3.1415926535894787008 1.5707963267948730213 0" />
<parent link="hombro-brazo_2" />
<child link="brazourdf_2" />
<axis xyz="0 0 1"/>
<limit effort="1" velocity="20" lower="-1.570796326794896558" upper="1.570796326794896558"/>
<joint_properties friction="0.0"/>
</joint>

<joint name="RightShoulder1" type="revolute">
<origin xyz="-0.085191785003578324176 0.0073712188771942856527 0.025468521028911415838" rpy="1.57079632679489678 -2.222614453594627363e-16 -1.57079632679489678" />
<parent link="torsourdf" />
<child link="hombro-brazo_2" />
<axis xyz="0 0 1"/>
<limit effort="1" velocity="20" lower="-1.570796326794896558" upper="1.570796326794896558"/>
<joint_properties friction="0.0"/>
</joint>

<link name="cintura_v01_2">
<visual>
<origin xyz="-0.00021213203435598362856 0.00021213203435594719937 -0.0020000000000000017764" rpy="3.141592653589793116 1.269540183574498349e-32 -0.78539816339744772389" />
<geometry>
<mesh filename="package:///cinturapt2_1.stl"/>
</geometry>
<material name="cinturapt2_1_material">
<color rgba="0.97254901960784312376 0.97254901960784312376 0.97254901960784312376 1.0"/>
</material>
</visual>
<collision>
<origin xyz="-0.00021213203435598362856 0.00021213203435594719937 -0.0020000000000000017764" rpy="3.141592653589793116 1.269540183574498349e-32 -0.78539816339744772389" />
<geometry>
<mesh filename="package:///cinturapt2_1.stl"/>
</geometry>
</collision>
<visual>
<origin xyz="0 0 -0.0020000000000000017764" rpy="3.141592653589793116 3.6945019166667676709e-34 -0.785398163397448279" />
<geometry>
<mesh filename="package:///cinturapt1.stl"/>
</geometry>
<material name="cinturapt1_material">
<color rgba="0.97254901960784312376 0.97254901960784312376 0.97254901960784312376 1.0"/>
</material>
</visual>
<collision>
<origin xyz="0 0 -0.0020000000000000017764" rpy="3.141592653589793116 3.6945019166667676709e-34 -0.785398163397448279" />
<geometry>
<mesh filename="package:///cinturapt1.stl"/>
</geometry>
</collision>
<visual>
<origin xyz="0.00021213203435592811741 -0.0002121320343559714855 -0.0020000000000000017764" rpy="3.141592653589793116 9.6139139247254115987e-33 -0.78539816339744772389" />
<geometry>
<mesh filename="package:///cinturapt2_2.stl"/>
</geometry>
<material name="cinturapt2_2_material">
<color rgba="0.97254901960784312376 0.97254901960784312376 0.97254901960784312376 1.0"/>
</material>
</visual>
<collision>
<origin xyz="0.00021213203435592811741 -0.0002121320343559714855 -0.0020000000000000017764" rpy="3.141592653589793116 9.6139139247254115987e-33 -0.78539816339744772389" />
<geometry>
<mesh filename="package:///cinturapt2_2.stl"/>
</geometry>
</collision>
<inertial>
<origin xyz="0.0079316365006479629118 0.0079316365006480427091 -0.0083693257381815717999" rpy="0 0 0"/>
<mass value="0.032703197933895256089" />
<inertia ixx="1.1474475218213256314e-05" ixy="5.247523969013894906e-06"  ixz="1.4935382828704694294e-06" iyy="1.147447521821324615e-05" iyz="1.4935382828704768409e-06" izz="1.7093428062395033342e-05" />
</inertial>
</link>

<link name="cadera_v01_2">
<visual>
<origin xyz="0.010027549229563323396 -0.0094859849723199496374 -0.023250000000000978218" rpy="1.5707963267948628072 4.4355611095289652706e-14 -1.5707963267948696906" />
<geometry>
<mesh filename="package:///caderapt1.stl"/>
</geometry>
<material name="caderapt1_material">
<color rgba="0.97254901960784312376 0.97254901960784312376 0.97254901960784312376 1.0"/>
</material>
</visual>
<collision>
<origin xyz="0.010027549229563323396 -0.0094859849723199496374 -0.023250000000000978218" rpy="1.5707963267948628072 4.4355611095289652706e-14 -1.5707963267948696906" />
<geometry>
<mesh filename="package:///caderapt1.stl"/>
</geometry>
</collision>
<visual>
<origin xyz="0.010027549229563045841 -0.0091859849723199479832 -0.023250000000001016381" rpy="1.5707963267948628072 4.4355611095289652706e-14 -1.5707963267948696906" />
<geometry>
<mesh filename="package:///caderapt2_1.stl"/>
</geometry>
<material name="caderapt2_1_material">
<color rgba="0.97254901960784312376 0.97254901960784312376 0.97254901960784312376 1.0"/>
</material>
</visual>
<collision>
<origin xyz="0.010027549229563045841 -0.0091859849723199479832 -0.023250000000001016381" rpy="1.5707963267948628072 4.4355611095289652706e-14 -1.5707963267948696906" />
<geometry>
<mesh filename="package:///caderapt2_1.stl"/>
</geometry>
</collision>
<visual>
<origin xyz="0.010027549229563087474 -0.0098109849723201497662 -0.023350000000001088635" rpy="1.5707963267948630293 4.5691823780892001633e-14 -1.5707963267948699126" />
<geometry>
<mesh filename="package:///caderapt3_2.stl"/>
</geometry>
<material name="caderapt3_2_material">
<color rgba="0.97254901960784312376 0.97254901960784312376 0.97254901960784312376 1.0"/>
</material>
</visual>
<collision>
<origin xyz="0.010027549229563087474 -0.0098109849723201497662 -0.023350000000001088635" rpy="1.5707963267948630293 4.5691823780892001633e-14 -1.5707963267948699126" />
<geometry>
<mesh filename="package:///caderapt3_2.stl"/>
</geometry>
</collision>
<visual>
<origin xyz="9.7144514654701197287e-17 -1.4571677198205179593e-16 -0.023399999999999990252" rpy="3.141592653589793116 -1.570092458683603836e-16 -4.710277376051407591e-16" />
<geometry>
<mesh filename="package:///motorejecaja.stl"/>
</geometry>
<material name="motorejecaja_material">
<color rgba="0.26274509803921569651 0.28235294117647058432 0.30196078431372547213 1.0"/>
</material>
</visual>
<collision>
<origin xyz="9.7144514654701197287e-17 -1.4571677198205179593e-16 -0.023399999999999990252" rpy="3.141592653589793116 -1.570092458683603836e-16 -4.710277376051407591e-16" />
<geometry>
<mesh filename="package:///motorejecaja.stl"/>
</geometry>
</collision>
<visual>
<origin xyz="0 -6.9388939039072283776e-18 -0.02340000000000000413" rpy="3.141592653589793116 3.2155364039432514302e-32 2.5559530017136119656e-32" />
<geometry>
<mesh filename="package:///motorejeeje2.stl"/>
</geometry>
<material name="motorejeeje2_material">
<color rgba="0.64705882352941179736 0.64705882352941179736 0.64705882352941179736 1.0"/>
</material>
</visual>
<collision>
<origin xyz="0 -6.9388939039072283776e-18 -0.02340000000000000413" rpy="3.141592653589793116 3.2155364039432514302e-32 2.5559530017136119656e-32" />
<geometry>
<mesh filename="package:///motorejeeje2.stl"/>
</geometry>
</collision>
<visual>
<origin xyz="0 -6.9388939039072283776e-18 -0.02340000000000000413" rpy="3.1415926535897926719 3.1401849173676716208e-16 -3.1401849173673979847e-16" />
<geometry>
<mesh filename="package:///motorejeeje1.stl"/>
</geometry>
<material name="motorejeeje1_material">
<color rgba="0.64705882352941179736 0.64705882352941179736 0.64705882352941179736 1.0"/>
</material>
</visual>
<collision>
<origin xyz="0 -6.9388939039072283776e-18 -0.02340000000000000413" rpy="3.1415926535897926719 3.1401849173676716208e-16 -3.1401849173673979847e-16" />
<geometry>
<mesh filename="package:///motorejeeje1.stl"/>
</geometry>
</collision>
<visual>
<origin xyz="0.010027549229563018085 -0.0097859849723198680249 -0.02325000000000102332" rpy="1.5707963267948630293 4.5691823780892001633e-14 -1.5707963267948699126" />
<geometry>
<mesh filename="package:///caderapt2_2.stl"/>
</geometry>
<material name="caderapt2_2_material">
<color rgba="0.97254901960784312376 0.97254901960784312376 0.97254901960784312376 1.0"/>
</material>
</visual>
<collision>
<origin xyz="0.010027549229563018085 -0.0097859849723198680249 -0.02325000000000102332" rpy="1.5707963267948630293 4.5691823780892001633e-14 -1.5707963267948699126" />
<geometry>
<mesh filename="package:///caderapt2_2.stl"/>
</geometry>
</collision>
<visual>
<origin xyz="0.010027549229563170741 -0.0098109849723200109883 -0.023150000000000975353" rpy="1.5707963267948636954 4.6097816159440460177e-14 -1.5707963267948896746" />
<geometry>
<mesh filename="package:///caderapt3_1.stl"/>
</geometry>
<material name="caderapt3_1_material">
<color rgba="0.97254901960784312376 0.97254901960784312376 0.97254901960784312376 1.0"/>
</material>
</visual>
<collision>
<origin xyz="0.010027549229563170741 -0.0098109849723200109883 -0.023150000000000975353" rpy="1.5707963267948636954 4.6097816159440460177e-14 -1.5707963267948896746" />
<geometry>
<mesh filename="package:///caderapt3_1.stl"/>
</geometry>
</collision>
<inertial>
<origin xyz="0.0019229001328384546024 -0.01004108560401212151 -0.0233545083414922576" rpy="0 0 0"/>
<mass value="0.36033150614011233426" />
<inertia ixx="0.00013063858229426822833" ixy="1.4491083148090035063e-07"  ixz="-7.2430643625450766624e-08" iyy="7.1173611389542242121e-05" iyz="4.0050341056190482379e-08" izz="0.00010253850500590708705" />
</inertial>
</link>

<link name="femururdf_2">
<visual>
<origin xyz="8.6736173798840354721e-19 2.7755575615628913511e-17 -0.023399999999999997191" rpy="3.141592653589793116 -1.0146536359607605475e-17 3.1577956855936908626e-30" />
<geometry>
<mesh filename="package:///motorejeacopleeje2.stl"/>
</geometry>
<material name="motorejeacopleeje2_material">
<color rgba="0.64705882352941179736 0.64705882352941179736 0.64705882352941179736 1.0"/>
</material>
</visual>
<collision>
<origin xyz="8.6736173798840354721e-19 2.7755575615628913511e-17 -0.023399999999999997191" rpy="3.141592653589793116 -1.0146536359607605475e-17 3.1577956855936908626e-30" />
<geometry>
<mesh filename="package:///motorejeacopleeje2.stl"/>
</geometry>
</collision>
<visual>
<origin xyz="1.5178830414797062076e-17 8.3266726846886740532e-17 -0.023399999999999927802" rpy="3.1415926535897922278 -9.5220201156990203357e-16 4.1062013512171870334e-16" />
<geometry>
<mesh filename="package:///motorejeacopleeje1.stl"/>
</geometry>
<material name="motorejeacopleeje1_material">
<color rgba="0.64705882352941179736 0.64705882352941179736 0.64705882352941179736 1.0"/>
</material>
</visual>
<collision>
<origin xyz="1.5178830414797062076e-17 8.3266726846886740532e-17 -0.023399999999999927802" rpy="3.1415926535897922278 -9.5220201156990203357e-16 4.1062013512171870334e-16" />
<geometry>
<mesh filename="package:///motorejeacopleeje1.stl"/>
</geometry>
</collision>
<visual>
<origin xyz="-8.8037216405822960041e-17 -0.064999999999999863443 -0.023399999999999789024" rpy="-3.1415926535897913396 7.610409904521134966e-16 -3.1415926535897926719" />
<geometry>
<mesh filename="package:///motorejeacoplecaja.stl"/>
</geometry>
<material name="motorejeacoplecaja_material">
<color rgba="0.26274509803921569651 0.28235294117647058432 0.30196078431372547213 1.0"/>
</material>
</visual>
<collision>
<origin xyz="-8.8037216405822960041e-17 -0.064999999999999863443 -0.023399999999999789024" rpy="-3.1415926535897913396 7.610409904521134966e-16 -3.1415926535897926719" />
<geometry>
<mesh filename="package:///motorejeacoplecaja.stl"/>
</geometry>
</collision>
<visual>
<origin xyz="-7.7628875549962117475e-17 -0.043745909016608325315 1.249000902703301108e-16" rpy="-3.2016517934425554071e-15 -1.5992874106942067408e-15 8.0972773596045408604e-16" />
<geometry>
<mesh filename="package:///femur.stl"/>
</geometry>
<material name="femur_material">
<color rgba="0.97254901960784312376 0.97254901960784312376 0.97254901960784312376 1.0"/>
</material>
</visual>
<collision>
<origin xyz="-7.7628875549962117475e-17 -0.043745909016608325315 1.249000902703301108e-16" rpy="-3.2016517934425554071e-15 -1.5992874106942067408e-15 8.0972773596045408604e-16" />
<geometry>
<mesh filename="package:///femur.stl"/>
</geometry>
</collision>
<visual>
<origin xyz="-9.4108748571741784872e-17 -0.064999999999999863443 -0.023399999999999823719" rpy="-3.1415926535897913396 8.411797091073821394e-16 -3.1415926535897926719" />
<geometry>
<mesh filename="package:///motorejeacopleeje2.stl"/>
</geometry>
<material name="motorejeacopleeje2_material">
<color rgba="0.64705882352941179736 0.64705882352941179736 0.64705882352941179736 1.0"/>
</material>
</visual>
<collision>
<origin xyz="-9.4108748571741784872e-17 -0.064999999999999863443 -0.023399999999999823719" rpy="-3.1415926535897913396 8.411797091073821394e-16 -3.1415926535897926719" />
<geometry>
<mesh filename="package:///motorejeacopleeje2.stl"/>
</geometry>
</collision>
<visual>
<origin xyz="8.6736173798840354721e-18 5.5511151231257827021e-17 -0.023399999999999955558" rpy="3.1415926535897904515 5.6728158304593112157e-16 8.3504625710706790382e-16" />
<geometry>
<mesh filename="package:///motorejeacoplecaja.stl"/>
</geometry>
<material name="motorejeacoplecaja_material">
<color rgba="0.26274509803921569651 0.28235294117647058432 0.30196078431372547213 1.0"/>
</material>
</visual>
<collision>
<origin xyz="8.6736173798840354721e-18 5.5511151231257827021e-17 -0.023399999999999955558" rpy="3.1415926535897904515 5.6728158304593112157e-16 8.3504625710706790382e-16" />
<geometry>
<mesh filename="package:///motorejeacoplecaja.stl"/>
</geometry>
</collision>
<visual>
<origin xyz="-4.3801767768414379134e-17 -0.043745909016608242048 -0.048799999999999767175" rpy="-3.2016517934425554071e-15 -1.5992874106942067408e-15 8.0972773596045408604e-16" />
<geometry>
<mesh filename="package:///femur.stl"/>
</geometry>
<material name="femur_material">
<color rgba="0.97254901960784312376 0.97254901960784312376 0.97254901960784312376 1.0"/>
</material>
</visual>
<collision>
<origin xyz="-4.3801767768414379134e-17 -0.043745909016608242048 -0.048799999999999767175" rpy="-3.2016517934425554071e-15 -1.5992874106942067408e-15 8.0972773596045408604e-16" />
<geometry>
<mesh filename="package:///femur.stl"/>
</geometry>
</collision>
<visual>
<origin xyz="-8.8904578143811363589e-17 -0.064999999999999863443 -0.023399999999999761269" rpy="-3.1415926535897913396 8.411797091073821394e-16 -3.1415926535897926719" />
<geometry>
<mesh filename="package:///motorejeacopleeje1.stl"/>
</geometry>
<material name="motorejeacopleeje1_material">
<color rgba="0.64705882352941179736 0.64705882352941179736 0.64705882352941179736 1.0"/>
</material>
</visual>
<collision>
<origin xyz="-8.8904578143811363589e-17 -0.064999999999999863443 -0.023399999999999761269" rpy="-3.1415926535897913396 8.411797091073821394e-16 -3.1415926535897926719" />
<geometry>
<mesh filename="package:///motorejeacopleeje1.stl"/>
</geometry>
</collision>
<inertial>
<origin xyz="-4.2488040651277896172e-17 -0.032499999999999897027 -0.023399999999999868822" rpy="0 0 0"/>
<mass value="0.53868761965446410045" />
<inertia ixx="0.00043791203235393392178" ixy="-2.2131579580356308622e-19"  ixz="-1.847384018206483652e-20" iyy="0.00010909446328561563642" iyz="5.2346636140315760954e-19" izz="0.00036348717125268473335" />
</inertial>
</link>

<link name="tibiaurdf_2">
<visual>
<origin xyz="-0.02922481448218121336 0.016872954508304172094 0" rpy="-3.141592653589793116 3.6152453675152847922e-17 1.0471975511965976313" />
<geometry>
<mesh filename="package:///tibia.stl"/>
</geometry>
<material name="tibia_material">
<color rgba="0.97254901960784312376 0.97254901960784312376 0.97254901960784312376 1.0"/>
</material>
</visual>
<collision>
<origin xyz="-0.02922481448218121336 0.016872954508304172094 0" rpy="-3.141592653589793116 3.6152453675152847922e-17 1.0471975511965976313" />
<geometry>
<mesh filename="package:///tibia.stl"/>
</geometry>
</collision>
<visual>
<origin xyz="-0.047631397208144736488 0.027500000000000440759 0.023399999999999851474" rpy="-3.141592653589793116 6.5880557316865246491e-17 1.0471975511965980754" />
<geometry>
<mesh filename="package:///motorejeacopleeje1.stl"/>
</geometry>
<material name="motorejeacopleeje1_material">
<color rgba="0.64705882352941179736 0.64705882352941179736 0.64705882352941179736 1.0"/>
</material>
</visual>
<collision>
<origin xyz="-0.047631397208144736488 0.027500000000000440759 0.023399999999999851474" rpy="-3.141592653589793116 6.5880557316865246491e-17 1.0471975511965980754" />
<geometry>
<mesh filename="package:///motorejeacopleeje1.stl"/>
</geometry>
</collision>
<visual>
<origin xyz="-0.047631397208144334032 0.027500000000000329736 0.023399999999999684941" rpy="-3.141592653589793116 -1.3173472923828476896e-16 1.0471975511965965211" />
<geometry>
<mesh filename="package:///motorejeacoplecaja.stl"/>
</geometry>
<material name="motorejeacoplecaja_material">
<color rgba="0.26274509803921569651 0.28235294117647058432 0.30196078431372547213 1.0"/>
</material>
</visual>
<collision>
<origin xyz="-0.047631397208144334032 0.027500000000000329736 0.023399999999999684941" rpy="-3.141592653589793116 -1.3173472923828476896e-16 1.0471975511965965211" />
<geometry>
<mesh filename="package:///motorejeacoplecaja.stl"/>
</geometry>
</collision>
<visual>
<origin xyz="-0.029224814482181196013 0.016872954508304144339 0.048799999999998761036" rpy="3.1415926535897926719 1.1273270626495436276e-15 1.0471975511965974093" />
<geometry>
<mesh filename="package:///tibia.stl"/>
</geometry>
<material name="tibia_material">
<color rgba="0.97254901960784312376 0.97254901960784312376 0.97254901960784312376 1.0"/>
</material>
</visual>
<collision>
<origin xyz="-0.029224814482181196013 0.016872954508304144339 0.048799999999998761036" rpy="3.1415926535897926719 1.1273270626495436276e-15 1.0471975511965974093" />
<geometry>
<mesh filename="package:///tibia.stl"/>
</geometry>
</collision>
<visual>
<origin xyz="-0.047631397208144715671 0.027500000000000468514 0.023399999999998886968" rpy="3.1415926535897926719 -1.6010910366031804335e-16 1.0471975511965976313" />
<geometry>
<mesh filename="package:///motorejeacopleeje2.stl"/>
</geometry>
<material name="motorejeacopleeje2_material">
<color rgba="0.64705882352941179736 0.64705882352941179736 0.64705882352941179736 1.0"/>
</material>
</visual>
<collision>
<origin xyz="-0.047631397208144715671 0.027500000000000468514 0.023399999999998886968" rpy="3.1415926535897926719 -1.6010910366031804335e-16 1.0471975511965976313" />
<geometry>
<mesh filename="package:///motorejeacopleeje2.stl"/>
</geometry>
</collision>
<inertial>
<origin xyz="-0.03718546664723530043 0.021469039178648872263 0.02339999999999962943" rpy="0 0 0"/>
<mass value="0.28552673687099017208" />
<inertia ixx="7.7012953898989867777e-05" ixy="2.1231284255096996783e-05"  ixz="9.5714723039735938315e-20" iyy="0.00010152872925693808839" iyz="-3.7904724389629940173e-20" izz="6.7501897454916754164e-05" />
</inertial>
</link>

<link name="tobillourdf_2">
<visual>
<origin xyz="0.00014999999999967816855 -0.035799999999999027045 0.023374999999999864636" rpy="-1.570796326794896558 -1.570796326794896558 0" />
<geometry>
<mesh filename="package:///tobillopt3_1.stl"/>
</geometry>
<material name="tobillopt3_1_material">
<color rgba="0.97254901960784312376 0.97254901960784312376 0.97254901960784312376 1.0"/>
</material>
</visual>
<collision>
<origin xyz="0.00014999999999967816855 -0.035799999999999027045 0.023374999999999864636" rpy="-1.570796326794896558 -1.570796326794896558 0" />
<geometry>
<mesh filename="package:///tobillopt3_1.stl"/>
</geometry>
</collision>
<visual>
<origin xyz="2.7755575615628913511e-16 -0.035800000000000303801 0.023550000000000074346" rpy="-1.570796326794896558 -1.570796326794896558 0" />
<geometry>
<mesh filename="package:///tobillopt1.stl"/>
</geometry>
<material name="tobillopt1_material">
<color rgba="0.97254901960784312376 0.97254901960784312376 0.97254901960784312376 1.0"/>
</material>
</visual>
<collision>
<origin xyz="2.7755575615628913511e-16 -0.035800000000000303801 0.023550000000000074346" rpy="-1.570796326794896558 -1.570796326794896558 0" />
<geometry>
<mesh filename="package:///tobillopt1.stl"/>
</geometry>
</collision>
<visual>
<origin xyz="0.00019999999999906203918 -0.025772450770437410617 0.013564015027679735687" rpy="1.5707963267948605868 -1.2626032688423955399e-13 1.5707963267950095787" />
<geometry>
<mesh filename="package:///motorejecaja.stl"/>
</geometry>
<material name="motorejecaja_material">
<color rgba="0.26274509803921569651 0.28235294117647058432 0.30196078431372547213 1.0"/>
</material>
</visual>
<collision>
<origin xyz="0.00019999999999906203918 -0.025772450770437410617 0.013564015027679735687" rpy="1.5707963267948605868 -1.2626032688423955399e-13 1.5707963267950095787" />
<geometry>
<mesh filename="package:///motorejecaja.stl"/>
</geometry>
</collision>
<visual>
<origin xyz="-0.00015000000000003899103 -0.035799999999999082556 0.023374999999999823003" rpy="-1.57079632679489678 -1.570796326794896336 0" />
<geometry>
<mesh filename="package:///tobillopt3_2.stl"/>
</geometry>
<material name="tobillopt3_2_material">
<color rgba="0.97254901960784312376 0.97254901960784312376 0.97254901960784312376 1.0"/>
</material>
</visual>
<collision>
<origin xyz="-0.00015000000000003899103 -0.035799999999999082556 0.023374999999999823003" rpy="-1.57079632679489678 -1.570796326794896336 0" />
<geometry>
<mesh filename="package:///tobillopt3_2.stl"/>
</geometry>
</collision>
<visual>
<origin xyz="0.00019999999999906203918 -0.025772450770437410617 0.013564015027679735687" rpy="1.5707963267948601427 -1.2503908155715198277e-13 1.5707963267950104669" />
<geometry>
<mesh filename="package:///motorejeeje2.stl"/>
</geometry>
<material name="motorejeeje2_material">
<color rgba="0.64705882352941179736 0.64705882352941179736 0.64705882352941179736 1.0"/>
</material>
</visual>
<collision>
<origin xyz="0.00019999999999906203918 -0.025772450770437410617 0.013564015027679735687" rpy="1.5707963267948601427 -1.2503908155715198277e-13 1.5707963267950104669" />
<geometry>
<mesh filename="package:///motorejeeje2.stl"/>
</geometry>
</collision>
<visual>
<origin xyz="0.0001999999999990342836 -0.025772450770437410617 0.013564015027679721809" rpy="1.5707963267948599206 -1.4189418551819127997e-13 1.5707963267950142416" />
<geometry>
<mesh filename="package:///motorejeeje1.stl"/>
</geometry>
<material name="motorejeeje1_material">
<color rgba="0.64705882352941179736 0.64705882352941179736 0.64705882352941179736 1.0"/>
</material>
</visual>
<collision>
<origin xyz="0.0001999999999990342836 -0.025772450770437410617 0.013564015027679721809" rpy="1.5707963267948599206 -1.4189418551819127997e-13 1.5707963267950142416" />
<geometry>
<mesh filename="package:///motorejeeje1.stl"/>
</geometry>
</collision>
<visual>
<origin xyz="2.498001805406602216e-16 -0.035800000000000220535 0.023849999999999992734" rpy="-1.570796326794896558 -1.570796326794896558 0" />
<geometry>
<mesh filename="package:///tobillopt2_2.stl"/>
</geometry>
<material name="tobillopt2_2_material">
<color rgba="0.97254901960784312376 0.97254901960784312376 0.97254901960784312376 1.0"/>
</material>
</visual>
<collision>
<origin xyz="2.498001805406602216e-16 -0.035800000000000220535 0.023849999999999992734" rpy="-1.570796326794896558 -1.570796326794896558 0" />
<geometry>
<mesh filename="package:///tobillopt2_2.stl"/>
</geometry>
</collision>
<visual>
<origin xyz="0 -0.03579999999999999849 0.023249999999999989425" rpy="-1.570796326794896558 -1.570796326794896558 0" />
<geometry>
<mesh filename="package:///tobillopt2_1.stl"/>
</geometry>
<material name="tobillopt2_1_material">
<color rgba="0.97254901960784312376 0.97254901960784312376 0.97254901960784312376 1.0"/>
</material>
</visual>
<collision>
<origin xyz="0 -0.03579999999999999849 0.023249999999999989425" rpy="-1.570796326794896558 -1.570796326794896558 0" />
<geometry>
<mesh filename="package:///tobillopt2_1.stl"/>
</geometry>
</collision>
<inertial>
<origin xyz="0.00013965747905073252165 -0.025656106121457231128 0.023688332336940860073" rpy="0 0 0"/>
<mass value="0.35953278469495453251" />
<inertia ixx="0.00010180132077840394443" ixy="5.841832609190234562e-09"  ixz="5.7602954081368282757e-08" iyy="0.00013007031479290607698" iyz="5.2659589177667986065e-07" izz="7.0605342570129211283e-05" />
</inertial>
</link>

<link name="pieurdf_2">
<visual>
<origin xyz="-0.010000000000000001943 -0.019000000000000016875 0.02340000000000000413" rpy="-1.57079632679489678 -1.570796326794896336 0" />
<geometry>
<mesh filename="package:///acoplepiemotor.stl"/>
</geometry>
<material name="acoplepiemotor_material">
<color rgba="0.97254901960784312376 0.97254901960784312376 0.97254901960784312376 1.0"/>
</material>
</visual>
<collision>
<origin xyz="-0.010000000000000001943 -0.019000000000000016875 0.02340000000000000413" rpy="-1.57079632679489678 -1.570796326794896336 0" />
<geometry>
<mesh filename="package:///acoplepiemotor.stl"/>
</geometry>
</collision>
<visual>
<origin xyz="-0.0099999999999998215316 -0.018999999999999656053 0.023500000000000437206" rpy="-1.57079632679489678 -1.570796326794896336 0" />
<geometry>
<mesh filename="package:///acoplepiemotor.stl"/>
</geometry>
<material name="acoplepiemotor_material">
<color rgba="0.97254901960784312376 0.97254901960784312376 0.97254901960784312376 1.0"/>
</material>
</visual>
<collision>
<origin xyz="-0.0099999999999998215316 -0.018999999999999656053 0.023500000000000437206" rpy="-1.57079632679489678 -1.570796326794896336 0" />
<geometry>
<mesh filename="package:///acoplepiemotor.stl"/>
</geometry>
</collision>
<visual>
<origin xyz="-0.0099999999999998354094 -0.018950000000000105649 0.02345000000000058149" rpy="-1.57079632679489678 -1.570796326794896336 0" />
<geometry>
<mesh filename="package:///plantapie.stl"/>
</geometry>
<material name="plantapie_material">
<color rgba="0.97254901960784312376 0.97254901960784312376 0.97254901960784312376 1.0"/>
</material>
</visual>
<collision>
<origin xyz="-0.0099999999999998354094 -0.018950000000000105649 0.02345000000000058149" rpy="-1.57079632679489678 -1.570796326794896336 0" />
<geometry>
<mesh filename="package:///plantapie.stl"/>
</geometry>
</collision>
<inertial>
<origin xyz="-0.0095981962877159897329 -0.018994815818902638371 0.023450000000000477407" rpy="0 0 0"/>
<mass value="0.12193030814742021606" />
<inertia ixx="5.579002840155350163e-05" ixy="-1.0383957421083906704e-06"  ixz="-4.749047541176840474e-20" iyy="7.8275338616851252338e-05" iyz="-4.6622654752731266578e-20" izz="3.3440055653628995001e-05" />
</inertial>
</link>

<joint name="RightAnkle2" type="revolute">
<origin xyz="-0.023200000000000914335 -0.025772450770440075152 0.013564015027678882203" rpy="-1.1383176501975356648e-13 1.5707963267947862018 0" />
<parent link="tobillourdf_2" />
<child link="pieurdf_2" />
<axis xyz="0 0 1"/>
<limit effort="1" velocity="20" lower="-0.26179938779914940783" upper="0.26179938779914940783"/>
<joint_properties friction="0.0"/>
</joint>

<joint name="RightAnkle1" type="revolute">
<origin xyz="-0.047631397208144729549 0.027500000000000440759 0.046799999999998891098" rpy="-3.141592653589793116 -8.7370753692816634214e-18 1.0471975511965838646" />
<parent link="tibiaurdf_2" />
<child link="tobillourdf_2" />
<axis xyz="0 0 1"/>
<limit effort="1" velocity="20" lower="-0.785398163397448279" upper="0.785398163397448279"/>
<joint_properties friction="0.0"/>
</joint>

<joint name="RightKnee" type="revolute">
<origin xyz="-2.0903417885520525488e-16 -0.065000000000000418554 -2.0816681711721685133e-16" rpy="3.1415926535897913396 -8.8716665251345430742e-16 -6.587726272486626974e-15" />
<parent link="femururdf_2" />
<child link="tibiaurdf_2" />
<axis xyz="0 0 1"/>
<limit effort="1" velocity="20" lower="-1.0471975511965976313" upper="1.0471975511965976313"/>
<joint_properties friction="0.0"/>
</joint>

<joint name="RightHip2" type="revolute">
<origin xyz="0.028027549229563658573 -0.033035984972319389075 -0.023250000000002678247" rpy="1.5707963267949249797 -1.5707963267948361619 0" />
<parent link="cadera_v01_2" />
<child link="femururdf_2" />
<axis xyz="0 0 1"/>
<limit effort="1" velocity="20" lower="-1.570796326794896558" upper="1.570796326794896558"/>
<joint_properties friction="0.0"/>
</joint>

<joint name="RightHip1" type="revolute">
<origin xyz="-0.00061949317509176534541 0.032685236218794461172 -0.023605436102933266551" rpy="-2.3561944901923457252 1.5707963267948956698 0" />
<parent link="cintura_v01_2" />
<child link="cadera_v01_2" />
<axis xyz="0 0 1"/>
<limit effort="1" velocity="20" lower="-0.785398163397448279" upper="0.785398163397448279"/>
<joint_properties friction="0.0"/>
</joint>

<joint name="RightWaist" type="revolute">
<origin xyz="-0.010742981990015255944 0.0083712188771943186333 -0.083178910040700992923" rpy="1.5914679956727636981e-17 5.1509014745192104691e-18 1.5707963267948981123" />
<parent link="torsourdf" />
<child link="cintura_v01_2" />
<axis xyz="0 0 1"/>
<limit effort="1" velocity="20" lower="-1.570796326794896558" upper="1.570796326794896558"/>
<joint_properties friction="0.0"/>
</joint>


</robot>
