<robot name="onshape">
<link name="torsourdf">
<visual>
<origin xyz="-0.030742981990015266769 0.038371218877194315788 -0.076728910040700981643" rpy="1.570796326794896558 -0 0" />
<geometry>
<mesh filename="package:///acople_tornillos_abdomen.stl"/>
</geometry>
<material name="acople_tornillos_abdomen_material">
<color rgba="0.26274509803921569651 0.28235294117647058432 0.30196078431372547213 1.0"/>
</material>
</visual>
<collision>
<origin xyz="-0.030742981990015266769 0.038371218877194315788 -0.076728910040700981643" rpy="1.570796326794896558 -0 0" />
<geometry>
<mesh filename="package:///acople_tornillos_abdomen.stl"/>
</geometry>
</collision>
<visual>
<origin xyz="0.064057018009984756368 0.038371218877194308849 0.050524780976926725318" rpy="-1.570796326794896558 -0 3.141592653589793116" />
<geometry>
<mesh filename="package:///acople_tornillos_cuello.stl"/>
</geometry>
<material name="acople_tornillos_cuello_material">
<color rgba="0.26274509803921569651 0.28235294117647058432 0.30196078431372547213 1.0"/>
</material>
</visual>
<collision>
<origin xyz="0.064057018009984756368 0.038371218877194308849 0.050524780976926725318" rpy="-1.570796326794896558 -0 3.141592653589793116" />
<geometry>
<mesh filename="package:///acople_tornillos_cuello.stl"/>
</geometry>
</collision>
<visual>
<origin xyz="0.019257018009984729068 0.0083712188771943168986 -0.059778910040700981854" rpy="3.141592653589793116 -0 3.141592653589793116" />
<geometry>
<mesh filename="package:///motorsemiejeeje.stl"/>
</geometry>
<material name="motorsemiejeeje_material">
<color rgba="0.64705882352941179736 0.64705882352941179736 0.64705882352941179736 1.0"/>
</material>
</visual>
<collision>
<origin xyz="0.019257018009984729068 0.0083712188771943168986 -0.059778910040700981854" rpy="3.141592653589793116 -0 3.141592653589793116" />
<geometry>
<mesh filename="package:///motorsemiejeeje.stl"/>
</geometry>
</collision>
<visual>
<origin xyz="-0.055542981990015269367 0.038371218877194329666 -0.037828910040700991502" rpy="1.570796326794896558 -0 0" />
<geometry>
<mesh filename="package:///acople_tornillos_abdomen.stl"/>
</geometry>
<material name="acople_tornillos_abdomen_material">
<color rgba="0.26274509803921569651 0.28235294117647058432 0.30196078431372547213 1.0"/>
</material>
</visual>
<collision>
<origin xyz="-0.055542981990015269367 0.038371218877194329666 -0.037828910040700991502" rpy="1.570796326794896558 -0 0" />
<geometry>
<mesh filename="package:///acople_tornillos_abdomen.stl"/>
</geometry>
</collision>
<visual>
<origin xyz="0.069405821023547836779 0.0073712188771943021326 0.025468521028911533799" rpy="-1.570796326794896558 -0 -1.570796326794896558" />
<geometry>
<mesh filename="package:///motorejeeje2.stl"/>
</geometry>
<material name="motorejeeje2_material">
<color rgba="0.64705882352941179736 0.64705882352941179736 0.64705882352941179736 1.0"/>
</material>
</visual>
<collision>
<origin xyz="0.069405821023547836779 0.0073712188771943021326 0.025468521028911533799" rpy="-1.570796326794896558 -0 -1.570796326794896558" />
<geometry>
<mesh filename="package:///motorejeeje2.stl"/>
</geometry>
</collision>
<visual>
<origin xyz="-0.060891785003578363655 0.0073712188771943021326 0.025468521028911547677" rpy="-1.570796326794896558 -0 1.570796326794896558" />
<geometry>
<mesh filename="package:///motorejeeje1.stl"/>
</geometry>
<material name="motorejeeje1_material">
<color rgba="0.64705882352941179736 0.64705882352941179736 0.64705882352941179736 1.0"/>
</material>
</visual>
<collision>
<origin xyz="-0.060891785003578363655 0.0073712188771943021326 0.025468521028911547677" rpy="-1.570796326794896558 -0 1.570796326794896558" />
<geometry>
<mesh filename="package:///motorejeeje1.stl"/>
</geometry>
</collision>
<visual>
<origin xyz="0.004057018009984730833 -0.023628781122805697645 -0.0045580513594990768045" rpy="1.570796326794896558 -0 0" />
<geometry>
<mesh filename="package:///pecho.stl"/>
</geometry>
<material name="pecho_material">
<color rgba="0.97254901960784312376 0.97254901960784312376 0.97254901960784312376 1.0"/>
</material>
</visual>
<collision>
<origin xyz="0.004057018009984730833 -0.023628781122805697645 -0.0045580513594990768045" rpy="1.570796326794896558 -0 0" />
<geometry>
<mesh filename="package:///pecho.stl"/>
</geometry>
</collision>
<visual>
<origin xyz="0.069405821023547836779 0.0073712188771943021326 0.025468521028911547677" rpy="-1.5707963267948976682 1.9721522630525216312e-31 -1.570796326794896336" />
<geometry>
<mesh filename="package:///motorejeeje1.stl"/>
</geometry>
<material name="motorejeeje1_material">
<color rgba="0.64705882352941179736 0.64705882352941179736 0.64705882352941179736 1.0"/>
</material>
</visual>
<collision>
<origin xyz="0.069405821023547836779 0.0073712188771943021326 0.025468521028911547677" rpy="-1.5707963267948976682 1.9721522630525216312e-31 -1.570796326794896336" />
<geometry>
<mesh filename="package:///motorejeeje1.stl"/>
</geometry>
</collision>
<visual>
<origin xyz="0.087855821023547830961 0.007371218877194305602 0.025468521028911547677" rpy="-1.570796326794896558 -0 -1.570796326794896558" />
<geometry>
<mesh filename="package:///hombro_pecho.stl"/>
</geometry>
<material name="hombro_pecho_material">
<color rgba="0.97254901960784312376 0.97254901960784312376 0.97254901960784312376 1.0"/>
</material>
</visual>
<collision>
<origin xyz="0.087855821023547830961 0.007371218877194305602 0.025468521028911547677" rpy="-1.570796326794896558 -0 -1.570796326794896558" />
<geometry>
<mesh filename="package:///hombro_pecho.stl"/>
</geometry>
</collision>
<visual>
<origin xyz="-0.010742981990015254209 0.0083712188771943238375 -0.059778910040700974915" rpy="3.141592653589793116 -0 3.141592653589793116" />
<geometry>
<mesh filename="package:///motorsemiejecaja.stl"/>
</geometry>
<material name="motorsemiejecaja_material">
<color rgba="0.26274509803921569651 0.28235294117647058432 0.30196078431372547213 1.0"/>
</material>
</visual>
<collision>
<origin xyz="-0.010742981990015254209 0.0083712188771943238375 -0.059778910040700974915" rpy="3.141592653589793116 -0 3.141592653589793116" />
<geometry>
<mesh filename="package:///motorsemiejecaja.stl"/>
</geometry>
</collision>
<visual>
<origin xyz="-0.079341785003578357838 0.0073712188771942951937 0.025468521028911547677" rpy="-1.570796326794896558 -0 1.570796326794896558" />
<geometry>
<mesh filename="package:///hombro_pecho.stl"/>
</geometry>
<material name="hombro_pecho_material">
<color rgba="0.97254901960784312376 0.97254901960784312376 0.97254901960784312376 1.0"/>
</material>
</visual>
<collision>
<origin xyz="-0.079341785003578357838 0.0073712188771942951937 0.025468521028911547677" rpy="-1.570796326794896558 -0 1.570796326794896558" />
<geometry>
<mesh filename="package:///hombro_pecho.stl"/>
</geometry>
</collision>
<visual>
<origin xyz="-0.060891785003578363655 0.0073712188771943021326 0.025468521028911547677" rpy="-1.57079632679489678 -7.8886090522100182116e-31 1.57079632679489678" />
<geometry>
<mesh filename="package:///motorejeeje2.stl"/>
</geometry>
<material name="motorejeeje2_material">
<color rgba="0.64705882352941179736 0.64705882352941179736 0.64705882352941179736 1.0"/>
</material>
</visual>
<collision>
<origin xyz="-0.060891785003578363655 0.0073712188771943021326 0.025468521028911547677" rpy="-1.57079632679489678 -7.8886090522100182116e-31 1.57079632679489678" />
<geometry>
<mesh filename="package:///motorejeeje2.stl"/>
</geometry>
</collision>
<visual>
<origin xyz="-0.010742981990015255944 0.0083712188771943168986 -0.059778910040700981854" rpy="3.141592653589793116 -0 3.141592653589793116" />
<geometry>
<mesh filename="package:///motorsemiejeeje.stl"/>
</geometry>
<material name="motorsemiejeeje_material">
<color rgba="0.64705882352941179736 0.64705882352941179736 0.64705882352941179736 1.0"/>
</material>
</visual>
<collision>
<origin xyz="-0.010742981990015255944 0.0083712188771943168986 -0.059778910040700981854" rpy="3.141592653589793116 -0 3.141592653589793116" />
<geometry>
<mesh filename="package:///motorsemiejeeje.stl"/>
</geometry>
</collision>
<visual>
<origin xyz="0.0042570180099847365618 0.040371218877194303687 -0.0045580513594990490489" rpy="1.570796326794896558 -0 0" />
<geometry>
<mesh filename="package:///espalda.stl"/>
</geometry>
<material name="espalda_material">
<color rgba="0.97254901960784312376 0.97254901960784312376 0.97254901960784312376 1.0"/>
</material>
</visual>
<collision>
<origin xyz="0.0042570180099847365618 0.040371218877194303687 -0.0045580513594990490489" rpy="1.570796326794896558 -0 0" />
<geometry>
<mesh filename="package:///espalda.stl"/>
</geometry>
</collision>
<visual>
<origin xyz="-0.060891785003578363655 0.0073712188771942917243 0.025468521028911547677" rpy="-1.570796326794896558 -0 1.570796326794896558" />
<geometry>
<mesh filename="package:///motorejecaja.stl"/>
</geometry>
<material name="motorejecaja_material">
<color rgba="0.26274509803921569651 0.28235294117647058432 0.30196078431372547213 1.0"/>
</material>
</visual>
<collision>
<origin xyz="-0.060891785003578363655 0.0073712188771942917243 0.025468521028911547677" rpy="-1.570796326794896558 -0 1.570796326794896558" />
<geometry>
<mesh filename="package:///motorejecaja.stl"/>
</geometry>
</collision>
<visual>
<origin xyz="-0.055942981990015253069 -0.023628781122805697645 0.050524780976926725318" rpy="-1.570796326794896558 -0 0" />
<geometry>
<mesh filename="package:///acople_tornillos_cuello.stl"/>
</geometry>
<material name="acople_tornillos_cuello_material">
<color rgba="0.26274509803921569651 0.28235294117647058432 0.30196078431372547213 1.0"/>
</material>
</visual>
<collision>
<origin xyz="-0.055942981990015253069 -0.023628781122805697645 0.050524780976926725318" rpy="-1.570796326794896558 -0 0" />
<geometry>
<mesh filename="package:///acople_tornillos_cuello.stl"/>
</geometry>
</collision>
<visual>
<origin xyz="0.014057018009984739715 0.007371218877194305602 0.054024780976926728426" rpy="3.141592653589793116 -0 -1.570796326794896558" />
<geometry>
<mesh filename="package:///base_cabeza.stl"/>
</geometry>
<material name="base_cabeza_material">
<color rgba="0.97254901960784312376 0.97254901960784312376 0.97254901960784312376 1.0"/>
</material>
</visual>
<collision>
<origin xyz="0.014057018009984739715 0.007371218877194305602 0.054024780976926728426" rpy="3.141592653589793116 -0 -1.570796326794896558" />
<geometry>
<mesh filename="package:///base_cabeza.stl"/>
</geometry>
</collision>
<visual>
<origin xyz="-0.010542981990015257154 0.023946218877194329344 -0.04132891004070099461" rpy="0 -0 0" />
<geometry>
<mesh filename="package:///acoplemotorestorso1.stl"/>
</geometry>
<material name="acoplemotorestorso1_material">
<color rgba="0.97254901960784312376 0.97254901960784312376 0.97254901960784312376 1.0"/>
</material>
</visual>
<collision>
<origin xyz="-0.010542981990015257154 0.023946218877194329344 -0.04132891004070099461" rpy="0 -0 0" />
<geometry>
<mesh filename="package:///acoplemotorestorso1.stl"/>
</geometry>
</collision>
<visual>
<origin xyz="-0.010742981990015262883 0.023946218877194322405 -0.080228910040700984752" rpy="0 -0 0" />
<geometry>
<mesh filename="package:///acoplemotorestorso2.stl"/>
</geometry>
<material name="acoplemotorestorso2_material">
<color rgba="0.97254901960784312376 0.97254901960784312376 0.97254901960784312376 1.0"/>
</material>
</visual>
<collision>
<origin xyz="-0.010742981990015262883 0.023946218877194322405 -0.080228910040700984752" rpy="0 -0 0" />
<geometry>
<mesh filename="package:///acoplemotorestorso2.stl"/>
</geometry>
</collision>
<visual>
<origin xyz="-0.077841785003578356505 -0.023628781122805683768 -0.0070314789710884256779" rpy="-1.570796326794896558 -1.570796326794896558 0" />
<geometry>
<mesh filename="package:///acople_tornillos_hombro.stl"/>
</geometry>
<material name="acople_tornillos_hombro_material">
<color rgba="0.26274509803921569651 0.28235294117647058432 0.30196078431372547213 1.0"/>
</material>
</visual>
<collision>
<origin xyz="-0.077841785003578356505 -0.023628781122805683768 -0.0070314789710884256779" rpy="-1.570796326794896558 -1.570796326794896558 0" />
<geometry>
<mesh filename="package:///acople_tornillos_hombro.stl"/>
</geometry>
</collision>
<visual>
<origin xyz="0.086355821023547829629 0.038371218877194274155 -0.0070314789710884395557" rpy="1.570796326794896558 -1.570796326794896558 0" />
<geometry>
<mesh filename="package:///acople_tornillos_hombro.stl"/>
</geometry>
<material name="acople_tornillos_hombro_material">
<color rgba="0.26274509803921569651 0.28235294117647058432 0.30196078431372547213 1.0"/>
</material>
</visual>
<collision>
<origin xyz="0.086355821023547829629 0.038371218877194274155 -0.0070314789710884395557" rpy="1.570796326794896558 -1.570796326794896558 0" />
<geometry>
<mesh filename="package:///acople_tornillos_hombro.stl"/>
</geometry>
</collision>
<visual>
<origin xyz="0.086355821023547829629 -0.023628781122805697645 0.037968521028911544901" rpy="-1.570796326794896558 1.570796326794896558 0" />
<geometry>
<mesh filename="package:///acople_tornillos_hombro.stl"/>
</geometry>
<material name="acople_tornillos_hombro_material">
<color rgba="0.26274509803921569651 0.28235294117647058432 0.30196078431372547213 1.0"/>
</material>
</visual>
<collision>
<origin xyz="0.086355821023547829629 -0.023628781122805697645 0.037968521028911544901" rpy="-1.570796326794896558 1.570796326794896558 0" />
<geometry>
<mesh filename="package:///acople_tornillos_hombro.stl"/>
</geometry>
</collision>
<visual>
<origin xyz="0.039257018009984739892 -0.0216287811228056924 -0.076728910040700981643" rpy="1.570796326794896558 -0 3.141592653589793116" />
<geometry>
<mesh filename="package:///acople_tornillos_abdomen.stl"/>
</geometry>
<material name="acople_tornillos_abdomen_material">
<color rgba="0.26274509803921569651 0.28235294117647058432 0.30196078431372547213 1.0"/>
</material>
</visual>
<collision>
<origin xyz="0.039257018009984739892 -0.0216287811228056924 -0.076728910040700981643" rpy="1.570796326794896558 -0 3.141592653589793116" />
<geometry>
<mesh filename="package:///acople_tornillos_abdomen.stl"/>
</geometry>
</collision>
<visual>
<origin xyz="0.064457018009984712315 -0.021628781122805678522 -0.037828910040700991502" rpy="1.570796326794896558 -0 3.141592653589793116" />
<geometry>
<mesh filename="package:///acople_tornillos_abdomen.stl"/>
</geometry>
<material name="acople_tornillos_abdomen_material">
<color rgba="0.26274509803921569651 0.28235294117647058432 0.30196078431372547213 1.0"/>
</material>
</visual>
<collision>
<origin xyz="0.064457018009984712315 -0.021628781122805678522 -0.037828910040700991502" rpy="1.570796326794896558 -0 3.141592653589793116" />
<geometry>
<mesh filename="package:///acople_tornillos_abdomen.stl"/>
</geometry>
</collision>
<visual>
<origin xyz="0.0042570180099847365618 -0.023628781122805683768 -0.0045580513594990629267" rpy="1.570796326794896558 -0 3.141592653589793116" />
<geometry>
<mesh filename="package:///abdomen.stl"/>
</geometry>
<material name="abdomen_material">
<color rgba="0.26274509803921569651 0.28235294117647058432 0.30196078431372547213 1.0"/>
</material>
</visual>
<collision>
<origin xyz="0.0042570180099847365618 -0.023628781122805683768 -0.0045580513594990629267" rpy="1.570796326794896558 -0 3.141592653589793116" />
<geometry>
<mesh filename="package:///abdomen.stl"/>
</geometry>
</collision>
<visual>
<origin xyz="-0.077841785003578356505 0.038371218877194301911 0.037968521028911544901" rpy="1.570796326794896558 1.570796326794896558 0" />
<geometry>
<mesh filename="package:///acople_tornillos_hombro.stl"/>
</geometry>
<material name="acople_tornillos_hombro_material">
<color rgba="0.26274509803921569651 0.28235294117647058432 0.30196078431372547213 1.0"/>
</material>
</visual>
<collision>
<origin xyz="-0.077841785003578356505 0.038371218877194301911 0.037968521028911544901" rpy="1.570796326794896558 1.570796326794896558 0" />
<geometry>
<mesh filename="package:///acople_tornillos_hombro.stl"/>
</geometry>
</collision>
<visual>
<origin xyz="0.069405821023547836779 0.0073712188771943021326 0.025468521028911533799" rpy="-1.570796326794896558 -0 -1.570796326794896558" />
<geometry>
<mesh filename="package:///motorejecaja.stl"/>
</geometry>
<material name="motorejecaja_material">
<color rgba="0.26274509803921569651 0.28235294117647058432 0.30196078431372547213 1.0"/>
</material>
</visual>
<collision>
<origin xyz="0.069405821023547836779 0.0073712188771943021326 0.025468521028911533799" rpy="-1.570796326794896558 -0 -1.570796326794896558" />
<geometry>
<mesh filename="package:///motorejecaja.stl"/>
</geometry>
</collision>
<visual>
<origin xyz="0.004057018009984730833 -0.023628781122805697645 -0.0045580513594990768045" rpy="1.570796326794896558 -0 0" />
<geometry>
<mesh filename="package:///luzpecho.stl"/>
</geometry>
<material name="luzpecho_material">
<color rgba="0.14117647058823529216 0.6941176470588235059 0.65098039215686276382 1.0"/>
</material>
</visual>
<collision>
<origin xyz="0.004057018009984730833 -0.023628781122805697645 -0.0045580513594990768045" rpy="1.570796326794896558 -0 0" />
<geometry>
<mesh filename="package:///luzpecho.stl"/>
</geometry>
</collision>
<visual>
<origin xyz="0.01925701800998471519 0.0083712188771943238375 -0.059778910040700974915" rpy="3.141592653589793116 -0 3.141592653589793116" />
<geometry>
<mesh filename="package:///motorsemiejecaja.stl"/>
</geometry>
<material name="motorsemiejecaja_material">
<color rgba="0.26274509803921569651 0.28235294117647058432 0.30196078431372547213 1.0"/>
</material>
</visual>
<collision>
<origin xyz="0.01925701800998471519 0.0083712188771943238375 -0.059778910040700974915" rpy="3.141592653589793116 -0 3.141592653589793116" />
<geometry>
<mesh filename="package:///motorsemiejecaja.stl"/>
</geometry>
</collision>
<inertial>
<origin xyz="0.0041641753467128745508 -0.0069926972537789049839 -0.005456539818586879538" rpy="0 0 0"/>
<mass value="3.2921674694109959169" />
<inertia ixx="0.0076880102936380534384" ixy="-6.7916077198654890108e-06"  ixz="6.7702832083634087619e-06" iyy="0.013499449690620729178" iyz="0.00096379853423082416028" izz="0.0097359687391726616734" />
</inertial>
</link>

<link name="hombro-brazo">
<visual>
<origin xyz="-1.1362438767648086468e-16 -0.010999809727072717286 -0.0020000000000000017764" rpy="3.141592653589793116 -4.9303806576206958108e-32 0" />
<geometry>
<mesh filename="package:///hombro_brazo1.stl"/>
</geometry>
<material name="hombro_brazo1_material">
<color rgba="0.97254901960784312376 0.97254901960784312376 0.97254901960784312376 1.0"/>
</material>
</visual>
<collision>
<origin xyz="-1.1362438767648086468e-16 -0.010999809727072717286 -0.0020000000000000017764" rpy="3.141592653589793116 -4.9303806576206958108e-32 0" />
<geometry>
<mesh filename="package:///hombro_brazo1.stl"/>
</geometry>
</collision>
<visual>
<origin xyz="-0.0002999999999956952032 0.011000190272924889254 9.4368957093138305936e-16" rpy="-3.1415926535897895633 -2.6645352591003760126e-14 -3.1415926535897864547" />
<geometry>
<mesh filename="package:///hombro_brazo2.stl"/>
</geometry>
<material name="hombro_brazo2_material">
<color rgba="0.97254901960784312376 0.97254901960784312376 0.97254901960784312376 1.0"/>
</material>
</visual>
<collision>
<origin xyz="-0.0002999999999956952032 0.011000190272924889254 9.4368957093138305936e-16" rpy="-3.1415926535897895633 -2.6645352591003760126e-14 -3.1415926535897864547" />
<geometry>
<mesh filename="package:///hombro_brazo2.stl"/>
</geometry>
</collision>
<visual>
<origin xyz="0.00029999999999982904925 -0.010999809727072731164 6.8001160258290838101e-16" rpy="3.1415926535897926719 5.5511151231205328328e-16 -2.488009798184976312e-13" />
<geometry>
<mesh filename="package:///hombro_brazo2.stl"/>
</geometry>
<material name="hombro_brazo2_material">
<color rgba="0.97254901960784312376 0.97254901960784312376 0.97254901960784312376 1.0"/>
</material>
</visual>
<collision>
<origin xyz="0.00029999999999982904925 -0.010999809727072731164 6.8001160258290838101e-16" rpy="3.1415926535897926719 5.5511151231205328328e-16 -2.488009798184976312e-13" />
<geometry>
<mesh filename="package:///hombro_brazo2.stl"/>
</geometry>
</collision>
<inertial>
<origin xyz="1.7014733176725471617e-15 1.1044824123134683803e-07 -0.0076081599888872253334" rpy="0 0 0"/>
<mass value="0.028276359613946901173" />
<inertia ixx="3.1909882339227920082e-06" ixy="7.6383436214787131524e-11"  ixz="4.6036240683271223428e-19" iyy="1.392592682798810539e-05" iyz="1.4915617611435922662e-11" izz="1.2743353645780904366e-05" />
</inertial>
</link>

<link name="brazourdf">
<visual>
<origin xyz="2.7755575615628913511e-17 -6.9388939039072283776e-18 -0.02340000000000000413" rpy="2.1094237467878266147e-15 -4.4408920985025036506e-16 1.570796326794896558" />
<geometry>
<mesh filename="package:///motorejeacopleeje2.stl"/>
</geometry>
<material name="motorejeacopleeje2_material">
<color rgba="0.64705882352941179736 0.64705882352941179736 0.64705882352941179736 1.0"/>
</material>
</visual>
<collision>
<origin xyz="2.7755575615628913511e-17 -6.9388939039072283776e-18 -0.02340000000000000413" rpy="2.1094237467878266147e-15 -4.4408920985025036506e-16 1.570796326794896558" />
<geometry>
<mesh filename="package:///motorejeacopleeje2.stl"/>
</geometry>
</collision>
<visual>
<origin xyz="-0.030000000000000012768 0 -0.023399999999999990252" rpy="1.5707963267948970021 -5.5511151229433647808e-17 1.570796326794896336" />
<geometry>
<mesh filename="package:///brazo.stl"/>
</geometry>
<material name="brazo_material">
<color rgba="0.97254901960784312376 0.97254901960784312376 0.97254901960784312376 1.0"/>
</material>
</visual>
<collision>
<origin xyz="-0.030000000000000012768 0 -0.023399999999999990252" rpy="1.5707963267948970021 -5.5511151229433647808e-17 1.570796326794896336" />
<geometry>
<mesh filename="package:///brazo.stl"/>
</geometry>
</collision>
<visual>
<origin xyz="1.3877787807814456755e-17 0 -0.023399999999999997191" rpy="-7.0879359787127582264e-31 -0 1.570796326794896558" />
<geometry>
<mesh filename="package:///motorejeacopleeje1.stl"/>
</geometry>
<material name="motorejeacopleeje1_material">
<color rgba="0.64705882352941179736 0.64705882352941179736 0.64705882352941179736 1.0"/>
</material>
</visual>
<collision>
<origin xyz="1.3877787807814456755e-17 0 -0.023399999999999997191" rpy="-7.0879359787127582264e-31 -0 1.570796326794896558" />
<geometry>
<mesh filename="package:///motorejeacopleeje1.stl"/>
</geometry>
</collision>
<visual>
<origin xyz="0 3.4694469519536141888e-18 -0.023400000000000000661" rpy="4.4408920984990405513e-16 -2.2204460492507504056e-16 1.570796326794896336" />
<geometry>
<mesh filename="package:///motorejeacoplecaja.stl"/>
</geometry>
<material name="motorejeacoplecaja_material">
<color rgba="0.26274509803921569651 0.28235294117647058432 0.30196078431372547213 1.0"/>
</material>
</visual>
<collision>
<origin xyz="0 3.4694469519536141888e-18 -0.023400000000000000661" rpy="4.4408920984990405513e-16 -2.2204460492507504056e-16 1.570796326794896336" />
<geometry>
<mesh filename="package:///motorejeacoplecaja.stl"/>
</geometry>
</collision>
<inertial>
<origin xyz="-0.064612740306650359723 0.00024409654353023735383 -0.023399999587718614547" rpy="0 0 0"/>
<mass value="1.080760232398511711" />
<inertia ixx="0.00022953897767025226119" ixy="2.1146337854862569833e-05"  ixz="-1.3608742073465570691e-10" iyy="0.0024710869173820305261" iyz="-1.081533924892316817e-11" izz="0.0023133411907278666683" />
</inertial>
</link>

<joint name="LeftShoulder2" type="revolute">
<origin xyz="-0.02354999999999616081 3.8054585194818857374e-07 -0.020946406845601450719" rpy="7.7715611723741378302e-15 -1.5707963267948685804 0" />
<parent link="hombro-brazo" />
<child link="brazourdf" />
<axis xyz="0 0 1"/>
<limit effort="1" velocity="20" lower="-1.570796326794896558" upper="1.570796326794896558"/>
<joint_properties friction="0.0"/>
</joint>

<joint name="LeftShoulder1" type="revolute">
<origin xyz="0.092805821023547840909 0.0073712188771943082041 0.02546852102891152686" rpy="-1.5707963267948943376 -5.5511151231257851673e-17 1.570796326794896336" />
<parent link="torsourdf" />
<child link="hombro-brazo" />
<axis xyz="0 0 1"/>
<limit effort="1" velocity="20" lower="-1.570796326794896558" upper="1.570796326794896558"/>
<joint_properties friction="0.0"/>
</joint>

<link name="cintura_v01">
<visual>
<origin xyz="-3.4694469519536141888e-18 -8.6736173798840354721e-19 -0.0020000000000000017764" rpy="-3.141592653589793116 1.4277249895144416927e-35 0.785398163397448279" />
<geometry>
<mesh filename="package:///cinturapt1.stl"/>
</geometry>
<material name="cinturapt1_material">
<color rgba="0.97254901960784312376 0.97254901960784312376 0.97254901960784312376 1.0"/>
</material>
</visual>
<collision>
<origin xyz="-3.4694469519536141888e-18 -8.6736173798840354721e-19 -0.0020000000000000017764" rpy="-3.141592653589793116 1.4277249895144416927e-35 0.785398163397448279" />
<geometry>
<mesh filename="package:///cinturapt1.stl"/>
</geometry>
</collision>
<visual>
<origin xyz="0.00021213203435581709511 0.00021213203435585092221 -0.0020000000000000017764" rpy="-3.141592653589793116 -3.8480247513544732215e-32 0.78539816339744938922" />
<geometry>
<mesh filename="package:///cinturapt2_2.stl"/>
</geometry>
<material name="cinturapt2_2_material">
<color rgba="0.97254901960784312376 0.97254901960784312376 0.97254901960784312376 1.0"/>
</material>
</visual>
<collision>
<origin xyz="0.00021213203435581709511 0.00021213203435585092221 -0.0020000000000000017764" rpy="-3.141592653589793116 -3.8480247513544732215e-32 0.78539816339744938922" />
<geometry>
<mesh filename="package:///cinturapt2_2.stl"/>
</geometry>
</collision>
<visual>
<origin xyz="-0.00021213203435575811451 -0.00021213203435576245132 -0.0020000000000000017764" rpy="-3.141592653589793116 -3.8480247513544732215e-32 0.78539816339744938922" />
<geometry>
<mesh filename="package:///cinturapt2_1.stl"/>
</geometry>
<material name="cinturapt2_1_material">
<color rgba="0.97254901960784312376 0.97254901960784312376 0.97254901960784312376 1.0"/>
</material>
</visual>
<collision>
<origin xyz="-0.00021213203435575811451 -0.00021213203435576245132 -0.0020000000000000017764" rpy="-3.141592653589793116 -3.8480247513544732215e-32 0.78539816339744938922" />
<geometry>
<mesh filename="package:///cinturapt2_1.stl"/>
</geometry>
</collision>
<inertial>
<origin xyz="-0.0079316365006480427091 0.0079316365006479941369 -0.0083693257381815735346" rpy="0 0 0"/>
<mass value="0.032703197933895256089" />
<inertia ixx="1.1474475218213164835e-05" ixy="-5.2475239690137881799e-06"  ixz="-1.4935382828704757821e-06" iyy="1.1474475218213136036e-05" iyz="1.4935382828704764174e-06" izz="1.7093428062394833443e-05" />
</inertial>
</link>

<link name="cadera_v01">
<visual>
<origin xyz="0.010027549229562018884 0.0091859849723172348757 -0.023549999999998509626" rpy="-1.5707963267949460739 -1.239053544894946692e-13 1.5707963267949798247" />
<geometry>
<mesh filename="package:///caderapt2_1.stl"/>
</geometry>
<material name="caderapt2_1_material">
<color rgba="0.97254901960784312376 0.97254901960784312376 0.97254901960784312376 1.0"/>
</material>
</visual>
<collision>
<origin xyz="0.010027549229562018884 0.0091859849723172348757 -0.023549999999998509626" rpy="-1.5707963267949460739 -1.239053544894946692e-13 1.5707963267949798247" />
<geometry>
<mesh filename="package:///caderapt2_1.stl"/>
</geometry>
</collision>
<visual>
<origin xyz="1.3877787807814456755e-17 6.9388939039072283776e-18 -0.023399999999999997191" rpy="-4.3984203539009321937e-19 -1.1950420445403110418e-31 2.6964675744201314301e-31" />
<geometry>
<mesh filename="package:///motorejecaja.stl"/>
</geometry>
<material name="motorejecaja_material">
<color rgba="0.26274509803921569651 0.28235294117647058432 0.30196078431372547213 1.0"/>
</material>
</visual>
<collision>
<origin xyz="1.3877787807814456755e-17 6.9388939039072283776e-18 -0.023399999999999997191" rpy="-4.3984203539009321937e-19 -1.1950420445403110418e-31 2.6964675744201314301e-31" />
<geometry>
<mesh filename="package:///motorejecaja.stl"/>
</geometry>
</collision>
<visual>
<origin xyz="0.01002754922956204664 0.0097859849723171896119 -0.023549999999998443706" rpy="-1.5707963267949460739 -1.2434933689636933179e-13 1.5707963267949798247" />
<geometry>
<mesh filename="package:///caderapt2_2.stl"/>
</geometry>
<material name="caderapt2_2_material">
<color rgba="0.97254901960784312376 0.97254901960784312376 0.97254901960784312376 1.0"/>
</material>
</visual>
<collision>
<origin xyz="0.01002754922956204664 0.0097859849723171896119 -0.023549999999998443706" rpy="-1.5707963267949460739 -1.2434933689636933179e-13 1.5707963267949798247" />
<geometry>
<mesh filename="package:///caderapt2_2.stl"/>
</geometry>
</collision>
<visual>
<origin xyz="-4.1633363423443370266e-17 -2.0816681711721685133e-17 -0.023399999999999993722" rpy="5.5057958823940190526e-17 2.0470146356161438135e-15 -8.0093952708803340692e-16" />
<geometry>
<mesh filename="package:///motorejeeje2.stl"/>
</geometry>
<material name="motorejeeje2_material">
<color rgba="0.64705882352941179736 0.64705882352941179736 0.64705882352941179736 1.0"/>
</material>
</visual>
<collision>
<origin xyz="-4.1633363423443370266e-17 -2.0816681711721685133e-17 -0.023399999999999993722" rpy="5.5057958823940190526e-17 2.0470146356161438135e-15 -8.0093952708803340692e-16" />
<geometry>
<mesh filename="package:///motorejeeje2.stl"/>
</geometry>
</collision>
<visual>
<origin xyz="0.010027549229561963373 0.0098109849723171035918 -0.023449999999998499822" rpy="-1.5707963267949460739 -1.2434933689636933179e-13 1.5707963267949798247" />
<geometry>
<mesh filename="package:///caderapt3_2.stl"/>
</geometry>
<material name="caderapt3_2_material">
<color rgba="0.97254901960784312376 0.97254901960784312376 0.97254901960784312376 1.0"/>
</material>
</visual>
<collision>
<origin xyz="0.010027549229561963373 0.0098109849723171035918 -0.023449999999998499822" rpy="-1.5707963267949460739 -1.2434933689636933179e-13 1.5707963267949798247" />
<geometry>
<mesh filename="package:///caderapt3_2.stl"/>
</geometry>
</collision>
<visual>
<origin xyz="0.010027549229561963373 0.0098109849723171868585 -0.023649999999998470857" rpy="-1.5707963267949460739 -1.2716931890253408191e-13 1.5707963267949782704" />
<geometry>
<mesh filename="package:///caderapt3_1.stl"/>
</geometry>
<material name="caderapt3_1_material">
<color rgba="0.97254901960784312376 0.97254901960784312376 0.97254901960784312376 1.0"/>
</material>
</visual>
<collision>
<origin xyz="0.010027549229561963373 0.0098109849723171868585 -0.023649999999998470857" rpy="-1.5707963267949460739 -1.2716931890253408191e-13 1.5707963267949782704" />
<geometry>
<mesh filename="package:///caderapt3_1.stl"/>
</geometry>
</collision>
<visual>
<origin xyz="0.010027549229562199296 0.0094859849723173891856 -0.023549999999998467992" rpy="-1.5707963267949460739 -1.239053544894946692e-13 1.5707963267949798247" />
<geometry>
<mesh filename="package:///caderapt1.stl"/>
</geometry>
<material name="caderapt1_material">
<color rgba="0.97254901960784312376 0.97254901960784312376 0.97254901960784312376 1.0"/>
</material>
</visual>
<collision>
<origin xyz="0.010027549229562199296 0.0094859849723173891856 -0.023549999999998467992" rpy="-1.5707963267949460739 -1.239053544894946692e-13 1.5707963267949798247" />
<geometry>
<mesh filename="package:///caderapt1.stl"/>
</geometry>
</collision>
<visual>
<origin xyz="1.3877787807814456755e-17 6.9388939039072283776e-18 -0.023399999999999997191" rpy="-4.3984203539009321937e-19 -1.1950420445403110418e-31 2.6964675744201314301e-31" />
<geometry>
<mesh filename="package:///motorejeeje1.stl"/>
</geometry>
<material name="motorejeeje1_material">
<color rgba="0.64705882352941179736 0.64705882352941179736 0.64705882352941179736 1.0"/>
</material>
</visual>
<collision>
<origin xyz="1.3877787807814456755e-17 6.9388939039072283776e-18 -0.023399999999999997191" rpy="-4.3984203539009321937e-19 -1.1950420445403110418e-31 2.6964675744201314301e-31" />
<geometry>
<mesh filename="package:///motorejeeje1.stl"/>
</geometry>
</collision>
<inertial>
<origin xyz="0.0019229001328379975028 0.010041085604011099758 -0.023445491658507545962" rpy="0 0 0"/>
<mass value="0.36033150614011222324" />
<inertia ixx="0.00013063858229426611414" ixy="-1.449108314751825606e-07"  ixz="7.2430643625300497685e-08" iyy="7.1173611389541212129e-05" iyz="4.0050341053337675413e-08" izz="0.00010253850500590411905" />
</inertial>
</link>

<link name="femururdf">
<visual>
<origin xyz="6.0715321659188248304e-17 0.043745909016608408582 -0.046799999999999848665" rpy="3.1415926535897926719 -2.0840480976176791736e-16 -4.0457617713667614469e-19" />
<geometry>
<mesh filename="package:///femur.stl"/>
</geometry>
<material name="femur_material">
<color rgba="0.97254901960784312376 0.97254901960784312376 0.97254901960784312376 1.0"/>
</material>
</visual>
<collision>
<origin xyz="6.0715321659188248304e-17 0.043745909016608408582 -0.046799999999999848665" rpy="3.1415926535897926719 -2.0840480976176791736e-16 -4.0457617713667614469e-19" />
<geometry>
<mesh filename="package:///femur.stl"/>
</geometry>
</collision>
<visual>
<origin xyz="1.0408340855860842566e-17 0 -0.023399999999999858413" rpy="2.764407038239037761e-16 -1.207970909970583986e-15 -4.04578781191647265e-19" />
<geometry>
<mesh filename="package:///motorejeacopleeje2.stl"/>
</geometry>
<material name="motorejeacopleeje2_material">
<color rgba="0.64705882352941179736 0.64705882352941179736 0.64705882352941179736 1.0"/>
</material>
</visual>
<collision>
<origin xyz="1.0408340855860842566e-17 0 -0.023399999999999858413" rpy="2.764407038239037761e-16 -1.207970909970583986e-15 -4.04578781191647265e-19" />
<geometry>
<mesh filename="package:///motorejeacopleeje2.stl"/>
</geometry>
</collision>
<visual>
<origin xyz="5.2041704279304212832e-18 0.064999999999999974465 -0.023400000000000552303" rpy="-1.0449627922234391459e-14 -1.5057151911913531403e-14 3.141592653589793116" />
<geometry>
<mesh filename="package:///motorejeacopleeje1.stl"/>
</geometry>
<material name="motorejeacopleeje1_material">
<color rgba="0.64705882352941179736 0.64705882352941179736 0.64705882352941179736 1.0"/>
</material>
</visual>
<collision>
<origin xyz="5.2041704279304212832e-18 0.064999999999999974465 -0.023400000000000552303" rpy="-1.0449627922234391459e-14 -1.5057151911913531403e-14 3.141592653589793116" />
<geometry>
<mesh filename="package:///motorejeacopleeje1.stl"/>
</geometry>
</collision>
<visual>
<origin xyz="2.7755575615628913511e-17 0 -0.023399999999999934741" rpy="4.0974296236180807348e-16 4.0203680924569909457e-16 -4.0455404266942114055e-19" />
<geometry>
<mesh filename="package:///motorejeacoplecaja.stl"/>
</geometry>
<material name="motorejeacoplecaja_material">
<color rgba="0.26274509803921569651 0.28235294117647058432 0.30196078431372547213 1.0"/>
</material>
</visual>
<collision>
<origin xyz="2.7755575615628913511e-17 0 -0.023399999999999934741" rpy="4.0974296236180807348e-16 4.0203680924569909457e-16 -4.0455404266942114055e-19" />
<geometry>
<mesh filename="package:///motorejeacoplecaja.stl"/>
</geometry>
</collision>
<visual>
<origin xyz="6.9388939039072283776e-18 0.064999999999999974465 -0.023399999999999823719" rpy="-2.6889756938302240474e-16 -1.9187315498319730585e-15 -3.141592653589793116" />
<geometry>
<mesh filename="package:///motorejeacopleeje2.stl"/>
</geometry>
<material name="motorejeacopleeje2_material">
<color rgba="0.64705882352941179736 0.64705882352941179736 0.64705882352941179736 1.0"/>
</material>
</visual>
<collision>
<origin xyz="6.9388939039072283776e-18 0.064999999999999974465 -0.023399999999999823719" rpy="-2.6889756938302240474e-16 -1.9187315498319730585e-15 -3.141592653589793116" />
<geometry>
<mesh filename="package:///motorejeacopleeje2.stl"/>
</geometry>
</collision>
<visual>
<origin xyz="5.2041704279304212832e-18 0.043745909016608408582 0.0019999999999999774902" rpy="3.1415926535897926719 -2.0840480976176791736e-16 -4.0457617713667614469e-19" />
<geometry>
<mesh filename="package:///femur.stl"/>
</geometry>
<material name="femur_material">
<color rgba="0.97254901960784312376 0.97254901960784312376 0.97254901960784312376 1.0"/>
</material>
</visual>
<collision>
<origin xyz="5.2041704279304212832e-18 0.043745909016608408582 0.0019999999999999774902" rpy="3.1415926535897926719 -2.0840480976176791736e-16 -4.0457617713667614469e-19" />
<geometry>
<mesh filename="package:///femur.stl"/>
</geometry>
</collision>
<visual>
<origin xyz="3.4694469519536141888e-18 0.064999999999999974465 -0.023399999999999900047" rpy="7.0788903078001232964e-17 -3.5453557477156813396e-15 3.141592653589793116" />
<geometry>
<mesh filename="package:///motorejeacoplecaja.stl"/>
</geometry>
<material name="motorejeacoplecaja_material">
<color rgba="0.26274509803921569651 0.28235294117647058432 0.30196078431372547213 1.0"/>
</material>
</visual>
<collision>
<origin xyz="3.4694469519536141888e-18 0.064999999999999974465 -0.023399999999999900047" rpy="7.0788903078001232964e-17 -3.5453557477156813396e-15 3.141592653589793116" />
<geometry>
<mesh filename="package:///motorejeacoplecaja.stl"/>
</geometry>
</collision>
<visual>
<origin xyz="1.7347234759768070944e-18 0 -0.023399999999999997191" rpy="5.362715301382675617e-21 3.5968323535784168144e-18 -4.0457487510919058453e-19" />
<geometry>
<mesh filename="package:///motorejeacopleeje1.stl"/>
</geometry>
<material name="motorejeacopleeje1_material">
<color rgba="0.64705882352941179736 0.64705882352941179736 0.64705882352941179736 1.0"/>
</material>
</visual>
<collision>
<origin xyz="1.7347234759768070944e-18 0 -0.023399999999999997191" rpy="5.362715301382675617e-21 3.5968323535784168144e-18 -4.0457487510919058453e-19" />
<geometry>
<mesh filename="package:///motorejeacopleeje1.stl"/>
</geometry>
</collision>
<inertial>
<origin xyz="1.5258049116074493477e-17 0.032499999999999987232 -0.023399999999999913924" rpy="0 0 0"/>
<mass value="0.53868761965446410045" />
<inertia ixx="0.00043791203235393451809" ixy="1.1528547013930489823e-19"  ixz="-2.721397447819416252e-19" iyy="0.00010909446328561569063" iyz="-2.0328790734103208138e-19" izz="0.00036348717125268495019" />
</inertial>
</link>

<link name="tibiaurdf">
<visual>
<origin xyz="-0.047631397208144132804 0.027500000000000024425 0.023400000000000000661" rpy="-3.141592653589793116 2.2177729580020338945e-16 1.0471975511965978534" />
<geometry>
<mesh filename="package:///motorejeacopleeje2.stl"/>
</geometry>
<material name="motorejeacopleeje2_material">
<color rgba="0.64705882352941179736 0.64705882352941179736 0.64705882352941179736 1.0"/>
</material>
</visual>
<collision>
<origin xyz="-0.047631397208144132804 0.027500000000000024425 0.023400000000000000661" rpy="-3.141592653589793116 2.2177729580020338945e-16 1.0471975511965978534" />
<geometry>
<mesh filename="package:///motorejeacopleeje2.stl"/>
</geometry>
</collision>
<visual>
<origin xyz="-0.04763139720814416056 0.027499999999999996669 0.023400000000000000661" rpy="3.141592653589793116 -2.6730912487010992942e-19 1.0471975511965974093" />
<geometry>
<mesh filename="package:///motorejeacopleeje1.stl"/>
</geometry>
<material name="motorejeacopleeje1_material">
<color rgba="0.64705882352941179736 0.64705882352941179736 0.64705882352941179736 1.0"/>
</material>
</visual>
<collision>
<origin xyz="-0.04763139720814416056 0.027499999999999996669 0.023400000000000000661" rpy="3.141592653589793116 -2.6730912487010992942e-19 1.0471975511965974093" />
<geometry>
<mesh filename="package:///motorejeacopleeje1.stl"/>
</geometry>
</collision>
<visual>
<origin xyz="-0.029224814482181143971 0.016872954508304185972 0.048800000000000010036" rpy="-3.141592653589793116 -5.1368237582615621572e-18 1.0471975511965974093" />
<geometry>
<mesh filename="package:///tibia.stl"/>
</geometry>
<material name="tibia_material">
<color rgba="0.97254901960784312376 0.97254901960784312376 0.97254901960784312376 1.0"/>
</material>
</visual>
<collision>
<origin xyz="-0.029224814482181143971 0.016872954508304185972 0.048800000000000010036" rpy="-3.141592653589793116 -5.1368237582615621572e-18 1.0471975511965974093" />
<geometry>
<mesh filename="package:///tibia.stl"/>
</geometry>
</collision>
<visual>
<origin xyz="-0.029224814482181227238 0.016872954508304172094 -3.4694469519536141888e-18" rpy="-3.141592653589793116 -2.6730912485641724159e-19 1.0471975511965976313" />
<geometry>
<mesh filename="package:///tibia.stl"/>
</geometry>
<material name="tibia_material">
<color rgba="0.97254901960784312376 0.97254901960784312376 0.97254901960784312376 1.0"/>
</material>
</visual>
<collision>
<origin xyz="-0.029224814482181227238 0.016872954508304172094 -3.4694469519536141888e-18" rpy="-3.141592653589793116 -2.6730912485641724159e-19 1.0471975511965976313" />
<geometry>
<mesh filename="package:///tibia.stl"/>
</geometry>
</collision>
<visual>
<origin xyz="-0.047631397208144105049 0.027499999999999982792 0.023400000000000000661" rpy="-3.141592653589793116 -2.1987715673321477986e-16 1.0471975511965974093" />
<geometry>
<mesh filename="package:///motorejeacoplecaja.stl"/>
</geometry>
<material name="motorejeacoplecaja_material">
<color rgba="0.26274509803921569651 0.28235294117647058432 0.30196078431372547213 1.0"/>
</material>
</visual>
<collision>
<origin xyz="-0.047631397208144105049 0.027499999999999982792 0.023400000000000000661" rpy="-3.141592653589793116 -2.1987715673321477986e-16 1.0471975511965974093" />
<geometry>
<mesh filename="package:///motorejeacoplecaja.stl"/>
</geometry>
</collision>
<inertial>
<origin xyz="-0.037185466647235390636 0.021469039178648834099 0.023400000000000000661" rpy="0 0 0"/>
<mass value="0.28552673687099017208" />
<inertia ixx="7.7012953898987848451e-05" ixy="2.1231284255097823487e-05"  ixz="-3.1719353279142159606e-20" iyy="0.00010152872925693647564" iyz="7.6362593266127131523e-21" izz="6.7501897454918529545e-05" />
</inertial>
</link>

<link name="tobillourdf">
<visual>
<origin xyz="-0.00014999999999898080971 0.035799999999999609912 0.023725000000000155687" rpy="1.5707963267948970021 1.5707963267948930053 0" />
<geometry>
<mesh filename="package:///tobillopt3_2.stl"/>
</geometry>
<material name="tobillopt3_2_material">
<color rgba="0.97254901960784312376 0.97254901960784312376 0.97254901960784312376 1.0"/>
</material>
</visual>
<collision>
<origin xyz="-0.00014999999999898080971 0.035799999999999609912 0.023725000000000155687" rpy="1.5707963267948970021 1.5707963267948930053 0" />
<geometry>
<mesh filename="package:///tobillopt3_2.stl"/>
</geometry>
</collision>
<visual>
<origin xyz="2.792904796322659422e-16 0.035799999999999942979 0.023550000000000070877" rpy="1.570796326794896558 1.570796326794896558 0" />
<geometry>
<mesh filename="package:///tobillopt1.stl"/>
</geometry>
<material name="tobillopt1_material">
<color rgba="0.97254901960784312376 0.97254901960784312376 0.97254901960784312376 1.0"/>
</material>
</visual>
<collision>
<origin xyz="2.792904796322659422e-16 0.035799999999999942979 0.023550000000000070877" rpy="1.570796326794896558 1.570796326794896558 0" />
<geometry>
<mesh filename="package:///tobillopt1.stl"/>
</geometry>
</collision>
<visual>
<origin xyz="0.00020000000000116278931 0.025772450770436605705 0.033535984972323705511" rpy="-1.5707963267948945596 -1.0093010815574408739e-13 -1.5707963267947000485" />
<geometry>
<mesh filename="package:///motorejecaja.stl"/>
</geometry>
<material name="motorejecaja_material">
<color rgba="0.26274509803921569651 0.28235294117647058432 0.30196078431372547213 1.0"/>
</material>
</visual>
<collision>
<origin xyz="0.00020000000000116278931 0.025772450770436605705 0.033535984972323705511" rpy="-1.5707963267948945596 -1.0093010815574408739e-13 -1.5707963267947000485" />
<geometry>
<mesh filename="package:///motorejecaja.stl"/>
</geometry>
</collision>
<visual>
<origin xyz="0.00020000000000116278931 0.025772450770436605705 0.033535984972323705511" rpy="-1.5707963267948956698 -1.0092243850574784271e-13 -1.5707963267947007147" />
<geometry>
<mesh filename="package:///motorejeeje2.stl"/>
</geometry>
<material name="motorejeeje2_material">
<color rgba="0.64705882352941179736 0.64705882352941179736 0.64705882352941179736 1.0"/>
</material>
</visual>
<collision>
<origin xyz="0.00020000000000116278931 0.025772450770436605705 0.033535984972323705511" rpy="-1.5707963267948956698 -1.0092243850574784271e-13 -1.5707963267947007147" />
<geometry>
<mesh filename="package:///motorejeeje2.stl"/>
</geometry>
</collision>
<visual>
<origin xyz="0.00015000000000088727081 0.035799999999999554401 0.023725000000000287526" rpy="1.570796326794896558 1.570796326794896558 0" />
<geometry>
<mesh filename="package:///tobillopt3_1.stl"/>
</geometry>
<material name="tobillopt3_1_material">
<color rgba="0.97254901960784312376 0.97254901960784312376 0.97254901960784312376 1.0"/>
</material>
</visual>
<collision>
<origin xyz="0.00015000000000088727081 0.035799999999999554401 0.023725000000000287526" rpy="1.570796326794896558 1.570796326794896558 0" />
<geometry>
<mesh filename="package:///tobillopt3_1.stl"/>
</geometry>
</collision>
<visual>
<origin xyz="0.00020000000000116278931 0.025772450770436605705 0.033535984972323705511" rpy="-1.5707963267948950037 -1.0293341534480637505e-13 -1.5707963267947000485" />
<geometry>
<mesh filename="package:///motorejeeje1.stl"/>
</geometry>
<material name="motorejeeje1_material">
<color rgba="0.64705882352941179736 0.64705882352941179736 0.64705882352941179736 1.0"/>
</material>
</visual>
<collision>
<origin xyz="0.00020000000000116278931 0.025772450770436605705 0.033535984972323705511" rpy="-1.5707963267948950037 -1.0293341534480637505e-13 -1.5707963267947000485" />
<geometry>
<mesh filename="package:///motorejeeje1.stl"/>
</geometry>
</collision>
<visual>
<origin xyz="2.7755575615628913511e-16 0.035799999999999942979 0.023850000000000259881" rpy="1.570796326794896558 1.570796326794896558 0" />
<geometry>
<mesh filename="package:///tobillopt2_1.stl"/>
</geometry>
<material name="tobillopt2_1_material">
<color rgba="0.97254901960784312376 0.97254901960784312376 0.97254901960784312376 1.0"/>
</material>
</visual>
<collision>
<origin xyz="2.7755575615628913511e-16 0.035799999999999942979 0.023850000000000259881" rpy="1.570796326794896558 1.570796326794896558 0" />
<geometry>
<mesh filename="package:///tobillopt2_1.stl"/>
</geometry>
</collision>
<visual>
<origin xyz="0 0.03579999999999999849 0.023250000000000006772" rpy="1.570796326794896558 1.570796326794896558 0" />
<geometry>
<mesh filename="package:///tobillopt2_2.stl"/>
</geometry>
<material name="tobillopt2_2_material">
<color rgba="0.97254901960784312376 0.97254901960784312376 0.97254901960784312376 1.0"/>
</material>
</visual>
<collision>
<origin xyz="0 0.03579999999999999849 0.023250000000000006772" rpy="1.570796326794896558 1.570796326794896558 0" />
<geometry>
<mesh filename="package:///tobillopt2_2.stl"/>
</geometry>
</collision>
<inertial>
<origin xyz="0.00013965747905249169388 0.025656106121455229258 0.023411667663061574984" rpy="0 0 0"/>
<mass value="0.35953278469495453251" />
<inertia ixx="0.00010180132077840609928" ixy="-5.8418326180033741501e-09"  ixz="-5.7602954082392663227e-08" iyy="0.00013007031479290851643" iyz="5.2659589177188946581e-07" izz="7.0605342570129184178e-05" />
</inertial>
</link>

<link name="pieurdf">
<visual>
<origin xyz="-0.010000000000000093883 0.019000000000000127898 0.023500000000000811906" rpy="1.570796326794896558 1.570796326794896336 0" />
<geometry>
<mesh filename="package:///acoplepiemotor.stl"/>
</geometry>
<material name="acoplepiemotor_material">
<color rgba="0.97254901960784312376 0.97254901960784312376 0.97254901960784312376 1.0"/>
</material>
</visual>
<collision>
<origin xyz="-0.010000000000000093883 0.019000000000000127898 0.023500000000000811906" rpy="1.570796326794896558 1.570796326794896336 0" />
<geometry>
<mesh filename="package:///acoplepiemotor.stl"/>
</geometry>
</collision>
<visual>
<origin xyz="-0.010000000000000024494 0.019000000000000016875 0.02340000000000000413" rpy="1.570796326794896558 1.570796326794896336 0" />
<geometry>
<mesh filename="package:///acoplepiemotor.stl"/>
</geometry>
<material name="acoplepiemotor_material">
<color rgba="0.97254901960784312376 0.97254901960784312376 0.97254901960784312376 1.0"/>
</material>
</visual>
<collision>
<origin xyz="-0.010000000000000024494 0.019000000000000016875 0.02340000000000000413" rpy="1.570796326794896558 1.570796326794896336 0" />
<geometry>
<mesh filename="package:///acoplepiemotor.stl"/>
</geometry>
</collision>
<visual>
<origin xyz="-0.0099999999999997746941 0.018949999999999855849 0.023450000000000428835" rpy="1.570796326794896558 1.570796326794896336 0" />
<geometry>
<mesh filename="package:///plantapie.stl"/>
</geometry>
<material name="plantapie_material">
<color rgba="0.97254901960784312376 0.97254901960784312376 0.97254901960784312376 1.0"/>
</material>
</visual>
<collision>
<origin xyz="-0.0099999999999997746941 0.018949999999999855849 0.023450000000000428835" rpy="1.570796326794896558 1.570796326794896336 0" />
<geometry>
<mesh filename="package:///plantapie.stl"/>
</geometry>
</collision>
<inertial>
<origin xyz="-0.0095981962877159845288 0.01899481581890252388 0.023450000000000425365" rpy="0 0 0"/>
<mass value="0.12193030814742024381" />
<inertia ixx="5.5790028401553616827e-05" ixy="1.0383957421083171903e-06"  ixz="1.8720653962812058855e-20" iyy="7.8275338616851577599e-05" iyz="-3.6426895224374301369e-20" izz="3.3440055653628751055e-05" />
</inertial>
</link>

<joint name="LeftAnkle2" type="revolute">
<origin xyz="0.023600000000001168654 0.02577245077044121313 0.033535984972323733266" rpy="-1.5707963267949103248 -1.458647397724844641 1.5707963267951052799" />
<parent link="tobillourdf" />
<child link="pieurdf" />
<axis xyz="0 0 1"/>
<limit effort="1" velocity="20" lower="-0.26179938779914940783" upper="0.26179938779914940783"/>
<joint_properties friction="0.0"/>
</joint>

<joint name="LeftAnkle1" type="revolute">
<origin xyz="-0.047631397208144216071 0.027499999999999982792 0.046800000000000036016" rpy="3.141592653589793116 -3.3493042203660128646e-16 -2.0943951023931943745" />
<parent link="tibiaurdf" />
<child link="tobillourdf" />
<axis xyz="0 0 1"/>
<limit effort="1" velocity="20" lower="-0.785398163397448279" upper="0.785398163397448279"/>
<joint_properties friction="0.0"/>
</joint>

<joint name="LeftKnee" type="revolute">
<origin xyz="8.1532003370909933437e-17 0.064999999999999891198 1.561251128379126385e-16" rpy="3.1415926535897922278 -7.3910170491445287467e-16 -2.0943951023931952626" />
<parent link="femururdf" />
<child link="tibiaurdf" />
<axis xyz="0 0 1"/>
<limit effort="1" velocity="20" lower="-1.0471975511965976313" upper="1.0471975511965976313"/>
<joint_properties friction="0.0"/>
</joint>

<joint name="LeftHip2" type="revolute">
<origin xyz="0.02802754922956399164 -0.014064015027681252279 -0.023550000000000497619" rpy="1.5707963268454843142 1.5683459094928371425 5.0356913078067518828e-11" />
<parent link="cadera_v01" />
<child link="femururdf" />
<axis xyz="0 0 1"/>
<limit effort="1" velocity="20" lower="-1.570796326794896558" upper="1.570796326794896558"/>
<joint_properties friction="0.0"/>
</joint>

<joint name="LeftHip1" type="revolute">
<origin xyz="0.0006194931750873496068 0.032685236218794766483 -0.023605436102933349818" rpy="-0.7853981633975747334 1.5707963267948947816 0" />
<parent link="cintura_v01" />
<child link="cadera_v01" />
<axis xyz="0 0 1"/>
<limit effort="1" velocity="20" lower="-0.785398163397448279" upper="0.785398163397448279"/>
<joint_properties friction="0.0"/>
</joint>

<joint name="LeftWaist" type="revolute">
<origin xyz="0.019257018009984729068 0.0083712188771943168986 -0.083178910040700979045" rpy="1.2791997842974976649e-19 8.2453707267879112331e-20 -2.3781265927246031389" />
<parent link="torsourdf" />
<child link="cintura_v01" />
<axis xyz="0 0 1"/>
<limit effort="1" velocity="20" lower="-1.570796326794896558" upper="1.570796326794896558"/>
<joint_properties friction="0.0"/>
</joint>

<link name="hombro-brazo_2">
<visual>
<origin xyz="-1.1449174941446926823e-16 0.010999809727072717286 0" rpy="3.0423430958599903309e-32 -5.2989295050620434327e-34 -4.0926011306615500854e-33" />
<geometry>
<mesh filename="package:///hombro_brazo1.stl"/>
</geometry>
<material name="hombro_brazo1_material">
<color rgba="0.97254901960784312376 0.97254901960784312376 0.97254901960784312376 1.0"/>
</material>
</visual>
<collision>
<origin xyz="-1.1449174941446926823e-16 0.010999809727072717286 0" rpy="3.0423430958599903309e-32 -5.2989295050620434327e-34 -4.0926011306615500854e-33" />
<geometry>
<mesh filename="package:///hombro_brazo1.stl"/>
</geometry>
</collision>
<visual>
<origin xyz="0.00029999999999985333538 0.010999809727072842186 -0.001999999999999960143" rpy="3.4416913763379651594e-15 4.6629367034255091639e-15 1.6819922191157922558e-13" />
<geometry>
<mesh filename="package:///hombro_brazo2.stl"/>
</geometry>
<material name="hombro_brazo2_material">
<color rgba="0.97254901960784312376 0.97254901960784312376 0.97254901960784312376 1.0"/>
</material>
</visual>
<collision>
<origin xyz="0.00029999999999985333538 0.010999809727072842186 -0.001999999999999960143" rpy="3.4416913763379651594e-15 4.6629367034255091639e-15 1.6819922191157922558e-13" />
<geometry>
<mesh filename="package:///hombro_brazo2.stl"/>
</geometry>
</collision>
<visual>
<origin xyz="-0.00029999999999145467167 -0.011000190272921067658 -0.0020000000000004042322" rpy="9.1038288019263151859e-15 2.0761170560490714451e-14 -3.1415926535894769245" />
<geometry>
<mesh filename="package:///hombro_brazo2.stl"/>
</geometry>
<material name="hombro_brazo2_material">
<color rgba="0.97254901960784312376 0.97254901960784312376 0.97254901960784312376 1.0"/>
</material>
</visual>
<collision>
<origin xyz="-0.00029999999999145467167 -0.011000190272921067658 -0.0020000000000004042322" rpy="9.1038288019263151859e-15 2.0761170560490714451e-14 -3.1415926535894769245" />
<geometry>
<mesh filename="package:///hombro_brazo2.stl"/>
</geometry>
</collision>
<inertial>
<origin xyz="1.6899703994685637881e-15 -1.1044824278885073236e-07 0.0056081599888875384094" rpy="0 0 0"/>
<mass value="0.028276359613946901173" />
<inertia ixx="3.1909882339228919581e-06" ixy="-7.6383436528517661012e-11"  ixz="-4.5273911030742353123e-19" iyy="1.3925926827987622581e-05" iyz="1.4915617865722697473e-11" izz="1.2743353645780319914e-05" />
</inertial>
</link>

<link name="brazourdf_2">
<visual>
<origin xyz="0 0 -0.023400000000000000661" rpy="1.8806818552538889383e-30 -2.3576385711398787497e-29 1.570796326794896558" />
<geometry>
<mesh filename="package:///motorejeacopleeje1.stl"/>
</geometry>
<material name="motorejeacopleeje1_material">
<color rgba="0.64705882352941179736 0.64705882352941179736 0.64705882352941179736 1.0"/>
</material>
</visual>
<collision>
<origin xyz="0 0 -0.023400000000000000661" rpy="1.8806818552538889383e-30 -2.3576385711398787497e-29 1.570796326794896558" />
<geometry>
<mesh filename="package:///motorejeacopleeje1.stl"/>
</geometry>
</collision>
<visual>
<origin xyz="-0.029999999999999915623 -3.4694469519536141888e-18 -0.023399999999999997191" rpy="1.5707963267948970021 3.3306690739421194931e-16 1.5707963267948972241" />
<geometry>
<mesh filename="package:///brazo.stl"/>
</geometry>
<material name="brazo_material">
<color rgba="0.97254901960784312376 0.97254901960784312376 0.97254901960784312376 1.0"/>
</material>
</visual>
<collision>
<origin xyz="-0.029999999999999915623 -3.4694469519536141888e-18 -0.023399999999999997191" rpy="1.5707963267948970021 3.3306690739421194931e-16 1.5707963267948972241" />
<geometry>
<mesh filename="package:///brazo.stl"/>
</geometry>
</collision>
<visual>
<origin xyz="0 0 -0.023400000000000000661" rpy="5.6354964637312311918e-28 4.7796026711870344834e-28 1.570796326794896558" />
<geometry>
<mesh filename="package:///motorejeacoplecaja.stl"/>
</geometry>
<material name="motorejeacoplecaja_material">
<color rgba="0.26274509803921569651 0.28235294117647058432 0.30196078431372547213 1.0"/>
</material>
</visual>
<collision>
<origin xyz="0 0 -0.023400000000000000661" rpy="5.6354964637312311918e-28 4.7796026711870344834e-28 1.570796326794896558" />
<geometry>
<mesh filename="package:///motorejeacoplecaja.stl"/>
</geometry>
</collision>
<visual>
<origin xyz="0 0 -0.023400000000000000661" rpy="2.1329540445451286226e-28 7.7397810156890723595e-29 1.570796326794896558" />
<geometry>
<mesh filename="package:///motorejeacopleeje2.stl"/>
</geometry>
<material name="motorejeacopleeje2_material">
<color rgba="0.64705882352941179736 0.64705882352941179736 0.64705882352941179736 1.0"/>
</material>
</visual>
<collision>
<origin xyz="0 0 -0.023400000000000000661" rpy="2.1329540445451286226e-28 7.7397810156890723595e-29 1.570796326794896558" />
<geometry>
<mesh filename="package:///motorejeacopleeje2.stl"/>
</geometry>
</collision>
<inertial>
<origin xyz="-0.064612740306650165434 0.00024409654353026510941 -0.023399999587718614547" rpy="0 0 0"/>
<mass value="1.080760232398511711" />
<inertia ixx="0.00022953897767025085172" ixy="2.1146337854861604216e-05"  ixz="-1.3608742167962309053e-10" iyy="0.002471086917382017082" iyz="-1.0815340757903505439e-11" izz="0.0023133411907278614641" />
</inertial>
</link>

<joint name="RightShoulder2" type="revolute">
<origin xyz="-0.023549999999995352429 -3.8054585540028829094e-07 0.018946406845602128954" rpy="3.1415926535894787008 1.5707963267948730213 0" />
<parent link="hombro-brazo_2" />
<child link="brazourdf_2" />
<axis xyz="0 0 1"/>
<limit effort="1" velocity="20" lower="-1.570796326794896558" upper="1.570796326794896558"/>
<joint_properties friction="0.0"/>
</joint>

<joint name="RightShoulder1" type="revolute">
<origin xyz="-0.085191785003578324176 0.0073712188771942856527 0.025468521028911415838" rpy="1.57079632679489678 -2.222614453594627363e-16 -1.57079632679489678" />
<parent link="torsourdf" />
<child link="hombro-brazo_2" />
<axis xyz="0 0 1"/>
<limit effort="1" velocity="20" lower="-1.570796326794896558" upper="1.570796326794896558"/>
<joint_properties friction="0.0"/>
</joint>

<link name="cintura_v01_2">
<visual>
<origin xyz="-0.00021213203435596628132 0.00021213203435591597434 -0.0020000000000000017764" rpy="3.141592653589793116 -4.930380657631292583e-32 -0.78539816339744739082" />
<geometry>
<mesh filename="package:///cinturapt2_1.stl"/>
</geometry>
<material name="cinturapt2_1_material">
<color rgba="0.97254901960784312376 0.97254901960784312376 0.97254901960784312376 1.0"/>
</material>
</visual>
<collision>
<origin xyz="-0.00021213203435596628132 0.00021213203435591597434 -0.0020000000000000017764" rpy="3.141592653589793116 -4.930380657631292583e-32 -0.78539816339744739082" />
<geometry>
<mesh filename="package:///cinturapt2_1.stl"/>
</geometry>
</collision>
<visual>
<origin xyz="1.7347234759768070944e-18 -2.168404344971008868e-19 -0.0020000000000000017764" rpy="-3.141592653589793116 9.3033813900781694918e-47 -0.785398163397448279" />
<geometry>
<mesh filename="package:///cinturapt1.stl"/>
</geometry>
<material name="cinturapt1_material">
<color rgba="0.97254901960784312376 0.97254901960784312376 0.97254901960784312376 1.0"/>
</material>
</visual>
<collision>
<origin xyz="1.7347234759768070944e-18 -2.168404344971008868e-19 -0.0020000000000000017764" rpy="-3.141592653589793116 9.3033813900781694918e-47 -0.785398163397448279" />
<geometry>
<mesh filename="package:///cinturapt1.stl"/>
</geometry>
</collision>
<visual>
<origin xyz="0.00021213203435592291324 -0.00021213203435592985213 -0.0020000000000000017764" rpy="3.141592653589793116 -4.930380657631292583e-32 -0.78539816339744739082" />
<geometry>
<mesh filename="package:///cinturapt2_2.stl"/>
</geometry>
<material name="cinturapt2_2_material">
<color rgba="0.97254901960784312376 0.97254901960784312376 0.97254901960784312376 1.0"/>
</material>
</visual>
<collision>
<origin xyz="0.00021213203435592291324 -0.00021213203435592985213 -0.0020000000000000017764" rpy="3.141592653589793116 -4.930380657631292583e-32 -0.78539816339744739082" />
<geometry>
<mesh filename="package:///cinturapt2_2.stl"/>
</geometry>
</collision>
<inertial>
<origin xyz="0.0079316365006479611771 0.0079316365006480409744 -0.0083693257381815665957" rpy="0 0 0"/>
<mass value="0.032703197933895256089" />
<inertia ixx="1.1474475218213225821e-05" ixy="5.2475239690138805065e-06"  ixz="1.4935382828704681588e-06" iyy="1.1474475218213239374e-05" iyz="1.4935382828704745116e-06" izz="1.7093428062395002849e-05" />
</inertial>
</link>

<link name="cadera_v01_2">
<visual>
<origin xyz="0.010027549229562462973 -0.0094859849723193043203 -0.023250000000000048406" rpy="1.5707963267949289765 -1.5663961579343559987e-14 -1.5707963267948827912" />
<geometry>
<mesh filename="package:///caderapt1.stl"/>
</geometry>
<material name="caderapt1_material">
<color rgba="0.97254901960784312376 0.97254901960784312376 0.97254901960784312376 1.0"/>
</material>
</visual>
<collision>
<origin xyz="0.010027549229562462973 -0.0094859849723193043203 -0.023250000000000048406" rpy="1.5707963267949289765 -1.5663961579343559987e-14 -1.5707963267948827912" />
<geometry>
<mesh filename="package:///caderapt1.stl"/>
</geometry>
</collision>
<visual>
<origin xyz="0.010027549229562185418 -0.0091859849723193512383 -0.023250000000000090039" rpy="1.5707963267949289765 -1.5663961579343559987e-14 -1.5707963267948827912" />
<geometry>
<mesh filename="package:///caderapt2_1.stl"/>
</geometry>
<material name="caderapt2_1_material">
<color rgba="0.97254901960784312376 0.97254901960784312376 0.97254901960784312376 1.0"/>
</material>
</visual>
<collision>
<origin xyz="0.010027549229562185418 -0.0091859849723193512383 -0.023250000000000090039" rpy="1.5707963267949289765 -1.5663961579343559987e-14 -1.5707963267948827912" />
<geometry>
<mesh filename="package:///caderapt2_1.stl"/>
</geometry>
</collision>
<visual>
<origin xyz="0.010027549229562240929 -0.0098109849723194697546 -0.023350000000000127598" rpy="1.5707963267949291986 -1.4735894692372500414e-14 -1.5707963267948830133" />
<geometry>
<mesh filename="package:///caderapt3_2.stl"/>
</geometry>
<material name="caderapt3_2_material">
<color rgba="0.97254901960784312376 0.97254901960784312376 0.97254901960784312376 1.0"/>
</material>
</visual>
<collision>
<origin xyz="0.010027549229562240929 -0.0098109849723194697546 -0.023350000000000127598" rpy="1.5707963267949291986 -1.4735894692372500414e-14 -1.5707963267948830133" />
<geometry>
<mesh filename="package:///caderapt3_2.stl"/>
</geometry>
</collision>
<visual>
<origin xyz="8.3266726846886740532e-17 -1.5265566588595902431e-16 -0.023399999999999983313" rpy="-3.141592653589793116 5.1028004907220370093e-16 -3.5327080320387570993e-16" />
<geometry>
<mesh filename="package:///motorejecaja.stl"/>
</geometry>
<material name="motorejecaja_material">
<color rgba="0.26274509803921569651 0.28235294117647058432 0.30196078431372547213 1.0"/>
</material>
</visual>
<collision>
<origin xyz="8.3266726846886740532e-17 -1.5265566588595902431e-16 -0.023399999999999983313" rpy="-3.141592653589793116 5.1028004907220370093e-16 -3.5327080320387570993e-16" />
<geometry>
<mesh filename="package:///motorejecaja.stl"/>
</geometry>
</collision>
<visual>
<origin xyz="-1.3877787807814456755e-17 0 -0.02340000000000000413" rpy="3.141592653589793116 6.6137023663277862663e-31 -7.2879673669429114232e-32" />
<geometry>
<mesh filename="package:///motorejeeje2.stl"/>
</geometry>
<material name="motorejeeje2_material">
<color rgba="0.64705882352941179736 0.64705882352941179736 0.64705882352941179736 1.0"/>
</material>
</visual>
<collision>
<origin xyz="-1.3877787807814456755e-17 0 -0.02340000000000000413" rpy="3.141592653589793116 6.6137023663277862663e-31 -7.2879673669429114232e-32" />
<geometry>
<mesh filename="package:///motorejeeje2.stl"/>
</geometry>
</collision>
<visual>
<origin xyz="-1.3877787807814456755e-17 0 -0.02340000000000000413" rpy="3.141592653589793116 8.2429854080898925333e-16 1.1775693440123706926e-16" />
<geometry>
<mesh filename="package:///motorejeeje1.stl"/>
</geometry>
<material name="motorejeeje1_material">
<color rgba="0.64705882352941179736 0.64705882352941179736 0.64705882352941179736 1.0"/>
</material>
</visual>
<collision>
<origin xyz="-1.3877787807814456755e-17 0 -0.02340000000000000413" rpy="3.141592653589793116 8.2429854080898925333e-16 1.1775693440123706926e-16" />
<geometry>
<mesh filename="package:///motorejeeje1.stl"/>
</geometry>
</collision>
<visual>
<origin xyz="0.010027549229562157662 -0.0097859849723192157689 -0.023250000000000093509" rpy="1.5707963267949291986 -1.4735894692372500414e-14 -1.5707963267948830133" />
<geometry>
<mesh filename="package:///caderapt2_2.stl"/>
</geometry>
<material name="caderapt2_2_material">
<color rgba="0.97254901960784312376 0.97254901960784312376 0.97254901960784312376 1.0"/>
</material>
</visual>
<collision>
<origin xyz="0.010027549229562157662 -0.0097859849723192157689 -0.023250000000000093509" rpy="1.5707963267949291986 -1.4735894692372500414e-14 -1.5707963267948830133" />
<geometry>
<mesh filename="package:///caderapt2_2.stl"/>
</geometry>
</collision>
<visual>
<origin xyz="0.010027549229562310318 -0.0098109849723193448545 -0.023150000000000038602" rpy="1.5707963267949298647 -1.4072370239894064944e-14 -1.5707963267949027752" />
<geometry>
<mesh filename="package:///caderapt3_1.stl"/>
</geometry>
<material name="caderapt3_1_material">
<color rgba="0.97254901960784312376 0.97254901960784312376 0.97254901960784312376 1.0"/>
</material>
</visual>
<collision>
<origin xyz="0.010027549229562310318 -0.0098109849723193448545 -0.023150000000000038602" rpy="1.5707963267949298647 -1.4072370239894064944e-14 -1.5707963267949027752" />
<geometry>
<mesh filename="package:///caderapt3_1.stl"/>
</geometry>
</collision>
<inertial>
<origin xyz="0.0019229001328381740109 -0.010041085604011925486 -0.023354508341491986984" rpy="0 0 0"/>
<mass value="0.36033150614011227875" />
<inertia ixx="0.00013063858229426779465" ixy="1.4491083147986162354e-07"  ixz="-7.2430643625583486099e-08" iyy="7.1173611389541496732e-05" iyz="4.0050341058351263427e-08" izz="0.00010253850500590584022" />
</inertial>
</link>

<link name="femururdf_2">
<visual>
<origin xyz="1.7347234759768070944e-18 0 -0.023400000000000011069" rpy="-3.141592653589793116 -1.1101267587731189653e-18 -4.2107675405146614509e-31" />
<geometry>
<mesh filename="package:///motorejeacopleeje2.stl"/>
</geometry>
<material name="motorejeacopleeje2_material">
<color rgba="0.64705882352941179736 0.64705882352941179736 0.64705882352941179736 1.0"/>
</material>
</visual>
<collision>
<origin xyz="1.7347234759768070944e-18 0 -0.023400000000000011069" rpy="-3.141592653589793116 -1.1101267587731189653e-18 -4.2107675405146614509e-31" />
<geometry>
<mesh filename="package:///motorejeacopleeje2.stl"/>
</geometry>
</collision>
<visual>
<origin xyz="-2.4633073358870660741e-16 0 -0.023400000000000246991" rpy="-3.1415926535897860106 1.3958213121289124443e-14 1.9455059616131085975e-30" />
<geometry>
<mesh filename="package:///motorejeacopleeje1.stl"/>
</geometry>
<material name="motorejeacopleeje1_material">
<color rgba="0.64705882352941179736 0.64705882352941179736 0.64705882352941179736 1.0"/>
</material>
</visual>
<collision>
<origin xyz="-2.4633073358870660741e-16 0 -0.023400000000000246991" rpy="-3.1415926535897860106 1.3958213121289124443e-14 1.9455059616131085975e-30" />
<geometry>
<mesh filename="package:///motorejeacopleeje1.stl"/>
</geometry>
</collision>
<visual>
<origin xyz="-4.6837533851373791549e-17 -0.065000000000000474065 -0.023400000000001031086" rpy="3.1415926535897851224 -9.072888763354148239e-15 -3.141592653589793116" />
<geometry>
<mesh filename="package:///motorejeacoplecaja.stl"/>
</geometry>
<material name="motorejeacoplecaja_material">
<color rgba="0.26274509803921569651 0.28235294117647058432 0.30196078431372547213 1.0"/>
</material>
</visual>
<collision>
<origin xyz="-4.6837533851373791549e-17 -0.065000000000000474065 -0.023400000000001031086" rpy="3.1415926535897851224 -9.072888763354148239e-15 -3.141592653589793116" />
<geometry>
<mesh filename="package:///motorejeacoplecaja.stl"/>
</geometry>
</collision>
<visual>
<origin xyz="2.5673907444456744997e-16 -0.043745909016608769404 -5.5511151231257827021e-16" rpy="8.9357632949541222883e-15 8.9620368400629350831e-15 4.3120886772756738781e-30" />
<geometry>
<mesh filename="package:///femur.stl"/>
</geometry>
<material name="femur_material">
<color rgba="0.97254901960784312376 0.97254901960784312376 0.97254901960784312376 1.0"/>
</material>
</visual>
<collision>
<origin xyz="2.5673907444456744997e-16 -0.043745909016608769404 -5.5511151231257827021e-16" rpy="8.9357632949541222883e-15 8.9620368400629350831e-15 4.3120886772756738781e-30" />
<geometry>
<mesh filename="package:///femur.stl"/>
</geometry>
</collision>
<visual>
<origin xyz="-4.5102810375396984455e-17 -0.065000000000000474065 -0.023400000000000982514" rpy="3.1415926535897851224 -6.6782745295603302685e-15 -3.141592653589793116" />
<geometry>
<mesh filename="package:///motorejeacopleeje2.stl"/>
</geometry>
<material name="motorejeacopleeje2_material">
<color rgba="0.64705882352941179736 0.64705882352941179736 0.64705882352941179736 1.0"/>
</material>
</visual>
<collision>
<origin xyz="-4.5102810375396984455e-17 -0.065000000000000474065 -0.023400000000000982514" rpy="3.1415926535897851224 -6.6782745295603302685e-15 -3.141592653589793116" />
<geometry>
<mesh filename="package:///motorejeacopleeje2.stl"/>
</geometry>
</collision>
<visual>
<origin xyz="-2.480654570646834145e-16 0 -0.023400000000000163725" rpy="-3.1415926535897722438 -1.4663131591062837822e-16 1.945505961612378521e-30" />
<geometry>
<mesh filename="package:///motorejeacoplecaja.stl"/>
</geometry>
<material name="motorejeacoplecaja_material">
<color rgba="0.26274509803921569651 0.28235294117647058432 0.30196078431372547213 1.0"/>
</material>
</visual>
<collision>
<origin xyz="-2.480654570646834145e-16 0 -0.023400000000000163725" rpy="-3.1415926535897722438 -1.4663131591062837822e-16 1.945505961612378521e-30" />
<geometry>
<mesh filename="package:///motorejeacoplecaja.stl"/>
</geometry>
</collision>
<visual>
<origin xyz="-4.0072112295064243881e-16 -0.043745909016608741648 -0.04880000000000092597" rpy="8.9357632949541222883e-15 8.9620368400629350831e-15 4.3120886772756738781e-30" />
<geometry>
<mesh filename="package:///femur.stl"/>
</geometry>
<material name="femur_material">
<color rgba="0.97254901960784312376 0.97254901960784312376 0.97254901960784312376 1.0"/>
</material>
</visual>
<collision>
<origin xyz="-4.0072112295064243881e-16 -0.043745909016608741648 -0.04880000000000092597" rpy="8.9357632949541222883e-15 8.9620368400629350831e-15 4.3120886772756738781e-30" />
<geometry>
<mesh filename="package:///femur.stl"/>
</geometry>
</collision>
<visual>
<origin xyz="-4.336808689942017736e-17 -0.065000000000000474065 -0.023400000000001044964" rpy="3.1415926535897846783 -9.184431368297370526e-15 -3.141592653589793116" />
<geometry>
<mesh filename="package:///motorejeacopleeje1.stl"/>
</geometry>
<material name="motorejeacopleeje1_material">
<color rgba="0.64705882352941179736 0.64705882352941179736 0.64705882352941179736 1.0"/>
</material>
</visual>
<collision>
<origin xyz="-4.336808689942017736e-17 -0.065000000000000474065 -0.023400000000001044964" rpy="3.1415926535897846783 -9.184431368297370526e-15 -3.141592653589793116" />
<geometry>
<mesh filename="package:///motorejeacopleeje1.stl"/>
</geometry>
</collision>
<inertial>
<origin xyz="-1.3117960147784488728e-16 -0.032500000000000257849 -0.023400000000000663325" rpy="0 0 0"/>
<mass value="0.53868761965446410045" />
<inertia ixx="0.00043791203235394308329" ixy="2.9436638870432294578e-19"  ixz="5.9616897511848644784e-20" iyy="0.00010909446328561783193" iyz="-2.5004412602946946009e-18" izz="0.00036348717125269020857" />
</inertial>
</link>

<link name="tibiaurdf_2">
<visual>
<origin xyz="-0.029224814482181199482 0.016872954508304185972 -1.3877787807814456755e-17" rpy="3.141592653589793116 5.6050809350437909526e-19 1.0471975511965976313" />
<geometry>
<mesh filename="package:///tibia.stl"/>
</geometry>
<material name="tibia_material">
<color rgba="0.97254901960784312376 0.97254901960784312376 0.97254901960784312376 1.0"/>
</material>
</visual>
<collision>
<origin xyz="-0.029224814482181199482 0.016872954508304185972 -1.3877787807814456755e-17" rpy="3.141592653589793116 5.6050809350437909526e-19 1.0471975511965976313" />
<geometry>
<mesh filename="package:///tibia.stl"/>
</geometry>
</collision>
<visual>
<origin xyz="-0.047631397208144604649 0.027500000000000232592 0.023400000000000080458" rpy="-3.141592653589793116 1.111997953713921346e-15 1.0471975511965987415" />
<geometry>
<mesh filename="package:///motorejeacopleeje1.stl"/>
</geometry>
<material name="motorejeacopleeje1_material">
<color rgba="0.64705882352941179736 0.64705882352941179736 0.64705882352941179736 1.0"/>
</material>
</visual>
<collision>
<origin xyz="-0.047631397208144604649 0.027500000000000232592 0.023400000000000080458" rpy="-3.141592653589793116 1.111997953713921346e-15 1.0471975511965987415" />
<geometry>
<mesh filename="package:///motorejeacopleeje1.stl"/>
</geometry>
</collision>
<visual>
<origin xyz="-0.047631397208144576894 0.027500000000000177081 0.023400000000000420464" rpy="3.141592653589793116 -5.410504819638764448e-17 1.0471975511965971872" />
<geometry>
<mesh filename="package:///motorejeacoplecaja.stl"/>
</geometry>
<material name="motorejeacoplecaja_material">
<color rgba="0.26274509803921569651 0.28235294117647058432 0.30196078431372547213 1.0"/>
</material>
</visual>
<collision>
<origin xyz="-0.047631397208144576894 0.027500000000000177081 0.023400000000000420464" rpy="3.141592653589793116 -5.410504819638764448e-17 1.0471975511965971872" />
<geometry>
<mesh filename="package:///motorejeacoplecaja.stl"/>
</geometry>
</collision>
<visual>
<origin xyz="-0.02922481448218108846 0.016872954508304088828 0.048800000000000898215" rpy="3.141592653589793116 -5.757564076921648084e-17 1.0471975511965974093" />
<geometry>
<mesh filename="package:///tibia.stl"/>
</geometry>
<material name="tibia_material">
<color rgba="0.97254901960784312376 0.97254901960784312376 0.97254901960784312376 1.0"/>
</material>
</visual>
<collision>
<origin xyz="-0.02922481448218108846 0.016872954508304088828 0.048800000000000898215" rpy="3.141592653589793116 -5.757564076921648084e-17 1.0471975511965974093" />
<geometry>
<mesh filename="package:///tibia.stl"/>
</geometry>
</collision>
<visual>
<origin xyz="-0.047631397208144354849 0.027500000000000107692 0.023400000000000427403" rpy="-3.141592653589793116 -2.6660924681397790619e-16 1.0471975511965971872" />
<geometry>
<mesh filename="package:///motorejeacopleeje2.stl"/>
</geometry>
<material name="motorejeacopleeje2_material">
<color rgba="0.64705882352941179736 0.64705882352941179736 0.64705882352941179736 1.0"/>
</material>
</visual>
<collision>
<origin xyz="-0.047631397208144354849 0.027500000000000107692 0.023400000000000427403" rpy="-3.141592653589793116 -2.6660924681397790619e-16 1.0471975511965971872" />
<geometry>
<mesh filename="package:///motorejeacopleeje2.stl"/>
</geometry>
</collision>
<inertial>
<origin xyz="-0.037185466647235605742 0.021469039178648879201 0.023400000000000427403" rpy="0 0 0"/>
<mass value="0.28552673687099011657" />
<inertia ixx="7.7012953898991087505e-05" ixy="2.1231284255098419798e-05"  ixz="-2.0879362149818503358e-19" iyy="0.00010152872925694055495" iyz="1.2430208500956857476e-19" izz="6.7501897454920901237e-05" />
</inertial>
</link>

<link name="tobillourdf_2">
<visual>
<origin xyz="0.00014999999999970592413 -0.035799999999999165823 0.023374999999999961781" rpy="-1.57079632679489678 -1.570796326794896558 0" />
<geometry>
<mesh filename="package:///tobillopt3_1.stl"/>
</geometry>
<material name="tobillopt3_1_material">
<color rgba="0.97254901960784312376 0.97254901960784312376 0.97254901960784312376 1.0"/>
</material>
</visual>
<collision>
<origin xyz="0.00014999999999970592413 -0.035799999999999165823 0.023374999999999961781" rpy="-1.57079632679489678 -1.570796326794896558 0" />
<geometry>
<mesh filename="package:///tobillopt3_1.stl"/>
</geometry>
</collision>
<visual>
<origin xyz="1.6653345369377348106e-16 -0.035799999999999970735 0.023550000000000109041" rpy="-1.57079632679489678 -1.570796326794896558 0" />
<geometry>
<mesh filename="package:///tobillopt1.stl"/>
</geometry>
<material name="tobillopt1_material">
<color rgba="0.97254901960784312376 0.97254901960784312376 0.97254901960784312376 1.0"/>
</material>
</visual>
<collision>
<origin xyz="1.6653345369377348106e-16 -0.035799999999999970735 0.023550000000000109041" rpy="-1.57079632679489678 -1.570796326794896558 0" />
<geometry>
<mesh filename="package:///tobillopt1.stl"/>
</geometry>
</collision>
<visual>
<origin xyz="0.00019999999999975592857 -0.025772450770436799994 0.013564015027679132003" rpy="1.5707963267948978903 -1.4839244958867523909e-13 1.5707963267949893726" />
<geometry>
<mesh filename="package:///motorejecaja.stl"/>
</geometry>
<material name="motorejecaja_material">
<color rgba="0.26274509803921569651 0.28235294117647058432 0.30196078431372547213 1.0"/>
</material>
</visual>
<collision>
<origin xyz="0.00019999999999975592857 -0.025772450770436799994 0.013564015027679132003" rpy="1.5707963267948978903 -1.4839244958867523909e-13 1.5707963267949893726" />
<geometry>
<mesh filename="package:///motorejecaja.stl"/>
</geometry>
</collision>
<visual>
<origin xyz="-0.00015000000000006674661 -0.03579999999999949889 0.023374999999999934025" rpy="-1.5707963267948970021 -1.570796326794896336 0" />
<geometry>
<mesh filename="package:///tobillopt3_2.stl"/>
</geometry>
<material name="tobillopt3_2_material">
<color rgba="0.97254901960784312376 0.97254901960784312376 0.97254901960784312376 1.0"/>
</material>
</visual>
<collision>
<origin xyz="-0.00015000000000006674661 -0.03579999999999949889 0.023374999999999934025" rpy="-1.5707963267948970021 -1.570796326794896336 0" />
<geometry>
<mesh filename="package:///tobillopt3_2.stl"/>
</geometry>
</collision>
<visual>
<origin xyz="0.00019999999999975592857 -0.025772450770436799994 0.013564015027679132003" rpy="1.5707963267948978903 -1.4778130662265069636e-13 1.5707963267949898167" />
<geometry>
<mesh filename="package:///motorejeeje2.stl"/>
</geometry>
<material name="motorejeeje2_material">
<color rgba="0.64705882352941179736 0.64705882352941179736 0.64705882352941179736 1.0"/>
</material>
</visual>
<collision>
<origin xyz="0.00019999999999975592857 -0.025772450770436799994 0.013564015027679132003" rpy="1.5707963267948978903 -1.4778130662265069636e-13 1.5707963267949898167" />
<geometry>
<mesh filename="package:///motorejeeje2.stl"/>
</geometry>
</collision>
<visual>
<origin xyz="0.00019999999999975592857 -0.025772450770436799994 0.013564015027679076492" rpy="1.5707963267948972241 -1.6353832254867047002e-13 1.5707963267949929254" />
<geometry>
<mesh filename="package:///motorejeeje1.stl"/>
</geometry>
<material name="motorejeeje1_material">
<color rgba="0.64705882352941179736 0.64705882352941179736 0.64705882352941179736 1.0"/>
</material>
</visual>
<collision>
<origin xyz="0.00019999999999975592857 -0.025772450770436799994 0.013564015027679076492" rpy="1.5707963267948972241 -1.6353832254867047002e-13 1.5707963267949929254" />
<geometry>
<mesh filename="package:///motorejeeje1.stl"/>
</geometry>
</collision>
<visual>
<origin xyz="8.3266726846886740532e-17 -0.035799999999999915223 0.023850000000000006611" rpy="-1.57079632679489678 -1.570796326794896558 0" />
<geometry>
<mesh filename="package:///tobillopt2_2.stl"/>
</geometry>
<material name="tobillopt2_2_material">
<color rgba="0.97254901960784312376 0.97254901960784312376 0.97254901960784312376 1.0"/>
</material>
</visual>
<collision>
<origin xyz="8.3266726846886740532e-17 -0.035799999999999915223 0.023850000000000006611" rpy="-1.57079632679489678 -1.570796326794896558 0" />
<geometry>
<mesh filename="package:///tobillopt2_2.stl"/>
</geometry>
</collision>
<visual>
<origin xyz="0 -0.035799999999999970735 0.023249999999999989425" rpy="-1.57079632679489678 -1.570796326794896558 0" />
<geometry>
<mesh filename="package:///tobillopt2_1.stl"/>
</geometry>
<material name="tobillopt2_1_material">
<color rgba="0.97254901960784312376 0.97254901960784312376 0.97254901960784312376 1.0"/>
</material>
</visual>
<collision>
<origin xyz="0 -0.035799999999999970735 0.023249999999999989425" rpy="-1.57079632679489678 -1.570796326794896558 0" />
<geometry>
<mesh filename="package:///tobillopt2_1.stl"/>
</geometry>
</collision>
<inertial>
<origin xyz="0.0001396574790514245679 -0.025656106121456905 0.023688332336940450679" rpy="0 0 0"/>
<mass value="0.35953278469495453251" />
<inertia ixx="0.00010180132077840424259" ixy="5.841832609753534633e-09"  ixz="5.7602954081961219055e-08" iyy="0.00013007031479290648355" iyz="5.2659589177717664547e-07" izz="7.0605342570129279046e-05" />
</inertial>
</link>

<link name="pieurdf_2">
<visual>
<origin xyz="-0.01000000000000001929 -0.019000000000000016875 0.02340000000000000413" rpy="-1.570796326794896558 -1.570796326794896336 0" />
<geometry>
<mesh filename="package:///acoplepiemotor.stl"/>
</geometry>
<material name="acoplepiemotor_material">
<color rgba="0.97254901960784312376 0.97254901960784312376 0.97254901960784312376 1.0"/>
</material>
</visual>
<collision>
<origin xyz="-0.01000000000000001929 -0.019000000000000016875 0.02340000000000000413" rpy="-1.570796326794896558 -1.570796326794896336 0" />
<geometry>
<mesh filename="package:///acoplepiemotor.stl"/>
</geometry>
</collision>
<visual>
<origin xyz="-0.0099999999999999533706 -0.01899999999999998912 0.023500000000000464961" rpy="-1.570796326794896558 -1.570796326794896336 0" />
<geometry>
<mesh filename="package:///acoplepiemotor.stl"/>
</geometry>
<material name="acoplepiemotor_material">
<color rgba="0.97254901960784312376 0.97254901960784312376 0.97254901960784312376 1.0"/>
</material>
</visual>
<collision>
<origin xyz="-0.0099999999999999533706 -0.01899999999999998912 0.023500000000000464961" rpy="-1.570796326794896558 -1.570796326794896336 0" />
<geometry>
<mesh filename="package:///acoplepiemotor.stl"/>
</geometry>
</collision>
<visual>
<origin xyz="-0.009999999999999932554 -0.018950000000000133404 0.023450000000000442713" rpy="-1.570796326794896558 -1.570796326794896336 0" />
<geometry>
<mesh filename="package:///plantapie.stl"/>
</geometry>
<material name="plantapie_material">
<color rgba="0.97254901960784312376 0.97254901960784312376 0.97254901960784312376 1.0"/>
</material>
</visual>
<collision>
<origin xyz="-0.009999999999999932554 -0.018950000000000133404 0.023450000000000442713" rpy="-1.570796326794896558 -1.570796326794896336 0" />
<geometry>
<mesh filename="package:///plantapie.stl"/>
</geometry>
</collision>
<inertial>
<origin xyz="-0.0095981962877160799386 -0.018994815818902704291 0.023450000000000380262" rpy="0 0 0"/>
<mass value="0.12193030814742024381" />
<inertia ixx="5.5790028401553488078e-05" ixy="-1.0383957421083847412e-06"  ixz="-5.3410475914821106123e-21" iyy="7.8275338616851306548e-05" iyz="5.6651782891039694346e-20" izz="3.3440055653628934014e-05" />
</inertial>
</link>

<joint name="RightAnkle2" type="revolute">
<origin xyz="-0.023200000000000303713 -0.025772450770438881662 0.013564015027679159758" rpy="-1.5707963267949147657 1.5122843990177565754 -1.5707963267948334973" />
<parent link="tobillourdf_2" />
<child link="pieurdf_2" />
<axis xyz="0 0 1"/>
<limit effort="1" velocity="20" lower="-0.26179938779914940783" upper="0.26179938779914940783"/>
<joint_properties friction="0.0"/>
</joint>

<joint name="RightAnkle1" type="revolute">
<origin xyz="-0.047631397208144327093 0.027500000000000093814 0.046800000000000861744" rpy="3.1415926535897922278 -5.3373354253318456839e-16 1.832595714594138725" />
<parent link="tibiaurdf_2" />
<child link="tobillourdf_2" />
<axis xyz="0 0 1"/>
<limit effort="1" velocity="20" lower="-0.785398163397448279" upper="0.52359877559829881566"/>
<joint_properties friction="0.0"/>
</joint>

<joint name="RightKnee" type="revolute">
<origin xyz="2.8449465006019636348e-16 -0.065000000000000363043 -1.0824674490095276269e-15" rpy="3.1415926535897717997 9.8745822879544016264e-15 1.0471975511965985195" />
<parent link="femururdf_2" />
<child link="tibiaurdf_2" />
<axis xyz="0 0 1"/>
<limit effort="1" velocity="20" lower="-1.0471975511965976313" upper="1.0471975511965976313"/>
<joint_properties friction="0.0"/>
</joint>

<joint name="RightHip2" type="revolute">
<origin xyz="0.028027549229562506716 -0.033035984972318972741 -0.023249999999999167166" rpy="1.5707963267949034414 -1.5707963267948585884 0" />
<parent link="cadera_v01_2" />
<child link="femururdf_2" />
<axis xyz="0 0 1"/>
<limit effort="1" velocity="20" lower="-1.570796326794896558" upper="1.570796326794896558"/>
<joint_properties friction="0.0"/>
</joint>

<joint name="RightHip1" type="revolute">
<origin xyz="-0.00061949317509168121132 0.032685236218795189755 -0.023605436102933877174" rpy="-2.3561944901923315143 1.5707963267948703567 0" />
<parent link="cintura_v01_2" />
<child link="cadera_v01_2" />
<axis xyz="0 0 1"/>
<limit effort="1" velocity="20" lower="-0.785398163397448279" upper="0.785398163397448279"/>
<joint_properties friction="0.0"/>
</joint>

<joint name="RightWaist" type="revolute">
<origin xyz="-0.010742981990015255944 0.0083712188771943168986 -0.083178910040700979045" rpy="5.0065502374750631335e-32 4.1312151660743903538e-31 2.3608809754637762879" />
<parent link="torsourdf" />
<child link="cintura_v01_2" />
<axis xyz="0 0 1"/>
<limit effort="1" velocity="20" lower="-1.570796326794896558" upper="1.570796326794896558"/>
<joint_properties friction="0.0"/>
</joint>


</robot>
